Workbook

Sheet Sheet1
B1: \\cenmes\CCE\LeakDetectionTest2\acpLeakDetection1|AcidPlantGasFlowrate_0_0 | D1: \\cenmes\CCE\LeakDetectionTest2\acpLeakDetection1|AmbientTemp_0_0 | F1: \\cenmes\CCE\LeakDetectionTest2\acpLeakDetection1|CircFlow_1_0 | H1: \\cenmes\CCE\LeakDetectionTest2\acpLeakDetection1|CircFlow_2_0 | J1: \\cenmes\CCE\LeakDetectionTest2\acpLeakDetection1|CircPress_1_0 | L1: \\cenmes\CCE\LeakDetectionTest2\acpLeakDetection1|CircPress_2_0 | N1: \\cenmes\CCE\LeakDetectionTest2\acpLeakDetection1|CircPump_1_1 | P1: \\cenmes\CCE\LeakDetectionTest2\acpLeakDetection1|CircPump_2_1 | R1: \\cenmes\CCE\LeakDetectionTest2\acpLeakDetection1|CircPumpCommon_0_1 | T1: \\cenmes\CCE\LeakDetectionTest2\acpLeakDetection1|ConvertorMode_0_0 | V1: \\cenmes\CCE\LeakDetectionTest2\acpLeakDetection1|ExpansionTankLevel_1_0 | X1: \\cenmes\CCE\LeakDetectionTest2\acpLeakDetection1|ExpansionTankLevel_2_0 | Z1: \\cenmes\CCE\LeakDetectionTest2\acpLeakDetection1|FuelCoalCarrierAir_0_0 | AB1: \\cenmes\CCE\LeakDetectionTest2\acpLeakDetection1|FurnaceSuctionPress_1_0 | AD1: \\cenmes\CCE\LeakDetectionTest2\acpLeakDetection1|FurnaceSuctionPress_2_0 | AF1: \\cenmes\CCE\LeakDetectionTest2\acpLeakDetection1|LanceAir_0_0 | AH1: \\cenmes\CCE\LeakDetectionTest2\acpLeakDetection1|LanceCoal_0_0 | AJ1: \\cenmes\CCE\LeakDetectionTest2\acpLeakDetection1|LanceCoalLoss_0_0 | AL1: \\cenmes\CCE\LeakDetectionTest2\acpLeakDetection1|LanceOxygen_0_0 | AN1: \\cenmes\CCE\LeakDetectionTest2\acpLeakDetection1|MakeUpPump005_0_1 | AP1: \\cenmes\CCE\LeakDetectionTest2\acpLeakDetection1|MakeUpPump012_0_1 | AR1: \\cenmes\CCE\LeakDetectionTest2\acpLeakDetection1|MakeupPump30 | AT1: \\cenmes\CCE\LeakDetectionTest2\acpLeakDetection1|MakeupPump60 | AV1: \\cenmes\CCE\LeakDetectionTest2\acpLeakDetection1|MatteCarrierAir_0_0 | AX1: \\cenmes\CCE\LeakDetectionTest2\acpLeakDetection1|MatteFeed_0_0 | AZ1: \\cenmes\CCE\LeakDetectionTest2\acpLeakDetection1|Moisture | BB1: \\cenmes\CCE\LeakDetectionTest2\acpLeakDetection1|Moisture_0_0 | BD1: \\cenmes\CCE\LeakDetectionTest2\acpLeakDetection1|RoofCoalCarrierAir_0_0 | BF1: \\cenmes\CCE\LeakDetectionTest2\acpLeakDetection1|RoofCoalLoss_0_0 | BH1: \\cenmes\CCE\LeakDetectionTest2\acpLeakDetection1|Run | BJ1: \\cenmes\CCE\LeakDetectionTest2\acpLeakDetection1|ShroudAir_0_0 | BL1: \\cenmes\CCE\LeakDetectionTest2\acpLeakDetection1|ShroudOxygen_0_0 | BN1: \\cenmes\CCE\LeakDetectionTest2\acpLeakDetection1|SprayCoolerInletTemp_1_0 | BP1: \\cenmes\CCE\LeakDetectionTest2\acpLeakDetection1|SprayCoolerInletTemp_2_0 | BR1: \\cenmes\CCE\LeakDetectionTest2\acpLeakDetection1|StandbyCoalLoss_0_0
A2: {=_xll.PICompDat(Sheet1!$B$1,"t","*",9,"","inside")} -> #NAME? | B2: #NAME? | C2: {=_xll.PICompDat(Sheet1!$D$1,"t","*",9,"","inside")} -> #NAME? | D2: #NAME? | E2: {=_xll.PICompDat(Sheet1!$F$1,"t","*",9,"","inside")} -> #NAME? | F2: #NAME? | G2: {=_xll.PICompDat(Sheet1!$H$1,"t","*",9,"","inside")} -> #NAME? | H2: #NAME? | I2: {=_xll.PICompDat(Sheet1!$J$1,"t","*",9,"","inside")} -> #NAME? | J2: #NAME? | K2: {=_xll.PICompDat(Sheet1!$L$1,"t","*",9,"","inside")} -> #NAME? | L2: #NAME? | M2: {=_xll.PICompDat(Sheet1!$N$1,"t","*",9,"","inside")} -> #NAME? | N2: #NAME? | O2: {=_xll.PICompDat(Sheet1!$P$1,"t","*",9,"","inside")} -> #NAME? | P2: #NAME? | Q2: {=_xll.PICompDat(Sheet1!$R$1,"t","*",9,"","inside")} -> #NAME? | R2: #NAME? | S2: {=_xll.PICompDat(Sheet1!$T$1,"t","*",9,"","inside")} -> #NAME? | T2: #NAME? | U2: {=_xll.PICompDat(Sheet1!$V$1,"t","*",9,"","inside")} -> #NAME? | V2: #NAME? | W2: {=_xll.PICompDat(Sheet1!$X$1,"t","*",9,"","inside")} -> #NAME? | X2: #NAME? | Y2: {=_xll.PICompDat(Sheet1!$Z$1,"t","*",9,"","inside")} -> #NAME? | Z2: #NAME? | AA2: {=_xll.PICompDat(Sheet1!$AB$1,"t","*",9,"","inside")} -> #NAME? | AB2: #NAME? | AC2: {=_xll.PICompDat(Sheet1!$AD$1,"t","*",9,"","inside")} -> #NAME? | AD2: #NAME? | AE2: {=_xll.PICompDat(Sheet1!$AF$1,"t","*",9,"","inside")} -> #NAME? | AF2: #NAME? | AG2: {=_xll.PICompDat(Sheet1!$AH$1,"t","*",9,"","inside")} -> #NAME? | AH2: #NAME? | AI2: {=_xll.PICompDat(Sheet1!$AJ$1,"t","*",9,"","inside")} -> #NAME? | AJ2: #NAME? | AK2: {=_xll.PICompDat(Sheet1!$AL$1,"t","*",9,"","inside")} -> #NAME? | AL2: #NAME? | AM2: {=_xll.PICompDat(Sheet1!$AN$1,"t","*",9,"","inside")} -> #NAME? | AN2: #NAME? | AO2: {=_xll.PICompDat(Sheet1!$AP$1,"t","*",9,"","inside")} -> #NAME? | AP2: #NAME? | AQ2: {=_xll.PICompDat(Sheet1!$AR$1,"t","*",9,"","inside")} -> #NAME? | AR2: #NAME? | AS2: {=_xll.PICompDat(Sheet1!$AT$1,"t","*",9,"","inside")} -> #NAME? | AT2: #NAME? | AU2: {=_xll.PICompDat(Sheet1!$AV$1,"t","*",9,"","inside")} -> #NAME? | AV2: #NAME? | AW2: {=_xll.PICompDat(Sheet1!$AX$1,"t","*",9,"","inside")} -> #NAME? | AX2: #NAME? | AY2: {=_xll.PICompDat(Sheet1!$AZ$1,"t","*",9,"","inside")} -> #NAME? | AZ2: #NAME? | BA2: {=_xll.PICompDat(Sheet1!$BB$1,"t","*",9,"","inside")} -> #NAME? | BB2: #NAME? | BC2: {=_xll.PICompDat(Sheet1!$BD$1,"t","*",9,"","inside")} -> #NAME? | BD2: #NAME? | BE2: {=_xll.PICompDat(Sheet1!$BF$1,"t","*",9,"","inside")} -> #NAME? | BF2: #NAME? | BG2: {=_xll.PICompDat(Sheet1!$BH$1,"t","*",9,"","inside")} -> #NAME? | BH2: #NAME? | BI2: {=_xll.PICompDat(Sheet1!$BJ$1,"t","*",9,"","inside")} -> #NAME? | BJ2: #NAME? | BK2: {=_xll.PICompDat(Sheet1!$BL$1,"t","*",9,"","inside")} -> #NAME? | BL2: #NAME? | BM2: {=_xll.PICompDat(Sheet1!$BN$1,"t","*",9,"","inside")} -> #NAME? | BN2: #NAME? | BO2: {=_xll.PICompDat(Sheet1!$BP$1,"t","*",9,"","inside")} -> #NAME? | BP2: #NAME? | BQ2: {=_xll.PICompDat(Sheet1!$BR$1,"t","*",9,"","inside")} -> #NAME? | BR2: #NAME?
A3: #NAME? | B3: #NAME? | C3: #NAME? | D3: #NAME? | E3: #NAME? | F3: #NAME? | G3: #NAME? | H3: #NAME? | I3: #NAME? | J3: #NAME? | K3: #NAME? | L3: #NAME? | S3: #NAME? | T3: #NAME? | U3: #NAME? | V3: #NAME? | W3: #NAME? | X3: #NAME? | Y3: #NAME? | Z3: #NAME? | AC3: #NAME? | AD3: #NAME? | AE3: #NAME? | AF3: #NAME? | AG3: #NAME? | AH3: #NAME? | AI3: #NAME? | AJ3: #NAME? | AK3: #NAME? | AL3: #NAME? | AM3: #NAME? | AN3: #NAME? | AO3: #NAME? | AP3: #NAME? | AQ3: #NAME? | AR3: #NAME? | AS3: #NAME? | AT3: #NAME? | AU3: #NAME? | AV3: #NAME? | AW3: #NAME? | AX3: #NAME? | AY3: #NAME? | AZ3: #NAME? | BC3: #NAME? | BD3: #NAME? | BE3: #NAME? | BF3: #NAME? | BG3: #NAME? | BH3: #NAME? | BI3: #NAME? | BJ3: #NAME? | BK3: #NAME? | BL3: #NAME? | BM3: #NAME? | BN3: #NAME? | BO3: #NAME? | BP3: #NAME?
A4: #NAME? | B4: #NAME? | C4: #NAME? | D4: #NAME? | E4: #NAME? | F4: #NAME? | G4: #NAME? | H4: #NAME? | I4: #NAME? | J4: #NAME? | K4: #NAME? | L4: #NAME? | S4: #NAME? | T4: #NAME? | U4: #NAME? | V4: #NAME? | W4: #NAME? | X4: #NAME? | Y4: #NAME? | Z4: #NAME? | AC4: #NAME? | AD4: #NAME? | AE4: #NAME? | AF4: #NAME? | AG4: #NAME? | AH4: #NAME? | AI4: #NAME? | AJ4: #NAME? | AK4: #NAME? | AL4: #NAME? | AM4: #NAME? | AN4: #NAME? | AO4: #NAME? | AP4: #NAME? | AQ4: #NAME? | AR4: #NAME? | AS4: #NAME? | AT4: #NAME? | AU4: #NAME? | AV4: #NAME? | AW4: #NAME? | AX4: #NAME? | AY4: #NAME? | AZ4: #NAME? | BC4: #NAME? | BD4: #NAME? | BE4: #NAME? | BF4: #NAME? | BG4: #NAME? | BH4: #NAME? | BI4: #NAME? | BJ4: #NAME? | BK4: #NAME? | BL4: #NAME? | BM4: #NAME? | BN4: #NAME? | BO4: #NAME? | BP4: #NAME?
A5: #NAME? | B5: #NAME? | C5: #NAME? | D5: #NAME? | E5: #NAME? | F5: #NAME? | G5: #NAME? | H5: #NAME? | I5: #NAME? | J5: #NAME? | K5: #NAME? | L5: #NAME? | S5: #NAME? | T5: #NAME? | U5: #NAME? | V5: #NAME? | W5: #NAME? | X5: #NAME? | Y5: #NAME? | Z5: #NAME? | AC5: #NAME? | AD5: #NAME? | AE5: #NAME? | AF5: #NAME? | AG5: #NAME? | AH5: #NAME? | AI5: #NAME? | AJ5: #NAME? | AK5: #NAME? | AL5: #NAME? | AO5: #NAME? | AP5: #NAME? | AQ5: #NAME? | AR5: #NAME? | AS5: #NAME? | AT5: #NAME? | AU5: #NAME? | AV5: #NAME? | AW5: #NAME? | AX5: #NAME? | AY5: #NAME? | AZ5: #NAME? | BC5: #NAME? | BD5: #NAME? | BE5: #NAME? | BF5: #NAME? | BI5: #NAME? | BJ5: #NAME? | BK5: #NAME? | BL5: #NAME? | BM5: #NAME? | BN5: #NAME? | BO5: #NAME? | BP5: #NAME?
A6: #NAME? | B6: #NAME? | C6: #NAME? | D6: #NAME? | E6: #NAME? | F6: #NAME? | G6: #NAME? | H6: #NAME? | I6: #NAME? | J6: #NAME? | K6: #NAME? | L6: #NAME? | S6: #NAME? | T6: #NAME? | U6: #NAME? | V6: #NAME? | W6: #NAME? | X6: #NAME? | Y6: #NAME? | Z6: #NAME? | AC6: #NAME? | AD6: #NAME? | AE6: #NAME? | AF6: #NAME? | AG6: #NAME? | AH6: #NAME? | AI6: #NAME? | AJ6: #NAME? | AK6: #NAME? | AL6: #NAME? | AO6: #NAME? | AP6: #NAME? | AQ6: #NAME? | AR6: #NAME? | AS6: #NAME? | AT6: #NAME? | AU6: #NAME? | AV6: #NAME? | AW6: #NAME? | AX6: #NAME? | AY6: #NAME? | AZ6: #NAME? | BC6: #NAME? | BD6: #NAME? | BE6: #NAME? | BF6: #NAME? | BI6: #NAME? | BJ6: #NAME? | BK6: #NAME? | BL6: #NAME? | BM6: #NAME? | BN6: #NAME? | BO6: #NAME? | BP6: #NAME?
A7: #NAME? | B7: #NAME? | C7: #NAME? | D7: #NAME? | E7: #NAME? | F7: #NAME? | G7: #NAME? | H7: #NAME? | I7: #NAME? | J7: #NAME? | K7: #NAME? | L7: #NAME? | U7: #NAME? | V7: #NAME? | W7: #NAME? | X7: #NAME? | Y7: #NAME? | Z7: #NAME? | AC7: #NAME? | AD7: #NAME? | AE7: #NAME? | AF7: #NAME? | AG7: #NAME? | AH7: #NAME? | AI7: #NAME? | AJ7: #NAME? | AK7: #NAME? | AL7: #NAME? | AQ7: #NAME? | AR7: #NAME? | AS7: #NAME? | AT7: #NAME? | AU7: #NAME? | AV7: #NAME? | AW7: #NAME? | AX7: #NAME? | AY7: #NAME? | AZ7: #NAME? | BC7: #NAME? | BD7: #NAME? | BE7: #NAME? | BF7: #NAME? | BI7: #NAME? | BJ7: #NAME? | BK7: #NAME? | BL7: #NAME? | BM7: #NAME? | BN7: #NAME? | BO7: #NAME? | BP7: #NAME?
A8: #NAME? | B8: #NAME? | C8: #NAME? | D8: #NAME? | E8: #NAME? | F8: #NAME? | G8: #NAME? | H8: #NAME? | I8: #NAME? | J8: #NAME? | K8: #NAME? | L8: #NAME? | U8: #NAME? | V8: #NAME? | W8: #NAME? | X8: #NAME? | Y8: #NAME? | Z8: #NAME? | AC8: #NAME? | AD8: #NAME? | AE8: #NAME? | AF8: #NAME? | AG8: #NAME? | AH8: #NAME? | AI8: #NAME? | AJ8: #NAME? | AK8: #NAME? | AL8: #NAME? | AQ8: #NAME? | AR8: #NAME? | AS8: #NAME? | AT8: #NAME? | AU8: #NAME? | AV8: #NAME? | AW8: #NAME? | AX8: #NAME? | AY8: #NAME? | AZ8: #NAME? | BC8: #NAME? | BD8: #NAME? | BE8: #NAME? | BF8: #NAME? | BI8: #NAME? | BJ8: #NAME? | BK8: #NAME? | BL8: #NAME? | BM8: #NAME? | BN8: #NAME? | BO8: #NAME? | BP8: #NAME?
A9: #NAME? | B9: #NAME? | C9: #NAME? | D9: #NAME? | E9: #NAME? | F9: #NAME? | G9: #NAME? | H9: #NAME? | I9: #NAME? | J9: #NAME? | K9: #NAME? | L9: #NAME? | U9: #NAME? | V9: #NAME? | W9: #NAME? | X9: #NAME? | Y9: #NAME? | Z9: #NAME? | AC9: #NAME? | AD9: #NAME? | AE9: #NAME? | AF9: #NAME? | AG9: #NAME? | AH9: #NAME? | AI9: #NAME? | AJ9: #NAME? | AK9: #NAME? | AL9: #NAME? | AQ9: #NAME? | AR9: #NAME? | AS9: #NAME? | AT9: #NAME? | AU9: #NAME? | AV9: #NAME? | AW9: #NAME? | AX9: #NAME? | AY9: #NAME? | AZ9: #NAME? | BC9: #NAME? | BD9: #NAME? | BE9: #NAME? | BF9: #NAME? | BI9: #NAME? | BJ9: #NAME? | BK9: #NAME? | BL9: #NAME? | BM9: #NAME? | BN9: #NAME? | BO9: #NAME? | BP9: #NAME?
A10: #NAME? | B10: #NAME? | C10: #NAME? | D10: #NAME? | E10: #NAME? | F10: #NAME? | G10: #NAME? | H10: #NAME? | I10: #NAME? | J10: #NAME? | K10: #NAME? | L10: #NAME? | U10: #NAME? | V10: #NAME? | W10: #NAME? | X10: #NAME? | Y10: #NAME? | Z10: #NAME? | AC10: #NAME? | AD10: #NAME? | AE10: #NAME? | AF10: #NAME? | AG10: #NAME? | AH10: #NAME? | AI10: #NAME? | AJ10: #NAME? | AK10: #NAME? | AL10: #NAME? | AQ10: #NAME? | AR10: #NAME? | AS10: #NAME? | AT10: #NAME? | AU10: #NAME? | AV10: #NAME? | AW10: #NAME? | AX10: #NAME? | AY10: #NAME? | AZ10: #NAME? | BC10: #NAME? | BD10: #NAME? | BE10: #NAME? | BF10: #NAME? | BI10: #NAME? | BJ10: #NAME? | BK10: #NAME? | BL10: #NAME? | BM10: #NAME? | BN10: #NAME? | BO10: #NAME? | BP10: #NAME?
A11: #NAME? | B11: #NAME? | C11: #NAME? | D11: #NAME? | E11: #NAME? | F11: #NAME? | G11: #NAME? | H11: #NAME? | I11: #NAME? | J11: #NAME? | K11: #NAME? | L11: #NAME? | U11: #NAME? | V11: #NAME? | W11: #NAME? | X11: #NAME? | Y11: #NAME? | Z11: #NAME? | AC11: #NAME? | AD11: #NAME? | AE11: #NAME? | AF11: #NAME? | AG11: #NAME? | AH11: #NAME? | AI11: #NAME? | AJ11: #NAME? | AK11: #NAME? | AL11: #NAME? | AQ11: #NAME? | AR11: #NAME? | AS11: #NAME? | AT11: #NAME? | AU11: #NAME? | AV11: #NAME? | AW11: #NAME? | AX11: #NAME? | AY11: #NAME? | AZ11: #NAME? | BC11: #NAME? | BD11: #NAME? | BE11: #NAME? | BF11: #NAME? | BI11: #NAME? | BJ11: #NAME? | BK11: #NAME? | BL11: #NAME? | BM11: #NAME? | BN11: #NAME? | BO11: #NAME? | BP11: #NAME?
A12: #NAME? | B12: #NAME? | C12: #NAME? | D12: #NAME? | E12: #NAME? | F12: #NAME? | G12: #NAME? | H12: #NAME? | I12: #NAME? | J12: #NAME? | K12: #NAME? | L12: #NAME? | U12: #NAME? | V12: #NAME? | W12: #NAME? | X12: #NAME? | Y12: #NAME? | Z12: #NAME? | AC12: #NAME? | AD12: #NAME? | AE12: #NAME? | AF12: #NAME? | AG12: #NAME? | AH12: #NAME? | AI12: #NAME? | AJ12: #NAME? | AK12: #NAME? | AL12: #NAME? | AQ12: #NAME? | AR12: #NAME? | AS12: #NAME? | AT12: #NAME? | AU12: #NAME? | AV12: #NAME? | AW12: #NAME? | AX12: #NAME? | AY12: #NAME? | AZ12: #NAME? | BC12: #NAME? | BD12: #NAME? | BE12: #NAME? | BF12: #NAME? | BI12: #NAME? | BJ12: #NAME? | BK12: #NAME? | BL12: #NAME? | BM12: #NAME? | BN12: #NAME? | BO12: #NAME? | BP12: #NAME?
A13: #NAME? | B13: #NAME? | C13: #NAME? | D13: #NAME? | E13: #NAME? | F13: #NAME? | G13: #NAME? | H13: #NAME? | I13: #NAME? | J13: #NAME? | K13: #NAME? | L13: #NAME? | U13: #NAME? | V13: #NAME? | W13: #NAME? | X13: #NAME? | Y13: #NAME? | Z13: #NAME? | AC13: #NAME? | AD13: #NAME? | AE13: #NAME? | AF13: #NAME? | AG13: #NAME? | AH13: #NAME? | AI13: #NAME? | AJ13: #NAME? | AK13: #NAME? | AL13: #NAME? | AQ13: #NAME? | AR13: #NAME? | AS13: #NAME? | AT13: #NAME? | AU13: #NAME? | AV13: #NAME? | AW13: #NAME? | AX13: #NAME? | AY13: #NAME? | AZ13: #NAME? | BC13: #NAME? | BD13: #NAME? | BE13: #NAME? | BF13: #NAME? | BI13: #NAME? | BJ13: #NAME? | BK13: #NAME? | BL13: #NAME? | BM13: #NAME? | BN13: #NAME? | BO13: #NAME? | BP13: #NAME?
A14: #NAME? | B14: #NAME? | C14: #NAME? | D14: #NAME? | E14: #NAME? | F14: #NAME? | G14: #NAME? | H14: #NAME? | I14: #NAME? | J14: #NAME? | K14: #NAME? | L14: #NAME? | U14: #NAME? | V14: #NAME? | W14: #NAME? | X14: #NAME? | Y14: #NAME? | Z14: #NAME? | AC14: #NAME? | AD14: #NAME? | AE14: #NAME? | AF14: #NAME? | AG14: #NAME? | AH14: #NAME? | AI14: #NAME? | AJ14: #NAME? | AK14: #NAME? | AL14: #NAME? | AQ14: #NAME? | AR14: #NAME? | AS14: #NAME? | AT14: #NAME? | AU14: #NAME? | AV14: #NAME? | AW14: #NAME? | AX14: #NAME? | AY14: #NAME? | AZ14: #NAME? | BC14: #NAME? | BD14: #NAME? | BE14: #NAME? | BF14: #NAME? | BI14: #NAME? | BJ14: #NAME? | BK14: #NAME? | BL14: #NAME? | BM14: #NAME? | BN14: #NAME? | BO14: #NAME? | BP14: #NAME?
A15: #NAME? | B15: #NAME? | C15: #NAME? | D15: #NAME? | E15: #NAME? | F15: #NAME? | G15: #NAME? | H15: #NAME? | I15: #NAME? | J15: #NAME? | K15: #NAME? | L15: #NAME? | U15: #NAME? | V15: #NAME? | W15: #NAME? | X15: #NAME? | Y15: #NAME? | Z15: #NAME? | AC15: #NAME? | AD15: #NAME? | AE15: #NAME? | AF15: #NAME? | AG15: #NAME? | AH15: #NAME? | AI15: #NAME? | AJ15: #NAME? | AK15: #NAME? | AL15: #NAME? | AU15: #NAME? | AV15: #NAME? | AW15: #NAME? | AX15: #NAME? | AY15: #NAME? | AZ15: #NAME? | BC15: #NAME? | BD15: #NAME? | BE15: #NAME? | BF15: #NAME? | BI15: #NAME? | BJ15: #NAME? | BK15: #NAME? | BL15: #NAME? | BM15: #NAME? | BN15: #NAME? | BO15: #NAME? | BP15: #NAME?
A16: #NAME? | B16: #NAME? | C16: #NAME? | D16: #NAME? | E16: #NAME? | F16: #NAME? | G16: #NAME? | H16: #NAME? | I16: #NAME? | J16: #NAME? | K16: #NAME? | L16: #NAME? | U16: #NAME? | V16: #NAME? | W16: #NAME? | X16: #NAME? | Y16: #NAME? | Z16: #NAME? | AC16: #NAME? | AD16: #NAME? | AE16: #NAME? | AF16: #NAME? | AG16: #NAME? | AH16: #NAME? | AI16: #NAME? | AJ16: #NAME? | AK16: #NAME? | AL16: #NAME? | AU16: #NAME? | AV16: #NAME? | AW16: #NAME? | AX16: #NAME? | AY16: #NAME? | AZ16: #NAME? | BC16: #NAME? | BD16: #NAME? | BE16: #NAME? | BF16: #NAME? | BI16: #NAME? | BJ16: #NAME? | BK16: #NAME? | BL16: #NAME? | BM16: #NAME? | BN16: #NAME? | BO16: #NAME? | BP16: #NAME?
A17: #NAME? | B17: #NAME? | C17: #NAME? | D17: #NAME? | E17: #NAME? | F17: #NAME? | G17: #NAME? | H17: #NAME? | I17: #NAME? | J17: #NAME? | K17: #NAME? | L17: #NAME? | U17: #NAME? | V17: #NAME? | W17: #NAME? | X17: #NAME? | Y17: #NAME? | Z17: #NAME? | AC17: #NAME? | AD17: #NAME? | AE17: #NAME? | AF17: #NAME? | AG17: #NAME? | AH17: #NAME? | AI17: #NAME? | AJ17: #NAME? | AK17: #NAME? | AL17: #NAME? | AU17: #NAME? | AV17: #NAME? | AW17: #NAME? | AX17: #NAME? | AY17: #NAME? | AZ17: #NAME? | BC17: #NAME? | BD17: #NAME? | BE17: #NAME? | BF17: #NAME? | BI17: #NAME? | BJ17: #NAME? | BK17: #NAME? | BL17: #NAME? | BM17: #NAME? | BN17: #NAME? | BO17: #NAME? | BP17: #NAME?
A18: #NAME? | B18: #NAME? | C18: #NAME? | D18: #NAME? | E18: #NAME? | F18: #NAME? | G18: #NAME? | H18: #NAME? | I18: #NAME? | J18: #NAME? | K18: #NAME? | L18: #NAME? | U18: #NAME? | V18: #NAME? | W18: #NAME? | X18: #NAME? | Y18: #NAME? | Z18: #NAME? | AC18: #NAME? | AD18: #NAME? | AE18: #NAME? | AF18: #NAME? | AG18: #NAME? | AH18: #NAME? | AI18: #NAME? | AJ18: #NAME? | AK18: #NAME? | AL18: #NAME? | AU18: #NAME? | AV18: #NAME? | AW18: #NAME? | AX18: #NAME? | AY18: #NAME? | AZ18: #NAME? | BC18: #NAME? | BD18: #NAME? | BE18: #NAME? | BF18: #NAME? | BI18: #NAME? | BJ18: #NAME? | BK18: #NAME? | BL18: #NAME? | BM18: #NAME? | BN18: #NAME? | BO18: #NAME? | BP18: #NAME?
A19: #NAME? | B19: #NAME? | C19: #NAME? | D19: #NAME? | E19: #NAME? | F19: #NAME? | G19: #NAME? | H19: #NAME? | I19: #NAME? | J19: #NAME? | K19: #NAME? | L19: #NAME? | U19: #NAME? | V19: #NAME? | W19: #NAME? | X19: #NAME? | Y19: #NAME? | Z19: #NAME? | AC19: #NAME? | AD19: #NAME? | AE19: #NAME? | AF19: #NAME? | AG19: #NAME? | AH19: #NAME? | AI19: #NAME? | AJ19: #NAME? | AK19: #NAME? | AL19: #NAME? | AU19: #NAME? | AV19: #NAME? | AW19: #NAME? | AX19: #NAME? | AY19: #NAME? | AZ19: #NAME? | BC19: #NAME? | BD19: #NAME? | BE19: #NAME? | BF19: #NAME? | BI19: #NAME? | BJ19: #NAME? | BK19: #NAME? | BL19: #NAME? | BM19: #NAME? | BN19: #NAME? | BO19: #NAME? | BP19: #NAME?
A20: #NAME? | B20: #NAME? | C20: #NAME? | D20: #NAME? | E20: #NAME? | F20: #NAME? | G20: #NAME? | H20: #NAME? | I20: #NAME? | J20: #NAME? | K20: #NAME? | L20: #NAME? | U20: #NAME? | V20: #NAME? | W20: #NAME? | X20: #NAME? | Y20: #NAME? | Z20: #NAME? | AC20: #NAME? | AD20: #NAME? | AE20: #NAME? | AF20: #NAME? | AG20: #NAME? | AH20: #NAME? | AI20: #NAME? | AJ20: #NAME? | AK20: #NAME? | AL20: #NAME? | AU20: #NAME? | AV20: #NAME? | AW20: #NAME? | AX20: #NAME? | AY20: #NAME? | AZ20: #NAME? | BC20: #NAME? | BD20: #NAME? | BE20: #NAME? | BF20: #NAME? | BI20: #NAME? | BJ20: #NAME? | BK20: #NAME? | BL20: #NAME? | BM20: #NAME? | BN20: #NAME? | BO20: #NAME? | BP20: #NAME?
A21: #NAME? | B21: #NAME? | C21: #NAME? | D21: #NAME? | E21: #NAME? | F21: #NAME? | G21: #NAME? | H21: #NAME? | I21: #NAME? | J21: #NAME? | K21: #NAME? | L21: #NAME? | U21: #NAME? | V21: #NAME? | W21: #NAME? | X21: #NAME? | Y21: #NAME? | Z21: #NAME? | AC21: #NAME? | AD21: #NAME? | AE21: #NAME? | AF21: #NAME? | AG21: #NAME? | AH21: #NAME? | AI21: #NAME? | AJ21: #NAME? | AK21: #NAME? | AL21: #NAME? | AU21: #NAME? | AV21: #NAME? | AW21: #NAME? | AX21: #NAME? | AY21: #NAME? | AZ21: #NAME? | BC21: #NAME? | BD21: #NAME? | BE21: #NAME? | BF21: #NAME? | BI21: #NAME? | BJ21: #NAME? | BK21: #NAME? | BL21: #NAME? | BM21: #NAME? | BN21: #NAME? | BO21: #NAME? | BP21: #NAME?
A22: #NAME? | B22: #NAME? | C22: #NAME? | D22: #NAME? | E22: #NAME? | F22: #NAME? | G22: #NAME? | H22: #NAME? | I22: #NAME? | J22: #NAME? | K22: #NAME? | L22: #NAME? | U22: #NAME? | V22: #NAME? | W22: #NAME? | X22: #NAME? | Y22: #NAME? | Z22: #NAME? | AC22: #NAME? | AD22: #NAME? | AE22: #NAME? | AF22: #NAME? | AG22: #NAME? | AH22: #NAME? | AI22: #NAME? | AJ22: #NAME? | AK22: #NAME? | AL22: #NAME? | AU22: #NAME? | AV22: #NAME? | AW22: #NAME? | AX22: #NAME? | AY22: #NAME? | AZ22: #NAME? | BC22: #NAME? | BD22: #NAME? | BE22: #NAME? | BF22: #NAME? | BI22: #NAME? | BJ22: #NAME? | BK22: #NAME? | BL22: #NAME? | BM22: #NAME? | BN22: #NAME? | BO22: #NAME? | BP22: #NAME?
A23: #NAME? | B23: #NAME? | C23: #NAME? | D23: #NAME? | E23: #NAME? | F23: #NAME? | G23: #NAME? | H23: #NAME? | I23: #NAME? | J23: #NAME? | K23: #NAME? | L23: #NAME? | U23: #NAME? | V23: #NAME? | W23: #NAME? | X23: #NAME? | Y23: #NAME? | Z23: #NAME? | AC23: #NAME? | AD23: #NAME? | AE23: #NAME? | AF23: #NAME? | AG23: #NAME? | AH23: #NAME? | AI23: #NAME? | AJ23: #NAME? | AK23: #NAME? | AL23: #NAME? | AU23: #NAME? | AV23: #NAME? | AW23: #NAME? | AX23: #NAME? | AY23: #NAME? | AZ23: #NAME? | BC23: #NAME? | BD23: #NAME? | BE23: #NAME? | BF23: #NAME? | BI23: #NAME? | BJ23: #NAME? | BK23: #NAME? | BL23: #NAME? | BM23: #NAME? | BN23: #NAME? | BO23: #NAME? | BP23: #NAME?
A24: #NAME? | B24: #NAME? | C24: #NAME? | D24: #NAME? | E24: #NAME? | F24: #NAME? | G24: #NAME? | H24: #NAME? | I24: #NAME? | J24: #NAME? | K24: #NAME? | L24: #NAME? | U24: #NAME? | V24: #NAME? | W24: #NAME? | X24: #NAME? | Y24: #NAME? | Z24: #NAME? | AC24: #NAME? | AD24: #NAME? | AE24: #NAME? | AF24: #NAME? | AG24: #NAME? | AH24: #NAME? | AI24: #NAME? | AJ24: #NAME? | AK24: #NAME? | AL24: #NAME? | AU24: #NAME? | AV24: #NAME? | AW24: #NAME? | AX24: #NAME? | AY24: #NAME? | AZ24: #NAME? | BC24: #NAME? | BD24: #NAME? | BE24: #NAME? | BF24: #NAME? | BI24: #NAME? | BJ24: #NAME? | BK24: #NAME? | BL24: #NAME? | BM24: #NAME? | BN24: #NAME? | BO24: #NAME? | BP24: #NAME?
A25: #NAME? | B25: #NAME? | C25: #NAME? | D25: #NAME? | E25: #NAME? | F25: #NAME? | G25: #NAME? | H25: #NAME? | I25: #NAME? | J25: #NAME? | K25: #NAME? | L25: #NAME? | U25: #NAME? | V25: #NAME? | W25: #NAME? | X25: #NAME? | Y25: #NAME? | Z25: #NAME? | AC25: #NAME? | AD25: #NAME? | AE25: #NAME? | AF25: #NAME? | AG25: #NAME? | AH25: #NAME? | AI25: #NAME? | AJ25: #NAME? | AK25: #NAME? | AL25: #NAME? | AU25: #NAME? | AV25: #NAME? | AW25: #NAME? | AX25: #NAME? | AY25: #NAME? | AZ25: #NAME? | BC25: #NAME? | BD25: #NAME? | BE25: #NAME? | BF25: #NAME? | BI25: #NAME? | BJ25: #NAME? | BK25: #NAME? | BL25: #NAME? | BM25: #NAME? | BN25: #NAME? | BO25: #NAME? | BP25: #NAME?
A26: #NAME? | B26: #NAME? | C26: #NAME? | D26: #NAME? | E26: #NAME? | F26: #NAME? | G26: #NAME? | H26: #NAME? | I26: #NAME? | J26: #NAME? | K26: #NAME? | L26: #NAME? | U26: #NAME? | V26: #NAME? | W26: #NAME? | X26: #NAME? | Y26: #NAME? | Z26: #NAME? | AC26: #NAME? | AD26: #NAME? | AE26: #NAME? | AF26: #NAME? | AG26: #NAME? | AH26: #NAME? | AI26: #NAME? | AJ26: #NAME? | AK26: #NAME? | AL26: #NAME? | AU26: #NAME? | AV26: #NAME? | AW26: #NAME? | AX26: #NAME? | AY26: #NAME? | AZ26: #NAME? | BC26: #NAME? | BD26: #NAME? | BE26: #NAME? | BF26: #NAME? | BI26: #NAME? | BJ26: #NAME? | BK26: #NAME? | BL26: #NAME? | BM26: #NAME? | BN26: #NAME? | BO26: #NAME? | BP26: #NAME?
... A91: #NAME? | B91: #NAME? | C91: #NAME? | D91: #NAME? | E91: #NAME? | F91: #NAME? | G91: #NAME? | H91: #NAME? | I91: #NAME? | J91: #NAME? | K91: #NAME? | L91: #NAME? | U91: #NAME? | V91: #NAME? | W91: #NAME? | X91: #NAME? | Y91: #NAME? | Z91: #NAME? | AC91: #NAME? | AD91: #NAME? | AE91: #NAME? | AF91: #NAME? | AG91: #NAME? | AH91: #NAME? | AI91: #NAME? | AJ91: #NAME? | AK91: #NAME? | AL91: #NAME? | AU91: #NAME? | AV91: #NAME? | AW91: #NAME? | AX91: #NAME? | AY91: #NAME? | AZ91: #NAME? | BC91: #NAME? | BD91: #NAME? | BE91: #NAME? | BF91: #NAME? | BI91: #NAME? | BJ91: #NAME? | BK91: #NAME? | BL91: #NAME? | BM91: #NAME? | BN91: #NAME? | BO91: #NAME? | BP91: #NAME?
A92: #NAME? | B92: #NAME? | C92: #NAME? | D92: #NAME? | E92: #NAME? | F92: #NAME? | G92: #NAME? | H92: #NAME? | I92: #NAME? | J92: #NAME? | K92: #NAME? | L92: #NAME? | U92: #NAME? | V92: #NAME? | W92: #NAME? | X92: #NAME? | Y92: #NAME? | Z92: #NAME? | AC92: #NAME? | AD92: #NAME? | AE92: #NAME? | AF92: #NAME? | AI92: #NAME? | AJ92: #NAME? | AK92: #NAME? | AL92: #NAME? | AU92: #NAME? | AV92: #NAME? | AW92: #NAME? | AX92: #NAME? | AY92: #NAME? | AZ92: #NAME? | BC92: #NAME? | BD92: #NAME? | BE92: #NAME? | BF92: #NAME? | BI92: #NAME? | BJ92: #NAME? | BK92: #NAME? | BL92: #NAME? | BM92: #NAME? | BN92: #NAME? | BO92: #NAME? | BP92: #NAME?
A93: #NAME? | B93: #NAME? | C93: #NAME? | D93: #NAME? | E93: #NAME? | F93: #NAME? | G93: #NAME? | H93: #NAME? | I93: #NAME? | J93: #NAME? | K93: #NAME? | L93: #NAME? | U93: #NAME? | V93: #NAME? | W93: #NAME? | X93: #NAME? | Y93: #NAME? | Z93: #NAME? | AC93: #NAME? | AD93: #NAME? | AE93: #NAME? | AF93: #NAME? | AI93: #NAME? | AJ93: #NAME? | AK93: #NAME? | AL93: #NAME? | AU93: #NAME? | AV93: #NAME? | AW93: #NAME? | AX93: #NAME? | AY93: #NAME? | AZ93: #NAME? | BC93: #NAME? | BD93: #NAME? | BE93: #NAME? | BF93: #NAME? | BI93: #NAME? | BJ93: #NAME? | BK93: #NAME? | BL93: #NAME? | BM93: #NAME? | BN93: #NAME? | BO93: #NAME? | BP93: #NAME?
A94: #NAME? | B94: #NAME? | C94: #NAME? | D94: #NAME? | E94: #NAME? | F94: #NAME? | G94: #NAME? | H94: #NAME? | I94: #NAME? | J94: #NAME? | K94: #NAME? | L94: #NAME? | U94: #NAME? | V94: #NAME? | W94: #NAME? | X94: #NAME? | Y94: #NAME? | Z94: #NAME? | AC94: #NAME? | AD94: #NAME? | AE94: #NAME? | AF94: #NAME? | AI94: #NAME? | AJ94: #NAME? | AK94: #NAME? | AL94: #NAME? | AU94: #NAME? | AV94: #NAME? | AW94: #NAME? | AX94: #NAME? | AY94: #NAME? | AZ94: #NAME? | BC94: #NAME? | BD94: #NAME? | BE94: #NAME? | BF94: #NAME? | BI94: #NAME? | BJ94: #NAME? | BK94: #NAME? | BL94: #NAME? | BM94: #NAME? | BN94: #NAME? | BO94: #NAME? | BP94: #NAME?
A95: #NAME? | B95: #NAME? | C95: #NAME? | D95: #NAME? | E95: #NAME? | F95: #NAME? | G95: #NAME? | H95: #NAME? | I95: #NAME? | J95: #NAME? | K95: #NAME? | L95: #NAME? | U95: #NAME? | V95: #NAME? | W95: #NAME? | X95: #NAME? | Y95: #NAME? | Z95: #NAME? | AC95: #NAME? | AD95: #NAME? | AE95: #NAME? | AF95: #NAME? | AI95: #NAME? | AJ95: #NAME? | AK95: #NAME? | AL95: #NAME? | AU95: #NAME? | AV95: #NAME? | AW95: #NAME? | AX95: #NAME? | AY95: #NAME? | AZ95: #NAME? | BC95: #NAME? | BD95: #NAME? | BE95: #NAME? | BF95: #NAME? | BI95: #NAME? | BJ95: #NAME? | BK95: #NAME? | BL95: #NAME? | BM95: #NAME? | BN95: #NAME? | BO95: #NAME? | BP95: #NAME?
A96: #NAME? | B96: #NAME? | C96: #NAME? | D96: #NAME? | E96: #NAME? | F96: #NAME? | G96: #NAME? | H96: #NAME? | I96: #NAME? | J96: #NAME? | K96: #NAME? | L96: #NAME? | U96: #NAME? | V96: #NAME? | W96: #NAME? | X96: #NAME? | Y96: #NAME? | Z96: #NAME? | AC96: #NAME? | AD96: #NAME? | AE96: #NAME? | AF96: #NAME? | AI96: #NAME? | AJ96: #NAME? | AK96: #NAME? | AL96: #NAME? | AU96: #NAME? | AV96: #NAME? | AW96: #NAME? | AX96: #NAME? | AY96: #NAME? | AZ96: #NAME? | BC96: #NAME? | BD96: #NAME? | BE96: #NAME? | BF96: #NAME? | BI96: #NAME? | BJ96: #NAME? | BK96: #NAME? | BL96: #NAME? | BM96: #NAME? | BN96: #NAME? | BO96: #NAME? | BP96: #NAME?
A97: #NAME? | B97: #NAME? | C97: #NAME? | D97: #NAME? | E97: #NAME? | F97: #NAME? | G97: #NAME? | H97: #NAME? | I97: #NAME? | J97: #NAME? | K97: #NAME? | L97: #NAME? | U97: #NAME? | V97: #NAME? | W97: #NAME? | X97: #NAME? | Y97: #NAME? | Z97: #NAME? | AC97: #NAME? | AD97: #NAME? | AE97: #NAME? | AF97: #NAME? | AI97: #NAME? | AJ97: #NAME? | AK97: #NAME? | AL97: #NAME? | AU97: #NAME? | AV97: #NAME? | AW97: #NAME? | AX97: #NAME? | AY97: #NAME? | AZ97: #NAME? | BC97: #NAME? | BD97: #NAME? | BE97: #NAME? | BF97: #NAME? | BI97: #NAME? | BJ97: #NAME? | BK97: #NAME? | BL97: #NAME? | BM97: #NAME? | BN97: #NAME? | BO97: #NAME? | BP97: #NAME?
A98: #NAME? | B98: #NAME? | C98: #NAME? | D98: #NAME? | E98: #NAME? | F98: #NAME? | G98: #NAME? | H98: #NAME? | I98: #NAME? | J98: #NAME? | K98: #NAME? | L98: #NAME? | U98: #NAME? | V98: #NAME? | W98: #NAME? | X98: #NAME? | Y98: #NAME? | Z98: #NAME? | AC98: #NAME? | AD98: #NAME? | AE98: #NAME? | AF98: #NAME? | AI98: #NAME? | AJ98: #NAME? | AK98: #NAME? | AL98: #NAME? | AU98: #NAME? | AV98: #NAME? | AW98: #NAME? | AX98: #NAME? | AY98: #NAME? | AZ98: #NAME? | BC98: #NAME? | BD98: #NAME? | BE98: #NAME? | BF98: #NAME? | BI98: #NAME? | BJ98: #NAME? | BK98: #NAME? | BL98: #NAME? | BM98: #NAME? | BN98: #NAME? | BO98: #NAME? | BP98: #NAME?
A99: #NAME? | B99: #NAME? | C99: #NAME? | D99: #NAME? | E99: #NAME? | F99: #NAME? | G99: #NAME? | H99: #NAME? | I99: #NAME? | J99: #NAME? | K99: #NAME? | L99: #NAME? | U99: #NAME? | V99: #NAME? | W99: #NAME? | X99: #NAME? | Y99: #NAME? | Z99: #NAME? | AC99: #NAME? | AD99: #NAME? | AE99: #NAME? | AF99: #NAME? | AI99: #NAME? | AJ99: #NAME? | AK99: #NAME? | AL99: #NAME? | AU99: #NAME? | AV99: #NAME? | AW99: #NAME? | AX99: #NAME? | AY99: #NAME? | AZ99: #NAME? | BC99: #NAME? | BD99: #NAME? | BE99: #NAME? | BF99: #NAME? | BI99: #NAME? | BJ99: #NAME? | BK99: #NAME? | BL99: #NAME? | BM99: #NAME? | BN99: #NAME? | BO99: #NAME? | BP99: #NAME?
A100: #NAME? | B100: #NAME? | C100: #NAME? | D100: #NAME? | E100: #NAME? | F100: #NAME? | G100: #NAME? | H100: #NAME? | I100: #NAME? | J100: #NAME? | K100: #NAME? | L100: #NAME? | U100: #NAME? | V100: #NAME? | W100: #NAME? | X100: #NAME? | Y100: #NAME? | Z100: #NAME? | AC100: #NAME? | AD100: #NAME? | AE100: #NAME? | AF100: #NAME? | AI100: #NAME? | AJ100: #NAME? | AK100: #NAME? | AL100: #NAME? | AU100: #NAME? | AV100: #NAME? | AW100: #NAME? | AX100: #NAME? | AY100: #NAME? | AZ100: #NAME? | BC100: #NAME? | BD100: #NAME? | BE100: #NAME? | BF100: #NAME? | BI100: #NAME? | BJ100: #NAME? | BK100: #NAME? | BL100: #NAME? | BM100: #NAME? | BN100: #NAME? | BO100: #NAME? | BP100: #NAME?
A101: #NAME? | B101: #NAME? | C101: #NAME? | D101: #NAME? | E101: #NAME? | F101: #NAME? | G101: #NAME? | H101: #NAME? | I101: #NAME? | J101: #NAME? | K101: #NAME? | L101: #NAME? | U101: #NAME? | V101: #NAME? | W101: #NAME? | X101: #NAME? | Y101: #NAME? | Z101: #NAME? | AC101: #NAME? | AD101: #NAME? | AE101: #NAME? | AF101: #NAME? | AI101: #NAME? | AJ101: #NAME? | AK101: #NAME? | AL101: #NAME? | AU101: #NAME? | AV101: #NAME? | AW101: #NAME? | AX101: #NAME? | AY101: #NAME? | AZ101: #NAME? | BC101: #NAME? | BD101: #NAME? | BE101: #NAME? | BF101: #NAME? | BI101: #NAME? | BJ101: #NAME? | BK101: #NAME? | BL101: #NAME? | BM101: #NAME? | BN101: #NAME? | BO101: #NAME? | BP101: #NAME?
A102: #NAME? | B102: #NAME? | C102: #NAME? | D102: #NAME? | E102: #NAME? | F102: #NAME? | G102: #NAME? | H102: #NAME? | I102: #NAME? | J102: #NAME? | K102: #NAME? | L102: #NAME? | U102: #NAME? | V102: #NAME? | W102: #NAME? | X102: #NAME? | Y102: #NAME? | Z102: #NAME? | AC102: #NAME? | AD102: #NAME? | AE102: #NAME? | AF102: #NAME? | AI102: #NAME? | AJ102: #NAME? | AK102: #NAME? | AL102: #NAME? | AU102: #NAME? | AV102: #NAME? | AW102: #NAME? | AX102: #NAME? | AY102: #NAME? | AZ102: #NAME? | BC102: #NAME? | BD102: #NAME? | BE102: #NAME? | BF102: #NAME? | BI102: #NAME? | BJ102: #NAME? | BK102: #NAME? | BL102: #NAME? | BM102: #NAME? | BN102: #NAME? | BO102: #NAME? | BP102: #NAME?
A103: #NAME? | B103: #NAME? | C103: #NAME? | D103: #NAME? | E103: #NAME? | F103: #NAME? | G103: #NAME? | H103: #NAME? | I103: #NAME? | J103: #NAME? | K103: #NAME? | L103: #NAME? | U103: #NAME? | V103: #NAME? | W103: #NAME? | X103: #NAME? | Y103: #NAME? | Z103: #NAME? | AC103: #NAME? | AD103: #NAME? | AE103: #NAME? | AF103: #NAME? | AI103: #NAME? | AJ103: #NAME? | AK103: #NAME? | AL103: #NAME? | AU103: #NAME? | AV103: #NAME? | AW103: #NAME? | AX103: #NAME? | AY103: #NAME? | AZ103: #NAME? | BC103: #NAME? | BD103: #NAME? | BE103: #NAME? | BF103: #NAME? | BI103: #NAME? | BJ103: #NAME? | BK103: #NAME? | BL103: #NAME? | BM103: #NAME? | BN103: #NAME? | BO103: #NAME? | BP103: #NAME?
... A206: #NAME? | B206: #NAME? | C206: #NAME? | D206: #NAME? | E206: #NAME? | F206: #NAME? | G206: #NAME? | H206: #NAME? | I206: #NAME? | J206: #NAME? | K206: #NAME? | L206: #NAME? | U206: #NAME? | V206: #NAME? | W206: #NAME? | X206: #NAME? | Y206: #NAME? | Z206: #NAME? | AC206: #NAME? | AD206: #NAME? | AE206: #NAME? | AF206: #NAME? | AI206: #NAME? | AJ206: #NAME? | AK206: #NAME? | AL206: #NAME? | AU206: #NAME? | AV206: #NAME? | AW206: #NAME? | AX206: #NAME? | AY206: #NAME? | AZ206: #NAME? | BC206: #NAME? | BD206: #NAME? | BE206: #NAME? | BF206: #NAME? | BI206: #NAME? | BJ206: #NAME? | BK206: #NAME? | BL206: #NAME? | BM206: #NAME? | BN206: #NAME? | BO206: #NAME? | BP206: #NAME?
...

Sheet Sheet2
B1: AcidPlantGasFlowrate_0_0 | D1: AmbientTemp_0_0 | F1: CircFlow_1_0 | H1: CircFlow_2_0 | J1: CircPress_1_0 | L1: CircPress_2_0 | N1: CircPump_1_1 | P1: CircPump_2_1 | R1: CircPumpCommon_0_1 | T1: ConvertorMode_0_0 | V1: ExpansionTankLevel_1_0 | X1: ExpansionTankLevel_2_0 | Z1: FuelCoalCarrierAir_0_0 | AB1: FurnaceSuctionPress_1_0 | AD1: FurnaceSuctionPress_2_0 | AF1: LanceAir_0_0 | AH1: LanceCoal_0_0 | AJ1: LanceCoalLoss_0_0 | AL1: LanceOxygen_0_0 | AN1: MakeUpPump005_0_1 | AP1: MakeUpPump012_0_1 | AR1: MakeupPump30 | AT1: MakeupPump60 | AV1: MatteCarrierAir_0_0 | AX1: MatteFeed_0_0 | AZ1: Moisture | BB1: Moisture_0_0 | BD1: RoofCoalCarrierAir_0_0 | BF1: RoofCoalLoss_0_0 | BH1: Run | BJ1: ShroudAir_0_0 | BL1: ShroudOxygen_0_0 | BN1: SprayCoolerInletTemp_1_0 | BP1: SprayCoolerInletTemp_2_0 | BR1: StandbyCoalLoss_0_0
A2: 45240 | B2: 14348.011 | C2: 45240.299 | D2: 29.386612 | E2: 45240 | F2: 40.881302 | G2: 45240 | H2: 1625.1456 | I2: 45240.001 | J2: 0.55070364 | K2: 45240 | L2: 54.698093 | S2: 45240.044 | T2: 8 | U2: 45240.001 | V2: 2.1019135 | W2: 45240 | X2: 52.33017 | Y2: 45240 | Z2: 596.87073 | AC2: 45240 | AD2: -5.1685333 | AE2: 45240 | AF2: 10384.734 | AG2: 45240.017 | AH2: 1.5074257 | AI2: 45240.001 | AJ2: 1.4603508 | AK2: 45240 | AL2: 5929.647 | AM2: 45240.141 | AN2: OFF | AO2: 45240.06 | AP2: OFF | AQ2: 45240.06 | AR2: 0 | AS2: 45240.06 | AT2: 0 | AU2: 45240 | AV2: 3477.2849 | AW2: 45240 | AX2: 30.074842 | AY2: 45240 | AZ2: 9.5926733 | BC2: 45240 | BD2: 340.10626 | BE2: 45240 | BF2: 2.1406877 | BG2: 45240.101 | BH2: 1 | BI2: 45240 | BJ2: 7591.8335 | BK2: 45240 | BL2: 1661.9187 | BM2: 45240.001 | BN2: 27.672453 | BO2: 45240 | BP2: 547.53827
A3: 45240 | B3: 14801.294 | C3: 45240.299 | D3: 29.452488 | E3: 45240 | F3: 41.740501 | G3: 45240 | H3: 1623.3149 | I3: 45240.009 | J3: 0.54844695 | K3: 45240 | L3: 54.709835 | S3: 45240.044 | T3: 7 | U3: 45240.001 | V3: 2.1313629 | W3: 45240 | X3: 52.454296 | Y3: 45240 | Z3: 592.3089 | AC3: 45240 | AD3: -5.9040985 | AE3: 45240 | AF3: 10390.223 | AG3: 45240.045 | AH3: 1.5302174 | AI3: 45240.001 | AJ3: 1.5061415 | AK3: 45240 | AL3: 5907.3706 | AM3: 45240.141 | AN3: ON | AO3: 45240.06 | AP3: ON | AQ3: 45240.063 | AR3: 5 | AS3: 45240.063 | AT3: 5 | AU3: 45240 | AV3: 3486.0142 | AW3: 45240 | AX3: 30.183401 | AY3: 45240.001 | AZ3: 9.692523 | BC3: 45240 | BD3: 342.66269 | BE3: 45240.001 | BF3: 2.1576047 | BG3: 45240.435 | BH3: 1 | BI3: 45240 | BJ3: 7414.1909 | BK3: 45240 | BL3: 1649.0551 | BM3: 45240.001 | BN3: 26.732183 | BO3: 45240 | BP3: 549.13525
A4: 45240 | B4: 14628.323 | C4: 45240.3 | D4: 29.416073 | E4: 45240 | F4: 41.564644 | G4: 45240 | H4: 1620.4961 | I4: 45240.01 | J4: 0.55572581 | K4: 45240.001 | L4: 54.681694 | S4: 45240.044 | T4: 6 | U4: 45240.001 | V4: 2.2835591 | W4: 45240 | X4: 52.61467 | Y4: 45240 | Z4: 589.763 | AC4: 45240 | AD4: -5.7256775 | AE4: 45240 | AF4: 10404.687 | AG4: 45240.045 | AH4: 1.6404808 | AI4: 45240.001 | AJ4: 1.5450644 | AK4: 45240 | AL4: 5973.0923 | AM4: 45240.143 | AN4: OFF | AO4: 45240.064 | AP4: OFF | AQ4: 45240.101 | AR4: 5 | AS4: 45240.101 | AT4: 5 | AU4: 45240 | AV4: 3497.0491 | AW4: 45240.002 | AX4: 30.177145 | AY4: 45240.001 | AZ4: 9.3962574 | BC4: 45240 | BD4: 341.12189 | BE4: 45240.001 | BF4: 2.1856918 | BG4: 45240.504 | BH4: 1 | BI4: 45240 | BJ4: 7663.6201 | BK4: 45240 | BL4: 1555.0061 | BM4: 45240.002 | BN4: 27.740488 | BO4: 45240 | BP4: 549.87183
A5: 45240 | B5: 15332.117 | C5: 45240.3 | D5: 29.426487 | E5: 45240.001 | F5: 41.113266 | G5: 45240 | H5: 1628.6284 | I5: 45240.01 | J5: 0.53514707 | K5: 45240.001 | L5: 54.658901 | S5: 45240.045 | T5: 7 | U5: 45240.002 | V5: 2.3563564 | W5: 45240 | X5: 52.69873 | Y5: 45240 | Z5: 487.93323 | AC5: 45240 | AD5: -5.8446655 | AE5: 45240 | AF5: 10370.476 | AG5: 45240.045 | AH5: 1.7929218 | AI5: 45240.001 | AJ5: 1.58606 | AK5: 45240 | AL5: 5971.2646 | AO5: 45240.286 | AP5: ON | AQ5: 45240.105 | AR5: 0 | AS5: 45240.105 | AT5: 0 | AU5: 45240 | AV5: 3493.5642 | AW5: 45240.002 | AX5: 30.223078 | AY5: 45240.002 | AZ5: 8.4661913 | BC5: 45240 | BD5: 336.86945 | BE5: 45240.001 | BF5: 2.1964061 | BI5: 45240 | BJ5: 7768.0127 | BK5: 45240 | BL5: 1611.1641 | BM5: 45240.002 | BN5: 27.672827 | BO5: 45240.001 | BP5: 551.93726
A6: 45240.001 | B6: 15156.725 | C6: 45240.3 | D6: 29.53373 | E6: 45240.001 | F6: 42.144939 | G6: 45240.001 | H6: 1630.6984 | I6: 45240.011 | J6: 0.54914498 | K6: 45240.002 | L6: 54.621773 | S6: 45240.156 | T6: 8 | U6: 45240.002 | V6: 2.3605168 | W6: 45240 | X6: 52.824432 | Y6: 45240.001 | Z6: 508.79248 | AC6: 45240.001 | AD6: -6.083786 | AE6: 45240.001 | AF6: 10402.534 | AG6: 45240.045 | AH6: 1.9282348 | AI6: 45240.001 | AJ6: 1.6208632 | AK6: 45240.001 | AL6: 5982.6758 | AO6: 45240.289 | AP6: OFF | AQ6: 45240.141 | AR6: 0 | AS6: 45240.141 | AT6: 0 | AU6: 45240.001 | AV6: 3486.8208 | AW6: 45240.002 | AX6: 30.098087 | AY6: 45240.003 | AZ6: 8.8338652 | BC6: 45240 | BD6: 338.45016 | BE6: 45240.001 | BF6: 2.2786078 | BI6: 45240.001 | BJ6: 7451.958 | BK6: 45240.001 | BL6: 1672.5087 | BM6: 45240.002 | BN6: 26.797754 | BO6: 45240.001 | BP6: 551.85815
A7: 45240.001 | B7: 14363.662 | C7: 45240.3 | D7: 29.472736 | E7: 45240.001 | F7: 42.276981 | G7: 45240.001 | H7: 1616.75 | I7: 45240.019 | J7: 0.55193788 | K7: 45240.002 | L7: 54.664352 | U7: 45240.002 | V7: 2.2977219 | W7: 45240.001 | X7: 52.858826 | Y7: 45240.001 | Z7: 526.37256 | AC7: 45240.001 | AD7: -5.7758789 | AE7: 45240.001 | AF7: 10357.283 | AG7: 45240.046 | AH7: 2.0464196 | AI7: 45240.001 | AJ7: 1.6504465 | AK7: 45240.001 | AL7: 6057.7959 | AQ7: 45240.142 | AR7: 2 | AS7: 45240.142 | AT7: 2 | AU7: 45240.001 | AV7: 3469.8069 | AW7: 45240.002 | AX7: 29.96558 | AY7: 45240.003 | AZ7: 8.7613707 | BC7: 45240.001 | BD7: 338.98602 | BE7: 45240.001 | BF7: 2.3054237 | BI7: 45240.001 | BJ7: 7901.6323 | BK7: 45240.001 | BL7: 1619.2971 | BM7: 45240.002 | BN7: 27.629583 | BO7: 45240.001 | BP7: 552.91504
A8: 45240.001 | B8: 14657.224 | C8: 45240.3 | D8: 29.477757 | E8: 45240.001 | F8: 43.944923 | G8: 45240.001 | H8: 1620.1531 | I8: 45240.023 | J8: 0.54720098 | K8: 45240.002 | L8: 54.773895 | U8: 45240.011 | V8: 2.2568741 | W8: 45240.001 | X8: 52.84296 | Y8: 45240.001 | Z8: 539.19501 | AC8: 45240.001 | AD8: -5.823288 | AE8: 45240.001 | AF8: 10313.967 | AG8: 45240.046 | AH8: 2.1474767 | AI8: 45240.002 | AJ8: 1.6773633 | AK8: 45240.001 | AL8: 6057.064 | AQ8: 45240.183 | AR8: 2 | AS8: 45240.183 | AT8: 2 | AU8: 45240.001 | AV8: 3442.7229 | AW8: 45240.002 | AX8: 29.899935 | AY8: 45240.004 | AZ8: 8.2913418 | BC8: 45240.001 | BD8: 341.86096 | BE8: 45240.001 | BF8: 2.3261726 | BI8: 45240.001 | BJ8: 7389.4619 | BK8: 45240.001 | BL8: 1545.4073 | BM8: 45240.009 | BN8: 27.64039 | BO8: 45240.001 | BP8: 552.78918
A9: 45240.001 | B9: 15122.451 | C9: 45240.3 | D9: 29.535759 | E9: 45240.001 | F9: 46.108604 | G9: 45240.001 | H9: 1644.142 | I9: 45240.029 | J9: 0.54922831 | K9: 45240.003 | L9: 54.816315 | U9: 45240.011 | V9: 2.1267521 | W9: 45240.001 | X9: 53.027527 | Y9: 45240.001 | Z9: 548.33215 | AC9: 45240.001 | AD9: -5.3819809 | AE9: 45240.001 | AF9: 10334.26 | AG9: 45240.046 | AH9: 2.2314048 | AI9: 45240.002 | AJ9: 1.6556474 | AK9: 45240.001 | AL9: 6018.7632 | AQ9: 45240.184 | AR9: 0 | AS9: 45240.184 | AT9: 0 | AU9: 45240.001 | AV9: 3428.5891 | AW9: 45240.002 | AX9: 29.907438 | AY9: 45240.006 | AZ9: 8.455102 | BC9: 45240.001 | BD9: 338.37436 | BE9: 45240.002 | BF9: 2.3403759 | BI9: 45240.001 | BJ9: 7562.7793 | BK9: 45240.001 | BL9: 1658.7206 | BM9: 45240.009 | BN9: 26.772623 | BO9: 45240.001 | BP9: 553.61548
A10: 45240.001 | B10: 15147.959 | C10: 45240.3 | D10: 29.475731 | E10: 45240.001 | F10: 47.648746 | G10: 45240.001 | H10: 1634.9209 | I10: 45240.032 | J10: 0.54504102 | K10: 45240.003 | L10: 54.787086 | U10: 45240.013 | V10: 2.1225483 | W10: 45240.001 | X10: 53.038219 | Y10: 45240.001 | Z10: 553.80579 | AC10: 45240.001 | AD10: -5.7054367 | AE10: 45240.001 | AF10: 10262.372 | AG10: 45240.046 | AH10: 2.2982054 | AI10: 45240.002 | AJ10: 1.6253505 | AK10: 45240.001 | AL10: 6084.6401 | AQ10: 45240.286 | AR10: 0 | AS10: 45240.286 | AT10: 0 | AU10: 45240.001 | AV10: 3369.9504 | AW10: 45240.003 | AX10: 30.050961 | AY10: 45240.006 | AZ10: 9.5670691 | BC10: 45240.001 | BD10: 337.21725 | BE10: 45240.002 | BF10: 2.3471723 | BI10: 45240.001 | BJ10: 7453.8354 | BK10: 45240.001 | BL10: 1670.458 | BM10: 45240.009 | BN10: 27.626671 | BO10: 45240.002 | BP10: 557.47192
A11: 45240.001 | B11: 15338.5 | C11: 45240.301 | D11: 29.512253 | E11: 45240.001 | F11: 48.114239 | G11: 45240.001 | H11: 1617.6741 | I11: 45240.033 | J11: 0.55708098 | K11: 45240.003 | L11: 54.565563 | U11: 45240.014 | V11: 2.2218323 | W11: 45240.001 | X11: 53.01445 | Y11: 45240.001 | Z11: 557.93134 | AC11: 45240.001 | AD11: -6.2718964 | AE11: 45240.001 | AF11: 10341.754 | AG11: 45240.046 | AH11: 2.3478768 | AI11: 45240.002 | AJ11: 1.5977845 | AK11: 45240.001 | AL11: 6114.7324 | AQ11: 45240.289 | AR11: 4 | AS11: 45240.289 | AT11: 4 | AU11: 45240.001 | AV11: 3351.7212 | AW11: 45240.003 | AX11: 30.625048 | AY11: 45240.007 | AZ11: 8.1282539 | BC11: 45240.001 | BD11: 336.40338 | BE11: 45240.004 | BF11: 2.3207846 | BI11: 45240.001 | BJ11: 7632.9688 | BK11: 45240.001 | BL11: 1577.2155 | BM11: 45240.011 | BN11: 27.61117 | BO11: 45240.002 | BP11: 554.26514
A12: 45240.001 | B12: 16106.104 | C12: 45240.301 | D12: 29.469406 | E12: 45240.002 | F12: 51.121574 | G12: 45240.001 | H12: 1652.4133 | I12: 45240.033 | J12: 0.55061066 | K12: 45240.003 | L12: 54.411072 | U12: 45240.015 | V12: 2.2464497 | W12: 45240.001 | X12: 52.905396 | Y12: 45240.001 | Z12: 560.7677 | AC12: 45240.001 | AD12: -6.0188141 | AE12: 45240.001 | AF12: 10311.414 | AG12: 45240.046 | AH12: 2.3804209 | AI12: 45240.002 | AJ12: 1.5764561 | AK12: 45240.001 | AL12: 6073.6138 | AQ12: 45240.328 | AR12: 4 | AS12: 45240.328 | AT12: 4 | AU12: 45240.001 | AV12: 3348.6548 | AW12: 45240.003 | AX12: 30.912092 | AY12: 45240.009 | AZ12: 7.5173488 | BC12: 45240.001 | BD12: 335.46802 | BE12: 45240.004 | BF12: 2.259419 | BI12: 45240.001 | BJ12: 7764.6782 | BK12: 45240.001 | BL12: 1621.7726 | BM12: 45240.011 | BN12: 26.763641 | BO12: 45240.002 | BP12: 546.22766
A13: 45240.001 | B13: 15073.508 | C13: 45240.301 | D13: 29.476406 | E13: 45240.002 | F13: 51.386711 | G13: 45240.001 | H13: 1618.3871 | I13: 45240.037 | J13: 0.55376023 | K13: 45240.004 | L13: 54.411991 | U13: 45240.016 | V13: 2.1676865 | W13: 45240.001 | X13: 52.684048 | Y13: 45240.001 | Z13: 561.5105 | AC13: 45240.001 | AD13: -6.5590286 | AE13: 45240.001 | AF13: 10287.591 | AG13: 45240.046 | AH13: 2.3960495 | AI13: 45240.002 | AJ13: 1.5479635 | AK13: 45240.001 | AL13: 6032.0742 | AQ13: 45240.331 | AR13: 0 | AS13: 45240.331 | AT13: 0 | AU13: 45240.001 | AV13: 3378.7983 | AW13: 45240.003 | AX13: 31.199133 | AY13: 45240.01 | AZ13: 8.0160236 | BC13: 45240.001 | BD13: 335.88504 | BE13: 45240.004 | BF13: 2.2072577 | BI13: 45240.001 | BJ13: 7637.1045 | BK13: 45240.001 | BL13: 1664.386 | BM13: 45240.011 | BN13: 27.633995 | BO13: 45240.002 | BP13: 545.81378
A14: 45240.002 | B14: 15799.521 | C14: 45240.301 | D14: 29.40435 | E14: 45240.002 | F14: 53.360096 | G14: 45240.001 | H14: 1617.6415 | I14: 45240.04 | J14: 0.55528742 | K14: 45240.004 | L14: 54.429993 | U14: 45240.016 | V14: 2.3019154 | W14: 45240.001 | X14: 52.686722 | Y14: 45240.001 | Z14: 562.73816 | AC14: 45240.002 | AD14: -7.1222153 | AE14: 45240.001 | AF14: 10252.766 | AG14: 45240.047 | AH14: 2.3788271 | AI14: 45240.002 | AJ14: 1.5373182 | AK14: 45240.001 | AL14: 6081.9634 | AQ14: 45240.504 | AR14: 0 | AS14: 45240.504 | AT14: 0 | AU14: 45240.001 | AV14: 3360.7942 | AW14: 45240.003 | AX14: 31.342653 | AY14: 45240.01 | AZ14: 7.899085 | BC14: 45240.002 | BD14: 335.10822 | BE14: 45240.004 | BF14: 2.1645856 | BI14: 45240.001 | BJ14: 7594.7324 | BK14: 45240.001 | BL14: 1671.9598 | BM14: 45240.012 | BN14: 27.629469 | BO14: 45240.002 | BP14: 552.07635
A15: 45240.002 | B15: 15591.847 | C15: 45240.303 | D15: 29.465309 | E15: 45240.002 | F15: 53.078461 | G15: 45240.002 | H15: 1639.1191 | I15: 45240.045 | J15: 0.54902035 | K15: 45240.004 | L15: 54.524487 | U15: 45240.021 | V15: 2.2915165 | W15: 45240.002 | X15: 52.465073 | Y15: 45240.002 | Z15: 562.78052 | AC15: 45240.002 | AD15: -8.0622406 | AE15: 45240.002 | AF15: 10314.491 | AG15: 45240.048 | AH15: 2.3952267 | AI15: 45240.002 | AJ15: 1.5350976 | AK15: 45240.002 | AL15: 6088.3242 | AU15: 45240.002 | AV15: 3324.7422 | AW15: 45240.003 | AX15: 31.916739 | AY15: 45240.011 | AZ15: 8.1344738 | BC15: 45240.002 | BD15: 335.29086 | BE15: 45240.004 | BF15: 2.1341927 | BI15: 45240.002 | BJ15: 7419.6294 | BK15: 45240.002 | BL15: 1581.5619 | BM15: 45240.012 | BN15: 26.781427 | BO15: 45240.002 | BP15: 553.15906
A16: 45240.002 | B16: 15479.974 | C16: 45240.303 | D16: 29.519077 | E16: 45240.003 | F16: 57.202648 | G16: 45240.002 | H16: 1646.8628 | I16: 45240.047 | J16: 0.5599395 | K16: 45240.004 | L16: 54.664722 | U16: 45240.024 | V16: 2.2653248 | W16: 45240.002 | X16: 52.144627 | Y16: 45240.002 | Z16: 564.90186 | AC16: 45240.002 | AD16: -8.5469131 | AE16: 45240.002 | AF16: 10264.761 | AG16: 45240.156 | AH16: 2.2993836 | AI16: 45240.007 | AJ16: 1.5309289 | AK16: 45240.002 | AL16: 6056.874 | AU16: 45240.002 | AV16: 3552.5457 | AW16: 45240.005 | AX16: 32 | AY16: 45240.012 | AZ16: 7.6644073 | BC16: 45240.002 | BD16: 341.63843 | BE16: 45240.005 | BF16: 2.1083579 | BI16: 45240.002 | BJ16: 7367.1567 | BK16: 45240.002 | BL16: 1595.1471 | BM16: 45240.012 | BN16: 27.58094 | BO16: 45240.003 | BP16: 553.63989
A17: 45240.002 | B17: 15410.776 | C17: 45240.304 | D17: 29.516975 | E17: 45240.003 | F17: 58.182213 | G17: 45240.002 | H17: 1622.6606 | I17: 45240.047 | J17: 0.5416649 | K17: 45240.004 | L17: 54.743561 | U17: 45240.026 | V17: 2.2206268 | W17: 45240.002 | X17: 51.96701 | Y17: 45240.002 | Z17: 465.70218 | AC17: 45240.002 | AD17: -7.2513428 | AE17: 45240.002 | AF17: 10392.941 | AG17: 45240.156 | AH17: 2.1379738 | AI17: 45240.007 | AJ17: 1.5178701 | AK17: 45240.002 | AL17: 6123.0112 | AU17: 45240.002 | AV17: 3821.9353 | AW17: 45240.005 | AX17: 31.39238 | AY17: 45240.013 | AZ17: 7.0364814 | BC17: 45240.002 | BD17: 342.89804 | BE17: 45240.005 | BF17: 2.1076438 | BI17: 45240.002 | BJ17: 7495.4004 | BK17: 45240.002 | BL17: 1633.8655 | BM17: 45240.013 | BN17: 27.662621 | BO17: 45240.003 | BP17: 552.18628
A18: 45240.002 | B18: 14849.963 | C18: 45240.304 | D18: 29.55341 | E18: 45240.003 | F18: 60.037132 | G18: 45240.002 | H18: 1623.6056 | I18: 45240.048 | J18: 0.56089544 | K18: 45240.005 | L18: 54.780357 | U18: 45240.026 | V18: 2.1551921 | W18: 45240.002 | X18: 51.955929 | Y18: 45240.002 | Z18: 488.43164 | AC18: 45240.002 | AD18: -5.3417892 | AE18: 45240.002 | AF18: 10215.825 | AG18: 45240.156 | AH18: 1.9986989 | AI18: 45240.007 | AJ18: 1.512991 | AK18: 45240.002 | AL18: 6161.7866 | AU18: 45240.002 | AV18: 2219.427 | AW18: 45240.005 | AX18: 31.084986 | AY18: 45240.014 | AZ18: 7.0249271 | BC18: 45240.002 | BD18: 342.1095 | BE18: 45240.005 | BF18: 2.1093807 | BI18: 45240.002 | BJ18: 10239.633 | BK18: 45240.002 | BL18: 1681.26 | BM18: 45240.013 | BN18: 26.784597 | BO18: 45240.003 | BP18: 551.83264
A19: 45240.002 | B19: 15858.136 | C19: 45240.304 | D19: 29.499485 | E19: 45240.003 | F19: 56.083813 | G19: 45240.002 | H19: 1628.1113 | I19: 45240.05 | J19: 0.5550918 | K19: 45240.006 | L19: 54.717564 | U19: 45240.027 | V19: 2.3564861 | W19: 45240.002 | X19: 51.897533 | Y19: 45240.002 | Z19: 509.63388 | AC19: 45240.002 | AD19: -5.1005707 | AE19: 45240.002 | AF19: 10147.181 | AG19: 45240.156 | AH19: 1.8765724 | AI19: 45240.007 | AJ19: 1.5057349 | AK19: 45240.002 | AL19: 6110.4575 | AU19: 45240.002 | AV19: 840.06024 | AW19: 45240.005 | AX19: 29.954653 | AY19: 45240.015 | AZ19: 8.3214321 | BC19: 45240.002 | BD19: 346.77484 | BE19: 45240.005 | BF19: 2.0685422 | BI19: 45240.002 | BJ19: 7299.46 | BK19: 45240.002 | BL19: 1694.5674 | BM19: 45240.013 | BN19: 27.651018 | BO19: 45240.003 | BP19: 548.97827
A20: 45240.002 | B20: 15311.817 | C20: 45240.304 | D20: 29.513058 | E20: 45240.003 | F20: 56.411411 | G20: 45240.002 | H20: 1628.3732 | I20: 45240.056 | J20: 0.55404365 | K20: 45240.006 | L20: 54.6535 | U20: 45240.027 | V20: 2.2389297 | W20: 45240.002 | X20: 52.162445 | Y20: 45240.002 | Z20: 457.76071 | AC20: 45240.002 | AD20: -5.9374695 | AE20: 45240.002 | AF20: 10497.099 | AG20: 45240.156 | AH20: 1.7715946 | AI20: 45240.007 | AJ20: 1.4622825 | AK20: 45240.002 | AL20: 6110.9458 | AU20: 45240.002 | AV20: 3383.2334 | AW20: 45240.006 | AX20: 29.959278 | AY20: 45240.015 | AZ20: 7.5143752 | BC20: 45240.002 | BD20: 406.7048 | BE20: 45240.005 | BF20: 2.0365148 | BI20: 45240.002 | BJ20: 7150.4238 | BK20: 45240.002 | BL20: 1686.8275 | BM20: 45240.014 | BN20: 27.616808 | BO20: 45240.004 | BP20: 549.79126
A21: 45240.002 | B21: 15156.107 | C21: 45240.304 | D21: 29.497257 | E21: 45240.003 | F21: 55.942223 | G21: 45240.002 | H21: 1623.6024 | I21: 45240.059 | J21: 0.54649973 | K21: 45240.006 | L21: 54.605804 | U21: 45240.028 | V21: 2.1894023 | W21: 45240.002 | X21: 52.380764 | Y21: 45240.002 | Z21: 504.0795 | AC21: 45240.003 | AD21: -4.9684448 | AE21: 45240.002 | AF21: 10647.818 | AG21: 45240.156 | AH21: 1.6837658 | AI21: 45240.007 | AJ21: 1.4282054 | AK21: 45240.002 | AL21: 6228.3159 | AU21: 45240.002 | AV21: 4169.4575 | AW21: 45240.006 | AX21: 29.994827 | AY21: 45240.016 | AZ21: 8.2422132 | BC21: 45240.002 | BD21: 406.45816 | BE21: 45240.005 | BF21: 2.0198514 | BI21: 45240.002 | BJ21: 7391.1304 | BK21: 45240.002 | BL21: 1615.0707 | BM21: 45240.014 | BN21: 26.775049 | BO21: 45240.004 | BP21: 551.50348
A22: 45240.002 | B22: 14728.85 | C22: 45240.305 | D22: 29.524902 | E22: 45240.003 | F22: 56.006546 | G22: 45240.002 | H22: 1632.4967 | I22: 45240.06 | J22: 0.56004345 | K22: 45240.006 | L22: 54.583359 | U22: 45240.029 | V22: 2.1451442 | W22: 45240.002 | X22: 52.877304 | Y22: 45240.002 | Z22: 503.27451 | AC22: 45240.003 | AD22: -4.7487106 | AE22: 45240.002 | AF22: 10677.03 | AG22: 45240.156 | AH22: 1.6130848 | AI22: 45240.007 | AJ22: 1.3992391 | AK22: 45240.002 | AL22: 6242.8384 | AU22: 45240.002 | AV22: 4914.7681 | AW22: 45240.007 | AX22: 29.968502 | AY22: 45240.017 | AZ22: 8.2718477 | BC22: 45240.002 | BD22: 411.43503 | BE22: 45240.005 | BF22: 2.0281503 | BI22: 45240.003 | BJ22: 7474.5352 | BK22: 45240.002 | BL22: 1583.4026 | BM22: 45240.014 | BN22: 27.620234 | BO22: 45240.004 | BP22: 553.01868
A23: 45240.003 | B23: 14714.325 | C23: 45240.305 | D23: 29.506645 | E23: 45240.004 | F23: 57.045498 | G23: 45240.003 | H23: 1624.9615 | I23: 45240.061 | J23: 0.54091394 | K23: 45240.007 | L23: 54.679363 | U23: 45240.029 | V23: 2.376704 | W23: 45240.002 | X23: 52.962784 | Y23: 45240.003 | Z23: 472.81619 | AC23: 45240.003 | AD23: -5.2218475 | AE23: 45240.003 | AF23: 10750.411 | AG23: 45240.156 | AH23: 1.5595521 | AI23: 45240.007 | AJ23: 1.4013187 | AK23: 45240.003 | AL23: 6185.3101 | AU23: 45240.003 | AV23: 4818.3628 | AW23: 45240.007 | AX23: 29.941195 | AY23: 45240.018 | AZ23: 7.867559 | BC23: 45240.003 | BD23: 367.03079 | BE23: 45240.005 | BF23: 2.0346582 | BI23: 45240.003 | BJ23: 7551.0508 | BK23: 45240.003 | BL23: 1545.6213 | BM23: 45240.016 | BN23: 27.597305 | BO23: 45240.004 | BP23: 556.07495
A24: 45240.003 | B24: 15235.731 | C24: 45240.305 | D24: 29.590832 | E24: 45240.004 | F24: 56.573662 | G24: 45240.003 | H24: 1625.8472 | I24: 45240.063 | J24: 0.55688453 | K24: 45240.007 | L24: 54.670731 | U24: 45240.03 | V24: 2.4368947 | W24: 45240.003 | X24: 52.915787 | Y24: 45240.003 | Z24: 463.46445 | AC24: 45240.003 | AD24: -5.3686142 | AE24: 45240.003 | AF24: 10778.493 | AG24: 45240.157 | AH24: 1.5231659 | AI24: 45240.008 | AJ24: 1.4272884 | AK24: 45240.003 | AL24: 6131.4526 | AU24: 45240.003 | AV24: 4535.1348 | AW24: 45240.008 | AX24: 29.908335 | AY24: 45240.019 | AZ24: 7.2415981 | BC24: 45240.003 | BD24: 213.06801 | BE24: 45240.008 | BF24: 2.0285358 | BI24: 45240.003 | BJ24: 7971.9976 | BK24: 45240.003 | BL24: 1612.1499 | BM24: 45240.016 | BN24: 26.819601 | BO24: 45240.004 | BP24: 556.84692
A25: 45240.003 | B25: 14283.817 | C25: 45240.305 | D25: 29.56871 | E25: 45240.004 | F25: 57.613979 | G25: 45240.003 | H25: 1621.8602 | I25: 45240.063 | J25: 0.54953969 | K25: 45240.007 | L25: 54.594936 | U25: 45240.03 | V25: 2.3283947 | W25: 45240.003 | X25: 53.095348 | Y25: 45240.003 | Z25: 472.85556 | AC25: 45240.003 | AD25: -6.0830917 | AE25: 45240.003 | AF25: 10720.001 | AG25: 45240.157 | AH25: 1.503926 | AI25: 45240.008 | AJ25: 1.4493632 | AK25: 45240.003 | AL25: 6144.7656 | AU25: 45240.003 | AV25: 4578.5508 | AW25: 45240.008 | AX25: 29.787851 | AY25: 45240.02 | AZ25: 7.5116248 | BC25: 45240.003 | BD25: 211.97292 | BE25: 45240.008 | BF25: 2.0159161 | BI25: 45240.003 | BJ25: 7492.0244 | BK25: 45240.003 | BL25: 1645.7505 | BM25: 45240.016 | BN25: 27.588028 | BO25: 45240.004 | BP25: 556.24243
A26: 45240.003 | B26: 14693.083 | C26: 45240.307 | D26: 29.793686 | E26: 45240.004 | F26: 56.599606 | G26: 45240.003 | H26: 1623.1046 | I26: 45240.07 | J26: 0.54906088 | K26: 45240.008 | L26: 54.558636 | U26: 45240.039 | V26: 2.3053944 | W26: 45240.003 | X26: 52.953838 | Y26: 45240.003 | Z26: 478.77682 | AC26: 45240.003 | AD26: -5.4275436 | AE26: 45240.003 | AF26: 10715.538 | AG26: 45240.23 | AH26: 1.487462 | AI26: 45240.008 | AJ26: 1.4694482 | AK26: 45240.003 | AL26: 6115.708 | AU26: 45240.003 | AV26: 4382.4355 | AW26: 45240.01 | AX26: 29.808428 | AY26: 45240.021 | AZ26: 8.2475605 | BC26: 45240.003 | BD26: 211.39766 | BE26: 45240.008 | BF26: 2.0165234 | BI26: 45240.003 | BJ26: 8056.9258 | BK26: 45240.003 | BL26: 1663.8284 | BM26: 45240.017 | BN26: 27.690695 | BO26: 45240.004 | BP26: 554.81604
... A91: 45240.011 | B91: 14972.148 | C91: 45240.4 | D91: 32.05278 | E91: 45240.016 | F91: 39.471863 | G91: 45240.011 | H91: 1625.0521 | I91: 45240.275 | J91: 0.55319738 | K91: 45240.026 | L91: 54.144943 | U91: 45240.152 | V91: 2.2728145 | W91: 45240.011 | X91: 50.25848 | Y91: 45240.01 | Z91: 576.1734 | AC91: 45240.011 | AD91: -6.381073 | AE91: 45240.01 | AF91: 10464.962 | AG91: 45240.506 | AH91: 0.79967999 | AI91: 45240.025 | AJ91: 1.6188385 | AK91: 45240.01 | AL91: 5971.3433 | AU91: 45240.01 | AV91: 3391.9897 | AW91: 45240.028 | AX91: 29.530531 | AY91: 45240.081 | AZ91: 11.227448 | BC91: 45240.011 | BD91: 339.5726 | BE91: 45240.027 | BF91: 1.9266212 | BI91: 45240.01 | BJ91: 7516.1753 | BK91: 45240.01 | BL91: 1641.7985 | BM91: 45240.06 | BN91: 26.639765 | BO91: 45240.014 | BP91: 544.63586
A92: 45240.011 | B92: 14669.378 | C92: 45240.401 | D92: 32.011299 | E92: 45240.016 | F92: 40.017746 | G92: 45240.011 | H92: 1629.9629 | I92: 45240.278 | J92: 0.54486012 | K92: 45240.026 | L92: 54.107437 | U92: 45240.152 | V92: 2.3156636 | W92: 45240.011 | X92: 50.317883 | Y92: 45240.01 | Z92: 576.07562 | AC92: 45240.011 | AD92: -6.3192215 | AE92: 45240.011 | AF92: 10597.8 | AI92: 45240.025 | AJ92: 1.5745404 | AK92: 45240.01 | AL92: 5963.9268 | AU92: 45240.01 | AV92: 3403.2004 | AW92: 45240.028 | AX92: 29.603485 | AY92: 45240.082 | AZ92: 10.887649 | BC92: 45240.011 | BD92: 339.11557 | BE92: 45240.027 | BF92: 1.9043356 | BI92: 45240.011 | BJ92: 7444.144 | BK92: 45240.01 | BL92: 1563.083 | BM92: 45240.06 | BN92: 27.572914 | BO92: 45240.014 | BP92: 545.05432
A93: 45240.011 | B93: 13919.107 | C93: 45240.401 | D93: 32.030205 | E93: 45240.016 | F93: 38.373947 | G93: 45240.011 | H93: 1623.6366 | I93: 45240.279 | J93: 0.53941023 | K93: 45240.027 | L93: 54.036171 | U93: 45240.152 | V93: 2.455518 | W93: 45240.011 | X93: 50.641308 | Y93: 45240.011 | Z93: 576.49847 | AC93: 45240.012 | AD93: -6.3052139 | AE93: 45240.011 | AF93: 10546.453 | AI93: 45240.025 | AJ93: 1.5593483 | AK93: 45240.011 | AL93: 5965.0967 | AU93: 45240.011 | AV93: 3409.1711 | AW93: 45240.028 | AX93: 29.798662 | AY93: 45240.085 | AZ93: 10.363415 | BC93: 45240.011 | BD93: 344.29025 | BE93: 45240.027 | BF93: 1.9365382 | BI93: 45240.011 | BJ93: 7469.1377 | BK93: 45240.011 | BL93: 1620.668 | BM93: 45240.061 | BN93: 27.512045 | BO93: 45240.014 | BP93: 546.02051
A94: 45240.011 | B94: 14307.326 | C94: 45240.401 | D94: 31.986324 | E94: 45240.016 | F94: 37.872707 | G94: 45240.011 | H94: 1634.1982 | I94: 45240.283 | J94: 0.53458977 | K94: 45240.027 | L94: 54.024822 | U94: 45240.152 | V94: 2.4920933 | W94: 45240.011 | X94: 50.837238 | Y94: 45240.011 | Z94: 574.9989 | AC94: 45240.012 | AD94: -5.4771347 | AE94: 45240.011 | AF94: 10591.73 | AI94: 45240.025 | AJ94: 1.5748475 | AK94: 45240.011 | AL94: 5904.2393 | AU94: 45240.011 | AV94: 3419.7056 | AW94: 45240.028 | AX94: 29.866865 | AY94: 45240.085 | AZ94: 10.589593 | BC94: 45240.011 | BD94: 346.20258 | BE94: 45240.028 | BF94: 1.9750082 | BI94: 45240.011 | BJ94: 7342.2495 | BK94: 45240.011 | BL94: 1673.8356 | BM94: 45240.061 | BN94: 26.640669 | BO94: 45240.015 | BP94: 545.54883
A95: 45240.011 | B95: 14306.503 | C95: 45240.401 | D95: 32.074226 | E95: 45240.016 | F95: 38.470375 | G95: 45240.011 | H95: 1630.7072 | I95: 45240.287 | J95: 0.53379941 | K95: 45240.027 | L95: 54.048409 | U95: 45240.153 | V95: 2.3190384 | W95: 45240.011 | X95: 51.175678 | Y95: 45240.011 | Z95: 575.33966 | AC95: 45240.012 | AD95: -6.1442566 | AE95: 45240.011 | AF95: 10414.567 | AI95: 45240.025 | AJ95: 1.7203819 | AK95: 45240.011 | AL95: 5931.7339 | AU95: 45240.011 | AV95: 3442.6113 | AW95: 45240.028 | AX95: 29.946272 | AY95: 45240.086 | AZ95: 10.325251 | BC95: 45240.011 | BD95: 346.37091 | BE95: 45240.028 | BF95: 2.005748 | BI95: 45240.011 | BJ95: 7640.7642 | BK95: 45240.011 | BL95: 1654.3723 | BM95: 45240.061 | BN95: 27.43611 | BO95: 45240.015 | BP95: 548.25494
A96: 45240.011 | B96: 14188.091 | C96: 45240.402 | D96: 32.053909 | E96: 45240.016 | F96: 37.629364 | G96: 45240.011 | H96: 1629.5615 | I96: 45240.287 | J96: 0.54585582 | K96: 45240.027 | L96: 54.107948 | U96: 45240.155 | V96: 2.2907131 | W96: 45240.011 | X96: 51.414688 | Y96: 45240.011 | Z96: 578.11945 | AC96: 45240.012 | AD96: -6.4434738 | AE96: 45240.011 | AF96: 10414.429 | AI96: 45240.025 | AJ96: 1.786727 | AK96: 45240.011 | AL96: 5951.4771 | AU96: 45240.011 | AV96: 3468.874 | AW96: 45240.028 | AX96: 29.970217 | AY96: 45240.087 | AZ96: 9.7601061 | BC96: 45240.011 | BD96: 343.40311 | BE96: 45240.028 | BF96: 2.0330596 | BI96: 45240.011 | BJ96: 7731.2656 | BK96: 45240.011 | BL96: 1556.7139 | BM96: 45240.063 | BN96: 27.50843 | BO96: 45240.015 | BP96: 548.18872
A97: 45240.011 | B97: 13926.615 | C97: 45240.402 | D97: 31.99538 | E97: 45240.017 | F97: 35.14539 | G97: 45240.011 | H97: 1623.2424 | I97: 45240.29 | J97: 0.54622704 | K97: 45240.028 | L97: 54.224815 | U97: 45240.162 | V97: 2.3171234 | W97: 45240.011 | X97: 51.925888 | Y97: 45240.011 | Z97: 578.61505 | AC97: 45240.012 | AD97: -6.1576004 | AE97: 45240.011 | AF97: 10384.608 | AI97: 45240.028 | AJ97: 1.744241 | AK97: 45240.011 | AL97: 5905.5283 | AU97: 45240.011 | AV97: 3480.2515 | AW97: 45240.029 | AX97: 29.932795 | AY97: 45240.088 | AZ97: 10.604075 | BC97: 45240.011 | BD97: 340.97809 | BE97: 45240.028 | BF97: 2.057909 | BI97: 45240.011 | BJ97: 7757.7563 | BK97: 45240.011 | BL97: 1604.0813 | BM97: 45240.063 | BN97: 26.608826 | BO97: 45240.015 | BP97: 550.35248
A98: 45240.012 | B98: 14318.305 | C98: 45240.402 | D98: 32.067467 | E98: 45240.017 | F98: 33.489197 | G98: 45240.012 | H98: 1630.7239 | I98: 45240.293 | J98: 0.54287189 | K98: 45240.028 | L98: 54.304516 | U98: 45240.165 | V98: 2.2894924 | W98: 45240.012 | X98: 52.136856 | Y98: 45240.011 | Z98: 581.34375 | AC98: 45240.012 | AD98: -6.3117676 | AE98: 45240.011 | AF98: 10523.839 | AI98: 45240.028 | AJ98: 1.708127 | AK98: 45240.011 | AL98: 5840.9883 | AU98: 45240.011 | AV98: 3493.3643 | AW98: 45240.029 | AX98: 29.857946 | AY98: 45240.088 | AZ98: 11.221933 | BC98: 45240.012 | BD98: 343.0752 | BE98: 45240.028 | BF98: 2.0581393 | BI98: 45240.011 | BJ98: 7380.2939 | BK98: 45240.011 | BL98: 1648.3728 | BM98: 45240.063 | BN98: 27.51796 | BO98: 45240.015 | BP98: 549.55072
