Workbook

Sheet Sheet1
A1: Timestamps | B1: \\usmlmes\USMLPI_MDB\USMLPIMBD\Conversions and Totals\GenTo2valTotal.24.5|ACE:315.Coal.Consumption.Day.Total.86400.18000.2Tot | C1: \\usmlmes\USMLPI_MDB\USMLPIMBD\Conversions and Totals\GenTo2valTotal.24.5|ACE:315.SCC.Feed.Day.Total.86400.18000.2Tot | D1: \\usmlmes\USMLPI_MDB\USMLPIMBD\Conversions and Totals\GenTo2valTotal.24.5|ACE:345-TIC-007C/MVC.QON.Daily.Utilization.86400.18000.2Tot | E1: \\usmlmes\USMLPI_MDB\USMLPIMBD\Conversions and Totals\GenTo2valTotal.24.5|ACE:345-WI-006/PV.V.Transfer.Daily.Ave.86400.18000.eAve | F1: \\usmlmes\USMLPI_MDB\USMLPIMBD\Conversions and Totals\GenTo2valTotal.24.5|ACE:345-WI-006/PV.V.Transfer.Daily.StdDev.86400.18000.eStdDev | G1: \\usmlmes\USMLPI_MDB\USMLPIMBD\Conversions and Totals\GenTo2valTotal.24.5|ACE:345-WI-007/PV.V.Transfer.Daily.Ave.86400.18000.eAve | H1: \\usmlmes\USMLPI_MDB\USMLPIMBD\Conversions and Totals\GenTo2valTotal.24.5|ACE:345-WI-007/PV.V.Transfer.Daily.StdDev.86400.18000.eStdDev | I1: \\usmlmes\USMLPI_MDB\USMLPIMBD\Conversions and Totals\GenTo2valTotal.24.5|ACE:414-PIC-610C/MVC.QON.Daily.Utilization.86400.18000.2Tot | J1: \\usmlmes\USMLPI_MDB\USMLPIMBD\Conversions and Totals\GenTo2valTotal.24.5|ACE:494-WI-020/PV.V.Transfer.Daily.Ave.86400.18000.eAve | K1: \\usmlmes\USMLPI_MDB\USMLPIMBD\Conversions and Totals\GenTo2valTotal.24.5|ACE:494-WI-020/PV.V.Transfer.Daily.StdDev.86400.18000.eStdDev | L1: \\usmlmes\USMLPI_MDB\USMLPIMBD\Conversions and Totals\GenTo2valTotal.24.5|ACE:494-WI-030/PV.V.Transfer.Daily.Ave.86400.18000.eAve | M1: \\usmlmes\USMLPI_MDB\USMLPIMBD\Conversions and Totals\GenTo2valTotal.24.5|ACE:494-WI-030/PV.V.Transfer.Daily.StdDev.86400.18000.eStdDev | N1: \\usmlmes\USMLPI_MDB\USMLPIMBD\Conversions and Totals\GenTo2valTotal.24.5|Formula
A2: {=_xll.PISampDat(Sheet1!$B$1,"t-30d","t","1d",1,"")} -> #NAME? | B2: #NAME? | C2: {=_xll.PISampDat(Sheet1!$C$1,"t-30d","t","1d",0,"")} -> #NAME? | D2: {=_xll.PISampDat(Sheet1!$D$1,"t-30d","t","1d",0,"")} -> #NAME? | E2: {=_xll.PISampDat(Sheet1!$E$1,"t-30d","t","1d",0,"")} -> #NAME? | F2: {=_xll.PISampDat(Sheet1!$F$1,"t-30d","t","1d",0,"")} -> #NAME? | G2: {=_xll.PISampDat(Sheet1!$G$1,"t-30d","t","1d",0,"")} -> #NAME? | H2: {=_xll.PISampDat(Sheet1!$H$1,"t-30d","t","1d",0,"")} -> #NAME? | I2: {=_xll.PISampDat(Sheet1!$I$1,"t-30d","t","1d",0,"")} -> #NAME? | J2: {=_xll.PISampDat(Sheet1!$J$1,"t-30d","t","1d",0,"")} -> #NAME? | K2: {=_xll.PISampDat(Sheet1!$K$1,"t-30d","t","1d",0,"")} -> #NAME? | L2: {=_xll.PISampDat(Sheet1!$L$1,"t-30d","t","1d",0,"")} -> #NAME? | M2: {=_xll.PISampDat(Sheet1!$M$1,"t-30d","t","1d",0,"")} -> #NAME? | N2: {=_xll.PISampDat(Sheet1!$N$1,"t-30d","t","1d",0,"")} -> #NAME?
A3: #NAME? | B3: #NAME? | C3: #NAME? | D3: #NAME? | E3: #NAME? | F3: #NAME? | G3: #NAME? | H3: #NAME? | I3: #NAME? | J3: #NAME? | K3: #NAME? | L3: #NAME? | M3: #NAME? | N3: #NAME?
A4: #NAME? | B4: #NAME? | C4: #NAME? | D4: #NAME? | E4: #NAME? | F4: #NAME? | G4: #NAME? | H4: #NAME? | I4: #NAME? | J4: #NAME? | K4: #NAME? | L4: #NAME? | M4: #NAME? | N4: #NAME?
A5: #NAME? | B5: #NAME? | C5: #NAME? | D5: #NAME? | E5: #NAME? | F5: #NAME? | G5: #NAME? | H5: #NAME? | I5: #NAME? | J5: #NAME? | K5: #NAME? | L5: #NAME? | M5: #NAME? | N5: #NAME?
A6: #NAME? | B6: #NAME? | C6: #NAME? | D6: #NAME? | E6: #NAME? | F6: #NAME? | G6: #NAME? | H6: #NAME? | I6: #NAME? | J6: #NAME? | K6: #NAME? | L6: #NAME? | M6: #NAME? | N6: #NAME?
A7: #NAME? | B7: #NAME? | C7: #NAME? | D7: #NAME? | E7: #NAME? | F7: #NAME? | G7: #NAME? | H7: #NAME? | I7: #NAME? | J7: #NAME? | K7: #NAME? | L7: #NAME? | M7: #NAME? | N7: #NAME?
A8: #NAME? | B8: #NAME? | C8: #NAME? | D8: #NAME? | E8: #NAME? | F8: #NAME? | G8: #NAME? | H8: #NAME? | I8: #NAME? | J8: #NAME? | K8: #NAME? | L8: #NAME? | M8: #NAME? | N8: #NAME?
A9: #NAME? | B9: #NAME? | C9: #NAME? | D9: #NAME? | E9: #NAME? | F9: #NAME? | G9: #NAME? | H9: #NAME? | I9: #NAME? | J9: #NAME? | K9: #NAME? | L9: #NAME? | M9: #NAME? | N9: #NAME?
A10: #NAME? | B10: #NAME? | C10: #NAME? | D10: #NAME? | E10: #NAME? | F10: #NAME? | G10: #NAME? | H10: #NAME? | I10: #NAME? | J10: #NAME? | K10: #NAME? | L10: #NAME? | M10: #NAME? | N10: #NAME?
A11: #NAME? | B11: #NAME? | C11: #NAME? | D11: #NAME? | E11: #NAME? | F11: #NAME? | G11: #NAME? | H11: #NAME? | I11: #NAME? | J11: #NAME? | K11: #NAME? | L11: #NAME? | M11: #NAME? | N11: #NAME?
A12: #NAME? | B12: #NAME? | C12: #NAME? | D12: #NAME? | E12: #NAME? | F12: #NAME? | G12: #NAME? | H12: #NAME? | I12: #NAME? | J12: #NAME? | K12: #NAME? | L12: #NAME? | M12: #NAME? | N12: #NAME?
A13: #NAME? | B13: #NAME? | C13: #NAME? | D13: #NAME? | E13: #NAME? | F13: #NAME? | G13: #NAME? | H13: #NAME? | I13: #NAME? | J13: #NAME? | K13: #NAME? | L13: #NAME? | M13: #NAME? | N13: #NAME?
A14: #NAME? | B14: #NAME? | C14: #NAME? | D14: #NAME? | E14: #NAME? | F14: #NAME? | G14: #NAME? | H14: #NAME? | I14: #NAME? | J14: #NAME? | K14: #NAME? | L14: #NAME? | M14: #NAME? | N14: #NAME?
... A32: #NAME? | B32: #NAME? | C32: #NAME? | D32: #NAME? | E32: #NAME? | F32: #NAME? | G32: #NAME? | H32: #NAME? | I32: #NAME? | J32: #NAME? | K32: #NAME? | L32: #NAME? | M32: #NAME? | N32: #NAME?

Sheet Sheet4
A1: Timestamps | B1: \\usmlmes\USMLPI_MDB\USMLPIMBD\Conversions and Totals\GenTo2valTotal.24.5\OutputTags|ACE:315.Coal.Consumption.Day.Total.86400.18000.2Tot | C1: \\usmlmes\USMLPI_MDB\USMLPIMBD\Conversions and Totals\GenTo2valTotal.24.5\OutputTags|ACE:315.SCC.Feed.Day.Total.86400.18000.2Tot | D1: \\usmlmes\USMLPI_MDB\USMLPIMBD\Conversions and Totals\GenTo2valTotal.24.5\OutputTags|ACE:345-TIC-007C/MVC.QON.Daily.Utilization.86400.18000.2Tot | E1: \\usmlmes\USMLPI_MDB\USMLPIMBD\Conversions and Totals\GenTo2valTotal.24.5\OutputTags|ACE:345-WI-006/PV.V.Transfer.Daily.Ave.86400.18000.eAve | F1: \\usmlmes\USMLPI_MDB\USMLPIMBD\Conversions and Totals\GenTo2valTotal.24.5\OutputTags|ACE:345-WI-006/PV.V.Transfer.Daily.StdDev.86400.18000.eStdDev | G1: \\usmlmes\USMLPI_MDB\USMLPIMBD\Conversions and Totals\GenTo2valTotal.24.5\OutputTags|ACE:345-WI-007/PV.V.Transfer.Daily.Ave.86400.18000.eAve | H1: \\usmlmes\USMLPI_MDB\USMLPIMBD\Conversions and Totals\GenTo2valTotal.24.5\OutputTags|ACE:345-WI-007/PV.V.Transfer.Daily.StdDev.86400.18000.eStdDev | I1: \\usmlmes\USMLPI_MDB\USMLPIMBD\Conversions and Totals\GenTo2valTotal.24.5\OutputTags|ACE:414-PIC-610C/MVC.QON.Daily.Utilization.86400.18000.2Tot | J1: \\usmlmes\USMLPI_MDB\USMLPIMBD\Conversions and Totals\GenTo2valTotal.24.5\OutputTags|ACE:494-WI-020/PV.V.Transfer.Daily.Ave.86400.18000.eAve | K1: \\usmlmes\USMLPI_MDB\USMLPIMBD\Conversions and Totals\GenTo2valTotal.24.5\OutputTags|ACE:494-WI-020/PV.V.Transfer.Daily.StdDev.86400.18000.eStdDev | L1: \\usmlmes\USMLPI_MDB\USMLPIMBD\Conversions and Totals\GenTo2valTotal.24.5\OutputTags|ACE:494-WI-030/PV.V.Transfer.Daily.Ave.86400.18000.eAve | M1: \\usmlmes\USMLPI_MDB\USMLPIMBD\Conversions and Totals\GenTo2valTotal.24.5\OutputTags|ACE:494-WI-030/PV.V.Transfer.Daily.StdDev.86400.18000.eStdDev | N1: \\usmlmes\USMLPI_MDB\USMLPIMBD\Conversions and Totals\GenTo2valTotal.24.5\OutputTags|NotusedPlaceholder
A2: {=_xll.PISampDat(Sheet4!$B$1,"t-30d","t","86400s",1,"")} -> #NAME? | B2: #NAME? | C2: {=_xll.PISampDat(Sheet4!$C$1,"t-30d","t","86400s",0,"")} -> #NAME? | D2: {=_xll.PISampDat(Sheet4!$D$1,"t-30d","t","86400s",0,"")} -> #NAME? | E2: {=_xll.PISampDat(Sheet4!$E$1,"t-30d","t","86400s",0,"")} -> #NAME? | F2: {=_xll.PISampDat(Sheet4!$F$1,"t-30d","t","86400s",0,"")} -> #NAME? | G2: {=_xll.PISampDat(Sheet4!$G$1,"t-30d","t","86400s",0,"")} -> #NAME? | H2: {=_xll.PISampDat(Sheet4!$H$1,"t-30d","t","86400s",0,"")} -> #NAME? | I2: {=_xll.PISampDat(Sheet4!$I$1,"t-30d","t","86400s",0,"")} -> #NAME? | J2: {=_xll.PISampDat(Sheet4!$J$1,"t-30d","t","86400s",0,"")} -> #NAME? | K2: {=_xll.PISampDat(Sheet4!$K$1,"t-30d","t","86400s",0,"")} -> #NAME? | L2: {=_xll.PISampDat(Sheet4!$L$1,"t-30d","t","86400s",0,"")} -> #NAME? | M2: {=_xll.PISampDat(Sheet4!$M$1,"t-30d","t","86400s",0,"")} -> #NAME? | N2: {=_xll.PISampDat(Sheet4!$N$1,"t-30d","t","86400s",0,"")} -> #NAME?
A3: #NAME? | B3: #NAME? | C3: #NAME? | D3: #NAME? | E3: #NAME? | F3: #NAME? | G3: #NAME? | H3: #NAME? | I3: #NAME? | J3: #NAME? | K3: #NAME? | L3: #NAME? | M3: #NAME? | N3: #NAME?
A4: #NAME? | B4: #NAME? | C4: #NAME? | D4: #NAME? | E4: #NAME? | F4: #NAME? | G4: #NAME? | H4: #NAME? | I4: #NAME? | J4: #NAME? | K4: #NAME? | L4: #NAME? | M4: #NAME? | N4: #NAME?
A5: #NAME? | B5: #NAME? | C5: #NAME? | D5: #NAME? | E5: #NAME? | F5: #NAME? | G5: #NAME? | H5: #NAME? | I5: #NAME? | J5: #NAME? | K5: #NAME? | L5: #NAME? | M5: #NAME? | N5: #NAME?
A6: #NAME? | B6: #NAME? | C6: #NAME? | D6: #NAME? | E6: #NAME? | F6: #NAME? | G6: #NAME? | H6: #NAME? | I6: #NAME? | J6: #NAME? | K6: #NAME? | L6: #NAME? | M6: #NAME? | N6: #NAME?
A7: #NAME? | B7: #NAME? | C7: #NAME? | D7: #NAME? | E7: #NAME? | F7: #NAME? | G7: #NAME? | H7: #NAME? | I7: #NAME? | J7: #NAME? | K7: #NAME? | L7: #NAME? | M7: #NAME? | N7: #NAME?
A8: #NAME? | B8: #NAME? | C8: #NAME? | D8: #NAME? | E8: #NAME? | F8: #NAME? | G8: #NAME? | H8: #NAME? | I8: #NAME? | J8: #NAME? | K8: #NAME? | L8: #NAME? | M8: #NAME? | N8: #NAME?
A9: #NAME? | B9: #NAME? | C9: #NAME? | D9: #NAME? | E9: #NAME? | F9: #NAME? | G9: #NAME? | H9: #NAME? | I9: #NAME? | J9: #NAME? | K9: #NAME? | L9: #NAME? | M9: #NAME? | N9: #NAME?
A10: #NAME? | B10: #NAME? | C10: #NAME? | D10: #NAME? | E10: #NAME? | F10: #NAME? | G10: #NAME? | H10: #NAME? | I10: #NAME? | J10: #NAME? | K10: #NAME? | L10: #NAME? | M10: #NAME? | N10: #NAME?
A11: #NAME? | B11: #NAME? | C11: #NAME? | D11: #NAME? | E11: #NAME? | F11: #NAME? | G11: #NAME? | H11: #NAME? | I11: #NAME? | J11: #NAME? | K11: #NAME? | L11: #NAME? | M11: #NAME? | N11: #NAME?
A12: #NAME? | B12: #NAME? | C12: #NAME? | D12: #NAME? | E12: #NAME? | F12: #NAME? | G12: #NAME? | H12: #NAME? | I12: #NAME? | J12: #NAME? | K12: #NAME? | L12: #NAME? | M12: #NAME? | N12: #NAME?
A13: #NAME? | B13: #NAME? | C13: #NAME? | D13: #NAME? | E13: #NAME? | F13: #NAME? | G13: #NAME? | H13: #NAME? | I13: #NAME? | J13: #NAME? | K13: #NAME? | L13: #NAME? | M13: #NAME? | N13: #NAME?
A14: #NAME? | B14: #NAME? | C14: #NAME? | D14: #NAME? | E14: #NAME? | F14: #NAME? | G14: #NAME? | H14: #NAME? | I14: #NAME? | J14: #NAME? | K14: #NAME? | L14: #NAME? | M14: #NAME? | N14: #NAME?
... A32: #NAME? | B32: #NAME? | C32: #NAME? | D32: #NAME? | E32: #NAME? | F32: #NAME? | G32: #NAME? | H32: #NAME? | I32: #NAME? | J32: #NAME? | K32: #NAME? | L32: #NAME? | M32: #NAME? | N32: #NAME?

Sheet Sheet6
A1: Timestamps | B1: \\usmlpi.angloiit.net\T:350-PY-201/PV.V.TIM | C1: \\usmlpi.angloiit.net\345-LI-203/PV.V | D1: \\usmlpi.angloiit.net\ACE:315.Coal.Consumption.Day.Total | E1: \\usmlpi.angloiit.net\T:345-WIT-301/PV.V.TIM
A2: {=_xll.PISampDat(Sheet6!$B$1,"t-30d","t","86400s",1,"")} -> #NAME? | B2: #NAME? | C2: {=_xll.PISampDat(Sheet6!$C$1,"t-30d","t","86400s",0,"")} -> #NAME? | D2: {=_xll.PISampDat(Sheet6!$D$1,"t-30d","t","86400s",0,"")} -> #NAME? | E2: {=_xll.PISampDat(Sheet6!$E$1,"t-30d","t","86400s",0,"")} -> #NAME?
A3: #NAME? | B3: #NAME? | C3: #NAME? | D3: #NAME? | E3: #NAME?
A4: #NAME? | B4: #NAME? | C4: #NAME? | D4: #NAME? | E4: #NAME?
A5: #NAME? | B5: #NAME? | C5: #NAME? | D5: #NAME? | E5: #NAME?
A6: #NAME? | B6: #NAME? | C6: #NAME? | D6: #NAME? | E6: #NAME?
A7: #NAME? | B7: #NAME? | C7: #NAME? | D7: #NAME? | E7: #NAME?
A8: #NAME? | B8: #NAME? | C8: #NAME? | D8: #NAME? | E8: #NAME?
A9: #NAME? | B9: #NAME? | C9: #NAME? | D9: #NAME? | E9: #NAME?
A10: #NAME? | B10: #NAME? | C10: #NAME? | D10: #NAME? | E10: #NAME?
A11: #NAME? | B11: #NAME? | C11: #NAME? | D11: #NAME? | E11: #NAME?
A12: #NAME? | B12: #NAME? | C12: #NAME? | D12: #NAME? | E12: #NAME?
A13: #NAME? | B13: #NAME? | C13: #NAME? | D13: #NAME? | E13: #NAME?
A14: #NAME? | B14: #NAME? | C14: #NAME? | D14: #NAME? | E14: #NAME?
... A32: #NAME? | B32: #NAME? | C32: #NAME? | D32: #NAME? | E32: #NAME?

Sheet Sheet8
B1: \\usmlmes\USMLPI_MDB\USMLPIMBD\Conversions and Totals\GenTo2valTotal.24.5|Formula|ACE:315.Coal.Consumption.Day.Total.86400.18000.2Tot | C1: \\usmlmes\USMLPI_MDB\USMLPIMBD\Conversions and Totals\GenTo2valTotal.24.5|Formula|ACE:315.SCC.Feed.Day.Total.86400.18000.2Tot | D1: \\usmlmes\USMLPI_MDB\USMLPIMBD\Conversions and Totals\GenTo2valTotal.24.5|Formula|ACE:345-TIC-007C/MVC.QON.Daily.Utilization.86400.18000.2Tot | E1: \\usmlmes\USMLPI_MDB\USMLPIMBD\Conversions and Totals\GenTo2valTotal.24.5|Formula|ACE:414-PIC-610C/MVC.QON.Daily.Utilization.86400.18000.2Tot | F1: \\usmlmes\USMLPI_MDB\USMLPIMBD\Conversions and Totals\GenTo2valTotal.24.5|Formula|ACE:FCE_bin_TOT.Daily.total.86400.18300.MeasE
A2: {=_xll.PISampDat(Sheet8!$B$1,"t-30d","t","86400s",1,"")} -> #NAME? | B2: #NAME? | C2: {=_xll.PISampDat(Sheet8!$C$1,"t-30d","t","86400s",0,"")} -> #NAME? | D2: {=_xll.PISampDat(Sheet8!$D$1,"t-30d","t","86400s",0,"")} -> #NAME? | E2: {=_xll.PISampDat(Sheet8!$E$1,"t-30d","t","86400s",0,"")} -> #NAME? | F2: {=_xll.PISampDat(Sheet8!$F$1,"t-30d","t","86400s",0,"")} -> #NAME?
A3: #NAME? | B3: #NAME? | C3: #NAME? | D3: #NAME? | E3: #NAME? | F3: #NAME?
A4: #NAME? | B4: #NAME? | C4: #NAME? | D4: #NAME? | E4: #NAME? | F4: #NAME?
A5: #NAME? | B5: #NAME? | C5: #NAME? | D5: #NAME? | E5: #NAME? | F5: #NAME?
A6: #NAME? | B6: #NAME? | C6: #NAME? | D6: #NAME? | E6: #NAME? | F6: #NAME?
A7: #NAME? | B7: #NAME? | C7: #NAME? | D7: #NAME? | E7: #NAME? | F7: #NAME?
A8: #NAME? | B8: #NAME? | C8: #NAME? | D8: #NAME? | E8: #NAME? | F8: #NAME?
A9: #NAME? | B9: #NAME? | C9: #NAME? | D9: #NAME? | E9: #NAME? | F9: #NAME?
A10: #NAME? | B10: #NAME? | C10: #NAME? | D10: #NAME? | E10: #NAME? | F10: #NAME?
A11: #NAME? | B11: #NAME? | C11: #NAME? | D11: #NAME? | E11: #NAME? | F11: #NAME?
A12: #NAME? | B12: #NAME? | C12: #NAME? | D12: #NAME? | E12: #NAME? | F12: #NAME?
A13: #NAME? | B13: #NAME? | C13: #NAME? | D13: #NAME? | E13: #NAME? | F13: #NAME?
A14: #NAME? | B14: #NAME? | C14: #NAME? | D14: #NAME? | E14: #NAME? | F14: #NAME?
... A32: #NAME? | B32: #NAME? | C32: #NAME? | D32: #NAME? | E32: #NAME? | F32: #NAME?

Sheet FormulaParam
A1: ACE:315.Coal.Consumption.Day.Total.86400.18000.2Tot | B1: ACE:315.SCC.Feed.Day.Total.86400.18000.2Tot | C1: ACE:345-TIC-007C/MVC.QON.Daily.Utilization.86400.18000.2Tot | D1: ACE:414-PIC-610C/MVC.QON.Daily.Utilization.86400.18000.2Tot | E1: ACE:FCE_bin_TOT.Daily.total.86400.18300.MeasE
A2: tag'/1000 + ('x345-LI-203/PV.V'86400.18000.SInt' - 'x345-LI-203/PV.V'86400.18000.EInt') | B2: Coal.Consumption.Day.Total'86400.18000.2Tot'*1000/'tag' | C2: 'tag'/'T:345-WIT-301/PV.V.TIM'86400.18000.2Tot'*100 | D2: 'tag'/'T:350-PY-201/PV.V.TIM'86400.18000.2Tot'*100 | E2: 'tag' + 'FCE_Wbin_TOT/REPORT.V_DISP'86400.18300.MeasE'

Sheet Formula
A1: Timestamps | B1: T:350-PY-201/PV.V.TIM | C1: 345-LI-203/PV.V | D1: ACE:315.Coal.Consumption.Day.Total | E1: T:345-WIT-301/PV.V.TIM
A2: 45033 | B2: 22.528936 | C2: 89.031151 | D2: -10.090487 | E2: 22.361109
A3: 45034 | B3: 21.894476 | C3: 84.538925 | D3: 0.9266001 | E3: 0.13830833
A4: 45035 | B4: 3.6589208 | C4: 83.446808 | D4: 0.72305781 | E4: 0.0083333338
A5: 45036 | B5: 0 | C5: 83.475746 | D5: -0.082313396 | E5: 0
A6: 45037 | B6: 0 | C6: 83.446808 | D6: 0.080219999 | E6: 0
A7: 45038 | B7: 0.16545278 | C7: 81.878571 | D7: 6.6201057 | E7: 5.9449673
A8: 45039 | B8: 9.2679291 | C8: 56.624622 | D8: 24.678551 | E8: 23.563881
A9: 45040 | B9: 19.132957 | C9: 37.006504 | D9: 15.625204 | E9: 15.210649
A10: 45041 | B10: 22.93222 | C10: 36.920296 | D10: -0.002521642 | E10: 0.29445416
A11: 45042 | B11: 11.557015 | C11: 36.430851 | D11: 0.40788999 | E11: 0
A12: 45043 | B12: 15.518989 | C12: 36.457344 | D12: 0.049146831 | E12: 0
A13: 45044 | B13: 15.999063 | C13: 36.457344 | D13: -0.050593302 | E13: 0
... A32: 45063 | B32: 0 | C32: 90 | D32: -0.0044245739 | E32: 0

Sheet Outputs
A1: Timestamps | B1: \\usmlmes\USMLPI_MDB\USMLPIMBD\Conversions and Totals\GenTo2valTotal.24.5\OutputTags|ACE:315.Coal.Consumption.Day.Total.86400.18000.2Tot | C1: \\usmlmes\USMLPI_MDB\USMLPIMBD\Conversions and Totals\GenTo2valTotal.24.5\OutputTags|ACE:315.SCC.Feed.Day.Total.86400.18000.2Tot | D1: \\usmlmes\USMLPI_MDB\USMLPIMBD\Conversions and Totals\GenTo2valTotal.24.5\OutputTags|ACE:345-TIC-007C/MVC.QON.Daily.Utilization.86400.18000.2Tot | E1: \\usmlmes\USMLPI_MDB\USMLPIMBD\Conversions and Totals\GenTo2valTotal.24.5\OutputTags|ACE:345-WI-006/PV.V.Transfer.Daily.Ave.86400.18000.eAve | F1: \\usmlmes\USMLPI_MDB\USMLPIMBD\Conversions and Totals\GenTo2valTotal.24.5\OutputTags|ACE:345-WI-006/PV.V.Transfer.Daily.StdDev.86400.18000.eStdDev | G1: \\usmlmes\USMLPI_MDB\USMLPIMBD\Conversions and Totals\GenTo2valTotal.24.5\OutputTags|ACE:345-WI-007/PV.V.Transfer.Daily.Ave.86400.18000.eAve | H1: \\usmlmes\USMLPI_MDB\USMLPIMBD\Conversions and Totals\GenTo2valTotal.24.5\OutputTags|ACE:345-WI-007/PV.V.Transfer.Daily.StdDev.86400.18000.eStdDev | I1: \\usmlmes\USMLPI_MDB\USMLPIMBD\Conversions and Totals\GenTo2valTotal.24.5\OutputTags|ACE:414-PIC-610C/MVC.QON.Daily.Utilization.86400.18000.2Tot | J1: \\usmlmes\USMLPI_MDB\USMLPIMBD\Conversions and Totals\GenTo2valTotal.24.5\OutputTags|ACE:494-WI-020/PV.V.Transfer.Daily.Ave.86400.18000.eAve | K1: \\usmlmes\USMLPI_MDB\USMLPIMBD\Conversions and Totals\GenTo2valTotal.24.5\OutputTags|ACE:494-WI-020/PV.V.Transfer.Daily.StdDev.86400.18000.eStdDev | L1: \\usmlmes\USMLPI_MDB\USMLPIMBD\Conversions and Totals\GenTo2valTotal.24.5\OutputTags|ACE:494-WI-030/PV.V.Transfer.Daily.Ave.86400.18000.eAve | M1: \\usmlmes\USMLPI_MDB\USMLPIMBD\Conversions and Totals\GenTo2valTotal.24.5\OutputTags|ACE:494-WI-030/PV.V.Transfer.Daily.StdDev.86400.18000.eStdDev | N1: \\usmlmes\USMLPI_MDB\USMLPIMBD\Conversions and Totals\GenTo2valTotal.24.5\OutputTags|NotusedPlaceholder
A2: 45033 | B2: -10.090487 | C2: -7.7361007 | D2: Calc Crash | E2: 0.48462918 | F2: 0.25628009 | G2: 0.67572117 | H2: 0.90772849 | I2: Calc Crash | J2: Calc Failed | K2: No Sample | L2: 0.66326094 | M2: No Sample | N2: Pt Created
A3: 45034 | B3: 0.9266001 | C3: 133.21039 | D3: Calc Crash | E3: 0.02184456 | F3: 0.02658616 | G3: 0.0062239151 | H3: 0.041160922 | I3: Calc Crash | J3: Calc Failed | K3: No Sample | L3: 0.62762022 | M3: No Sample | N3: Pt Created
A4: 45035 | B4: 0.72305781 | C4: Calc Crash | D4: Calc Crash | E4: Calc Failed | F4: No Sample | G4: Calc Failed | H4: No Sample | I4: Calc Crash | J4: Calc Failed | K4: No Sample | L4: 0.58254594 | M4: No Sample | N4: Pt Created
A5: 45036 | B5: -0.082313396 | C5: Calc Crash | D5: Calc Crash | E5: 1.8980964 | F5: 2.6712196 | G5: Calc Failed | H5: No Sample | I5: Calc Crash | J5: Calc Failed | K5: No Sample | L5: Calc Failed | M5: No Sample | N5: Pt Created
A6: 45037 | B6: 0.080219999 | C6: Calc Crash | D6: Calc Crash | E6: Calc Failed | F6: No Sample | G6: Calc Failed | H6: No Sample | I6: Calc Crash | J6: Calc Failed | K6: No Sample | L6: Calc Failed | M6: No Sample | N6: Pt Created
A7: 45038 | B7: 6.6201057 | C7: 16.008919 | D7: Calc Crash | E7: 0.11378632 | F7: 0.19776294 | G7: 0.98984265 | H7: 1.3211498 | I7: Calc Crash | J7: Calc Failed | K7: No Sample | L7: Calc Failed | M7: No Sample | N7: Pt Created
A8: 45039 | B8: 24.678551 | C8: 24.27739 | D8: Calc Crash | E8: 0.42334244 | F8: 0.56156075 | G8: 0.36171427 | H8: 0.72194719 | I8: Calc Crash | J8: Calc Failed | K8: No Sample | L8: Calc Failed | M8: No Sample | N8: Pt Created
A9: 45040 | B9: 15.625204 | C9: Calc Crash | D9: Calc Crash | E9: 0.48069683 | F9: 0.01274871 | G9: 0.2235314 | H9: 0.52833909 | I9: Calc Crash | J9: Calc Failed | K9: No Sample | L9: Calc Failed | M9: No Sample | N9: Pt Created
A10: 45041 | B10: -0.002521642 | C10: Calc Crash | D10: Calc Crash | E10: Calc Failed | F10: No Sample | G10: 1.326816 | H10: 2.5749195 | I10: Calc Crash | J10: Calc Failed | K10: No Sample | L10: Calc Failed | M10: No Sample | N10: Pt Created
A11: 45042 | B11: 0.40788999 | C11: Calc Crash | D11: Calc Crash | E11: Calc Failed | F11: No Sample | G11: Calc Failed | H11: No Sample | I11: Calc Crash | J11: Calc Failed | K11: No Sample | L11: Calc Failed | M11: No Sample | N11: Pt Created
A12: 45043 | B12: 0.049146831 | C12: Calc Crash | D12: Calc Crash | E12: Calc Failed | F12: No Sample | G12: Calc Failed | H12: No Sample | I12: Calc Crash | J12: Calc Failed | K12: No Sample | L12: Calc Failed | M12: No Sample | N12: Pt Created
A13: 45044 | B13: -0.050593302 | C13: Calc Crash | D13: Calc Crash | E13: Calc Failed | F13: No Sample | G13: Calc Failed | H13: No Sample | I13: Calc Crash | J13: Calc Failed | K13: No Sample | L13: 0.29937461 | M13: No Sample | N13: Pt Created
A14: 45045 | B14: 0.26041001 | C14: Calc Crash | D14: Calc Crash | E14: Calc Failed | F14: No Sample | G14: 0 | H14: 0 | I14: Calc Crash | J14: Calc Failed | K14: No Sample | L14: 0.010561053 | M14: No Sample | N14: Pt Created
A15: 45046 | B15: 0.11573 | C15: Calc Crash | D15: Calc Crash | E15: Calc Failed | F15: No Sample | G15: Calc Failed | H15: No Sample | I15: Calc Crash | J15: Calc Failed | K15: No Sample | L15: 0.35022196 | M15: No Sample | N15: Pt Created
A16: 45047 | B16: 0 | C16: Calc Crash | D16: Calc Crash | E16: Calc Failed | F16: No Sample | G16: Calc Failed | H16: No Sample | I16: Calc Crash | J16: Calc Failed | K16: No Sample | L16: Calc Failed | M16: No Sample | N16: Pt Created
A17: 45048 | B17: 0.0096032675 | C17: Calc Crash | D17: Calc Crash | E17: Calc Failed | F17: No Sample | G17: 0.001543164 | H17: 0.0033227741 | I17: Calc Crash | J17: Calc Failed | K17: No Sample | L17: Calc Failed | M17: No Sample | N17: Pt Created
A18: 45049 | B18: -0.7466138 | C18: Calc Crash | D18: Calc Crash | E18: Calc Failed | F18: No Sample | G18: Calc Failed | H18: No Sample | I18: Calc Crash | J18: Calc Failed | K18: No Sample | L18: Calc Failed | M18: No Sample | N18: Pt Created
A19: 45050 | B19: -0.036974117 | C19: Calc Crash | D19: Calc Crash | E19: Calc Failed | F19: No Sample | G19: Calc Failed | H19: No Sample | I19: Calc Crash | J19: Calc Failed | K19: No Sample | L19: Calc Failed | M19: No Sample | N19: Pt Created
A20: 45051 | B20: -0.079809383 | C20: Calc Crash | D20: Calc Crash | E20: Calc Failed | F20: No Sample | G20: 0.0069442755 | H20: 0.011802988 | I20: Calc Crash | J20: Calc Failed | K20: No Sample | L20: 0.82752383 | M20: No Sample | N20: Pt Created
A21: 45052 | B21: 0.71926641 | C21: Calc Crash | D21: Calc Crash | E21: Calc Failed | F21: No Sample | G21: Calc Failed | H21: No Sample | I21: Calc Crash | J21: Calc Failed | K21: No Sample | L21: Calc Failed | M21: No Sample | N21: Pt Created
A22: 45053 | B22: -0.71277022 | C22: Calc Crash | D22: Calc Crash | E22: Calc Failed | F22: No Sample | G22: 0.00077158201 | H22: 0.0013364193 | I22: Calc Crash | J22: Calc Failed | K22: No Sample | L22: 0 | M22: No Sample | N22: Pt Created
A23: 45054 | B23: 0.57844532 | C23: 34295840 | D23: Calc Crash | E23: Calc Failed | F23: No Sample | G23: Calc Failed | H23: No Sample | I23: Calc Crash | J23: Calc Failed | K23: No Sample | L23: Calc Failed | M23: No Sample | N23: Pt Created
A24: 45055 | B24: -0.4329192 | C24: Calc Crash | D24: Calc Crash | E24: Calc Failed | F24: No Sample | G24: Calc Failed | H24: No Sample | I24: Calc Crash | J24: Calc Failed | K24: No Sample | L24: Calc Failed | M24: No Sample | N24: Pt Created
A25: 45056 | B25: -0.11261296 | C25: -5205075 | D25: Calc Crash | E25: Calc Failed | F25: No Sample | G25: Calc Failed | H25: No Sample | I25: Calc Crash | J25: Calc Failed | K25: No Sample | L25: Calc Failed | M25: No Sample | N25: Pt Created
A26: 45057 | B26: -0.030609898 | C26: Calc Crash | D26: Calc Crash | E26: Calc Failed | F26: No Sample | G26: Calc Failed | H26: No Sample | I26: Calc Crash | J26: Calc Failed | K26: No Sample | L26: Calc Failed | M26: No Sample | N26: Pt Created
A27: 45058 | B27: 0 | C27: Calc Crash | D27: Calc Crash | E27: Calc Failed | F27: No Sample | G27: Calc Failed | H27: No Sample | I27: Calc Crash | J27: Calc Failed | K27: No Sample | L27: Calc Failed | M27: No Sample | N27: Pt Created
A28: 45059 | B28: -0.086800002 | C28: Calc Crash | D28: Calc Crash | E28: Calc Failed | F28: No Sample | G28: Calc Failed | H28: No Sample | I28: Calc Crash | J28: Calc Failed | K28: No Sample | L28: Calc Failed | M28: No Sample | N28: Pt Created
A29: 45060 | B29: -52.96759 | C29: -1057076.1 | D29: Calc Crash | E29: Calc Failed | F29: No Sample | G29: Calc Failed | H29: No Sample | I29: Calc Crash | J29: Calc Failed | K29: No Sample | L29: Calc Failed | M29: No Sample | N29: Pt Created
A30: 45061 | B30: -0.0044250279 | C30: Calc Crash | D30: Calc Crash | E30: Calc Failed | F30: No Sample | G30: Calc Failed | H30: No Sample | I30: Calc Crash | J30: Calc Failed | K30: No Sample | L30: Calc Failed | M30: No Sample | N30: Pt Created
A31: 45062 | B31: -0.0044248011 | C31: Calc Crash | D31: Calc Crash | E31: Calc Failed | F31: No Sample | G31: Calc Failed | H31: No Sample | I31: Calc Crash | J31: Calc Failed | K31: No Sample | L31: Calc Failed | M31: No Sample | N31: Pt Created
A32: 45063 | B32: -0.0044245739 | C32: Calc Crash | D32: Calc Crash | E32: Calc Failed | F32: No Sample | G32: Calc Failed | H32: No Sample | I32: Calc Crash | J32: Calc Failed | K32: No Sample | L32: Calc Failed | M32: No Sample | N32: Pt Created

Sheet Sheet2
A1: Timestamps | B1: ACE:315.Coal.Consumption.Day.Total.86400.18000.2Tot | C1: ACE:315.SCC.Feed.Day.Total.86400.18000.2Tot | D1: ACE:345-TIC-007C/MVC.QON.Daily.Utilization.86400.18000.2Tot | E1: ACE:345-WI-006/PV.V.Transfer.Daily.Ave.86400.18000.eAve | F1: ACE:345-WI-006/PV.V.Transfer.Daily.StdDev.86400.18000.eStdDev | G1: ACE:345-WI-007/PV.V.Transfer.Daily.Ave.86400.18000.eAve | H1: ACE:345-WI-007/PV.V.Transfer.Daily.StdDev.86400.18000.eStdDev | I1: ACE:414-PIC-610C/MVC.QON.Daily.Utilization.86400.18000.2Tot | J1: ACE:494-WI-020/PV.V.Transfer.Daily.Ave.86400.18000.eAve | K1: ACE:494-WI-020/PV.V.Transfer.Daily.StdDev.86400.18000.eStdDev | L1: ACE:494-WI-030/PV.V.Transfer.Daily.Ave.86400.18000.eAve | M1: ACE:494-WI-030/PV.V.Transfer.Daily.StdDev.86400.18000.eStdDev
A2: 45027 | B2: 33.74091 | C2: 1331.9534 | D2: 24.000193 | E2: Good-Off | F2: Good-Off | G2: 0 | H2: 0 | I2: 23.357143 | J2: No Sample | K2: No Sample | L2: No Sample | M2: No Sample
A3: 45028 | B3: 40.164532 | C3: 1011.4565 | D3: 20.455153 | E3: Good-Off | F3: Good-Off | G3: 0 | H3: 0 | I3: 23.999081 | J3: Good-Off | K3: Good-Off | L3: Good-Off | M3: Good-Off
A4: 45029 | B4: 39.301498 | C4: 1202.5372 | D4: 20.005995 | E4: Good-Off | F4: Good-Off | G4: 0.93747455 | H4: 0.93747455 | I4: 23.835314 | J4: No Sample | K4: No Sample | L4: No Sample | M4: No Sample
A5: 45030 | B5: 4.0103574 | C5: 1092.9659 | D5: 17.849306 | E5: Good-Off | F5: Good-Off | G5: 5.8702111 | H5: 5.8702111 | I5: 23.806341 | J5: No Sample | K5: No Sample | L5: No Sample | M5: No Sample
A6: 45031 | B6: 39.470695 | C6: 1365.9036 | D6: 22.051285 | E6: Good-Off | F6: Good-Off | G6: 0 | H6: 0 | I6: 23.999077 | J6: No Sample | K6: No Sample | L6: No Sample | M6: No Sample
A7: 45032 | B7: 46.654232 | C7: 1464.3242 | D7: 23.969913 | E7: Good-Off | F7: Good-Off | G7: 0 | H7: 0 | I7: 23.838566 | J7: No Sample | K7: No Sample | L7: No Sample | M7: No Sample
A8: 45033 | B8: 46.202255 | C8: 1304.3375 | D8: 21.592072 | E8: Good-Off | F8: Good-Off | G8: 0.87266147 | H8: 0.87266147 | I8: 22.528009 | J8: No Sample | K8: No Sample | L8: No Sample | M8: No Sample
A9: 45034 | B9: 0 | C9: 6.9559155 | D9: 0.12108458 | E9: Good-Off | F9: Good-Off | G9: 8.4557886 | H9: 8.4557886 | I9: 21.892534 | J9: No Sample | K9: No Sample | L9: No Sample | M9: No Sample
A10: 45035 | B10: 0 | C10: Bad Total | D10: 0 | E10: Good-Off | F10: Good-Off | G10: 8.4557886 | H10: 8.4557886 | I10: 3.6392436 | J10: No Sample | K10: No Sample | L10: No Sample | M10: No Sample
A11: 45036 | B11: 0 | C11: Bad Total | D11: 0 | E11: Good-Off | F11: Good-Off | G11: 8.4557886 | H11: 8.4557886 | I11: 0 | J11: No Sample | K11: No Sample | L11: No Sample | M11: No Sample
A12: 45037 | B12: 0 | C12: Bad Total | D12: 0 | E12: Good-Off | F12: Good-Off | G12: 8.4557886 | H12: 8.4557886 | I12: 0 | J12: No Sample | K12: No Sample | L12: No Sample | M12: No Sample
A13: 45038 | B13: 0 | C13: 413.52609 | D13: 4.9930487 | E13: Good-Off | F13: Good-Off | G13: 8.4557886 | H13: 8.4557886 | I13: 0 | J13: Good-Off | K13: Good-Off | L13: Good-Off | M13: Good-Off
A14: 45039 | B14: 0 | C14: 1016.5237 | D14: 23.203506 | E14: Good-Off | F14: Good-Off | G14: 0 | H14: 0 | I14: 0 | J14: Good-Off | K14: Good-Off | L14: Good-Off | M14: Good-Off
A15: 45040 | B15: 0 | C15: 501.67346 | D15: 13.524963 | E15: Good-Off | F15: Good-Off | G15: 5.925765 | H15: 5.925765 | I15: 0 | J15: Good-Off | K15: Good-Off | L15: Good-Off | M15: Good-Off
A16: 45041 | B16: 0 | C16: 0 | D16: 0 | E16: Good-Off | F16: Good-Off | G16: 0 | H16: 0 | I16: 0 | J16: Good-Off | K16: Good-Off | L16: Good-Off | M16: Good-Off
A17: 45042 | B17: 0 | C17: Bad Total | D17: 0 | E17: Good-Off | F17: Good-Off | G17: 0 | H17: 0 | I17: 0 | J17: Good-Off | K17: Good-Off | L17: Good-Off | M17: Good-Off
A18: 45043 | B18: 0 | C18: 0 | D18: 0 | E18: Good-Off | F18: Good-Off | G18: 0 | H18: 0 | I18: 0 | J18: Good-Off | K18: Good-Off | L18: Good-Off | M18: Good-Off
A19: 45044 | B19: 0 | C19: 0 | D19: 0 | E19: Good-Off | F19: Good-Off | G19: 0 | H19: 0 | I19: 0 | J19: Good-Off | K19: Good-Off | L19: Good-Off | M19: Good-Off
A20: 45045 | B20: 0 | C20: 0 | D20: 0 | E20: Good-Off | F20: Good-Off | G20: Good-Off | H20: Good-Off | I20: 0 | J20: Good-Off | K20: Good-Off | L20: Good-Off | M20: Good-Off
A21: 45046 | B21: 0 | C21: 0 | D21: 0 | E21: Good-Off | F21: Good-Off | G21: Good-Off | H21: Good-Off | I21: 0 | J21: Good-Off | K21: Good-Off | L21: Good-Off | M21: Good-Off
A22: 45047 | B22: 0 | C22: 0 | D22: 0 | E22: Good-Off | F22: Good-Off | G22: Good-Off | H22: Good-Off | I22: 0 | J22: Good-Off | K22: Good-Off | L22: Good-Off | M22: Good-Off
A23: 45048 | B23: 0 | C23: 0 | D23: 0 | E23: Good-Off | F23: Good-Off | G23: Good-Off | H23: Good-Off | I23: 0 | J23: Good-Off | K23: Good-Off | L23: Good-Off | M23: Good-Off
A24: 45049 | B24: 4.0963206 | C24: 0 | D24: 0 | E24: Good-Off | F24: Good-Off | G24: Good-Off | H24: Good-Off | I24: 0 | J24: Good-Off | K24: Good-Off | L24: Good-Off | M24: Good-Off
A25: 45050 | B25: 0 | C25: 0 | D25: 0 | E25: Good-Off | F25: Good-Off | G25: Good-Off | H25: Good-Off | I25: 0 | J25: Good-Off | K25: Good-Off | L25: Good-Off | M25: Good-Off
A26: 45051 | B26: 0.0017381232 | C26: 0.00051635387 | D26: 0 | E26: Good-Off | F26: Good-Off | G26: Good-Off | H26: Good-Off | I26: 0 | J26: Good-Off | K26: Good-Off | L26: Good-Off | M26: Good-Off
A27: 45052 | B27: 0.0014350157 | C27: 0 | D27: 0 | E27: Good-Off | F27: Good-Off | G27: Good-Off | H27: Good-Off | I27: 0 | J27: Good-Off | K27: Good-Off | L27: Good-Off | M27: Good-Off
A28: 45053 | B28: 0.001131908 | C28: 0 | D28: 0 | E28: Good-Off | F28: Good-Off | G28: Good-Off | H28: Good-Off | I28: 0 | J28: Good-Off | K28: Good-Off | L28: Good-Off | M28: Good-Off
A29: 45054 | B29: 0.00082880037 | C29: 1.6866343e-05 | D29: 0 | E29: Good-Off | F29: Good-Off | G29: Good-Off | H29: Good-Off | I29: 0 | J29: Good-Off | K29: Good-Off | L29: Good-Off | M29: Good-Off
A30: 45055 | B30: 0.00052569271 | C30: 1.6229102e-05 | D30: 0 | E30: Good-Off | F30: Good-Off | G30: Good-Off | H30: Good-Off | I30: 0 | J30: Good-Off | K30: Good-Off | L30: Good-Off | M30: Good-Off
A31: 45056 | B31: 0.00022258505 | C31: 2.1635225e-05 | D31: 0 | E31: Good-Off | F31: Good-Off | G31: Good-Off | H31: Good-Off | I31: 0 | J31: Good-Off | K31: Good-Off | L31: Good-Off | M31: Good-Off
A32: 45057 | B32: 0.00022258505 | C32: Bad Total | D32: 0 | E32: Good-Off | F32: Good-Off | G32: Good-Off | H32: Good-Off | I32: 0 | J32: Good-Off | K32: Good-Off | L32: Good-Off | M32: Good-Off

Sheet Sheet11
B1: \\usmlmes\USMLPI_MDB\USMLPIMBD\Conversions and Totals\GenTo2valTotal.24.5|ACE:315.Coal.Consumption.Day.Total.86400.18000.2Tot | D1: \\usmlmes\USMLPI_MDB\USMLPIMBD\Conversions and Totals\GenTo2valTotal.24.5|ACE:315.SCC.Feed.Day.Total.86400.18000.2Tot | F1: \\usmlmes\USMLPI_MDB\USMLPIMBD\Conversions and Totals\GenTo2valTotal.24.5|ACE:345-TIC-007C/MVC.QON.Daily.Utilization.86400.18000.2Tot | H1: \\usmlmes\USMLPI_MDB\USMLPIMBD\Conversions and Totals\GenTo2valTotal.24.5|ACE:345-WI-006/PV.V.Transfer.Daily.Ave.86400.18000.eAve | J1: \\usmlmes\USMLPI_MDB\USMLPIMBD\Conversions and Totals\GenTo2valTotal.24.5|ACE:345-WI-006/PV.V.Transfer.Daily.StdDev.86400.18000.eStdDev | L1: \\usmlmes\USMLPI_MDB\USMLPIMBD\Conversions and Totals\GenTo2valTotal.24.5|ACE:345-WI-007/PV.V.Transfer.Daily.Ave.86400.18000.eAve | N1: \\usmlmes\USMLPI_MDB\USMLPIMBD\Conversions and Totals\GenTo2valTotal.24.5|ACE:345-WI-007/PV.V.Transfer.Daily.StdDev.86400.18000.eStdDev | P1: \\usmlmes\USMLPI_MDB\USMLPIMBD\Conversions and Totals\GenTo2valTotal.24.5|ACE:315.Coal.Consumption.Day.Total.86400.18000.2Tot | R1: \\usmlmes\USMLPI_MDB\USMLPIMBD\Conversions and Totals\GenTo2valTotal.24.5|ACE:315.SCC.Feed.Day.Total.86400.18000.2Tot | T1: \\usmlmes\USMLPI_MDB\USMLPIMBD\Conversions and Totals\GenTo2valTotal.24.5|ACE:345-TIC-007C/MVC.QON.Daily.Utilization.86400.18000.2Tot | V1: \\usmlmes\USMLPI_MDB\USMLPIMBD\Conversions and Totals\GenTo2valTotal.24.5|ACE:345-WI-006/PV.V.Transfer.Daily.Ave.86400.18000.eAve | X1: \\usmlmes\USMLPI_MDB\USMLPIMBD\Conversions and Totals\GenTo2valTotal.24.5|ACE:345-WI-006/PV.V.Transfer.Daily.StdDev.86400.18000.eStdDev | Z1: \\usmlmes\USMLPI_MDB\USMLPIMBD\Conversions and Totals\GenTo2valTotal.24.5|ACE:345-WI-007/PV.V.Transfer.Daily.Ave.86400.18000.eAve
A2: {=_xll.PICompDat(Sheet11!$B$1,"t-30d","t",9,"","inside")} -> #NAME? | B2: #NAME? | C2: {=_xll.PICompDat(Sheet11!$D$1,"t-30d","t",9,"","inside")} -> #NAME? | D2: #NAME? | E2: {=_xll.PICompDat(Sheet11!$F$1,"t-30d","t",9,"","inside")} -> #NAME? | F2: #NAME? | G2: {=_xll.PICompDat(Sheet11!$H$1,"t-30d","t",9,"","inside")} -> #NAME? | H2: #NAME? | I2: {=_xll.PICompDat(Sheet11!$J$1,"t-30d","t",9,"","inside")} -> #NAME? | J2: #NAME? | K2: {=_xll.PICompDat(Sheet11!$L$1,"t-30d","t",9,"","inside")} -> #NAME? | L2: #NAME? | M2: {=_xll.PICompDat(Sheet11!$N$1,"t-30d","t",9,"","inside")} -> #NAME? | N2: #NAME? | O2: {=_xll.PICompDat(Sheet11!$B$1,"t-30d","t",9,"","inside")} -> #NAME? | P2: #NAME? | Q2: {=_xll.PICompDat(Sheet11!$D$1,"t-30d","t",9,"","inside")} -> #NAME? | R2: #NAME? | S2: {=_xll.PICompDat(Sheet11!$F$1,"t-30d","t",9,"","inside")} -> #NAME? | T2: #NAME? | U2: {=_xll.PICompDat(Sheet11!$H$1,"t-30d","t",9,"","inside")} -> #NAME? | V2: #NAME? | W2: {=_xll.PICompDat(Sheet11!$J$1,"t-30d","t",9,"","inside")} -> #NAME? | X2: #NAME? | Y2: {=_xll.PICompDat(Sheet11!$L$1,"t-30d","t",9,"","inside")} -> #NAME? | Z2: #NAME?
A3: #NAME? | B3: #NAME? | C3: #NAME? | D3: #NAME? | E3: #NAME? | F3: #NAME? | G3: #NAME? | H3: #NAME? | I3: #NAME? | J3: #NAME? | K3: #NAME? | L3: #NAME? | M3: #NAME? | N3: #NAME? | O3: #NAME? | P3: #NAME? | Q3: #NAME? | R3: #NAME? | S3: #NAME? | T3: #NAME? | U3: #NAME? | V3: #NAME? | W3: #NAME? | X3: #NAME? | Y3: #NAME? | Z3: #NAME?
A4: #NAME? | B4: #NAME? | C4: #NAME? | D4: #NAME? | E4: #NAME? | F4: #NAME? | G4: #NAME? | H4: #NAME? | I4: #NAME? | J4: #NAME? | K4: #NAME? | L4: #NAME? | M4: #NAME? | N4: #NAME? | O4: #NAME? | P4: #NAME? | Q4: #NAME? | R4: #NAME? | S4: #NAME? | T4: #NAME? | U4: #NAME? | V4: #NAME? | W4: #NAME? | X4: #NAME? | Y4: #NAME? | Z4: #NAME?
A5: #NAME? | B5: #NAME? | C5: #NAME? | D5: #NAME? | E5: #NAME? | F5: #NAME? | G5: #NAME? | H5: #NAME? | I5: #NAME? | J5: #NAME? | K5: #NAME? | L5: #NAME? | M5: #NAME? | N5: #NAME? | O5: #NAME? | P5: #NAME? | Q5: #NAME? | R5: #NAME? | S5: #NAME? | T5: #NAME? | U5: #NAME? | V5: #NAME? | W5: #NAME? | X5: #NAME? | Y5: #NAME? | Z5: #NAME?
A6: #NAME? | B6: #NAME? | C6: #NAME? | D6: #NAME? | E6: #NAME? | F6: #NAME? | G6: #NAME? | H6: #NAME? | I6: #NAME? | J6: #NAME? | K6: #NAME? | L6: #NAME? | M6: #NAME? | N6: #NAME? | O6: #NAME? | P6: #NAME? | Q6: #NAME? | R6: #NAME? | S6: #NAME? | T6: #NAME? | U6: #NAME? | V6: #NAME? | W6: #NAME? | X6: #NAME? | Y6: #NAME? | Z6: #NAME?
A7: #NAME? | B7: #NAME? | C7: #NAME? | D7: #NAME? | E7: #NAME? | F7: #NAME? | G7: #NAME? | H7: #NAME? | I7: #NAME? | J7: #NAME? | K7: #NAME? | L7: #NAME? | M7: #NAME? | N7: #NAME? | O7: #NAME? | P7: #NAME? | Q7: #NAME? | R7: #NAME? | S7: #NAME? | T7: #NAME? | U7: #NAME? | V7: #NAME? | W7: #NAME? | X7: #NAME? | Y7: #NAME? | Z7: #NAME?
A8: #NAME? | B8: #NAME? | C8: #NAME? | D8: #NAME? | E8: #NAME? | F8: #NAME? | G8: #NAME? | H8: #NAME? | I8: #NAME? | J8: #NAME? | K8: #NAME? | L8: #NAME? | M8: #NAME? | N8: #NAME? | O8: #NAME? | P8: #NAME? | Q8: #NAME? | R8: #NAME? | S8: #NAME? | T8: #NAME? | U8: #NAME? | V8: #NAME? | W8: #NAME? | X8: #NAME? | Y8: #NAME? | Z8: #NAME?
A9: #NAME? | B9: #NAME? | C9: #NAME? | D9: #NAME? | E9: #NAME? | F9: #NAME? | G9: #NAME? | H9: #NAME? | I9: #NAME? | J9: #NAME? | K9: #NAME? | L9: #NAME? | M9: #NAME? | N9: #NAME? | O9: #NAME? | P9: #NAME? | Q9: #NAME? | R9: #NAME? | S9: #NAME? | T9: #NAME? | U9: #NAME? | V9: #NAME? | W9: #NAME? | X9: #NAME? | Y9: #NAME? | Z9: #NAME?
A10: #NAME? | B10: #NAME? | C10: #NAME? | D10: #NAME? | E10: #NAME? | F10: #NAME? | G10: #NAME? | H10: #NAME? | I10: #NAME? | J10: #NAME? | K10: #NAME? | L10: #NAME? | M10: #NAME? | N10: #NAME? | O10: #NAME? | P10: #NAME? | Q10: #NAME? | R10: #NAME? | S10: #NAME? | T10: #NAME? | U10: #NAME? | V10: #NAME? | W10: #NAME? | X10: #NAME? | Y10: #NAME? | Z10: #NAME?
A11: #NAME? | B11: #NAME? | C11: #NAME? | D11: #NAME? | E11: #NAME? | F11: #NAME? | G11: #NAME? | H11: #NAME? | I11: #NAME? | J11: #NAME? | K11: #NAME? | L11: #NAME? | M11: #NAME? | N11: #NAME? | O11: #NAME? | P11: #NAME? | Q11: #NAME? | R11: #NAME? | S11: #NAME? | T11: #NAME? | U11: #NAME? | V11: #NAME? | W11: #NAME? | X11: #NAME? | Y11: #NAME? | Z11: #NAME?
A12: #NAME? | B12: #NAME? | C12: #NAME? | D12: #NAME? | E12: #NAME? | F12: #NAME? | G12: #NAME? | H12: #NAME? | I12: #NAME? | J12: #NAME? | K12: #NAME? | L12: #NAME? | M12: #NAME? | N12: #NAME? | O12: #NAME? | P12: #NAME? | Q12: #NAME? | R12: #NAME? | S12: #NAME? | T12: #NAME? | U12: #NAME? | V12: #NAME? | W12: #NAME? | X12: #NAME? | Y12: #NAME? | Z12: #NAME?
A13: #NAME? | B13: #NAME? | C13: #NAME? | D13: #NAME? | E13: #NAME? | F13: #NAME? | G13: #NAME? | H13: #NAME? | I13: #NAME? | J13: #NAME? | K13: #NAME? | L13: #NAME? | M13: #NAME? | N13: #NAME? | O13: #NAME? | P13: #NAME? | Q13: #NAME? | R13: #NAME? | S13: #NAME? | T13: #NAME? | U13: #NAME? | V13: #NAME? | W13: #NAME? | X13: #NAME? | Y13: #NAME? | Z13: #NAME?
A14: #NAME? | B14: #NAME? | C14: #NAME? | D14: #NAME? | E14: #NAME? | F14: #NAME? | G14: #NAME? | H14: #NAME? | I14: #NAME? | J14: #NAME? | K14: #NAME? | L14: #NAME? | M14: #NAME? | N14: #NAME? | O14: #NAME? | P14: #NAME? | Q14: #NAME? | R14: #NAME? | S14: #NAME? | T14: #NAME? | U14: #NAME? | V14: #NAME? | W14: #NAME? | X14: #NAME? | Y14: #NAME? | Z14: #NAME?
... A46: #NAME? | B46: #NAME? | C46: #NAME? | D46: #NAME? | E46: #NAME? | F46: #NAME? | G46: #NAME? | H46: #NAME? | I46: #NAME? | J46: #NAME? | K46: #NAME? | L46: #NAME? | M46: #NAME? | N46: #NAME? | O46: #NAME? | P46: #NAME? | Q46: #NAME? | R46: #NAME? | S46: #NAME? | T46: #NAME? | U46: #NAME? | V46: #NAME? | W46: #NAME? | X46: #NAME? | Y46: #NAME? | Z46: #NAME?
C47: #NAME? | D47: #NAME? | E47: #NAME? | F47: #NAME? | G47: #NAME? | H47: #NAME? | I47: #NAME? | J47: #NAME? | K47: #NAME? | L47: #NAME? | M47: #NAME? | N47: #NAME? | Q47: #NAME? | R47: #NAME? | S47: #NAME? | T47: #NAME? | U47: #NAME? | V47: #NAME? | W47: #NAME? | X47: #NAME? | Y47: #NAME? | Z47: #NAME?
C48: #NAME? | D48: #NAME? | E48: #NAME? | F48: #NAME? | G48: #NAME? | H48: #NAME? | I48: #NAME? | J48: #NAME? | K48: #NAME? | L48: #NAME? | M48: #NAME? | N48: #NAME? | Q48: #NAME? | R48: #NAME? | S48: #NAME? | T48: #NAME? | U48: #NAME? | V48: #NAME? | W48: #NAME? | X48: #NAME? | Y48: #NAME? | Z48: #NAME?
C49: #NAME? | D49: #NAME? | E49: #NAME? | F49: #NAME? | G49: #NAME? | H49: #NAME? | I49: #NAME? | J49: #NAME? | K49: #NAME? | L49: #NAME? | M49: #NAME? | N49: #NAME? | Q49: #NAME? | R49: #NAME? | S49: #NAME? | T49: #NAME? | U49: #NAME? | V49: #NAME? | W49: #NAME? | X49: #NAME? | Y49: #NAME? | Z49: #NAME?
C50: #NAME? | D50: #NAME? | G50: #NAME? | H50: #NAME? | I50: #NAME? | J50: #NAME? | K50: #NAME? | L50: #NAME? | M50: #NAME? | N50: #NAME? | Q50: #NAME? | R50: #NAME? | U50: #NAME? | V50: #NAME? | W50: #NAME? | X50: #NAME? | Y50: #NAME? | Z50: #NAME?
C51: #NAME? | D51: #NAME? | G51: #NAME? | H51: #NAME? | I51: #NAME? | J51: #NAME? | K51: #NAME? | L51: #NAME? | M51: #NAME? | N51: #NAME? | Q51: #NAME? | R51: #NAME? | U51: #NAME? | V51: #NAME? | W51: #NAME? | X51: #NAME? | Y51: #NAME? | Z51: #NAME?
C52: #NAME? | D52: #NAME? | G52: #NAME? | H52: #NAME? | I52: #NAME? | J52: #NAME? | K52: #NAME? | L52: #NAME? | M52: #NAME? | N52: #NAME? | Q52: #NAME? | R52: #NAME? | U52: #NAME? | V52: #NAME? | W52: #NAME? | X52: #NAME? | Y52: #NAME? | Z52: #NAME?
C53: #NAME? | D53: #NAME? | G53: #NAME? | H53: #NAME? | I53: #NAME? | J53: #NAME? | K53: #NAME? | L53: #NAME? | M53: #NAME? | N53: #NAME? | Q53: #NAME? | R53: #NAME? | U53: #NAME? | V53: #NAME? | W53: #NAME? | X53: #NAME? | Y53: #NAME? | Z53: #NAME?
C54: #NAME? | D54: #NAME? | G54: #NAME? | H54: #NAME? | I54: #NAME? | J54: #NAME? | K54: #NAME? | L54: #NAME? | M54: #NAME? | N54: #NAME? | Q54: #NAME? | R54: #NAME? | U54: #NAME? | V54: #NAME? | W54: #NAME? | X54: #NAME? | Y54: #NAME? | Z54: #NAME?
C55: #NAME? | D55: #NAME? | G55: #NAME? | H55: #NAME? | I55: #NAME? | J55: #NAME? | K55: #NAME? | L55: #NAME? | M55: #NAME? | N55: #NAME? | Q55: #NAME? | R55: #NAME? | U55: #NAME? | V55: #NAME? | W55: #NAME? | X55: #NAME? | Y55: #NAME? | Z55: #NAME?
G56: #NAME? | H56: #NAME? | I56: #NAME? | J56: #NAME? | K56: #NAME? | L56: #NAME? | M56: #NAME? | N56: #NAME? | U56: #NAME? | V56: #NAME? | W56: #NAME? | X56: #NAME? | Y56: #NAME? | Z56: #NAME?
G57: #NAME? | H57: #NAME? | I57: #NAME? | J57: #NAME? | K57: #NAME? | L57: #NAME? | M57: #NAME? | N57: #NAME? | U57: #NAME? | V57: #NAME? | W57: #NAME? | X57: #NAME? | Y57: #NAME? | Z57: #NAME?
G58: #NAME? | H58: #NAME? | I58: #NAME? | J58: #NAME? | K58: #NAME? | L58: #NAME? | M58: #NAME? | N58: #NAME? | U58: #NAME? | V58: #NAME? | W58: #NAME? | X58: #NAME? | Y58: #NAME? | Z58: #NAME?
G59: #NAME? | H59: #NAME? | I59: #NAME? | J59: #NAME? | K59: #NAME? | L59: #NAME? | M59: #NAME? | N59: #NAME? | U59: #NAME? | V59: #NAME? | W59: #NAME? | X59: #NAME? | Y59: #NAME? | Z59: #NAME?
G60: #NAME? | H60: #NAME? | I60: #NAME? | J60: #NAME? | K60: #NAME? | L60: #NAME? | M60: #NAME? | N60: #NAME? | U60: #NAME? | V60: #NAME? | W60: #NAME? | X60: #NAME? | Y60: #NAME? | Z60: #NAME?
G61: #NAME? | H61: #NAME? | I61: #NAME? | J61: #NAME? | K61: #NAME? | L61: #NAME? | M61: #NAME? | N61: #NAME? | U61: #NAME? | V61: #NAME? | W61: #NAME? | X61: #NAME? | Y61: #NAME? | Z61: #NAME?
G62: #NAME? | H62: #NAME? | I62: #NAME? | J62: #NAME? | K62: #NAME? | L62: #NAME? | M62: #NAME? | N62: #NAME? | U62: #NAME? | V62: #NAME? | W62: #NAME? | X62: #NAME? | Y62: #NAME? | Z62: #NAME?
G63: #NAME? | H63: #NAME? | I63: #NAME? | J63: #NAME? | K63: #NAME? | L63: #NAME? | M63: #NAME? | N63: #NAME? | U63: #NAME? | V63: #NAME? | W63: #NAME? | X63: #NAME? | Y63: #NAME? | Z63: #NAME?
G64: #NAME? | H64: #NAME? | I64: #NAME? | J64: #NAME? | K64: #NAME? | L64: #NAME? | M64: #NAME? | N64: #NAME? | U64: #NAME? | V64: #NAME? | W64: #NAME? | X64: #NAME? | Y64: #NAME? | Z64: #NAME?
G65: #NAME? | H65: #NAME? | I65: #NAME? | J65: #NAME? | K65: #NAME? | L65: #NAME? | M65: #NAME? | N65: #NAME? | U65: #NAME? | V65: #NAME? | W65: #NAME? | X65: #NAME? | Y65: #NAME? | Z65: #NAME?
G66: #NAME? | H66: #NAME? | I66: #NAME? | J66: #NAME? | K66: #NAME? | L66: #NAME? | M66: #NAME? | N66: #NAME? | U66: #NAME? | V66: #NAME? | W66: #NAME? | X66: #NAME? | Y66: #NAME? | Z66: #NAME?
G67: #NAME? | H67: #NAME? | I67: #NAME? | J67: #NAME? | K67: #NAME? | L67: #NAME? | M67: #NAME? | N67: #NAME? | U67: #NAME? | V67: #NAME? | W67: #NAME? | X67: #NAME? | Y67: #NAME? | Z67: #NAME?
... G995: #NAME? | H995: #NAME? | I995: #NAME? | J995: #NAME? | K995: #NAME? | L995: #NAME? | M995: #NAME? | N995: #NAME? | U995: #NAME? | V995: #NAME? | W995: #NAME? | X995: #NAME? | Y995: #NAME? | Z995: #NAME?
K996: #NAME? | L996: #NAME? | M996: #NAME? | N996: #NAME? | Y996: #NAME? | Z996: #NAME?
K997: #NAME? | L997: #NAME? | M997: #NAME? | N997: #NAME? | Y997: #NAME? | Z997: #NAME?
K998: #NAME? | L998: #NAME? | M998: #NAME? | N998: #NAME? | Y998: #NAME? | Z998: #NAME?
...

Sheet InputsCompressed
B1: Coal.Consumption.Day.Total.86400.18000.2Tot | D1: SCC.Feed.Day.Total.86400.18000.2Tot | F1: MVC.QON.Daily.Utilization.86400.18000.2Tot | H1: PV.V.Transfer.Daily.Ave.86400.18000.eAve | J1: PV.V.Transfer.Daily.StdDev.86400.18000.eStdDev | L1: PV.V.Transfer.Daily.Ave.86400.18000.eAve | N1: PV.V.Transfer.Daily.StdDev.86400.18000.eStdDev
A2: 45034.208 | B2: 0 | C2: 45034.208 | D2: 6.9559155 | E2: 45034.208 | F2: 0.12108458 | G2: 45034.001 | H2: 0.011573792 | I2: 45034.001 | J2: 0.011573792 | K2: 45038.088 | L2: 8.4557886 | M2: 45038.088 | N2: 8.4557886
A3: 45034.208 | B3: 0 | C3: 45034.208 | D3: Bad Total | E3: 45034.208 | F3: 0 | G3: 45034.002 | H3: Good-Off | I3: 45034.002 | J3: Good-Off | K3: 45038.088 | L3: Good-Off | M3: 45038.088 | N3: Good-Off
A4: 45035.208 | B4: 0 | C4: 45035.208 | D4: Bad Total | E4: 45035.208 | F4: 0 | G4: 45034.003 | H4: 0.018517971 | I4: 45034.003 | J4: 0.018517971 | K4: 45038.088 | L4: 0.72220254 | M4: 45038.088 | N4: 0.72220254
A5: 45035.208 | B5: 0 | C5: 45035.208 | D5: Bad Total | E5: 45035.208 | F5: 0 | G5: 45034.003 | H5: Good-Off | I5: 45034.003 | J5: Good-Off | K5: 45038.09 | L5: Good-Off | M5: 45038.09 | N5: Good-Off
A6: 45036.208 | B6: 0 | C6: 45036.208 | D6: Bad Total | E6: 45036.208 | F6: 0 | G6: 45034.005 | H6: 0.018517971 | I6: 45034.005 | J6: 0.018517971 | K6: 45038.09 | L6: 3.3818526 | M6: 45038.09 | N6: 3.3818526
A7: 45036.208 | B7: 0 | C7: 45036.208 | D7: Bad Total | E7: 45036.208 | F7: 0 | G7: 45034.005 | H7: Good-Off | I7: 45034.005 | J7: Good-Off | K7: 45038.092 | L7: Good-Off | M7: 45038.092 | N7: Good-Off
A8: 45037.208 | B8: 0 | C8: 45037.208 | D8: Bad Total | E8: 45037.208 | F8: 0 | G8: 45034.006 | H8: 0.018517971 | I8: 45034.006 | J8: 0.018517971 | K8: 45038.092 | L8: 3.4698133 | M8: 45038.092 | N8: 3.4698133
A9: 45037.208 | B9: 0 | C9: 45037.208 | D9: 413.52609 | E9: 45037.208 | F9: 4.9930487 | G9: 45034.006 | H9: Good-Off | I9: 45034.006 | J9: Good-Off | K9: 45038.093 | L9: Good-Off | M9: 45038.093 | N9: Good-Off
A10: 45038.208 | B10: 0 | C10: 45038.208 | D10: 413.52609 | E10: 45038.208 | F10: 4.9930487 | G10: 45034.008 | H10: 0.018517971 | I10: 45034.008 | J10: 0.018517971 | K10: 45038.094 | L10: 3.296207 | M10: 45038.094 | N10: 3.296207
A11: 45038.208 | B11: 0 | C11: 45038.208 | D11: 1016.5237 | E11: 45038.208 | F11: 23.203506 | G11: 45034.008 | H11: Good-Off | I11: 45034.008 | J11: Good-Off | K11: 45038.095 | L11: Good-Off | M11: 45038.095 | N11: Good-Off
A12: 45039.208 | B12: 0 | C12: 45039.208 | D12: 1016.5237 | E12: 45039.208 | F12: 23.203506 | G12: 45034.01 | H12: 0.018517971 | I12: 45034.01 | J12: 0.018517971 | K12: 45038.095 | L12: 2.9814005 | M12: 45038.095 | N12: 2.9814005
A13: 45039.208 | B13: 0 | C13: 45039.208 | D13: 501.67346 | E13: 45039.208 | F13: 13.524963 | G13: 45034.01 | H13: Good-Off | I13: 45034.01 | J13: Good-Off | K13: 45038.097 | L13: Good-Off | M13: 45038.097 | N13: Good-Off
A14: 45040.208 | B14: 0 | C14: 45040.208 | D14: 501.67346 | E14: 45040.208 | F14: 13.524963 | G14: 45034.011 | H14: 0.020832777 | I14: 45034.011 | J14: 0.020832777 | K14: 45038.097 | L14: 2.863348 | M14: 45038.097 | N14: 2.863348
A15: 45040.208 | B15: 0 | C15: 45040.208 | D15: 0 | E15: 45040.208 | F15: 0 | G15: 45034.011 | H15: Good-Off | I15: 45034.011 | J15: Good-Off | K15: 45038.098 | L15: Good-Off | M15: 45038.098 | N15: Good-Off
A16: 45041.208 | B16: 0 | C16: 45041.208 | D16: 0 | E16: 45041.208 | F16: 0 | G16: 45034.013 | H16: 0.020832777 | I16: 45034.013 | J16: 0.020832777 | K16: 45038.098 | L16: 3.0763054 | M16: 45038.098 | N16: 3.0763054
A17: 45041.208 | B17: 0 | C17: 45041.208 | D17: Bad Total | E17: 45041.208 | F17: 0 | G17: 45034.013 | H17: Good-Off | I17: 45034.013 | J17: Good-Off | K17: 45038.1 | L17: Good-Off | M17: 45038.1 | N17: Good-Off
A18: 45042.208 | B18: 0 | C18: 45042.208 | D18: Bad Total | E18: 45042.208 | F18: 0 | G18: 45034.014 | H18: 0.018518209 | I18: 45034.014 | J18: 0.018518209 | K18: 45038.1 | L18: 3.1688955 | M18: 45038.1 | N18: 3.1688955
A19: 45042.208 | B19: 0 | C19: 45042.208 | D19: 0 | E19: 45042.208 | F19: 0 | G19: 45034.014 | H19: Good-Off | I19: 45034.014 | J19: Good-Off | K19: 45038.101 | L19: Good-Off | M19: 45038.101 | N19: Good-Off
A20: 45043.208 | B20: 0 | C20: 45043.208 | D20: 0 | E20: 45043.208 | F20: 0 | G20: 45034.016 | H20: 0.027776957 | I20: 45034.016 | J20: 0.027776957 | K20: 45038.101 | L20: 1.2731135 | M20: 45038.101 | N20: 1.2731135
A21: 45043.208 | B21: 0 | C21: 45043.208 | D21: 0 | E21: 45043.208 | F21: 0 | G21: 45034.016 | H21: Good-Off | I21: 45034.016 | J21: Good-Off | K21: 45038.103 | L21: Good-Off | M21: 45038.103 | N21: Good-Off
A22: 45044.208 | B22: 0 | C22: 45044.208 | D22: 0 | E22: 45044.208 | F22: 0 | G22: 45034.018 | H22: 0.030091763 | I22: 45034.018 | J22: 0.030091763 | K22: 45038.103 | L22: 0 | M22: 45038.103 | N22: 0
A23: 45044.208 | B23: 0 | C23: 45044.208 | D23: 0 | E23: 45044.208 | F23: 0 | G23: 45034.018 | H23: Good-Off | I23: 45034.018 | J23: Good-Off | K23: 45038.104 | L23: Good-Off | M23: 45038.104 | N23: Good-Off
A24: 45045.208 | B24: 0 | C24: 45045.208 | D24: 0 | E24: 45045.208 | F24: 0 | G24: 45034.019 | H24: 0.020832777 | I24: 45034.019 | J24: 0.020832777 | K24: 45038.104 | L24: 2.4328043 | M24: 45038.104 | N24: 2.4328043
A25: 45045.208 | B25: 0 | C25: 45045.208 | D25: 0 | E25: 45045.208 | F25: 0 | G25: 45034.019 | H25: Good-Off | I25: 45034.019 | J25: Good-Off | K25: 45038.105 | L25: Good-Off | M25: 45038.105 | N25: Good-Off
A26: 45046.208 | B26: 0 | C26: 45046.208 | D26: 0 | E26: 45046.208 | F26: 0 | G26: 45034.021 | H26: 0.025462389 | I26: 45034.021 | J26: 0.025462389 | K26: 45038.105 | L26: 2.398083 | M26: 45038.105 | N26: 2.398083
A27: 45046.208 | B27: 0 | C27: 45046.208 | D27: 0 | E27: 45046.208 | F27: 0 | G27: 45034.021 | H27: Good-Off | I27: 45034.021 | J27: Good-Off | K27: 45038.106 | L27: Good-Off | M27: 45038.106 | N27: Good-Off
A28: 45047.208 | B28: 0 | C28: 45047.208 | D28: 0 | E28: 45047.208 | F28: 0 | G28: 45034.022 | H28: 0.023147583 | I28: 45034.022 | J28: 0.023147583 | K28: 45038.107 | L28: 2.4652109 | M28: 45038.107 | N28: 2.4652109
A29: 45047.208 | B29: 0 | C29: 45047.208 | D29: 0 | E29: 45047.208 | F29: 0 | G29: 45034.023 | H29: Good-Off | I29: 45034.023 | J29: Good-Off | K29: 45038.108 | L29: Good-Off | M29: 45038.108 | N29: Good-Off
A30: 45048.208 | B30: 0 | C30: 45048.208 | D30: 0 | E30: 45048.208 | F30: 0 | G30: 45034.024 | H30: 0.027777195 | I30: 45034.024 | J30: 0.027777195 | K30: 45038.108 | L30: 2.5971518 | M30: 45038.108 | N30: 2.5971518
A31: 45048.208 | B31: 4.0963206 | C31: 45048.208 | D31: 0 | E31: 45048.208 | F31: 0 | G31: 45034.024 | H31: Good-Off | I31: 45034.024 | J31: Good-Off | K31: 45038.109 | L31: Good-Off | M31: 45038.109 | N31: Good-Off
A32: 45049.208 | B32: 4.1158714 | C32: 45049.208 | D32: 0 | E32: 45049.208 | F32: 0 | G32: 45034.026 | H32: 0.027776718 | I32: 45034.026 | J32: 0.027776718 | K32: 45038.109 | L32: 2.2754011 | M32: 45038.109 | N32: 2.2754011
A33: 45049.208 | B33: 0 | C33: 45049.208 | D33: 0 | E33: 45049.208 | F33: 0 | G33: 45034.026 | H33: Good-Off | I33: 45034.026 | J33: Good-Off | K33: 45038.111 | L33: Good-Off | M33: 45038.111 | N33: Good-Off
A34: 45050.208 | B34: 0.0020412309 | C34: 45050.208 | D34: 0 | E34: 45050.208 | F34: 0 | G34: 45034.027 | H34: 0.020832777 | I34: 45034.027 | J34: 0.020832777 | K34: 45038.111 | L34: 2.5045617 | M34: 45038.111 | N34: 2.5045617
A35: 45050.208 | B35: 0.0017381232 | C35: 45050.208 | D35: 0.00051635387 | E35: 45050.208 | F35: 0 | G35: 45034.027 | H35: Good-Off | I35: 45034.027 | J35: Good-Off | K35: 45038.112 | L35: Good-Off | M35: 45038.112 | N35: Good-Off
A36: 45051.208 | B36: 0.0017381232 | C36: 45051.208 | D36: 0.00051635387 | E36: 45051.208 | F36: 0 | G36: 45034.029 | H36: 0.018517971 | I36: 45034.029 | J36: 0.018517971 | K36: 45038.112 | L36: 2.4721551 | M36: 45038.112 | N36: 2.4721551
A37: 45051.208 | B37: 0.0014350157 | C37: 45051.208 | D37: 0 | E37: 45051.208 | F37: 0 | G37: 45034.029 | H37: Good-Off | I37: 45034.029 | J37: Good-Off | K37: 45038.113 | L37: Good-Off | M37: 45038.113 | N37: Good-Off
A38: 45052.208 | B38: 0.0014350157 | C38: 45052.208 | D38: 0 | E38: 45052.208 | F38: 0 | G38: 45034.031 | H38: 0.018517971 | I38: 45034.031 | J38: 0.018517971 | K38: 45038.113 | L38: 2.3147519 | M38: 45038.113 | N38: 2.3147519
A39: 45052.208 | B39: 0.001131908 | C39: 45052.208 | D39: 0 | E39: 45052.208 | F39: 0 | G39: 45034.031 | H39: Good-Off | I39: 45034.031 | J39: Good-Off | K39: 45038.114 | L39: Good-Off | M39: 45038.114 | N39: Good-Off
A40: 45053.208 | B40: 0.001131908 | C40: 45053.208 | D40: 0 | E40: 45053.208 | F40: 0 | G40: 45034.032 | H40: 0.013888597 | I40: 45034.032 | J40: 0.013888597 | K40: 45038.115 | L40: 1.0624712 | M40: 45038.115 | N40: 1.0624712
...

Sheet Sheet13
B1: \\usmlmes\USMLPI_MDB\USMLPIMBD\Conversions and Totals\GenTo2valTotal.24.5|ACE:315.Coal.Consumption.Day.Total.86400.18000.2Tot | D1: \\usmlpi.angloiit.net\T:350-PY-201/PV.V.TIM | F1: \\usmlpi.angloiit.net\345-LI-203/PV.V | H1: \\usmlpi.angloiit.net\ACE:315.Coal.Consumption.Day.Total | J1: \\usmlpi.angloiit.net\T:345-WIT-301/PV.V.TIM
A2: {=_xll.PICompDat(Sheet13!$B$1,"t-30d","t",9,"","inside")} -> #NAME? | B2: #NAME? | C2: {=_xll.PICompDat(Sheet13!$D$1,"t-30d","t",9,"","inside")} -> #NAME? | D2: #NAME? | E2: {=_xll.PICompDat(Sheet13!$F$1,"t-30d","t",9,"","inside")} -> #NAME? | F2: #NAME? | G2: {=_xll.PICompDat(Sheet13!$H$1,"t-30d","t",9,"","inside")} -> #NAME? | H2: #NAME? | I2: {=_xll.PICompDat(Sheet13!$J$1,"t-30d","t",9,"","inside")} -> #NAME? | J2: #NAME?
A3: #NAME? | B3: #NAME? | C3: #NAME? | D3: #NAME? | E3: #NAME? | F3: #NAME? | G3: #NAME? | H3: #NAME? | I3: #NAME? | J3: #NAME?
A4: #NAME? | B4: #NAME? | C4: #NAME? | D4: #NAME? | E4: #NAME? | F4: #NAME? | G4: #NAME? | H4: #NAME? | I4: #NAME? | J4: #NAME?
A5: #NAME? | B5: #NAME? | C5: #NAME? | D5: #NAME? | E5: #NAME? | F5: #NAME? | G5: #NAME? | H5: #NAME? | I5: #NAME? | J5: #NAME?
A6: #NAME? | B6: #NAME? | C6: #NAME? | D6: #NAME? | E6: #NAME? | F6: #NAME? | G6: #NAME? | H6: #NAME? | I6: #NAME? | J6: #NAME?
A7: #NAME? | B7: #NAME? | C7: #NAME? | D7: #NAME? | E7: #NAME? | F7: #NAME? | G7: #NAME? | H7: #NAME? | I7: #NAME? | J7: #NAME?
A8: #NAME? | B8: #NAME? | C8: #NAME? | D8: #NAME? | E8: #NAME? | F8: #NAME? | G8: #NAME? | H8: #NAME? | I8: #NAME? | J8: #NAME?
A9: #NAME? | B9: #NAME? | C9: #NAME? | D9: #NAME? | E9: #NAME? | F9: #NAME? | G9: #NAME? | H9: #NAME? | I9: #NAME? | J9: #NAME?
A10: #NAME? | B10: #NAME? | C10: #NAME? | D10: #NAME? | E10: #NAME? | F10: #NAME? | G10: #NAME? | H10: #NAME? | I10: #NAME? | J10: #NAME?
A11: #NAME? | B11: #NAME? | C11: #NAME? | D11: #NAME? | E11: #NAME? | F11: #NAME? | G11: #NAME? | H11: #NAME? | I11: #NAME? | J11: #NAME?
A12: #NAME? | B12: #NAME? | C12: #NAME? | D12: #NAME? | E12: #NAME? | F12: #NAME? | G12: #NAME? | H12: #NAME? | I12: #NAME? | J12: #NAME?
A13: #NAME? | B13: #NAME? | C13: #NAME? | D13: #NAME? | E13: #NAME? | F13: #NAME? | G13: #NAME? | H13: #NAME? | I13: #NAME? | J13: #NAME?
A14: #NAME? | B14: #NAME? | C14: #NAME? | D14: #NAME? | E14: #NAME? | F14: #NAME? | G14: #NAME? | H14: #NAME? | I14: #NAME? | J14: #NAME?
... A31: #NAME? | B31: #NAME? | C31: #NAME? | D31: #NAME? | E31: #NAME? | F31: #NAME? | G31: #NAME? | H31: #NAME? | I31: #NAME? | J31: #NAME?
A32: #NAME? | B32: #NAME? | E32: #NAME? | F32: #NAME? | G32: #NAME? | H32: #NAME?
A33: #NAME? | B33: #NAME? | E33: #NAME? | F33: #NAME? | G33: #NAME? | H33: #NAME?
A34: #NAME? | B34: #NAME? | E34: #NAME? | F34: #NAME? | G34: #NAME? | H34: #NAME?
A35: #NAME? | B35: #NAME? | E35: #NAME? | F35: #NAME? | G35: #NAME? | H35: #NAME?
A36: #NAME? | B36: #NAME? | E36: #NAME? | F36: #NAME? | G36: #NAME? | H36: #NAME?
A37: #NAME? | B37: #NAME? | E37: #NAME? | F37: #NAME? | G37: #NAME? | H37: #NAME?
A38: #NAME? | B38: #NAME? | E38: #NAME? | F38: #NAME? | G38: #NAME? | H38: #NAME?
A39: #NAME? | B39: #NAME? | E39: #NAME? | F39: #NAME? | G39: #NAME? | H39: #NAME?
A40: #NAME? | B40: #NAME? | E40: #NAME? | F40: #NAME? | G40: #NAME? | H40: #NAME?
A41: #NAME? | B41: #NAME? | E41: #NAME? | F41: #NAME? | G41: #NAME? | H41: #NAME?
A42: #NAME? | B42: #NAME? | E42: #NAME? | F42: #NAME? | G42: #NAME? | H42: #NAME?
A43: #NAME? | B43: #NAME? | E43: #NAME? | F43: #NAME? | G43: #NAME? | H43: #NAME?
... A46: #NAME? | B46: #NAME? | E46: #NAME? | F46: #NAME? | G46: #NAME? | H46: #NAME?
E47: #NAME? | F47: #NAME? | G47: #NAME? | H47: #NAME?
E48: #NAME? | F48: #NAME? | G48: #NAME? | H48: #NAME?
E49: #NAME? | F49: #NAME? | G49: #NAME? | H49: #NAME?
E50: #NAME? | F50: #NAME? | G50: #NAME? | H50: #NAME?
E51: #NAME? | F51: #NAME? | G51: #NAME? | H51: #NAME?
E52: #NAME? | F52: #NAME? | G52: #NAME? | H52: #NAME?
E53: #NAME? | F53: #NAME? | G53: #NAME? | H53: #NAME?
E54: #NAME? | F54: #NAME? | G54: #NAME? | H54: #NAME?
E55: #NAME? | F55: #NAME? | G55: #NAME? | H55: #NAME?
E56: #NAME? | F56: #NAME? | G56: #NAME? | H56: #NAME?
E57: #NAME? | F57: #NAME? | G57: #NAME? | H57: #NAME?
E58: #NAME? | F58: #NAME? | G58: #NAME? | H58: #NAME?
...

Sheet FormulaCompressed
B1: Coal.Consumption.Day.Total.86400.18000.2Tot | D1: T:350-PY-201/PV.V.TIM | F1: 345-LI-203/PV.V | H1: Coal.Consumption.Day.Total | J1: T:345-WIT-301/PV.V.TIM
A2: 45034.208 | B2: 0 | C2: 45034.208 | D2: 3.6589208 | E2: 45034 | F2: 84.546318 | G2: 45034.208 | H2: 0.9266001 | I2: 45034.208 | J2: 0.0083333338
A3: 45034.208 | B3: 0 | C3: 45035.208 | D3: 0 | E3: 45034 | F3: 84.517387 | G3: 45034.208 | H3: 0.72305781 | I3: 45035.208 | J3: 0
A4: 45035.208 | B4: 0 | C4: 45036.208 | D4: 0 | E4: 45034.002 | F4: 84.517387 | G4: 45035.208 | H4: 0.72305781 | I4: 45036.208 | J4: 0
A5: 45035.208 | B5: 0 | C5: 45037.208 | D5: 0.16545278 | E5: 45034.003 | F5: 84.546318 | G5: 45035.208 | H5: -0.082313396 | I5: 45037.208 | J5: 5.9449673
A6: 45036.208 | B6: 0 | C6: 45038.208 | D6: 9.2679291 | E6: 45034.003 | F6: 84.546318 | G6: 45036.208 | H6: -0.082313396 | I6: 45038.208 | J6: 23.563881
A7: 45036.208 | B7: 0 | C7: 45039.208 | D7: 19.132957 | E7: 45034.004 | F7: 84.517387 | G7: 45036.208 | H7: 0.080219999 | I7: 45039.208 | J7: 15.210649
A8: 45037.208 | B8: 0 | C8: 45040.208 | D8: 22.93222 | E8: 45034.004 | F8: 84.546318 | G8: 45037.208 | H8: 0.080219999 | I8: 45040.208 | J8: 0.29445416
A9: 45037.208 | B9: 0 | C9: 45041.208 | D9: 11.557015 | E9: 45034.007 | F9: 84.546318 | G9: 45037.208 | H9: 6.6201057 | I9: 45041.208 | J9: 0
A10: 45038.208 | B10: 0 | C10: 45042.208 | D10: 15.518989 | E10: 45034.007 | F10: 84.604187 | G10: 45038.208 | H10: 6.6201057 | I10: 45042.208 | J10: 0
A11: 45038.208 | B11: 0 | C11: 45043.208 | D11: 15.999063 | E11: 45034.008 | F11: 84.546318 | G11: 45038.208 | H11: 24.678551 | I11: 45043.208 | J11: 0
A12: 45039.208 | B12: 0 | C12: 45044.208 | D12: 22.287752 | E12: 45034.008 | F12: 84.604187 | G12: 45039.208 | H12: 24.678551 | I12: 45044.208 | J12: 0
A13: 45039.208 | B13: 0 | C13: 45045.208 | D13: 24 | E13: 45034.008 | F13: 84.546318 | G13: 45039.208 | H13: 15.625204 | I13: 45045.208 | J13: 0
... A31: 45048.208 | B31: 4.0963206 | C31: 45063.208 | D31: 0 | E31: 45034.015 | F31: 84.633125 | G31: 45048.208 | H31: -0.7466138 | I31: 45063.208 | J31: 0
A32: 45049.208 | B32: 4.1158714 | E32: 45034.015 | F32: 84.604187 | G32: 45049.208 | H32: -0.7466138
A33: 45049.208 | B33: 0 | E33: 45034.015 | F33: 84.633125 | G33: 45049.208 | H33: -0.036974117
A34: 45050.208 | B34: 0.0020412309 | E34: 45034.016 | F34: 84.604187 | G34: 45050.208 | H34: -0.036974117
A35: 45050.208 | B35: 0.0017381232 | E35: 45034.016 | F35: 84.633125 | G35: 45050.208 | H35: -0.079809383
A36: 45051.208 | B36: 0.0017381232 | E36: 45034.016 | F36: 84.604187 | G36: 45051.208 | H36: -0.079809383
A37: 45051.208 | B37: 0.0014350157 | E37: 45034.017 | F37: 84.604187 | G37: 45051.208 | H37: 0.71926641
