Workbook

Sheet Sheet1
B1: \\wsmlmes\WSMLPI_MDB\WSMLPI ModuleDB\Anglo Platinum\Smelters\Waterval Smelter\Hot Metals\Slag Cleaning Furnace 1\Feed\Profile|ACE.Profile.Delta.Port13 | D1: \\wsmlmes\WSMLPI_MDB\WSMLPI ModuleDB\Anglo Platinum\Smelters\Waterval Smelter\Hot Metals\Slag Cleaning Furnace 1\Feed\Profile|ACE.Profile.Delta.Port6 | F1: \\wsmlmes\WSMLPI_MDB\WSMLPI ModuleDB\Anglo Platinum\Smelters\Waterval Smelter\Hot Metals\Slag Cleaning Furnace 1\Feed\Profile|ACE.Profile.Delta.Port9 | H1: \\wsmlmes\WSMLPI_MDB\WSMLPI ModuleDB\Anglo Platinum\Smelters\Waterval Smelter\Hot Metals\Slag Cleaning Furnace 1\Feed\Profile|ACE.Profile.Total.Centre | J1: \\wsmlmes\WSMLPI_MDB\WSMLPI ModuleDB\Anglo Platinum\Smelters\Waterval Smelter\Hot Metals\Slag Cleaning Furnace 1\Feed\Profile|ACE.Profile.Total.Delta | L1: \\wsmlmes\WSMLPI_MDB\WSMLPI ModuleDB\Anglo Platinum\Smelters\Waterval Smelter\Hot Metals\Slag Cleaning Furnace 1\Feed\Profile|ACE.Profile.Total.Wall | N1: \\wsmlmes\WSMLPI_MDB\WSMLPI ModuleDB\Anglo Platinum\Smelters\Waterval Smelter\Hot Metals\Slag Cleaning Furnace 1\Feed\Profile|ACE.Profile.Wall.Port10 | P1: \\wsmlmes\WSMLPI_MDB\WSMLPI ModuleDB\Anglo Platinum\Smelters\Waterval Smelter\Hot Metals\Slag Cleaning Furnace 1\Feed\Profile|ACE.Profile.Wall.Port12 | R1: \\wsmlmes\WSMLPI_MDB\WSMLPI ModuleDB\Anglo Platinum\Smelters\Waterval Smelter\Hot Metals\Slag Cleaning Furnace 1\Feed\Profile|ACE.Profile.Wall.Port14 | T1: \\wsmlmes\WSMLPI_MDB\WSMLPI ModuleDB\Anglo Platinum\Smelters\Waterval Smelter\Hot Metals\Slag Cleaning Furnace 1\Feed\Profile|ACE.Profile.Wall.Port5 | V1: \\wsmlmes\WSMLPI_MDB\WSMLPI ModuleDB\Anglo Platinum\Smelters\Waterval Smelter\Hot Metals\Slag Cleaning Furnace 1\Feed\Profile|ACE.Profile.Wall.Port7 | X1: \\wsmlmes\WSMLPI_MDB\WSMLPI ModuleDB\Anglo Platinum\Smelters\Waterval Smelter\Hot Metals\Slag Cleaning Furnace 1\Feed\Profile|ACE.Profile.Wall.Port8 | Z1: \\wsmlmes\WSMLPI_MDB\WSMLPI ModuleDB\Anglo Platinum\Smelters\Waterval Smelter\Hot Metals\Slag Cleaning Furnace 1\Feed\Profile|WACS.Centre.Port11.tot | AB1: \\wsmlmes\WSMLPI_MDB\WSMLPI ModuleDB\Anglo Platinum\Smelters\Waterval Smelter\Hot Metals\Slag Cleaning Furnace 1\Feed\Profile|WACS.Delta.Port13.tot | AD1: \\wsmlmes\WSMLPI_MDB\WSMLPI ModuleDB\Anglo Platinum\Smelters\Waterval Smelter\Hot Metals\Slag Cleaning Furnace 1\Feed\Profile|WACS.Delta.Port6.tot | AF1: \\wsmlmes\WSMLPI_MDB\WSMLPI ModuleDB\Anglo Platinum\Smelters\Waterval Smelter\Hot Metals\Slag Cleaning Furnace 1\Feed\Profile|WACS.Delta.Port9.tot | AH1: \\wsmlmes\WSMLPI_MDB\WSMLPI ModuleDB\Anglo Platinum\Smelters\Waterval Smelter\Hot Metals\Slag Cleaning Furnace 1\Feed\Profile|WACS.Wall.Port10.tot | AJ1: \\wsmlmes\WSMLPI_MDB\WSMLPI ModuleDB\Anglo Platinum\Smelters\Waterval Smelter\Hot Metals\Slag Cleaning Furnace 1\Feed\Profile|WACS.Wall.Port12.tot | AL1: \\wsmlmes\WSMLPI_MDB\WSMLPI ModuleDB\Anglo Platinum\Smelters\Waterval Smelter\Hot Metals\Slag Cleaning Furnace 1\Feed\Profile|WACS.Wall.Port14.tot | AN1: \\wsmlmes\WSMLPI_MDB\WSMLPI ModuleDB\Anglo Platinum\Smelters\Waterval Smelter\Hot Metals\Slag Cleaning Furnace 1\Feed\Profile|WACS.Wall.Port5.tot | AP1: \\wsmlmes\WSMLPI_MDB\WSMLPI ModuleDB\Anglo Platinum\Smelters\Waterval Smelter\Hot Metals\Slag Cleaning Furnace 1\Feed\Profile|WACS.Wall.Port7.tot | AR1: \\wsmlmes\WSMLPI_MDB\WSMLPI ModuleDB\Anglo Platinum\Smelters\Waterval Smelter\Hot Metals\Slag Cleaning Furnace 1\Feed\Profile|WACS.Wall.Port8.tot
A2: {=_xll.PICompDat(Sheet1!$B$1,"2021/06/07","2021/06/17",9,"","inside")} -> 44354.208 | B2: 36.408485 | C2: {=_xll.PICompDat(Sheet1!$D$1,"2021/06/07","2021/06/17",9,"","inside")} -> 44354.208 | D2: 38.631065 | E2: {=_xll.PICompDat(Sheet1!$F$1,"2021/06/07","2021/06/17",9,"","inside")} -> 44354.208 | F2: 24.960449 | G2: {=_xll.PICompDat(Sheet1!$H$1,"2021/06/07","2021/06/17",9,"","inside")} -> 44354.208 | H2: 37.582695 | I2: {=_xll.PICompDat(Sheet1!$J$1,"2021/06/07","2021/06/17",9,"","inside")} -> 44354.208 | J2: 37.582695 | K2: {=_xll.PICompDat(Sheet1!$L$1,"2021/06/07","2021/06/17",9,"","inside")} -> 44354.208 | L2: 30.44297 | M2: {=_xll.PICompDat(Sheet1!$N$1,"2021/06/07","2021/06/17",9,"","inside")} -> 44354.208 | N2: 8.7615147 | O2: {=_xll.PICompDat(Sheet1!$P$1,"2021/06/07","2021/06/17",9,"","inside")} -> 44354.208 | P2: 15.8234 | Q2: {=_xll.PICompDat(Sheet1!$R$1,"2021/06/07","2021/06/17",9,"","inside")} -> 44354.208 | R2: 12.170356 | S2: {=_xll.PICompDat(Sheet1!$T$1,"2021/06/07","2021/06/17",9,"","inside")} -> 44354.208 | T2: 30.44297 | U2: {=_xll.PICompDat(Sheet1!$V$1,"2021/06/07","2021/06/17",9,"","inside")} -> 44354.208 | V2: 25.8937 | W2: {=_xll.PICompDat(Sheet1!$X$1,"2021/06/07","2021/06/17",9,"","inside")} -> 44354.208 | X2: 20.716917 | Y2: {=_xll.PICompDat(Sheet1!$Z$1,"2021/06/07","2021/06/17",9,"","inside")} -> 44354.019 | Z2: 100.50642 | AA2: {=_xll.PICompDat(Sheet1!$AB$1,"2021/06/07","2021/06/17",9,"","inside")} -> 44354.021 | AB2: 32.920021 | AC2: {=_xll.PICompDat(Sheet1!$AD$1,"2021/06/07","2021/06/17",9,"","inside")} -> 44354.021 | AD2: 33.840027 | AE2: {=_xll.PICompDat(Sheet1!$AF$1,"2021/06/07","2021/06/17",9,"","inside")} -> 44354.021 | AF2: 22.169991 | AG2: {=_xll.PICompDat(Sheet1!$AH$1,"2021/06/07","2021/06/17",9,"","inside")} -> 44354.033 | AH2: 7.9000244 | AI2: {=_xll.PICompDat(Sheet1!$AJ$1,"2021/06/07","2021/06/17",9,"","inside")} -> 44354.031 | AJ2: 13.620064 | AK2: {=_xll.PICompDat(Sheet1!$AL$1,"2021/06/07","2021/06/17",9,"","inside")} -> 44354.018 | AL2: 10.380013 | AM2: {=_xll.PICompDat(Sheet1!$AN$1,"2021/06/07","2021/06/17",9,"","inside")} -> 44354.018 | AN2: 13.419998 | AO2: {=_xll.PICompDat(Sheet1!$AP$1,"2021/06/07","2021/06/17",9,"","inside")} -> 44354.02 | AP2: 21.300011 | AQ2: {=_xll.PICompDat(Sheet1!$AR$1,"2021/06/07","2021/06/17",9,"","inside")} -> 44354.018 | AR2: 17.089989
A3: 44354.208 | B3: 31.383009 | C3: 44354.208 | D3: 40.107594 | E3: 44354.208 | F3: 28.509396 | G3: 44354.208 | H3: 38.421417 | I3: 44354.208 | J3: 38.421417 | K3: 44354.208 | L3: 28.896894 | M3: 44354.208 | N3: 10.976896 | O3: 44354.208 | P3: 20.039299 | Q3: 44354.208 | R3: 17.859573 | S3: 44354.208 | T3: 28.896894 | U3: 44354.208 | V3: 15.758492 | W3: 44354.208 | X3: 15.571957 | Y3: 44354.019 | Z3: 101.00651 | AA3: 44354.021 | AB3: 33.450031 | AC3: 44354.023 | AD3: 34.350021 | AE3: 44354.036 | AF3: 22.679985 | AG3: 44354.12 | AH3: 8.4100266 | AI3: 44354.069 | AJ3: 14.130058 | AK3: 44354.07 | AL3: 10.88002 | AM3: 44354.069 | AN3: 13.940002 | AO3: 44354.034 | AP3: 21.82 | AQ3: 44354.068 | AR3: 17.639984
A4: 44355.208 | B4: 31.383009 | C4: 44355.208 | D4: 40.107594 | E4: 44355.208 | F4: 28.509396 | G4: 44355.208 | H4: 38.421417 | I4: 44355.208 | J4: 38.421417 | K4: 44355.208 | L4: 28.896894 | M4: 44355.208 | N4: 10.976896 | O4: 44355.208 | P4: 20.039299 | Q4: 44355.208 | R4: 17.859573 | S4: 44355.208 | T4: 28.896894 | U4: 44355.208 | V4: 15.758492 | W4: 44355.208 | X4: 15.571957 | Y4: 44354.02 | Z4: 101.50661 | AA4: 44354.072 | AB4: 33.960052 | AC4: 44354.036 | AD4: 34.850029 | AE4: 44354.073 | AF4: 23.179993 | AG4: 44354.184 | AH4: 8.970047 | AI4: 44354.11 | AJ4: 14.640045 | AK4: 44354.119 | AL4: 11.380028 | AM4: 44354.083 | AN4: 14.450005 | AO4: 44354.071 | AP4: 22.370003 | AQ4: 44354.082 | AR4: 18.149986
A5: 44355.208 | B5: 30.781971 | C5: 44355.208 | D5: 38.699554 | E5: 44355.208 | F5: 30.518475 | G5: 44355.208 | H5: 37.52536 | I5: 44355.208 | J5: 37.52536 | K5: 44355.208 | L5: 27.238012 | M5: 44355.208 | N5: 10.519578 | O5: 44355.208 | P5: 18.888416 | Q5: 44355.208 | R5: 16.258524 | S5: 44355.208 | T5: 27.238012 | U5: 44355.208 | V5: 14.310054 | W5: 44355.208 | X5: 17.120966 | Y5: 44354.02 | Z5: 102.01672 | AA5: 44354.072 | AB5: 34.510067 | AC5: 44354.037 | AD5: 35.370026 | AE5: 44354.087 | AF5: 23.68 | AG5: 44354.212 | AH5: 0 | AI5: 44354.146 | AJ5: 15.160034 | AK5: 44354.148 | AL5: 11.940033 | AM5: 44354.119 | AN5: 14.950012 | AO5: 44354.085 | AP5: 22.880005 | AQ5: 44354.11 | AR5: 18.659981
A6: 44356.208 | B6: 30.781971 | C6: 44356.208 | D6: 38.699554 | E6: 44356.208 | F6: 30.518475 | G6: 44356.208 | H6: 37.52536 | I6: 44356.208 | J6: 37.52536 | K6: 44356.208 | L6: 27.238012 | M6: 44356.208 | N6: 10.519578 | O6: 44356.208 | P6: 18.888416 | Q6: 44356.208 | R6: 16.258524 | S6: 44356.208 | T6: 27.238012 | U6: 44356.208 | V6: 14.310054 | W6: 44356.208 | X6: 17.120966 | Y6: 44354.02 | Z6: 102.51682 | AA6: 44354.086 | AB6: 35.050091 | AC6: 44354.074 | AD6: 35.89003 | AE6: 44354.122 | AF6: 24.239998 | AG6: 44354.316 | AH6: 0.62000275 | AI6: 44354.161 | AJ6: 15.690025 | AK6: 44354.183 | AL6: 12.460022 | AM6: 44354.126 | AN6: 15.480011 | AO6: 44354.121 | AP6: 23.389999 | AQ6: 44354.125 | AR6: 19.169983
A7: 44356.208 | B7: 31.611771 | C7: 44356.208 | D7: 41.437832 | E7: 44356.208 | F7: 26.950397 | G7: 44356.208 | H7: 37.023903 | I7: 44356.208 | J7: 37.023903 | K7: 44356.208 | L7: 32.117321 | M7: 44356.208 | N7: 7.9229736 | O7: 44356.208 | P7: 14.413179 | Q7: 44356.208 | R7: 10.864413 | S7: 44356.208 | T7: 32.117321 | U7: 44356.208 | V7: 25.600128 | W7: 44356.208 | X7: 20.628084 | Y7: 44354.033 | Z7: 103.0169 | AA7: 44354.086 | AB7: 35.570091 | AC7: 44354.086 | AD7: 36.420029 | AE7: 44354.129 | AF7: 24.759995 | AG7: 44354.348 | AH7: 1.1600037 | AI7: 44354.196 | AJ7: 16.200012 | AK7: 44354.212 | AL7: 0 | AM7: 44354.148 | AN7: 15.990021 | AO7: 44354.127 | AP7: 23.919998 | AQ7: 44354.147 | AR7: 19.679993
A8: 44357.208 | B8: 31.611771 | C8: 44357.208 | D8: 41.437832 | E8: 44357.208 | F8: 26.950397 | G8: 44357.208 | H8: 37.023903 | I8: 44357.208 | J8: 37.023903 | K8: 44357.208 | L8: 32.117321 | M8: 44357.208 | N8: 7.9229736 | O8: 44357.208 | P8: 14.413179 | Q8: 44357.208 | R8: 10.864413 | S8: 44357.208 | T8: 32.117321 | U8: 44357.208 | V8: 25.600128 | W8: 44357.208 | X8: 20.628084 | Y8: 44354.033 | Z8: 103.52699 | AA8: 44354.122 | AB8: 36.110104 | AC8: 44354.088 | AD8: 36.940025 | AE8: 44354.151 | AF8: 25.260002 | AG8: 44354.362 | AH8: 1.6699982 | AI8: 44354.212 | AJ8: 0 | AK8: 44354.218 | AL8: 0.52000427 | AM8: 44354.162 | AN8: 16.500031 | AO8: 44354.149 | AP8: 24.439987 | AQ8: 44354.16 | AR8: 20.18
A9: 44357.208 | B9: 31.774279 | C9: 44357.208 | D9: 41.379051 | E9: 44357.208 | F9: 26.84667 | G9: 44357.208 | H9: 37.306091 | I9: 44357.208 | J9: 37.306091 | K9: 44357.208 | L9: 30.699699 | M9: 44357.208 | N9: 6.7891827 | O9: 44357.208 | P9: 15.947788 | Q9: 44357.208 | R9: 11.42168 | S9: 44357.208 | T9: 30.699699 | U9: 44357.208 | V9: 24.032928 | W9: 44357.208 | X9: 21.440962 | Y9: 44354.033 | Z9: 104.03709 | AA9: 44354.128 | AB9: 36.630093 | AC9: 44354.123 | AD9: 37.450035 | AE9: 44354.164 | AF9: 25.790001 | AG9: 44354.397 | AH9: 2.1899948 | AI9: 44354.217 | AJ9: 0.53999329 | AK9: 44354.228 | AL9: 1.0700073 | AM9: 44354.183 | AN9: 17.030022 | AO9: 44354.162 | AP9: 24.939995 | AQ9: 44354.182 | AR9: 20.690002
A10: 44358.208 | B10: 31.774279 | C10: 44358.208 | D10: 41.379051 | E10: 44358.208 | F10: 26.84667 | G10: 44358.208 | H10: 37.306091 | I10: 44358.208 | J10: 37.306091 | K10: 44358.208 | L10: 30.699699 | M10: 44358.208 | N10: 6.7891827 | O10: 44358.208 | P10: 15.947788 | Q10: 44358.208 | R10: 11.42168 | S10: 44358.208 | T10: 30.699699 | U10: 44358.208 | V10: 24.032928 | W10: 44358.208 | X10: 21.440962 | Y10: 44354.034 | Z10: 104.5672 | AA10: 44354.129 | AB10: 37.18008 | AC10: 44354.124 | AD10: 37.960037 | AE10: 44354.186 | AF10: 26.299995 | AG10: 44354.421 | AH10: 2.7099915 | AI10: 44354.218 | AJ10: 1.0499954 | AK10: 44354.243 | AL10: 1.5800095 | AM10: 44354.212 | AN10: 0 | AO10: 44354.184 | AP10: 25.459991 | AQ10: 44354.195 | AR10: 21.209999
A11: 44358.208 | B11: 35.200172 | C11: 44358.208 | D11: 35.71571 | E11: 44358.208 | F11: 29.08412 | G11: 44358.208 | H11: 34.237404 | I11: 44358.208 | J11: 34.237404 | K11: 44358.208 | L11: 29.316648 | M11: 44358.208 | N11: 9.815258 | O11: 44358.208 | P11: 16.928452 | Q11: 44358.208 | R11: 21.91781 | S11: 44358.208 | T11: 29.316648 | U11: 44358.208 | V11: 17.041601 | W11: 44358.208 | X11: 22.219419 | Y11: 44354.034 | Z11: 105.08731 | AA11: 44354.185 | AB11: 37.710068 | AC11: 44354.13 | AD11: 38.470039 | AE11: 44354.2 | AF11: 26.839996 | AG11: 44354.448 | AH11: 3.2299957 | AI11: 44354.219 | AJ11: 1.5899963 | AK11: 44354.285 | AL11: 2.1100006 | AM11: 44354.242 | AN11: 0.51000214 | AO11: 44354.197 | AP11: 25.999992 | AQ11: 44354.212 | AR11: 0
A12: 44359.208 | B12: 35.200172 | C12: 44359.208 | D12: 35.71571 | E12: 44359.208 | F12: 29.08412 | G12: 44359.208 | H12: 34.237404 | I12: 44359.208 | J12: 34.237404 | K12: 44359.208 | L12: 29.316648 | M12: 44359.208 | N12: 9.815258 | O12: 44359.208 | P12: 16.928452 | Q12: 44359.208 | R12: 21.91781 | S12: 44359.208 | T12: 29.316648 | U12: 44359.208 | V12: 17.041601 | W12: 44359.208 | X12: 22.219419 | Y12: 44354.071 | Z12: 105.5974 | AA12: 44354.185 | AB12: 38.250072 | AC12: 44354.151 | AD12: 38.980034 | AE12: 44354.212 | AF12: 0 | AG12: 44354.492 | AH12: 3.730011 | AI12: 44354.24 | AJ12: 2.090004 | AK12: 44354.313 | AL12: 2.6300049 | AM12: 44354.313 | AN12: 1.0200119 | AO12: 44354.199 | AP12: 26.509995 | AQ12: 44354.227 | AR12: 0.51999664
A13: 44359.208 | B13: 35.742126 | C13: 44359.208 | D13: 39.278236 | E13: 44359.208 | F13: 24.979639 | G13: 44359.208 | H13: 37.371338 | I13: 44359.208 | J13: 37.371338 | K13: 44359.208 | L13: 29.86533 | M13: 44359.208 | N13: 8.8699236 | O13: 44359.208 | P13: 16.896473 | Q13: 44359.208 | R13: 12.917962 | S13: 44359.208 | T13: 29.86533 | U13: 44359.208 | V13: 20.924686 | W13: 44359.208 | X13: 24.149229 | Y13: 44354.071 | Z13: 106.09746 | AA13: 44354.186 | AB13: 39.150082 | AC13: 44354.164 | AD13: 39.490036 | AE13: 44354.231 | AF13: 0.52999878 | AG13: 44354.504 | AH13: 4.2900009 | AI13: 44354.241 | AJ13: 2.6500015 | AK13: 44354.315 | AL13: 3.1399994 | AM13: 44354.327 | AN13: 1.5400009 | AO13: 44354.212 | AP13: 0 | AQ13: 44354.282 | AR13: 1.0200043
A14: 44360.208 | B14: 35.742126 | C14: 44360.208 | D14: 39.278236 | E14: 44360.208 | F14: 24.979639 | G14: 44360.208 | H14: 37.371338 | I14: 44360.208 | J14: 37.371338 | K14: 44360.208 | L14: 29.86533 | M14: 44360.208 | N14: 8.8699236 | O14: 44360.208 | P14: 16.896473 | Q14: 44360.208 | R14: 12.917962 | S14: 44360.208 | T14: 29.86533 | U14: 44360.208 | V14: 20.924686 | W14: 44360.208 | X14: 24.149229 | Y14: 44354.071 | Z14: 106.61752 | AA14: 44354.212 | AB14: 0 | AC14: 44354.166 | AD14: 40.000038 | AE14: 44354.246 | AF14: 1.0399933 | AG14: 44354.587 | AH14: 4.8099899 | AI14: 44354.283 | AJ14: 3.1600037 | AK14: 44354.327 | AL14: 3.6600037 | AM14: 44354.347 | AN14: 2.0400085 | AO14: 44354.229 | AP14: 0.51000214 | AQ14: 44354.46 | AR14: 1.5400009
... A21: 44363.208 | B21: 42.342598 | C21: 44363.208 | D21: 34.380363 | E21: 44363.208 | F21: 23.277039 | G21: 44363.208 | H21: 37.866104 | I21: 44363.208 | J21: 37.866104 | K21: 44363.208 | L21: 27.677311 | M21: 44363.208 | N21: 9.5439205 | O21: 44363.208 | P21: 19.326187 | Q21: 44363.208 | R21: 16.422981 | S21: 44363.208 | T21: 27.677311 | U21: 44363.208 | V21: 10.42143 | W21: 44363.208 | X21: 26.920128 | Y21: 44354.085 | Z21: 110.18809 | AA21: 44354.245 | AB21: 3.6699994 | AC21: 44354.247 | AD21: 1.5299988 | AE21: 44354.33 | AF21: 4.6299896 | AG21: 44355.029 | AH21: 8.4699936 | AI21: 44354.446 | AJ21: 6.8600006 | AK21: 44354.491 | AL21: 7.3100204 | AM21: 44354.503 | AN21: 5.6300201 | AO21: 44354.715 | AP21: 4.1600342 | AQ21: 44354.599 | AR21: 5.1300278
Y22: 44354.12 | Z22: 110.69819 | AA22: 44354.245 | AB22: 4.170001 | AC22: 44354.288 | AD22: 2.0499954 | AE22: 44354.332 | AF22: 5.1399918 | AG22: 44355.07 | AH22: 9.0399933 | AI22: 44354.488 | AJ22: 7.3700027 | AK22: 44354.517 | AL22: 7.8300247 | AM22: 44354.517 | AN22: 6.1400146 | AO22: 44354.729 | AP22: 4.6700516 | AQ22: 44354.622 | AR22: 5.650032
Y23: 44354.12 | Z23: 111.20829 | AA23: 44354.245 | AB23: 4.7000036 | AC23: 44354.29 | AD23: 2.5500031 | AE23: 44354.35 | AF23: 5.6699982 | AG23: 44355.072 | AH23: 9.5599899 | AI23: 44354.501 | AJ23: 7.8700104 | AK23: 44354.564 | AL23: 8.3400192 | AM23: 44354.551 | AN23: 6.6500168 | AO23: 44354.77 | AP23: 5.1700592 | AQ23: 44354.634 | AR23: 6.1600266
Y24: 44354.12 | Z24: 111.70837 | AA24: 44354.329 | AB24: 5.2400055 | AC24: 44354.292 | AD24: 3.0699997 | AE24: 44354.364 | AF24: 6.1799927 | AG24: 44355.081 | AH24: 10.099998 | AI24: 44354.515 | AJ24: 8.3800125 | AK24: 44354.6 | AL24: 8.8400269 | AM24: 44354.565 | AN24: 7.1700134 | AO24: 44354.789 | AP24: 5.6900558 | AQ24: 44354.648 | AR24: 6.6700211
Y25: 44354.121 | Z25: 112.21844 | AA25: 44354.33 | AB25: 5.7700057 | AC25: 44354.293 | AD25: 3.5800018 | AE25: 44354.365 | AF25: 6.6800003 | AG25: 44355.119 | AH25: 10.609993 | AI25: 44354.548 | AJ25: 8.9000092 | AK25: 44354.635 | AL25: 9.3800278 | AM25: 44354.6 | AN25: 7.7200165 | AO25: 44354.824 | AP25: 6.1900635 | AQ25: 44354.669 | AR25: 7.1900177
Y26: 44354.121 | Z26: 112.72855 | AA26: 44354.33 | AB26: 6.2900071 | AC26: 44354.319 | AD26: 4.090004 | AE26: 44354.388 | AF26: 7.1899948 | AG26: 44355.187 | AH26: 11.179985 | AI26: 44354.549 | AJ26: 9.4400101 | AK26: 44354.65 | AL26: 9.8900223 | AM26: 44354.623 | AN26: 8.2500076 | AO26: 44354.826 | AP26: 6.700058 | AQ26: 44354.689 | AR26: 7.690033
Y27: 44354.121 | Z27: 113.23866 | AA27: 44354.33 | AB27: 6.8300076 | AC27: 44354.33 | AD27: 4.5999985 | AE27: 44354.4 | AF27: 7.6999893 | AG27: 44355.212 | AH27: 0 | AI27: 44354.563 | AJ27: 9.9600143 | AK27: 44354.689 | AL27: 10.410011 | AM27: 44354.635 | AN27: 8.7800064 | AO27: 44354.854 | AP27: 7.2300644 | AQ27: 44354.713 | AR27: 8.2100372
Y28: 44354.127 | Z28: 113.73874 | AA28: 44354.33 | AB28: 6.3100076 | AC28: 44354.331 | AD28: 5.1100006 | AE28: 44354.422 | AF28: 8.2099915 | AG28: 44355.255 | AH28: 0.50999451 | AI28: 44354.585 | AJ28: 10.490013 | AK28: 44354.714 | AL28: 10.920013 | AM28: 44354.65 | AN28: 9.2900009 | AO28: 44354.878 | AP28: 7.7400589 | AQ28: 44354.727 | AR28: 8.7200394
Y29: 44354.127 | Z29: 114.23883 | AA29: 44354.363 | AB29: 6.8600073 | AC29: 44354.35 | AD29: 5.6199951 | AE29: 44354.424 | AF29: 8.719986 | AG29: 44355.297 | AH29: 1.0100021 | AI29: 44354.622 | AJ29: 11.000008 | AK29: 44354.769 | AL29: 11.45002 | AM29: 44354.671 | AN29: 9.7900085 | AO29: 44354.894 | AP29: 8.2400665 | AQ29: 44354.872 | AR29: 9.2300339
Y30: 44354.127 | Z30: 114.74894 | AA30: 44354.363 | AB30: 7.3700113 | AC30: 44354.351 | AD30: 6.1499939 | AE30: 44354.437 | AF30: 9.2299881 | AG30: 44355.313 | AH30: 1.5500031 | AI30: 44354.623 | AJ30: 11.520004 | AK30: 44354.824 | AL30: 11.970024 | AM30: 44354.713 | AN30: 10.300003 | AO30: 44354.907 | AP30: 8.7500687 | AQ30: 44354.889 | AR30: 9.7300415
Y31: 44354.128 | Z31: 115.25904 | AA31: 44354.363 | AB31: 7.9100137 | AC31: 44354.364 | AD31: 6.6599884 | AE31: 44354.45 | AF31: 9.7399826 | AG31: 44355.357 | AH31: 2.0800018 | AI31: 44354.649 | AJ31: 12.040009 | AK31: 44354.876 | AL31: 12.490021 | AM31: 44354.728 | AN31: 10.830002 | AO31: 44354.936 | AP31: 9.2600555 | AQ31: 44354.901 | AR31: 10.250046
Y32: 44354.128 | Z32: 115.77915 | AA32: 44354.422 | AB32: 8.4200163 | AC32: 44354.366 | AD32: 7.1699905 | AE32: 44354.452 | AF32: 10.259987 | AG32: 44355.379 | AH32: 2.6000061 | AI32: 44354.67 | AJ32: 12.560005 | AK32: 44354.905 | AL32: 13.010017 | AM32: 44354.768 | AN32: 11.339996 | AO32: 44354.95 | AP32: 9.7600632 | AQ32: 44354.944 | AR32: 10.750053
Y33: 44354.148 | Z33: 116.28925 | AA33: 44354.422 | AB33: 8.9400167 | AC33: 44354.387 | AD33: 7.6999893 | AE33: 44354.506 | AF33: 10.769989 | AG33: 44355.393 | AH33: 3.1300049 | AI33: 44354.727 | AJ33: 13.060013 | AK33: 44354.948 | AL33: 13.520012 | AM33: 44354.789 | AN33: 11.87999 | AO33: 44354.975 | AP33: 10.270058 | AQ33: 44354.972 | AR33: 11.260056
... Y175: 44354.716 | Z175: 62.121712 | AA175: 44356.314 | AB175: 3.7099981 | AC175: 44355.902 | AD175: 34.019989 | AE175: 44356.621 | AF175: 12.780022 | AG175: 44363.98 | AH175: 6.7099915 | AI175: 44359.31 | AJ175: 1.5800095 | AK175: 44360.01 | AL175: 10.430016 | AM175: 44358.133 | AN175: 20.039948 | AO175: 44358.226 | AP175: 0.58000183 | AQ175: 44358.603 | AR175: 6.7700043
Y176: 44354.729 | Z176: 62.62175 | AA176: 44356.314 | AB176: 4.2399988 | AC176: 44355.953 | AD176: 34.549988 | AE176: 44356.65 | AF176: 13.280029 | AI176: 44359.324 | AJ176: 2.1100082 | AK176: 44360.05 | AL176: 10.970009 | AM176: 44358.148 | AN176: 20.549942 | AO176: 44358.24 | AP176: 1.109993 | AQ176: 44358.617 | AR176: 7.2900009
Y177: 44354.729 | Z177: 63.121773 | AA177: 44356.328 | AB177: 4.8199987 | AC177: 44355.954 | AD177: 35.05999 | AE177: 44356.664 | AF177: 13.830025 | AI177: 44359.365 | AJ177: 2.6199951 | AK177: 44360.089 | AL177: 11.470024 | AM177: 44358.192 | AN177: 21.059944 | AO177: 44358.283 | AP177: 1.6399841 | AQ177: 44358.646 | AR177: 7.7999954
Y178: 44354.729 | Z178: 63.63179 | AA178: 44356.328 | AB178: 5.3999987 | AC178: 44355.956 | AD178: 35.569992 | AE178: 44356.685 | AF178: 14.340034 | AI178: 44359.407 | AJ178: 3.1500015 | AK178: 44360.134 | AL178: 11.990021 | AM178: 44358.212 | AN178: 0 | AO178: 44358.312 | AP178: 2.1399918 | AQ178: 44358.66 | AR178: 8.3299942
Y179: 44354.729 | Z179: 64.141838 | AA179: 44356.369 | AB179: 5.9299989 | AC179: 44355.957 | AD179: 36.079987 | AE179: 44356.698 | AF179: 14.870033 | AI179: 44359.436 | AJ179: 3.7000046 | AK179: 44360.177 | AL179: 12.500015 | AM179: 44358.238 | AN179: 0.50000763 | AO179: 44358.326 | AP179: 2.6699905 | AQ179: 44358.686 | AR179: 8.8399963
Y180: 44354.73 | Z180: 64.651947 | AA180: 44356.37 | AB180: 6.5199986 | AC180: 44355.982 | AD180: 36.659988 | AE180: 44356.728 | AF180: 15.370041 | AI180: 44359.479 | AJ180: 4.2200012 | AK180: 44360.192 | AL180: 13.020012 | AM180: 44358.239 | AN180: 0.88000488 | AO180: 44358.354 | AP180: 3.1899872 | AQ180: 44358.7 | AR180: 9.3899918
Y181: 44354.77 | Z181: 65.152054 | AA181: 44356.37 | AB181: 5.8799987 | AC181: 44355.984 | AD181: 37.169998 | AE181: 44356.742 | AF181: 15.890038 | AI181: 44359.522 | AJ181: 4.7299881 | AK181: 44360.212 | AL181: 0 | AM181: 44358.618 | AN181: 0.88000488 | AO181: 44358.356 | AP181: 3.6899948 | AQ181: 44358.725 | AR181: 9.8999939
Y182: 44354.77 | Z182: 65.652161 | AA182: 44356.397 | AB182: 6.4099984 | AC182: 44355.995 | AD182: 37.679985 | AE182: 44356.767 | AF182: 16.400032 | AI182: 44359.536 | AJ182: 5.3099899 | AK182: 44360.24 | AL182: 0.51000214 | AM182: 44358.647 | AN182: 1.3800125 | AO182: 44358.537 | AP182: 4.2099762 | AQ182: 44358.738 | AR182: 10.400002
Y183: 44354.77 | Z183: 66.16227 | AA183: 44356.397 | AB183: 6.9299984 | AC183: 44355.996 | AD183: 38.179993 | AE183: 44356.781 | AF183: 16.920044 | AI183: 44359.562 | AJ183: 5.8399963 | AK183: 44360.283 | AL183: 1.0100098 | AM183: 44358.662 | AN183: 1.8899994 | AO183: 44358.559 | AP183: 4.719986 | AQ183: 44358.739 | AR183: 10.559998
Y184: 44354.77 | Z184: 66.682373 | AA184: 44356.397 | AB184: 7.5899982 | AC184: 44356.026 | AD184: 38.689995 | AE184: 44356.813 | AF184: 17.430038 | AI184: 44359.6 | AJ184: 6.340004 | AK184: 44360.322 | AL184: 1.5199966 | AM184: 44358.687 | AN184: 2.4000015 | AO184: 44358.573 | AP184: 5.2399826 | AQ184: 44358.744 | AR184: 10.559998
Y185: 44354.771 | Z185: 67.182472 | AA185: 44356.41 | AB185: 6.9399981 | AC185: 44356.038 | AD185: 39.199989 | AE185: 44356.827 | AF185: 17.940033 | AI185: 44359.644 | AJ185: 6.890007 | AK185: 44360.366 | AL185: 2.0299988 | AM185: 44358.702 | AN185: 2.9100037 | AO185: 44358.606 | AP185: 5.7499847 | AQ185: 44358.892 | AR185: 11.060005
Y186: 44354.789 | Z186: 67.682526 | AA186: 44356.41 | AB186: 7.4499979 | AC186: 44356.04 | AD186: 39.719994 | AE186: 44356.847 | AF186: 18.490028 | AI186: 44359.658 | AJ186: 7.4500046 | AK186: 44360.392 | AL186: 2.5399933 | AM186: 44358.726 | AN186: 3.4300079 | AO186: 44358.62 | AP186: 6.2599945 | AQ186: 44358.906 | AR186: 11.570007
Y187: 44354.79 | Z187: 68.192589 | AA187: 44356.411 | AB187: 7.9499984 | AC187: 44356.067 | AD187: 40.23999 | AE187: 44356.861 | AF187: 19.000023 | AI187: 44359.698 | AJ187: 7.9599915 | AK187: 44360.475 | AL187: 3.0599899 | AM187: 44358.74 | AN187: 3.9400024 | AO187: 44358.649 | AP187: 6.769989 | AQ187: 44358.938 | AR187: 12.080002
...

Sheet Sheet2
B1: ACE.Profile.Delta.Port13 | D1: ACE.Profile.Delta.Port6 | F1: ACE.Profile.Delta.Port9 | H1: ACE.Profile.Total.Centre | J1: ACE.Profile.Total.Delta | L1: ACE.Profile.Total.Wall | N1: ACE.Profile.Wall.Port10 | P1: ACE.Profile.Wall.Port12 | R1: ACE.Profile.Wall.Port14 | T1: ACE.Profile.Wall.Port5 | V1: ACE.Profile.Wall.Port7 | X1: ACE.Profile.Wall.Port8 | Z1: WACS.Centre.Port11.tot | AB1: WACS.Delta.Port13.tot | AD1: WACS.Delta.Port6.tot | AF1: WACS.Delta.Port9.tot | AH1: WACS.Wall.Port10.tot | AJ1: WACS.Wall.Port12.tot | AL1: WACS.Wall.Port14.tot | AN1: WACS.Wall.Port5.tot | AP1: WACS.Wall.Port7.tot | AR1: WACS.Wall.Port8.tot
A2: 44354.208 | B2: 36.408485 | C2: 44354.208 | D2: 38.631065 | E2: 44354.208 | F2: 24.960449 | G2: 44354.208 | H2: 37.582695 | I2: 44354.208 | J2: 31.974337 | K2: 44354.208 | L2: 30.44297 | M2: 44354.208 | N2: 8.7615147 | O2: 44354.208 | P2: 15.8234 | Q2: 44354.208 | R2: 12.170356 | S2: 44354.208 | T2: 16.634113 | U2: 44354.208 | V2: 25.8937 | W2: 44354.208 | X2: 20.716917 | Y2: 44354.019 | Z2: 100.50642 | AA2: 44354.021 | AB2: 32.920021 | AC2: 44354.021 | AD2: 33.840027 | AE2: 44354.021 | AF2: 22.169991 | AG2: 44354.033 | AH2: 7.9000244 | AI2: 44354.031 | AJ2: 13.620064 | AK2: 44354.018 | AL2: 10.380013 | AM2: 44354.018 | AN2: 13.419998 | AO2: 44354.02 | AP2: 21.300011 | AQ2: 44354.018 | AR2: 17.089989
A3: 44354.208 | B3: 31.383009 | C3: 44354.208 | D3: 40.107594 | E3: 44354.208 | F3: 28.509396 | G3: 44354.208 | H3: 38.421417 | I3: 44354.208 | J3: 32.681686 | K3: 44354.208 | L3: 28.896894 | M3: 44354.208 | N3: 10.976896 | O3: 44354.208 | P3: 20.039299 | Q3: 44354.208 | R3: 17.859573 | S3: 44354.208 | T3: 19.793781 | U3: 44354.208 | V3: 15.758492 | W3: 44354.208 | X3: 15.571957 | Y3: 44354.019 | Z3: 101.00651 | AA3: 44354.021 | AB3: 33.450031 | AC3: 44354.023 | AD3: 34.350021 | AE3: 44354.036 | AF3: 22.679985 | AG3: 44354.12 | AH3: 8.4100266 | AI3: 44354.069 | AJ3: 14.130058 | AK3: 44354.07 | AL3: 10.88002 | AM3: 44354.069 | AN3: 13.940002 | AO3: 44354.034 | AP3: 21.82 | AQ3: 44354.068 | AR3: 17.639984
A4: 44355.208 | B4: 31.383009 | C4: 44355.208 | D4: 40.107594 | E4: 44355.208 | F4: 28.509396 | G4: 44355.208 | H4: 38.421417 | I4: 44355.208 | J4: 32.681686 | K4: 44355.208 | L4: 28.896894 | M4: 44355.208 | N4: 10.976896 | O4: 44355.208 | P4: 20.039299 | Q4: 44355.208 | R4: 17.859573 | S4: 44355.208 | T4: 19.793781 | U4: 44355.208 | V4: 15.758492 | W4: 44355.208 | X4: 15.571957 | Y4: 44354.02 | Z4: 101.50661 | AA4: 44354.072 | AB4: 33.960052 | AC4: 44354.036 | AD4: 34.850029 | AE4: 44354.073 | AF4: 23.179993 | AG4: 44354.184 | AH4: 8.970047 | AI4: 44354.11 | AJ4: 14.640045 | AK4: 44354.119 | AL4: 11.380028 | AM4: 44354.083 | AN4: 14.450005 | AO4: 44354.071 | AP4: 22.370003 | AQ4: 44354.082 | AR4: 18.149986
A5: 44355.208 | B5: 30.781971 | C5: 44355.208 | D5: 38.699554 | E5: 44355.208 | F5: 30.518475 | G5: 44355.208 | H5: 37.52536 | I5: 44355.208 | J5: 35.236629 | K5: 44355.208 | L5: 27.238012 | M5: 44355.208 | N5: 10.519578 | O5: 44355.208 | P5: 18.888416 | Q5: 44355.208 | R5: 16.258524 | S5: 44355.208 | T5: 22.902462 | U5: 44355.208 | V5: 14.310054 | W5: 44355.208 | X5: 17.120966 | Y5: 44354.02 | Z5: 102.01672 | AA5: 44354.072 | AB5: 34.510067 | AC5: 44354.037 | AD5: 35.370026 | AE5: 44354.087 | AF5: 23.68 | AG5: 44354.212 | AH5: 0 | AI5: 44354.146 | AJ5: 15.160034 | AK5: 44354.148 | AL5: 11.940033 | AM5: 44354.119 | AN5: 14.950012 | AO5: 44354.085 | AP5: 22.880005 | AQ5: 44354.11 | AR5: 18.659981
A6: 44356.208 | B6: 30.781971 | C6: 44356.208 | D6: 38.699554 | E6: 44356.208 | F6: 30.518475 | G6: 44356.208 | H6: 37.52536 | I6: 44356.208 | J6: 35.236629 | K6: 44356.208 | L6: 27.238012 | M6: 44356.208 | N6: 10.519578 | O6: 44356.208 | P6: 18.888416 | Q6: 44356.208 | R6: 16.258524 | S6: 44356.208 | T6: 22.902462 | U6: 44356.208 | V6: 14.310054 | W6: 44356.208 | X6: 17.120966 | Y6: 44354.02 | Z6: 102.51682 | AA6: 44354.086 | AB6: 35.050091 | AC6: 44354.074 | AD6: 35.89003 | AE6: 44354.122 | AF6: 24.239998 | AG6: 44354.316 | AH6: 0.62000275 | AI6: 44354.161 | AJ6: 15.690025 | AK6: 44354.183 | AL6: 12.460022 | AM6: 44354.126 | AN6: 15.480011 | AO6: 44354.121 | AP6: 23.389999 | AQ6: 44354.125 | AR6: 19.169983
A7: 44356.208 | B7: 31.611771 | C7: 44356.208 | D7: 41.437832 | E7: 44356.208 | F7: 26.950397 | G7: 44356.208 | H7: 37.023903 | I7: 44356.208 | J7: 30.858776 | K7: 44356.208 | L7: 32.117321 | M7: 44356.208 | N7: 7.9229736 | O7: 44356.208 | P7: 14.413179 | Q7: 44356.208 | R7: 10.864413 | S7: 44356.208 | T7: 20.57122 | U7: 44356.208 | V7: 25.600128 | W7: 44356.208 | X7: 20.628084 | Y7: 44354.033 | Z7: 103.0169 | AA7: 44354.086 | AB7: 35.570091 | AC7: 44354.086 | AD7: 36.420029 | AE7: 44354.129 | AF7: 24.759995 | AG7: 44354.348 | AH7: 1.1600037 | AI7: 44354.196 | AJ7: 16.200012 | AK7: 44354.212 | AL7: 0 | AM7: 44354.148 | AN7: 15.990021 | AO7: 44354.127 | AP7: 23.919998 | AQ7: 44354.147 | AR7: 19.679993
A8: 44357.208 | B8: 31.611771 | C8: 44357.208 | D8: 41.437832 | E8: 44357.208 | F8: 26.950397 | G8: 44357.208 | H8: 37.023903 | I8: 44357.208 | J8: 30.858776 | K8: 44357.208 | L8: 32.117321 | M8: 44357.208 | N8: 7.9229736 | O8: 44357.208 | P8: 14.413179 | Q8: 44357.208 | R8: 10.864413 | S8: 44357.208 | T8: 20.57122 | U8: 44357.208 | V8: 25.600128 | W8: 44357.208 | X8: 20.628084 | Y8: 44354.033 | Z8: 103.52699 | AA8: 44354.122 | AB8: 36.110104 | AC8: 44354.088 | AD8: 36.940025 | AE8: 44354.151 | AF8: 25.260002 | AG8: 44354.362 | AH8: 1.6699982 | AI8: 44354.212 | AJ8: 0 | AK8: 44354.218 | AL8: 0.52000427 | AM8: 44354.162 | AN8: 16.500031 | AO8: 44354.149 | AP8: 24.439987 | AQ8: 44354.16 | AR8: 20.18
A9: 44357.208 | B9: 31.774279 | C9: 44357.208 | D9: 41.379051 | E9: 44357.208 | F9: 26.84667 | G9: 44357.208 | H9: 37.306091 | I9: 44357.208 | J9: 31.994211 | K9: 44357.208 | L9: 30.699699 | M9: 44357.208 | N9: 6.7891827 | O9: 44357.208 | P9: 15.947788 | Q9: 44357.208 | R9: 11.42168 | S9: 44357.208 | T9: 20.36746 | U9: 44357.208 | V9: 24.032928 | W9: 44357.208 | X9: 21.440962 | Y9: 44354.033 | Z9: 104.03709 | AA9: 44354.128 | AB9: 36.630093 | AC9: 44354.123 | AD9: 37.450035 | AE9: 44354.164 | AF9: 25.790001 | AG9: 44354.397 | AH9: 2.1899948 | AI9: 44354.217 | AJ9: 0.53999329 | AK9: 44354.228 | AL9: 1.0700073 | AM9: 44354.183 | AN9: 17.030022 | AO9: 44354.162 | AP9: 24.939995 | AQ9: 44354.182 | AR9: 20.690002
A10: 44358.208 | B10: 31.774279 | C10: 44358.208 | D10: 41.379051 | E10: 44358.208 | F10: 26.84667 | G10: 44358.208 | H10: 37.306091 | I10: 44358.208 | J10: 31.994211 | K10: 44358.208 | L10: 30.699699 | M10: 44358.208 | N10: 6.7891827 | O10: 44358.208 | P10: 15.947788 | Q10: 44358.208 | R10: 11.42168 | S10: 44358.208 | T10: 20.36746 | U10: 44358.208 | V10: 24.032928 | W10: 44358.208 | X10: 21.440962 | Y10: 44354.034 | Z10: 104.5672 | AA10: 44354.129 | AB10: 37.18008 | AC10: 44354.124 | AD10: 37.960037 | AE10: 44354.186 | AF10: 26.299995 | AG10: 44354.421 | AH10: 2.7099915 | AI10: 44354.218 | AJ10: 1.0499954 | AK10: 44354.243 | AL10: 1.5800095 | AM10: 44354.212 | AN10: 0 | AO10: 44354.184 | AP10: 25.459991 | AQ10: 44354.195 | AR10: 21.209999
A11: 44358.208 | B11: 35.200172 | C11: 44358.208 | D11: 35.71571 | E11: 44358.208 | F11: 29.08412 | G11: 44358.208 | H11: 34.237404 | I11: 44358.208 | J11: 36.44595 | K11: 44358.208 | L11: 29.316648 | M11: 44358.208 | N11: 9.815258 | O11: 44358.208 | P11: 16.928452 | Q11: 44358.208 | R11: 21.91781 | S11: 44358.208 | T11: 12.07746 | U11: 44358.208 | V11: 17.041601 | W11: 44358.208 | X11: 22.219419 | Y11: 44354.034 | Z11: 105.08731 | AA11: 44354.185 | AB11: 37.710068 | AC11: 44354.13 | AD11: 38.470039 | AE11: 44354.2 | AF11: 26.839996 | AG11: 44354.448 | AH11: 3.2299957 | AI11: 44354.219 | AJ11: 1.5899963 | AK11: 44354.285 | AL11: 2.1100006 | AM11: 44354.242 | AN11: 0.51000214 | AO11: 44354.197 | AP11: 25.999992 | AQ11: 44354.212 | AR11: 0
A12: 44359.208 | B12: 35.200172 | C12: 44359.208 | D12: 35.71571 | E12: 44359.208 | F12: 29.08412 | G12: 44359.208 | H12: 34.237404 | I12: 44359.208 | J12: 36.44595 | K12: 44359.208 | L12: 29.316648 | M12: 44359.208 | N12: 9.815258 | O12: 44359.208 | P12: 16.928452 | Q12: 44359.208 | R12: 21.91781 | S12: 44359.208 | T12: 12.07746 | U12: 44359.208 | V12: 17.041601 | W12: 44359.208 | X12: 22.219419 | Y12: 44354.071 | Z12: 105.5974 | AA12: 44354.185 | AB12: 38.250072 | AC12: 44354.151 | AD12: 38.980034 | AE12: 44354.212 | AF12: 0 | AG12: 44354.492 | AH12: 3.730011 | AI12: 44354.24 | AJ12: 2.090004 | AK12: 44354.313 | AL12: 2.6300049 | AM12: 44354.313 | AN12: 1.0200119 | AO12: 44354.199 | AP12: 26.509995 | AQ12: 44354.227 | AR12: 0.51999664
A13: 44359.208 | B13: 35.742126 | C13: 44359.208 | D13: 39.278236 | E13: 44359.208 | F13: 24.979639 | G13: 44359.208 | H13: 37.371338 | I13: 44359.208 | J13: 32.763332 | K13: 44359.208 | L13: 29.86533 | M13: 44359.208 | N13: 8.8699236 | O13: 44359.208 | P13: 16.896473 | Q13: 44359.208 | R13: 12.917962 | S13: 44359.208 | T13: 16.241726 | U13: 44359.208 | V13: 20.924686 | W13: 44359.208 | X13: 24.149229 | Y13: 44354.071 | Z13: 106.09746 | AA13: 44354.186 | AB13: 39.150082 | AC13: 44354.164 | AD13: 39.490036 | AE13: 44354.231 | AF13: 0.52999878 | AG13: 44354.504 | AH13: 4.2900009 | AI13: 44354.241 | AJ13: 2.6500015 | AK13: 44354.315 | AL13: 3.1399994 | AM13: 44354.327 | AN13: 1.5400009 | AO13: 44354.212 | AP13: 0 | AQ13: 44354.282 | AR13: 1.0200043
... A21: 44363.208 | B21: 42.342598 | C21: 44363.208 | D21: 34.380363 | E21: 44363.208 | F21: 23.277039 | G21: 44363.208 | H21: 37.866104 | I21: 44363.208 | J21: 34.456585 | K21: 44363.208 | L21: 27.677311 | M21: 44363.208 | N21: 9.5439205 | O21: 44363.208 | P21: 19.326187 | Q21: 44363.208 | R21: 16.422981 | S21: 44363.208 | T21: 17.365355 | U21: 44363.208 | V21: 10.42143 | W21: 44363.208 | X21: 26.920128 | Y21: 44354.085 | Z21: 110.18809 | AA21: 44354.245 | AB21: 3.6699994 | AC21: 44354.247 | AD21: 1.5299988 | AE21: 44354.33 | AF21: 4.6299896 | AG21: 44355.029 | AH21: 8.4699936 | AI21: 44354.446 | AJ21: 6.8600006 | AK21: 44354.491 | AL21: 7.3100204 | AM21: 44354.503 | AN21: 5.6300201 | AO21: 44354.715 | AP21: 4.1600342 | AQ21: 44354.599 | AR21: 5.1300278
Y22: 44354.12 | Z22: 110.69819 | AA22: 44354.245 | AB22: 4.170001 | AC22: 44354.288 | AD22: 2.0499954 | AE22: 44354.332 | AF22: 5.1399918 | AG22: 44355.07 | AH22: 9.0399933 | AI22: 44354.488 | AJ22: 7.3700027 | AK22: 44354.517 | AL22: 7.8300247 | AM22: 44354.517 | AN22: 6.1400146 | AO22: 44354.729 | AP22: 4.6700516 | AQ22: 44354.622 | AR22: 5.650032
Y23: 44354.12 | Z23: 111.20829 | AA23: 44354.245 | AB23: 4.7000036 | AC23: 44354.29 | AD23: 2.5500031 | AE23: 44354.35 | AF23: 5.6699982 | AG23: 44355.072 | AH23: 9.5599899 | AI23: 44354.501 | AJ23: 7.8700104 | AK23: 44354.564 | AL23: 8.3400192 | AM23: 44354.551 | AN23: 6.6500168 | AO23: 44354.77 | AP23: 5.1700592 | AQ23: 44354.634 | AR23: 6.1600266
Y24: 44354.12 | Z24: 111.70837 | AA24: 44354.329 | AB24: 5.2400055 | AC24: 44354.292 | AD24: 3.0699997 | AE24: 44354.364 | AF24: 6.1799927 | AG24: 44355.081 | AH24: 10.099998 | AI24: 44354.515 | AJ24: 8.3800125 | AK24: 44354.6 | AL24: 8.8400269 | AM24: 44354.565 | AN24: 7.1700134 | AO24: 44354.789 | AP24: 5.6900558 | AQ24: 44354.648 | AR24: 6.6700211
Y25: 44354.121 | Z25: 112.21844 | AA25: 44354.33 | AB25: 5.7700057 | AC25: 44354.293 | AD25: 3.5800018 | AE25: 44354.365 | AF25: 6.6800003 | AG25: 44355.119 | AH25: 10.609993 | AI25: 44354.548 | AJ25: 8.9000092 | AK25: 44354.635 | AL25: 9.3800278 | AM25: 44354.6 | AN25: 7.7200165 | AO25: 44354.824 | AP25: 6.1900635 | AQ25: 44354.669 | AR25: 7.1900177
Y26: 44354.121 | Z26: 112.72855 | AA26: 44354.33 | AB26: 6.2900071 | AC26: 44354.319 | AD26: 4.090004 | AE26: 44354.388 | AF26: 7.1899948 | AG26: 44355.187 | AH26: 11.179985 | AI26: 44354.549 | AJ26: 9.4400101 | AK26: 44354.65 | AL26: 9.8900223 | AM26: 44354.623 | AN26: 8.2500076 | AO26: 44354.826 | AP26: 6.700058 | AQ26: 44354.689 | AR26: 7.690033
Y27: 44354.121 | Z27: 113.23866 | AA27: 44354.33 | AB27: 6.8300076 | AC27: 44354.33 | AD27: 4.5999985 | AE27: 44354.4 | AF27: 7.6999893 | AG27: 44355.212 | AH27: 0 | AI27: 44354.563 | AJ27: 9.9600143 | AK27: 44354.689 | AL27: 10.410011 | AM27: 44354.635 | AN27: 8.7800064 | AO27: 44354.854 | AP27: 7.2300644 | AQ27: 44354.713 | AR27: 8.2100372
Y28: 44354.127 | Z28: 113.73874 | AA28: 44354.33 | AB28: 6.3100076 | AC28: 44354.331 | AD28: 5.1100006 | AE28: 44354.422 | AF28: 8.2099915 | AG28: 44355.255 | AH28: 0.50999451 | AI28: 44354.585 | AJ28: 10.490013 | AK28: 44354.714 | AL28: 10.920013 | AM28: 44354.65 | AN28: 9.2900009 | AO28: 44354.878 | AP28: 7.7400589 | AQ28: 44354.727 | AR28: 8.7200394
Y29: 44354.127 | Z29: 114.23883 | AA29: 44354.363 | AB29: 6.8600073 | AC29: 44354.35 | AD29: 5.6199951 | AE29: 44354.424 | AF29: 8.719986 | AG29: 44355.297 | AH29: 1.0100021 | AI29: 44354.622 | AJ29: 11.000008 | AK29: 44354.769 | AL29: 11.45002 | AM29: 44354.671 | AN29: 9.7900085 | AO29: 44354.894 | AP29: 8.2400665 | AQ29: 44354.872 | AR29: 9.2300339
Y30: 44354.127 | Z30: 114.74894 | AA30: 44354.363 | AB30: 7.3700113 | AC30: 44354.351 | AD30: 6.1499939 | AE30: 44354.437 | AF30: 9.2299881 | AG30: 44355.313 | AH30: 1.5500031 | AI30: 44354.623 | AJ30: 11.520004 | AK30: 44354.824 | AL30: 11.970024 | AM30: 44354.713 | AN30: 10.300003 | AO30: 44354.907 | AP30: 8.7500687 | AQ30: 44354.889 | AR30: 9.7300415
Y31: 44354.128 | Z31: 115.25904 | AA31: 44354.363 | AB31: 7.9100137 | AC31: 44354.364 | AD31: 6.6599884 | AE31: 44354.45 | AF31: 9.7399826 | AG31: 44355.357 | AH31: 2.0800018 | AI31: 44354.649 | AJ31: 12.040009 | AK31: 44354.876 | AL31: 12.490021 | AM31: 44354.728 | AN31: 10.830002 | AO31: 44354.936 | AP31: 9.2600555 | AQ31: 44354.901 | AR31: 10.250046
Y32: 44354.128 | Z32: 115.77915 | AA32: 44354.422 | AB32: 8.4200163 | AC32: 44354.366 | AD32: 7.1699905 | AE32: 44354.452 | AF32: 10.259987 | AG32: 44355.379 | AH32: 2.6000061 | AI32: 44354.67 | AJ32: 12.560005 | AK32: 44354.905 | AL32: 13.010017 | AM32: 44354.768 | AN32: 11.339996 | AO32: 44354.95 | AP32: 9.7600632 | AQ32: 44354.944 | AR32: 10.750053
Y33: 44354.148 | Z33: 116.28925 | AA33: 44354.422 | AB33: 8.9400167 | AC33: 44354.387 | AD33: 7.6999893 | AE33: 44354.506 | AF33: 10.769989 | AG33: 44355.393 | AH33: 3.1300049 | AI33: 44354.727 | AJ33: 13.060013 | AK33: 44354.948 | AL33: 13.520012 | AM33: 44354.789 | AN33: 11.87999 | AO33: 44354.975 | AP33: 10.270058 | AQ33: 44354.972 | AR33: 11.260056
... Y175: 44354.716 | Z175: 62.121712 | AA175: 44356.314 | AB175: 3.7099981 | AC175: 44355.902 | AD175: 34.019989 | AE175: 44356.621 | AF175: 12.780022 | AG175: 44363.98 | AH175: 6.7099915 | AI175: 44359.31 | AJ175: 1.5800095 | AK175: 44360.01 | AL175: 10.430016 | AM175: 44358.133 | AN175: 20.039948 | AO175: 44358.226 | AP175: 0.58000183 | AQ175: 44358.603 | AR175: 6.7700043
Y176: 44354.729 | Z176: 62.62175 | AA176: 44356.314 | AB176: 4.2399988 | AC176: 44355.953 | AD176: 34.549988 | AE176: 44356.65 | AF176: 13.280029 | AI176: 44359.324 | AJ176: 2.1100082 | AK176: 44360.05 | AL176: 10.970009 | AM176: 44358.148 | AN176: 20.549942 | AO176: 44358.24 | AP176: 1.109993 | AQ176: 44358.617 | AR176: 7.2900009
Y177: 44354.729 | Z177: 63.121773 | AA177: 44356.328 | AB177: 4.8199987 | AC177: 44355.954 | AD177: 35.05999 | AE177: 44356.664 | AF177: 13.830025 | AI177: 44359.365 | AJ177: 2.6199951 | AK177: 44360.089 | AL177: 11.470024 | AM177: 44358.192 | AN177: 21.059944 | AO177: 44358.283 | AP177: 1.6399841 | AQ177: 44358.646 | AR177: 7.7999954
Y178: 44354.729 | Z178: 63.63179 | AA178: 44356.328 | AB178: 5.3999987 | AC178: 44355.956 | AD178: 35.569992 | AE178: 44356.685 | AF178: 14.340034 | AI178: 44359.407 | AJ178: 3.1500015 | AK178: 44360.134 | AL178: 11.990021 | AM178: 44358.212 | AN178: 0 | AO178: 44358.312 | AP178: 2.1399918 | AQ178: 44358.66 | AR178: 8.3299942
Y179: 44354.729 | Z179: 64.141838 | AA179: 44356.369 | AB179: 5.9299989 | AC179: 44355.957 | AD179: 36.079987 | AE179: 44356.698 | AF179: 14.870033 | AI179: 44359.436 | AJ179: 3.7000046 | AK179: 44360.177 | AL179: 12.500015 | AM179: 44358.238 | AN179: 0.50000763 | AO179: 44358.326 | AP179: 2.6699905 | AQ179: 44358.686 | AR179: 8.8399963
Y180: 44354.73 | Z180: 64.651947 | AA180: 44356.37 | AB180: 6.5199986 | AC180: 44355.982 | AD180: 36.659988 | AE180: 44356.728 | AF180: 15.370041 | AI180: 44359.479 | AJ180: 4.2200012 | AK180: 44360.192 | AL180: 13.020012 | AM180: 44358.239 | AN180: 0.88000488 | AO180: 44358.354 | AP180: 3.1899872 | AQ180: 44358.7 | AR180: 9.3899918
Y181: 44354.77 | Z181: 65.152054 | AA181: 44356.37 | AB181: 5.8799987 | AC181: 44355.984 | AD181: 37.169998 | AE181: 44356.742 | AF181: 15.890038 | AI181: 44359.522 | AJ181: 4.7299881 | AK181: 44360.212 | AL181: 0 | AM181: 44358.618 | AN181: 0.88000488 | AO181: 44358.356 | AP181: 3.6899948 | AQ181: 44358.725 | AR181: 9.8999939
Y182: 44354.77 | Z182: 65.652161 | AA182: 44356.397 | AB182: 6.4099984 | AC182: 44355.995 | AD182: 37.679985 | AE182: 44356.767 | AF182: 16.400032 | AI182: 44359.536 | AJ182: 5.3099899 | AK182: 44360.24 | AL182: 0.51000214 | AM182: 44358.647 | AN182: 1.3800125 | AO182: 44358.537 | AP182: 4.2099762 | AQ182: 44358.738 | AR182: 10.400002
Y183: 44354.77 | Z183: 66.16227 | AA183: 44356.397 | AB183: 6.9299984 | AC183: 44355.996 | AD183: 38.179993 | AE183: 44356.781 | AF183: 16.920044 | AI183: 44359.562 | AJ183: 5.8399963 | AK183: 44360.283 | AL183: 1.0100098 | AM183: 44358.662 | AN183: 1.8899994 | AO183: 44358.559 | AP183: 4.719986 | AQ183: 44358.739 | AR183: 10.559998
Y184: 44354.77 | Z184: 66.682373 | AA184: 44356.397 | AB184: 7.5899982 | AC184: 44356.026 | AD184: 38.689995 | AE184: 44356.813 | AF184: 17.430038 | AI184: 44359.6 | AJ184: 6.340004 | AK184: 44360.322 | AL184: 1.5199966 | AM184: 44358.687 | AN184: 2.4000015 | AO184: 44358.573 | AP184: 5.2399826 | AQ184: 44358.744 | AR184: 10.559998
Y185: 44354.771 | Z185: 67.182472 | AA185: 44356.41 | AB185: 6.9399981 | AC185: 44356.038 | AD185: 39.199989 | AE185: 44356.827 | AF185: 17.940033 | AI185: 44359.644 | AJ185: 6.890007 | AK185: 44360.366 | AL185: 2.0299988 | AM185: 44358.702 | AN185: 2.9100037 | AO185: 44358.606 | AP185: 5.7499847 | AQ185: 44358.892 | AR185: 11.060005
Y186: 44354.789 | Z186: 67.682526 | AA186: 44356.41 | AB186: 7.4499979 | AC186: 44356.04 | AD186: 39.719994 | AE186: 44356.847 | AF186: 18.490028 | AI186: 44359.658 | AJ186: 7.4500046 | AK186: 44360.392 | AL186: 2.5399933 | AM186: 44358.726 | AN186: 3.4300079 | AO186: 44358.62 | AP186: 6.2599945 | AQ186: 44358.906 | AR186: 11.570007
Y187: 44354.79 | Z187: 68.192589 | AA187: 44356.411 | AB187: 7.9499984 | AC187: 44356.067 | AD187: 40.23999 | AE187: 44356.861 | AF187: 19.000023 | AI187: 44359.698 | AJ187: 7.9599915 | AK187: 44360.475 | AL187: 3.0599899 | AM187: 44358.74 | AN187: 3.9400024 | AO187: 44358.649 | AP187: 6.769989 | AQ187: 44358.938 | AR187: 12.080002
... Y275: 44355.037 | Z275: 112.87032 | AA275: 44357.576 | AB275: 14.449999 | AC275: 44357.102 | AD275: 37.850006 | AE275: 44358.651 | AF275: 7.2499847 | AI275: 44362.067 | AJ275: 16.779991 | AK275: 44363.979 | AL275: 11.990036 | AM275: 44361.443 | AN275: 4.590004 | AO275: 44361.155 | AP275: 15.980003 | AQ275: 44361.112 | AR275: 14.470016
...

Sheet Sheet3
B1: \\wsmlmes\WSMLPI_MDB\WSMLPI ModuleDB\Anglo Platinum\Smelters\Waterval Smelter\Hot Metals\Slag Cleaning Furnace 1\Feed\Profile|ACE.Profile.Delta.Port13 | D1: \\wsmlmes\WSMLPI_MDB\WSMLPI ModuleDB\Anglo Platinum\Smelters\Waterval Smelter\Hot Metals\Slag Cleaning Furnace 1\Feed\Profile|ACE.Profile.Delta.Port6 | F1: \\wsmlmes\WSMLPI_MDB\WSMLPI ModuleDB\Anglo Platinum\Smelters\Waterval Smelter\Hot Metals\Slag Cleaning Furnace 1\Feed\Profile|ACE.Profile.Delta.Port9 | H1: \\wsmlmes\WSMLPI_MDB\WSMLPI ModuleDB\Anglo Platinum\Smelters\Waterval Smelter\Hot Metals\Slag Cleaning Furnace 1\Feed\Profile|ACE.Profile.Total.Centre | J1: \\wsmlmes\WSMLPI_MDB\WSMLPI ModuleDB\Anglo Platinum\Smelters\Waterval Smelter\Hot Metals\Slag Cleaning Furnace 1\Feed\Profile|ACE.Profile.Total.Delta | L1: \\wsmlmes\WSMLPI_MDB\WSMLPI ModuleDB\Anglo Platinum\Smelters\Waterval Smelter\Hot Metals\Slag Cleaning Furnace 1\Feed\Profile|ACE.Profile.Total.Wall | N1: \\wsmlmes\WSMLPI_MDB\WSMLPI ModuleDB\Anglo Platinum\Smelters\Waterval Smelter\Hot Metals\Slag Cleaning Furnace 1\Feed\Profile|ACE.Profile.Wall.Port10 | P1: \\wsmlmes\WSMLPI_MDB\WSMLPI ModuleDB\Anglo Platinum\Smelters\Waterval Smelter\Hot Metals\Slag Cleaning Furnace 1\Feed\Profile|ACE.Profile.Wall.Port12 | R1: \\wsmlmes\WSMLPI_MDB\WSMLPI ModuleDB\Anglo Platinum\Smelters\Waterval Smelter\Hot Metals\Slag Cleaning Furnace 1\Feed\Profile|ACE.Profile.Wall.Port14 | T1: \\wsmlmes\WSMLPI_MDB\WSMLPI ModuleDB\Anglo Platinum\Smelters\Waterval Smelter\Hot Metals\Slag Cleaning Furnace 1\Feed\Profile|ACE.Profile.Wall.Port5 | V1: \\wsmlmes\WSMLPI_MDB\WSMLPI ModuleDB\Anglo Platinum\Smelters\Waterval Smelter\Hot Metals\Slag Cleaning Furnace 1\Feed\Profile|ACE.Profile.Wall.Port7 | X1: \\wsmlmes\WSMLPI_MDB\WSMLPI ModuleDB\Anglo Platinum\Smelters\Waterval Smelter\Hot Metals\Slag Cleaning Furnace 1\Feed\Profile|ACE.Profile.Wall.Port8 | Z1: \\wsmlmes\WSMLPI_MDB\WSMLPI ModuleDB\Anglo Platinum\Smelters\Waterval Smelter\Hot Metals\Slag Cleaning Furnace 1\Feed\Profile|WACS.Centre.Port11.tot | AB1: \\wsmlmes\WSMLPI_MDB\WSMLPI ModuleDB\Anglo Platinum\Smelters\Waterval Smelter\Hot Metals\Slag Cleaning Furnace 1\Feed\Profile|WACS.Delta.Port13.tot | AD1: \\wsmlmes\WSMLPI_MDB\WSMLPI ModuleDB\Anglo Platinum\Smelters\Waterval Smelter\Hot Metals\Slag Cleaning Furnace 1\Feed\Profile|WACS.Delta.Port6.tot | AF1: \\wsmlmes\WSMLPI_MDB\WSMLPI ModuleDB\Anglo Platinum\Smelters\Waterval Smelter\Hot Metals\Slag Cleaning Furnace 1\Feed\Profile|WACS.Delta.Port9.tot | AH1: \\wsmlmes\WSMLPI_MDB\WSMLPI ModuleDB\Anglo Platinum\Smelters\Waterval Smelter\Hot Metals\Slag Cleaning Furnace 1\Feed\Profile|WACS.Wall.Port10.tot | AJ1: \\wsmlmes\WSMLPI_MDB\WSMLPI ModuleDB\Anglo Platinum\Smelters\Waterval Smelter\Hot Metals\Slag Cleaning Furnace 1\Feed\Profile|WACS.Wall.Port12.tot | AL1: \\wsmlmes\WSMLPI_MDB\WSMLPI ModuleDB\Anglo Platinum\Smelters\Waterval Smelter\Hot Metals\Slag Cleaning Furnace 1\Feed\Profile|WACS.Wall.Port14.tot | AN1: \\wsmlmes\WSMLPI_MDB\WSMLPI ModuleDB\Anglo Platinum\Smelters\Waterval Smelter\Hot Metals\Slag Cleaning Furnace 1\Feed\Profile|WACS.Wall.Port5.tot | AP1: \\wsmlmes\WSMLPI_MDB\WSMLPI ModuleDB\Anglo Platinum\Smelters\Waterval Smelter\Hot Metals\Slag Cleaning Furnace 1\Feed\Profile|WACS.Wall.Port7.tot | AR1: \\wsmlmes\WSMLPI_MDB\WSMLPI ModuleDB\Anglo Platinum\Smelters\Waterval Smelter\Hot Metals\Slag Cleaning Furnace 1\Feed\Profile|WACS.Wall.Port8.tot
A2: {=_xll.PICompDat(Sheet3!$B$1,"2021-07-25","2021-07-30",9,"","inside")} -> 44402.208 | B2: 32.382572 | C2: {=_xll.PICompDat(Sheet3!$D$1,"2021-07-25","2021-07-30",9,"","inside")} -> 44402.208 | D2: 34.342987 | E2: {=_xll.PICompDat(Sheet3!$F$1,"2021-07-25","2021-07-30",9,"","inside")} -> 44402.208 | F2: 33.274441 | G2: {=_xll.PICompDat(Sheet3!$H$1,"2021-07-25","2021-07-30",9,"","inside")} -> 44402.208 | H2: 40.616993 | I2: {=_xll.PICompDat(Sheet3!$J$1,"2021-07-25","2021-07-30",9,"","inside")} -> 44402.208 | J2: 40.616993 | K2: {=_xll.PICompDat(Sheet3!$L$1,"2021-07-25","2021-07-30",9,"","inside")} -> 44402.208 | L2: 26.55961 | M2: {=_xll.PICompDat(Sheet3!$N$1,"2021-07-25","2021-07-30",9,"","inside")} -> 44402.208 | N2: 8.0541296 | O2: {=_xll.PICompDat(Sheet3!$P$1,"2021-07-25","2021-07-30",9,"","inside")} -> 44402.208 | P2: 18.902115 | Q2: {=_xll.PICompDat(Sheet3!$R$1,"2021-07-25","2021-07-30",9,"","inside")} -> 44402.208 | R2: 8.5561476 | S2: {=_xll.PICompDat(Sheet3!$T$1,"2021-07-25","2021-07-30",9,"","inside")} -> 44402.208 | T2: 26.55961 | U2: {=_xll.PICompDat(Sheet3!$V$1,"2021-07-25","2021-07-30",9,"","inside")} -> 44402.208 | V2: 19.480543 | W2: {=_xll.PICompDat(Sheet3!$X$1,"2021-07-25","2021-07-30",9,"","inside")} -> 44402.208 | X2: 21.925121 | Y2: {=_xll.PICompDat(Sheet3!$Z$1,"2021-07-25","2021-07-30",9,"","inside")} -> 44402.018 | Z2: 107.71968 | AA2: {=_xll.PICompDat(Sheet3!$AB$1,"2021-07-25","2021-07-30",9,"","inside")} -> 44402.027 | AB2: 29.410017 | AC2: {=_xll.PICompDat(Sheet3!$AD$1,"2021-07-25","2021-07-30",9,"","inside")} -> 44402.027 | AD2: 29.649979 | AE2: {=_xll.PICompDat(Sheet3!$AF$1,"2021-07-25","2021-07-30",9,"","inside")} -> 44402.027 | AF2: 30.029984 | AG2: {=_xll.PICompDat(Sheet3!$AH$1,"2021-07-25","2021-07-30",9,"","inside")} -> 44402.039 | AH2: 5.1700211 | AI2: {=_xll.PICompDat(Sheet3!$AJ$1,"2021-07-25","2021-07-30",9,"","inside")} -> 44402.023 | AJ2: 14.590012 | AK2: {=_xll.PICompDat(Sheet3!$AL$1,"2021-07-25","2021-07-30",9,"","inside")} -> 44402.024 | AL2: 5.7199936 | AM2: {=_xll.PICompDat(Sheet3!$AN$1,"2021-07-25","2021-07-30",9,"","inside")} -> 44402.024 | AN2: 16.530022 | AO2: {=_xll.PICompDat(Sheet3!$AP$1,"2021-07-25","2021-07-30",9,"","inside")} -> 44402.025 | AP2: 13.620018 | AQ2: {=_xll.PICompDat(Sheet3!$AR$1,"2021-07-25","2021-07-30",9,"","inside")} -> 44402.178 | AR2: 19.060013
A3: 44402.208 | B3: 27.876688 | C3: 44402.208 | D3: 37.228489 | E3: 44402.208 | F3: 34.894821 | G3: 44402.208 | H3: 39.717865 | I3: 44402.208 | J3: 39.717865 | K3: 44402.208 | L3: 24.978222 | M3: 44402.208 | N3: 13.205716 | O3: 44402.208 | P3: 10.894432 | Q3: 44402.208 | R3: 15.023472 | S3: 44402.208 | T3: 24.978222 | U3: 44402.208 | V3: 23.02879 | W3: 44402.208 | X3: 15.55314 | Y3: 44402.018 | Z3: 108.22977 | AA3: 44402.027 | AB3: 29.94002 | AC3: 44402.029 | AD3: 30.159981 | AE3: 44402.029 | AF3: 30.539978 | AG3: 44402.062 | AH3: 5.7000122 | AI3: 44402.06 | AJ3: 15.100014 | AK3: 44402.061 | AL3: 6.2200012 | AM3: 44402.038 | AN3: 17.050018 | AO3: 44402.039 | AP3: 14.130013 | AQ3: 44402.194 | AR3: 19.580009
A4: 44403.208 | B4: 27.876688 | C4: 44403.208 | D4: 37.228489 | E4: 44403.208 | F4: 34.894821 | G4: 44403.208 | H4: 39.717865 | I4: 44403.208 | J4: 39.717865 | K4: 44403.208 | L4: 24.978222 | M4: 44403.208 | N4: 13.205716 | O4: 44403.208 | P4: 10.894432 | Q4: 44403.208 | R4: 15.023472 | S4: 44403.208 | T4: 24.978222 | U4: 44403.208 | V4: 23.02879 | W4: 44403.208 | X4: 15.55314 | Y4: 44402.019 | Z4: 108.73988 | AA4: 44402.027 | AB4: 29.320021 | AC4: 44402.041 | AD4: 30.679985 | AE4: 44402.042 | AF4: 31.039986 | AG4: 44402.102 | AH4: 6.2100067 | AI4: 44402.074 | AJ4: 15.710022 | AK4: 44402.1 | AL4: 6.7600021 | AM4: 44402.061 | AN4: 17.56002 | AO4: 44402.04 | AP4: 14.63002 | AQ4: 44402.203 | AR4: 20.090004
A5: 44403.208 | B5: 21.713308 | C5: 44403.208 | D5: 38.833168 | E5: 44403.208 | F5: 39.453522 | G5: 44403.208 | H5: 40.26828 | I5: 44403.208 | J5: 40.26828 | K5: 44403.208 | L5: 21.566305 | M5: 44403.208 | N5: 7.3113437 | O5: 44403.208 | P5: 8.6662149 | Q5: 44403.208 | R5: 11.00207 | S5: 44403.208 | T5: 21.566305 | U5: 44403.208 | V5: 13.66504 | W5: 44403.208 | X5: 31.417896 | Y5: 44402.019 | Z5: 109.24997 | AA5: 44402.041 | AB5: 29.830023 | AC5: 44402.043 | AD5: 31.189987 | AE5: 44402.064 | AF5: 31.549988 | AG5: 44402.124 | AH5: 6.8200073 | AI5: 44402.136 | AJ5: 16.230019 | AK5: 44402.137 | AL5: 7.2800064 | AM5: 44402.075 | AN5: 18.080017 | AO5: 44402.063 | AP5: 15.140015 | AQ5: 44402.214 | AR5: 0
A6: 44404.208 | B6: 21.713308 | C6: 44404.208 | D6: 38.833168 | E6: 44404.208 | F6: 39.453522 | G6: 44404.208 | H6: 40.26828 | I6: 44404.208 | J6: 40.26828 | K6: 44404.208 | L6: 21.566305 | M6: 44404.208 | N6: 7.3113437 | O6: 44404.208 | P6: 8.6662149 | Q6: 44404.208 | R6: 11.00207 | S6: 44404.208 | T6: 21.566305 | U6: 44404.208 | V6: 13.66504 | W6: 44404.208 | X6: 31.417896 | Y6: 44402.019 | Z6: 109.75007 | AA6: 44402.041 | AB6: 30.340025 | AC6: 44402.065 | AD6: 31.709991 | AE6: 44402.066 | AF6: 32.05999 | AG6: 44402.148 | AH6: 7.3800049 | AI6: 44402.145 | AJ6: 16.760025 | AK6: 44402.156 | AL6: 7.840004 | AM6: 44402.123 | AN6: 18.590019 | AO6: 44402.076 | AP6: 15.670013 | AQ6: 44402.229 | AR6: 0.51998901
A7: 44404.208 | B7: 33.96027 | C7: 44404.208 | D7: 31.00264 | E7: 44404.208 | F7: 35.03709 | G7: 44404.208 | H7: 36.799675 | I7: 44404.208 | J7: 36.799675 | K7: 44404.208 | L7: 28.855783 | M7: 44404.208 | N7: 13.216795 | O7: 44404.208 | P7: 20.606102 | Q7: 44404.208 | R7: 15.804191 | S7: 44404.208 | T7: 28.855783 | U7: 44404.208 | V7: 29.393936 | W7: 44404.208 | X7: 20.978977 | Y7: 44402.022 | Z7: 110.27017 | AA7: 44402.041 | AB7: 31.040022 | AC7: 44402.077 | AD7: 32.220001 | AE7: 44402.079 | AF7: 32.569984 | AG7: 44402.214 | AH7: 0 | AI7: 44402.156 | AJ7: 17.320023 | AK7: 44402.214 | AL7: 0 | AM7: 44402.137 | AN7: 19.100006 | AO7: 44402.102 | AP7: 16.230026 | AQ7: 44402.242 | AR7: 1.0299911
A8: 44405.208 | B8: 33.96027 | C8: 44405.208 | D8: 31.00264 | E8: 44405.208 | F8: 35.03709 | G8: 44405.208 | H8: 36.799675 | I8: 44405.208 | J8: 36.799675 | K8: 44405.208 | L8: 28.855783 | M8: 44405.208 | N8: 13.216795 | O8: 44405.208 | P8: 20.606102 | Q8: 44405.208 | R8: 15.804191 | S8: 44405.208 | T8: 28.855783 | U8: 44405.208 | V8: 29.393936 | W8: 44405.208 | X8: 20.978977 | Y8: 44402.022 | Z8: 110.78027 | AA8: 44402.077 | AB8: 31.580027 | AC8: 44402.079 | AD8: 32.730003 | AE8: 44402.104 | AF8: 33.069992 | AG8: 44402.278 | AH8: 0.51000214 | AI8: 44402.214 | AJ8: 0 | AK8: 44402.264 | AL8: 0.59999847 | AM8: 44402.146 | AN8: 19.600014 | AO8: 44402.124 | AP8: 16.760025 | AQ8: 44402.263 | AR8: 1.5699844
A9: 44405.208 | B9: 100 | C9: 44405.208 | D9: 0 | E9: 44405.208 | F9: 0 | G9: 44405.208 | H9: 38.728836 | I9: 44405.208 | J9: 38.728836 | K9: 44405.208 | L9: 42.098362 | M9: 44405.208 | N9: 24.802872 | O9: 44405.208 | P9: 27.16803 | Q9: 44405.208 | R9: 23.529413 | S9: 44405.208 | T9: 42.098362 | U9: 44405.208 | V9: 24.499685 | W9: 44405.208 | X9: 0 | Y9: 44402.022 | Z9: 111.29037 | AA9: 44402.077 | AB9: 32.120022 | AC9: 44402.103 | AD9: 33.230011 | AE9: 44402.106 | AF9: 33.579987 | AG9: 44402.28 | AH9: 1.0399933 | AI9: 44402.402 | AJ9: 0.54000854 | AK9: 44402.266 | AL9: 1.1100006 | AM9: 44402.156 | AN9: 20.130005 | AO9: 44402.147 | AP9: 17.280037 | AQ9: 44402.345 | AR9: 2.0799789
A10: 44406.208 | B10: 100 | C10: 44406.208 | D10: 0 | E10: 44406.208 | F10: 0 | G10: 44406.208 | H10: 38.728836 | I10: 44406.208 | J10: 38.728836 | K10: 44406.208 | L10: 42.098362 | M10: 44406.208 | N10: 24.802872 | O10: 44406.208 | P10: 27.16803 | Q10: 44406.208 | R10: 23.529413 | S10: 44406.208 | T10: 42.098362 | U10: 44406.208 | V10: 24.499685 | W10: 44406.208 | X10: 0 | Y10: 44402.022 | Z10: 111.81049 | AA10: 44402.103 | AB10: 32.670021 | AC10: 44402.105 | AD10: 33.750008 | AE10: 44402.127 | AF10: 34.079994 | AG10: 44402.3 | AH10: 1.640007 | AI10: 44402.43 | AJ10: 1.0800018 | AK10: 44402.346 | AL10: 1.6399918 | AM10: 44402.179 | AN10: 20.640007 | AO10: 44402.157 | AP10: 17.850037 | AQ10: 44402.36 | AR10: 2.6099701
A11: 44406.208 | B11: Bad Data | C11: 44406.208 | D11: Bad Data | E11: 44406.208 | F11: Bad Data | G11: 44406.208 | H11: Bad Data | I11: 44406.208 | J11: Bad Data | K11: 44406.208 | L11: Bad Data | M11: 44406.208 | N11: Bad Data | O11: 44406.208 | P11: Bad Data | Q11: 44406.208 | R11: Bad Data | S11: 44406.208 | T11: Bad Data | U11: 44406.208 | V11: Bad Data | W11: 44406.208 | X11: Bad Data | Y11: 44402.023 | Z11: 112.33058 | AA11: 44402.103 | AB11: 33.240021 | AC11: 44402.126 | AD11: 34.270004 | AE11: 44402.149 | AF11: 34.599998 | AG11: 44402.302 | AH11: 2.1500092 | AI11: 44402.473 | AJ11: 1.590004 | AK11: 44402.347 | AL11: 2.1599884 | AM11: 44402.195 | AN11: 21.150002 | AO11: 44402.214 | AP11: 0 | AQ11: 44402.388 | AR11: 3.1099777
Y12: 44402.023 | Z12: 112.84068 | AA12: 44402.162 | AB12: 33.810024 | AC12: 44402.128 | AD12: 34.780006 | AE12: 44402.151 | AF12: 35.119995 | AG12: 44402.362 | AH12: 2.6800079 | AI12: 44402.517 | AJ12: 2.1000061 | AK12: 44402.391 | AL12: 2.659996 | AM12: 44402.214 | AN12: 0 | AO12: 44402.394 | AP12: 0.51000214 | AQ12: 44402.401 | AR12: 3.6399765
Y13: 44402.023 | Z13: 113.34079 | AA13: 44402.163 | AB13: 34.360023 | AC13: 44402.15 | AD13: 35.290009 | AE13: 44402.16 | AF13: 35.639999 | AG13: 44402.364 | AH13: 3.1999969 | AI13: 44402.551 | AJ13: 2.6100082 | AK13: 44402.392 | AL13: 3.1699905 | AM13: 44402.243 | AN13: 0.51000214 | AO13: 44402.406 | AP13: 1.0199966 | AQ13: 44402.429 | AR13: 4.1599731
Y14: 44402.023 | Z14: 113.85089 | AA14: 44402.181 | AB14: 34.870022 | AC14: 44402.151 | AD14: 35.810005 | AE14: 44402.181 | AF14: 36.149986 | AG14: 44402.365 | AH14: 3.7000046 | AI14: 44402.569 | AJ14: 3.1700058 | AK14: 44402.403 | AL14: 3.679985 | AM14: 44402.263 | AN14: 1.0299988 | AO14: 44402.432 | AP14: 1.5299988 | AQ14: 44402.443 | AR14: 4.6599808
Y15: 44402.024 | Z15: 114.35099 | AA15: 44402.181 | AB15: 35.390022 | AC15: 44402.16 | AD15: 36.320007 | AE15: 44402.183 | AF15: 36.659988 | AG15: 44402.432 | AH15: 4.2200089 | AI15: 44402.595 | AJ15: 3.7500076 | AK15: 44402.43 | AL15: 4.1999817 | AM15: 44402.277 | AN15: 1.5300064 | AO15: 44402.445 | AP15: 2.0300064 | AQ15: 44402.472 | AR15: 5.1799774
Y16: 44402.024 | Z16: 114.85109 | AA16: 44402.181 | AB16: 35.910023 | AC16: 44402.162 | AD16: 36.840012 | AE16: 44402.197 | AF16: 37.169983 | AG16: 44402.488 | AH16: 4.7300262 | AI16: 44402.641 | AJ16: 4.3100128 | AK16: 44402.444 | AL16: 4.6999893 | AM16: 44402.299 | AN16: 2.0400085 | AO16: 44402.474 | AP16: 2.5400009 | AQ16: 44402.486 | AR16: 5.6899719
Y17: 44402.024 | Z17: 115.3612 | AA17: 44402.182 | AB17: 36.430023 | AC17: 44402.183 | AD17: 37.350006 | AE17: 44402.199 | AF17: 37.679977 | AG17: 44402.597 | AH17: 5.3000259 | AI17: 44402.676 | AJ17: 4.8200073 | AK17: 44402.487 | AL17: 5.2099915 | AM17: 44402.313 | AN17: 2.5400162 | AO17: 44402.476 | AP17: 3.0500031 | AQ17: 44402.517 | AR17: 6.2099762
Y18: 44402.024 | Z18: 115.8713 | AA18: 44402.182 | AB18: 37.240025 | AC18: 44402.198 | AD18: 37.860001 | AE18: 44402.214 | AF18: 0 | AG18: 44402.611 | AH18: 5.8300247 | AI18: 44402.691 | AJ18: 5.4000015 | AK18: 44402.532 | AL18: 5.7299957 | AM18: 44402.346 | AN18: 3.0500107 | AO18: 44402.519 | AP18: 3.5600128 | AQ18: 44402.531 | AR18: 6.7299728
Y19: 44402.025 | Z19: 116.37139 | AA19: 44402.182 | AB19: 36.670025 | AC19: 44402.199 | AD19: 38.370003 | AE19: 44402.233 | AF19: 0.51999664 | AG19: 44402.643 | AH19: 6.3400192 | AI19: 44402.744 | AJ19: 5.9199905 | AK19: 44402.571 | AL19: 6.2499924 | AM19: 44402.361 | AN19: 3.5700073 | AO19: 44402.533 | AP19: 4.070015 | AQ19: 44402.552 | AR19: 7.2399673
Y20: 44402.029 | Z20: 116.87153 | AA20: 44402.214 | AB20: 0 | AC20: 44402.208 | AD20: 38.889999 | AE20: 44402.235 | AF20: 1.0599976 | AG20: 44402.656 | AH20: 6.8500137 | AI20: 44402.935 | AJ20: 6.4199982 | AK20: 44402.61 | AL20: 6.7600021 | AM20: 44402.39 | AN20: 4.0900192 | AO20: 44402.534 | AP20: 4.5800171 | AQ20: 44402.731 | AR20: 7.7899628
Y21: 44402.029 | Z21: 117.38163 | AA21: 44402.231 | AB21: 0.50999832 | AC21: 44402.214 | AD21: 0 | AE21: 44402.247 | AF21: 1.5600052 | AG21: 44402.783 | AH21: 7.3700027 | AI21: 44402.949 | AJ21: 6.9300079 | AK21: 44402.654 | AL21: 7.3100052 | AM21: 44402.403 | AN21: 4.6300125 | AO21: 44402.554 | AP21: 5.1200104 | AQ21: 44402.743 | AR21: 8.2899704
Y22: 44402.061 | Z22: 117.89169 | AA22: 44402.231 | AB22: 1.0299988 | AC22: 44402.233 | AD22: 0.50000763 | AE22: 44402.249 | AF22: 2.0699997 | AG22: 44402.813 | AH22: 7.8799973 | AI22: 44403.022 | AJ22: 7.4500046 | AK22: 44402.77 | AL22: 7.8199997 | AM22: 44402.431 | AN22: 5.140007 | AO22: 44402.573 | AP22: 5.620018 | AQ22: 44402.935 | AR22: 8.789978
Y23: 44402.062 | Z23: 118.42177 | AA23: 44402.232 | AB23: 1.5499992 | AC23: 44402.245 | AD23: 1.0200043 | AE23: 44402.27 | AF23: 2.5800018 | AG23: 44402.846 | AH23: 8.3899918 | AI23: 44403.032 | AJ23: 8.0000076 | AK23: 44402.783 | AL23: 8.3600006 | AM23: 44402.444 | AN23: 5.6400146 | AO23: 44402.598 | AP23: 6.1300201 | AQ23: 44402.949 | AR23: 9.2899857
... Y67: 44402.23 | Z67: 0.52000046 | AA67: 44402.861 | AB67: 18.480005 | AC67: 44402.748 | AD67: 23.69001 | AE67: 44402.815 | AF67: 25.350044 | AG67: 44406.214 | AH67: 0 | AI67: 44405.315 | AJ67: 1.5600033 | AK67: 44404.974 | AL67: 6.7799988 | AM67: 44403.562 | AN67: 7.5300331 | AO67: 44404.185 | AP67: 5.8500099 | AQ67: 44403.575 | AR67: 8.140007
