Workbook

Sheet Sheet1
B1: \\wsmlmes\WSMLPI_MDB\WSMLPI ModuleDB\Anglo Platinum\Smelters\Waterval Smelter\Hot Metals\Furnace 1\Feed\Feed Profile\East|ACE.Profile.1 | D1: \\wsmlmes\WSMLPI_MDB\WSMLPI ModuleDB\Anglo Platinum\Smelters\Waterval Smelter\Hot Metals\Furnace 1\Feed\Feed Profile\East|ACE.Profile.2 | F1: \\wsmlmes\WSMLPI_MDB\WSMLPI ModuleDB\Anglo Platinum\Smelters\Waterval Smelter\Hot Metals\Furnace 1\Feed\Feed Profile\East|ACE.Profile.3 | H1: \\wsmlmes\WSMLPI_MDB\WSMLPI ModuleDB\Anglo Platinum\Smelters\Waterval Smelter\Hot Metals\Furnace 1\Feed\Feed Profile\East|ACE.Profile.4 | J1: \\wsmlmes\WSMLPI_MDB\WSMLPI ModuleDB\Anglo Platinum\Smelters\Waterval Smelter\Hot Metals\Furnace 1\Feed\Feed Profile\East|ACE.Profile.5 | L1: \\wsmlmes\WSMLPI_MDB\WSMLPI ModuleDB\Anglo Platinum\Smelters\Waterval Smelter\Hot Metals\Furnace 1\Feed\Feed Profile\East|ACE.Profile.6 | N1: \\wsmlmes\WSMLPI_MDB\WSMLPI ModuleDB\Anglo Platinum\Smelters\Waterval Smelter\Hot Metals\Furnace 1\Feed\Feed Profile\East|ACE.Profile.7 | P1: \\wsmlmes\WSMLPI_MDB\WSMLPI ModuleDB\Anglo Platinum\Smelters\Waterval Smelter\Hot Metals\Furnace 1\Feed\Feed Profile\East|Autofeed.Port1.tot | R1: \\wsmlmes\WSMLPI_MDB\WSMLPI ModuleDB\Anglo Platinum\Smelters\Waterval Smelter\Hot Metals\Furnace 1\Feed\Feed Profile\East|Autofeed.Port2.tot | T1: \\wsmlmes\WSMLPI_MDB\WSMLPI ModuleDB\Anglo Platinum\Smelters\Waterval Smelter\Hot Metals\Furnace 1\Feed\Feed Profile\East|Autofeed.Port3.tot | V1: \\wsmlmes\WSMLPI_MDB\WSMLPI ModuleDB\Anglo Platinum\Smelters\Waterval Smelter\Hot Metals\Furnace 1\Feed\Feed Profile\East|Autofeed.Port4.tot | X1: \\wsmlmes\WSMLPI_MDB\WSMLPI ModuleDB\Anglo Platinum\Smelters\Waterval Smelter\Hot Metals\Furnace 1\Feed\Feed Profile\East|Autofeed.Port5.tot | Z1: \\wsmlmes\WSMLPI_MDB\WSMLPI ModuleDB\Anglo Platinum\Smelters\Waterval Smelter\Hot Metals\Furnace 1\Feed\Feed Profile\East|Autofeed.Port6.tot | AB1: \\wsmlmes\WSMLPI_MDB\WSMLPI ModuleDB\Anglo Platinum\Smelters\Waterval Smelter\Hot Metals\Furnace 1\Feed\Feed Profile\East|Autofeed.Port7.tot | AD1: \\wsmlmes\WSMLPI_MDB\WSMLPI ModuleDB\Anglo Platinum\Smelters\Waterval Smelter\Hot Metals\Furnace 1\Feed\Feed Profile\East|Manual.Port1.tot | AF1: \\wsmlmes\WSMLPI_MDB\WSMLPI ModuleDB\Anglo Platinum\Smelters\Waterval Smelter\Hot Metals\Furnace 1\Feed\Feed Profile\East|Manual.Port2.tot | AH1: \\wsmlmes\WSMLPI_MDB\WSMLPI ModuleDB\Anglo Platinum\Smelters\Waterval Smelter\Hot Metals\Furnace 1\Feed\Feed Profile\East|Manual.Port3.tot | AJ1: \\wsmlmes\WSMLPI_MDB\WSMLPI ModuleDB\Anglo Platinum\Smelters\Waterval Smelter\Hot Metals\Furnace 1\Feed\Feed Profile\East|Manual.Port4.tot | AL1: \\wsmlmes\WSMLPI_MDB\WSMLPI ModuleDB\Anglo Platinum\Smelters\Waterval Smelter\Hot Metals\Furnace 1\Feed\Feed Profile\East|Manual.Port5.tot | AN1: \\wsmlmes\WSMLPI_MDB\WSMLPI ModuleDB\Anglo Platinum\Smelters\Waterval Smelter\Hot Metals\Furnace 1\Feed\Feed Profile\East|Manual.Port6.tot | AP1: \\wsmlmes\WSMLPI_MDB\WSMLPI ModuleDB\Anglo Platinum\Smelters\Waterval Smelter\Hot Metals\Furnace 1\Feed\Feed Profile\East|Manual.Port7.tot | AR1: \\wsmlmes\WSMLPI_MDB\WSMLPI ModuleDB\Anglo Platinum\Smelters\Waterval Smelter\Hot Metals\Furnace 1\Feed\Feed Profile\East|TopUp.Port1.tot | AT1: \\wsmlmes\WSMLPI_MDB\WSMLPI ModuleDB\Anglo Platinum\Smelters\Waterval Smelter\Hot Metals\Furnace 1\Feed\Feed Profile\East|TopUp.Port2.tot | AV1: \\wsmlmes\WSMLPI_MDB\WSMLPI ModuleDB\Anglo Platinum\Smelters\Waterval Smelter\Hot Metals\Furnace 1\Feed\Feed Profile\East|TopUp.Port3.tot | AX1: \\wsmlmes\WSMLPI_MDB\WSMLPI ModuleDB\Anglo Platinum\Smelters\Waterval Smelter\Hot Metals\Furnace 1\Feed\Feed Profile\East|TopUp.Port4.tot | AZ1: \\wsmlmes\WSMLPI_MDB\WSMLPI ModuleDB\Anglo Platinum\Smelters\Waterval Smelter\Hot Metals\Furnace 1\Feed\Feed Profile\East|TopUp.Port5.tot | BB1: \\wsmlmes\WSMLPI_MDB\WSMLPI ModuleDB\Anglo Platinum\Smelters\Waterval Smelter\Hot Metals\Furnace 1\Feed\Feed Profile\East|TopUp.Port6.tot | BD1: \\wsmlmes\WSMLPI_MDB\WSMLPI ModuleDB\Anglo Platinum\Smelters\Waterval Smelter\Hot Metals\Furnace 1\Feed\Feed Profile\East|TopUp.Port7.tot
A2: {=_xll.PICompDat(Sheet1!$B$1,"*-10d","*",9,"","inside")} -> 45061.208 | B2: 3.4358022 | C2: {=_xll.PICompDat(Sheet1!$D$1,"*-10d","*",9,"","inside")} -> 45061.208 | D2: 14.541006 | E2: {=_xll.PICompDat(Sheet1!$F$1,"*-10d","*",9,"","inside")} -> 45061.208 | F2: 20.598877 | G2: {=_xll.PICompDat(Sheet1!$H$1,"*-10d","*",9,"","inside")} -> 45061.208 | H2: 18.928843 | I2: {=_xll.PICompDat(Sheet1!$J$1,"*-10d","*",9,"","inside")} -> 45061.208 | J2: 24.492065 | K2: {=_xll.PICompDat(Sheet1!$L$1,"*-10d","*",9,"","inside")} -> 45061.208 | L2: 16.168497 | M2: {=_xll.PICompDat(Sheet1!$N$1,"*-10d","*",9,"","inside")} -> 45061.208 | N2: 1.8349104 | O2: {=_xll.PICompDat(Sheet1!$P$1,"*-10d","*",9,"","inside")} -> 45060.629 | P2: 4.993999 | Q2: {=_xll.PICompDat(Sheet1!$R$1,"*-10d","*",9,"","inside")} -> 45060.623 | R2: 20.569996 | S2: {=_xll.PICompDat(Sheet1!$T$1,"*-10d","*",9,"","inside")} -> 45060.617 | T2: 30.601994 | U2: {=_xll.PICompDat(Sheet1!$V$1,"*-10d","*",9,"","inside")} -> 45060.617 | V2: 29.303999 | W2: {=_xll.PICompDat(Sheet1!$X$1,"*-10d","*",9,"","inside")} -> 45060.618 | X2: 43.911987 | Y2: {=_xll.PICompDat(Sheet1!$Z$1,"*-10d","*",9,"","inside")} -> 45060.618 | Z2: 28.731997 | AA2: {=_xll.PICompDat(Sheet1!$AB$1,"*-10d","*",9,"","inside")} -> 45060.876 | AB2: 5.323997 | AC2: {=_xll.PICompDat(Sheet1!$AD$1,"*-10d","*",9,"","inside")} -> 45060.881 | AD2: 0 | AE2: {=_xll.PICompDat(Sheet1!$AF$1,"*-10d","*",9,"","inside")} -> 45060.86 | AF2: 0 | AG2: {=_xll.PICompDat(Sheet1!$AH$1,"*-10d","*",9,"","inside")} -> 45060.86 | AH2: 0 | AI2: {=_xll.PICompDat(Sheet1!$AJ$1,"*-10d","*",9,"","inside")} -> 45060.853 | AJ2: 0 | AK2: {=_xll.PICompDat(Sheet1!$AL$1,"*-10d","*",9,"","inside")} -> 45060.877 | AL2: 0 | AM2: {=_xll.PICompDat(Sheet1!$AN$1,"*-10d","*",9,"","inside")} -> 45060.867 | AN2: 0 | AO2: {=_xll.PICompDat(Sheet1!$AP$1,"*-10d","*",9,"","inside")} -> 45060.877 | AP2: 0 | AQ2: {=_xll.PICompDat(Sheet1!$AR$1,"*-10d","*",9,"","inside")} -> 45060.877 | AR2: 0 | AS2: {=_xll.PICompDat(Sheet1!$AT$1,"*-10d","*",9,"","inside")} -> 45060.877 | AT2: 0 | AU2: {=_xll.PICompDat(Sheet1!$AV$1,"*-10d","*",9,"","inside")} -> 45060.877 | AV2: 0 | AW2: {=_xll.PICompDat(Sheet1!$AX$1,"*-10d","*",9,"","inside")} -> 45060.877 | AX2: 0 | AY2: {=_xll.PICompDat(Sheet1!$AZ$1,"*-10d","*",9,"","inside")} -> 45060.877 | AZ2: 0 | BA2: {=_xll.PICompDat(Sheet1!$BB$1,"*-10d","*",9,"","inside")} -> 45060.877 | BB2: 0 | BC2: {=_xll.PICompDat(Sheet1!$BD$1,"*-10d","*",9,"","inside")} -> 45060.877 | BD2: 0
A3: 45061.208 | B3: 4.2091274 | C3: 45061.208 | D3: 16.5853 | E3: 45061.208 | F3: 20.244591 | G3: 45061.208 | H3: 21.889366 | I3: 45061.208 | J3: 21.533861 | K3: 45061.208 | L3: 14.030433 | M3: 45061.208 | N3: 1.5073233 | O3: 45060.74 | P3: 6.2479978 | Q3: 45060.624 | R3: 21.229996 | S3: 45060.624 | T3: 30.601994 | U3: 45060.624 | V3: 29.303999 | W3: 45060.625 | X3: 43.911987 | Y3: 45060.625 | Z3: 28.731997 | AA3: 45060.983 | AB3: 5.9399972 | AC3: 45061.214 | AD3: 0 | AE3: 45061.193 | AF3: 0 | AG3: 45060.907 | AH3: 2.9920001 | AI3: 45060.91 | AJ3: 3.9820001 | AK3: 45061.21 | AL3: 0 | AM3: 45061.2 | AN3: 0 | AO3: 45061.21 | AP3: 0 | AQ3: 45061.21 | AR3: 0 | AS3: 45061.21 | AT3: 0 | AU3: 45061.21 | AV3: 0 | AW3: 45061.21 | AX3: 0 | AY3: 45061.21 | AZ3: 0 | BA3: 45061.21 | BB3: 0 | BC3: 45061.21 | BD3: 0
A4: 45062.208 | B4: 4.2091274 | C4: 45062.208 | D4: 16.5853 | E4: 45062.208 | F4: 20.244591 | G4: 45062.208 | H4: 21.889366 | I4: 45062.208 | J4: 21.533861 | K4: 45062.208 | L4: 14.030433 | M4: 45062.208 | N4: 1.5073233 | O4: 45060.782 | P4: 6.8419976 | Q4: 45060.636 | R4: 21.559996 | S4: 45060.624 | T4: 31.063993 | U4: 45060.624 | V4: 29.765999 | W4: 45060.625 | X4: 44.593987 | Y4: 45060.626 | Z4: 29.193996 | AA4: 45061.206 | AB4: 7.4799972 | AC4: 45061.547 | AD4: 0 | AE4: 45061.527 | AF4: 0 | AG4: 45060.922 | AH4: 0 | AI4: 45060.922 | AJ4: 0 | AK4: 45061.544 | AL4: 0 | AM4: 45061.534 | AN4: 0 | AO4: 45061.544 | AP4: 0 | AQ4: 45061.544 | AR4: 0 | AS4: 45061.544 | AT4: 0 | AU4: 45061.544 | AV4: 0 | AW4: 45061.544 | AX4: 0 | AY4: 45061.544 | AZ4: 0 | BA4: 45061.544 | BB4: 0 | BC4: 45061.544 | BD4: 0
A5: 45062.208 | B5: 3.5936167 | C5: 45062.208 | D5: 14.748515 | E5: 45062.208 | F5: 17.714237 | G5: 45062.208 | H5: 21.37466 | I5: 45062.208 | J5: 24.654325 | K5: 45062.208 | L5: 16.164593 | M5: 45062.208 | N5: 1.7500509 | O5: 45060.857 | P5: 7.6779981 | Q5: 45060.643 | R5: 21.559996 | S5: 45060.637 | T5: 32.031994 | U5: 45060.637 | V5: 30.667999 | W5: 45060.638 | X5: 45.957985 | Y5: 45060.638 | Z5: 30.095997 | AA5: 45061.213 | AB5: 7.5899973 | AC5: 45061.881 | AD5: 0 | AE5: 45061.86 | AF5: 0 | AG5: 45061.256 | AH5: 0 | AI5: 45061.256 | AJ5: 0 | AK5: 45061.877 | AL5: 0 | AM5: 45061.867 | AN5: 0 | AO5: 45061.877 | AP5: 0 | AQ5: 45061.877 | AR5: 0 | AS5: 45061.877 | AT5: 0 | AU5: 45061.877 | AV5: 0 | AW5: 45061.877 | AX5: 0 | AY5: 45061.877 | AZ5: 0 | BA5: 45061.877 | BB5: 0 | BC5: 45061.877 | BD5: 0
A6: 45063.208 | B6: 3.5936167 | C6: 45063.208 | D6: 14.748515 | E6: 45063.208 | F6: 17.714237 | G6: 45063.208 | H6: 21.37466 | I6: 45063.208 | J6: 24.654325 | K6: 45063.208 | L6: 16.164593 | M6: 45063.208 | N6: 1.7500509 | O6: 45060.88 | P6: 8.0959978 | Q6: 45060.644 | R6: 22.219995 | S6: 45060.644 | T6: 32.031994 | U6: 45060.644 | V6: 30.667999 | W6: 45060.645 | X6: 45.957985 | Y6: 45060.645 | Z6: 30.095997 | AA6: 45061.214 | AB6: 0 | AC6: 45062.214 | AD6: 0 | AE6: 45062.193 | AF6: 0 | AG6: 45061.589 | AH6: 0 | AI6: 45061.589 | AJ6: 0 | AK6: 45062.21 | AL6: 0 | AM6: 45062.2 | AN6: 0 | AO6: 45062.21 | AP6: 0 | AQ6: 45062.21 | AR6: 0 | AS6: 45062.21 | AT6: 0 | AU6: 45062.21 | AV6: 0 | AW6: 45062.21 | AX6: 0 | AY6: 45062.21 | AZ6: 0 | BA6: 45062.21 | BB6: 0 | BC6: 45062.21 | BD6: 0
A7: 45063.208 | B7: Bad Data | C7: 45063.208 | D7: Bad Data | E7: 45063.208 | F7: Bad Data | G7: 45063.208 | H7: Bad Data | I7: 45063.208 | J7: Bad Data | K7: 45063.208 | L7: Bad Data | M7: 45063.208 | N7: Bad Data | O7: 45060.902 | P7: 8.5359983 | Q7: 45060.651 | R7: 22.219995 | S7: 45060.644 | T7: 32.493996 | U7: 45060.645 | V7: 31.129999 | W7: 45060.645 | X7: 46.639984 | Y7: 45060.646 | Z7: 30.557997 | AA7: 45061.464 | AB7: 1.5180001 | AC7: 45062.547 | AD7: 0 | AE7: 45062.52 | AF7: 0 | AG7: 45061.922 | AH7: 0 | AI7: 45061.922 | AJ7: 0 | AK7: 45062.544 | AL7: 0 | AM7: 45062.263 | AN7: 2.9920001 | AO7: 45062.544 | AP7: 0 | AQ7: 45062.544 | AR7: 0 | AS7: 45062.544 | AT7: 0 | AU7: 45062.544 | AV7: 0 | AW7: 45062.544 | AX7: 0 | AY7: 45062.544 | AZ7: 0 | BA7: 45062.544 | BB7: 0 | BC7: 45062.544 | BD7: 0
A8: 45064.208 | B8: Bad Data | C8: 45064.208 | D8: Bad Data | E8: 45064.208 | F8: Bad Data | G8: 45064.208 | H8: Bad Data | I8: 45064.208 | J8: Bad Data | K8: 45064.208 | L8: Bad Data | M8: 45064.208 | N8: Bad Data | O8: 45060.931 | P8: 8.8439989 | Q8: 45060.664 | R8: 23.187996 | S8: 45060.651 | T8: 32.977997 | U8: 45060.651 | V8: 31.57 | W8: 45060.652 | X8: 47.299984 | Y8: 45060.652 | Z8: 30.997997 | AA8: 45061.563 | AB8: 2.0680001 | AC8: 45062.881 | AD8: 0 | AE8: 45062.853 | AF8: 0 | AG8: 45062.255 | AH8: 2.9920001 | AI8: 45062.256 | AJ8: 0 | AK8: 45062.877 | AL8: 0 | AM8: 45062.298 | AN8: 0 | AO8: 45062.877 | AP8: 0 | AQ8: 45062.877 | AR8: 0 | AS8: 45062.877 | AT8: 0 | AU8: 45062.766 | AV8: 0 | AW8: 45062.773 | AX8: 0 | AY8: 45062.773 | AZ8: 0 | BA8: 45062.877 | BB8: 0 | BC8: 45062.877 | BD8: 0
A9: 45064.208 | B9: 3.09517 | C9: 45064.208 | D9: 17.298235 | E9: 45064.208 | F9: 1.7356089 | G9: 45064.208 | H9: 26.554821 | I9: 45064.208 | J9: 28.89789 | K9: 45064.208 | L9: 20.65374 | M9: 45064.208 | N9: 1.7645364 | O9: 45060.955 | P9: 9.3059998 | Q9: 45060.671 | R9: 23.187996 | S9: 45060.658 | T9: 32.977997 | U9: 45060.658 | V9: 31.57 | W9: 45060.659 | X9: 47.299984 | Y9: 45060.659 | Z9: 30.997997 | AA9: 45061.761 | AB9: 3.2779989 | AC9: 45063.207 | AD9: 0 | AE9: 45063.179 | AF9: 0 | AG9: 45062.256 | AH9: 0 | AI9: 45062.258 | AJ9: 2.9920001 | AK9: 45063.21 | AL9: 0 | AM9: 45062.631 | AN9: 0 | AO9: 45063.21 | AP9: 0 | AQ9: 45063.21 | AR9: 0 | AS9: 45063.21 | AT9: 0 | AU9: 45062.773 | AV9: 1.012 | AW9: 45062.774 | AX9: 1.012 | AY9: 45062.775 | AZ9: 1.012 | BA9: 45063.21 | BB9: 0 | BC9: 45063.21 | BD9: 0
A10: 45065.208 | B10: 3.09517 | C10: 45065.208 | D10: 17.298235 | E10: 45065.208 | F10: 1.7356089 | G10: 45065.208 | H10: 26.554821 | I10: 45065.208 | J10: 28.89789 | K10: 45065.208 | L10: 20.65374 | M10: 45065.208 | N10: 1.7645364 | O10: 45060.974 | P10: 9.79 | Q10: 45060.671 | R10: 23.517996 | S10: 45060.658 | T10: 33.439999 | U10: 45060.658 | V10: 32.032001 | W10: 45060.659 | X10: 47.981983 | Y10: 45060.66 | Z10: 31.459997 | AA10: 45061.986 | AB10: 5.0379996 | AC10: 45063.541 | AD10: 0 | AE10: 45063.513 | AF10: 0 | AG10: 45062.589 | AH10: 0 | AI10: 45062.298 | AJ10: 0 | AK10: 45063.544 | AL10: 0 | AM10: 45062.843 | AN10: 2.9920001 | AO10: 45063.544 | AP10: 0 | AQ10: 45063.544 | AR10: 0 | AS10: 45063.544 | AT10: 0 | AU10: 45063.106 | AV10: 1.012 | AW10: 45063.107 | AX10: 1.012 | AY10: 45063.108 | AZ10: 1.012 | BA10: 45063.544 | BB10: 0 | BC10: 45063.544 | BD10: 0
A11: 45065.208 | B11: 3.5747097 | C11: 45065.208 | D11: 17.29945 | E11: 45065.208 | F11: 12.101957 | G11: 45065.208 | H11: 22.910294 | I11: 45065.208 | J11: 26.607471 | K11: 45065.208 | L11: 15.845064 | M11: 45065.208 | N11: 1.6610543 | O11: 45061.017 | P11: 10.669998 | Q11: 45060.685 | R11: 24.155996 | S11: 45060.665 | T11: 33.924 | U11: 45060.665 | V11: 32.472 | W11: 45060.666 | X11: 48.663982 | Y11: 45060.666 | Z11: 31.899998 | AA11: 45062.208 | AB11: 6.9960008 | AC11: 45063.712 | AD11: Bad | AE11: 45063.712 | AF11: Bad | AG11: 45062.923 | AH11: 0 | AI11: 45062.631 | AJ11: 0 | AK11: 45063.712 | AL11: Bad | AM11: 45062.853 | AN11: 5.9840002 | AO11: 45063.712 | AP11: Bad | AQ11: 45063.712 | AR11: Bad | AS11: 45063.712 | AT11: Bad | AU11: 45063.21 | AV11: 1.012 | AW11: 45063.211 | AX11: 1.012 | AY11: 45063.212 | AZ11: 1.012 | BA11: 45063.712 | BB11: Bad | BC11: 45063.712 | BD11: Bad
A12: 45066.208 | B12: 3.5747097 | C12: 45066.208 | D12: 17.29945 | E12: 45066.208 | F12: 12.101957 | G12: 45066.208 | H12: 22.910294 | I12: 45066.208 | J12: 26.607471 | K12: 45066.208 | L12: 15.845064 | M12: 45066.208 | N12: 1.6610543 | O12: 45061.046 | P12: 11.197997 | Q12: 45060.692 | R12: 24.155996 | S12: 45060.671 | T12: 33.924 | U12: 45060.672 | V12: 32.472 | W12: 45060.673 | X12: 48.663982 | Y12: 45060.673 | Z12: 31.899998 | AA12: 45062.214 | AB12: 0 | AC12: 45063.713 | AD12: 0 | AE12: 45063.713 | AF12: 0 | AG12: 45063.04 | AH12: 2.9920001 | AI12: 45062.779 | AJ12: 1.98 | AK12: 45063.713 | AL12: 0 | AM12: 45062.873 | AN12: 8.9759998 | AO12: 45063.713 | AP12: 0 | AQ12: 45063.713 | AR12: 0 | AS12: 45063.713 | AT12: 0 | AU12: 45063.214 | AV12: 0 | AW12: 45063.214 | AX12: 0 | AY12: 45063.214 | AZ12: 0 | BA12: 45063.713 | BB12: 0 | BC12: 45063.713 | BD12: 0
A13: 45066.208 | B13: 3.9453444 | C13: 45066.208 | D13: 15.905598 | E13: 45066.208 | F13: 17.780663 | G13: 45066.208 | H13: 20.199936 | I13: 45066.208 | J13: 26.032181 | K13: 45066.208 | L13: 14.545127 | M13: 45066.208 | N13: 1.5911504 | O13: 45061.133 | P13: 12.781994 | Q13: 45060.692 | R13: 24.485996 | S13: 45060.672 | T13: 34.408001 | U13: 45060.672 | V13: 32.934002 | W13: 45060.673 | X13: 49.323982 | Y13: 45060.673 | Z13: 32.362 | AA13: 45062.275 | AB13: 0.39600003 | AC13: 45064.046 | AD13: 0 | AE13: 45064.046 | AF13: 0 | AG13: 45063.048 | AH13: 0 | AI13: 45062.791 | AJ13: 3.96 | AK13: 45064.046 | AL13: 0 | AM13: 45062.881 | AN13: 0 | AO13: 45064.046 | AP13: 0 | AQ13: 45064.046 | AR13: 0 | AS13: 45064.046 | AT13: 0 | AU13: 45063.548 | AV13: 0 | AW13: 45063.548 | AX13: 0 | AY13: 45063.548 | AZ13: 0 | BA13: 45064.046 | BB13: 0 | BC13: 45064.046 | BD13: 0
A14: 45067.208 | B14: 3.9453444 | C14: 45067.208 | D14: 15.905598 | E14: 45067.208 | F14: 17.780663 | G14: 45067.208 | H14: 20.199936 | I14: 45067.208 | J14: 26.032181 | K14: 45067.208 | L14: 14.545127 | M14: 45067.208 | N14: 1.5911504 | O14: 45061.191 | P14: 13.859992 | Q14: 45060.706 | R14: 24.485996 | S14: 45060.685 | T14: 35.354004 | U14: 45060.679 | V14: 33.374001 | W14: 45060.68 | X14: 50.005981 | Y14: 45060.68 | Z14: 32.801998 | AA14: 45062.317 | AB14: 0.61600006 | AC14: 45064.38 | AD14: 0 | AE14: 45064.38 | AF14: 0 | AG14: 45063.381 | AH14: 0 | AI14: 45062.797 | AJ14: 5.9400001 | AK14: 45064.38 | AL14: 0 | AM14: 45062.894 | AN14: 2.9920001 | AO14: 45064.38 | AP14: 0 | AQ14: 45064.38 | AR14: 0 | AS14: 45064.38 | AT14: 0 | AU14: 45063.712 | AV14: Bad | AW14: 45063.712 | AX14: Bad | AY14: 45063.712 | AZ14: Bad | BA14: 45064.38 | BB14: 0 | BC14: 45064.38 | BD14: 0
A15: 45067.208 | B15: 4.0239472 | C15: 45067.208 | D15: 16.117363 | E15: 45067.208 | F15: 18.021469 | G15: 45067.208 | H15: 20.475748 | I15: 45067.208 | J15: 26.295933 | K15: 45067.208 | L15: 13.587575 | M15: 45067.208 | N15: 1.4779646 | O15: 45061.208 | P15: 14.211991 | Q15: 45060.706 | R15: 25.145996 | S15: 45060.692 | T15: 35.354004 | U15: 45060.686 | V15: 33.374001 | W15: 45060.686 | X15: 50.005981 | Y15: 45060.687 | Z15: 32.801998 | AA15: 45062.593 | AB15: 2.8379998 | AC15: 45064.713 | AD15: 0 | AE15: 45064.713 | AF15: 0 | AG15: 45063.712 | AH15: Bad | AI15: 45062.798 | AJ15: 0 | AK15: 45064.713 | AL15: 0 | AM15: 45062.923 | AN15: 0 | AO15: 45064.713 | AP15: 0 | AQ15: 45064.713 | AR15: 0 | AS15: 45064.713 | AT15: 0 | AU15: 45063.713 | AV15: 0 | AW15: 45063.713 | AX15: 0 | AY15: 45063.713 | AZ15: 0 | BA15: 45064.713 | BB15: 0 | BC15: 45064.713 | BD15: 0
A16: 45068.208 | B16: 4.0239472 | C16: 45068.208 | D16: 16.117363 | E16: 45068.208 | F16: 18.021469 | G16: 45068.208 | H16: 20.475748 | I16: 45068.208 | J16: 26.295933 | K16: 45068.208 | L16: 13.587575 | M16: 45068.208 | N16: 1.4779646 | O16: 45061.214 | P16: 0 | Q16: 45060.72 | R16: 25.783997 | S16: 45060.692 | T16: 35.816006 | U16: 45060.686 | V16: 33.836002 | W16: 45060.686 | X16: 50.687981 | Y16: 45060.687 | Z16: 33.264 | AA16: 45062.756 | AB16: 4.3780003 | AC16: 45065.046 | AD16: 0 | AE16: 45065.046 | AF16: 0 | AG16: 45063.713 | AH16: 0 | AI16: 45062.836 | AJ16: 1.98 | AK16: 45065.046 | AL16: 0 | AM16: 45063.256 | AN16: 0 | AO16: 45065.046 | AP16: 0 | AQ16: 45065.046 | AR16: 0 | AS16: 45065.046 | AT16: 0 | AU16: 45064.046 | AV16: 0 | AW16: 45064.046 | AX16: 0 | AY16: 45064.046 | AZ16: 0 | BA16: 45064.886 | BB16: 0 | BC16: 45065.046 | BD16: 0
A17: 45068.208 | B17: 2.9766212 | C17: 45068.208 | D17: 12.867215 | E17: 45068.208 | F17: 16.188148 | G17: 45068.208 | H17: 21.197315 | I17: 45068.208 | J17: 28.405615 | K17: 45068.208 | L17: 16.532463 | M17: 45068.208 | N17: 1.8326216 | O17: 45061.257 | P17: 1.056 | Q17: 45060.727 | R17: 25.783997 | S17: 45060.699 | T17: 35.816006 | U17: 45060.693 | V17: 33.836002 | W17: 45060.693 | X17: 51.34798 | Y17: 45060.694 | Z17: 33.703999 | AA17: 45062.791 | AB17: 4.6860003 | AC17: 45065.38 | AD17: 0 | AE17: 45065.374 | AF17: 0 | AG17: 45064.046 | AH17: 0 | AI17: 45062.839 | AJ17: 0 | AK17: 45065.38 | AL17: 0 | AM17: 45063.589 | AN17: 0 | AO17: 45065.38 | AP17: 0 | AQ17: 45065.38 | AR17: 0 | AS17: 45065.227 | AT17: 0 | AU17: 45064.38 | AV17: 0 | AW17: 45064.38 | AX17: 0 | AY17: 45064.38 | AZ17: 0 | BA17: 45064.891 | BB17: 0.50599998 | BC17: 45065.38 | BD17: 0
A18: 45069.208 | B18: 2.9766212 | C18: 45069.208 | D18: 12.867215 | E18: 45069.208 | F18: 16.188148 | G18: 45069.208 | H18: 21.197315 | I18: 45069.208 | J18: 28.405615 | K18: 45069.208 | L18: 16.532463 | M18: 45069.208 | N18: 1.8326216 | O18: 45061.293 | P18: 1.584 | Q18: 45060.727 | R18: 26.113997 | S18: 45060.699 | T18: 36.300007 | U18: 45060.693 | V18: 34.276001 | W18: 45060.7 | X18: 51.34798 | Y18: 45060.701 | Z18: 33.703999 | AA18: 45062.884 | AB18: 5.0160007 | AC18: 45065.707 | AD18: 0 | AE18: 45065.707 | AF18: 0 | AG18: 45064.38 | AH18: 0 | AI18: 45062.848 | AJ18: 1.98 | AK18: 45065.713 | AL18: 0 | AM18: 45063.712 | AN18: Bad | AO18: 45065.713 | AP18: 0 | AQ18: 45065.4 | AR18: 0 | AS18: 45065.232 | AT18: 1.012 | AU18: 45064.713 | AV18: 0 | AW18: 45064.713 | AX18: 0 | AY18: 45064.713 | AZ18: 0 | BA18: 45064.894 | BB18: 1.5179999 | BC18: 45065.713 | BD18: 0
A19: 45069.208 | B19: 2.9342833 | C19: 45069.208 | D19: 13.115029 | E19: 45069.208 | F19: 15.530494 | G19: 45069.208 | H19: 20.517696 | I19: 45069.208 | J19: 29.538092 | K19: 45069.208 | L19: 16.50119 | M19: 45069.208 | N19: 1.8632154 | O19: 45061.401 | P19: 4.0040002 | Q19: 45060.74 | R19: 26.113997 | S19: 45060.706 | T19: 36.300007 | U19: 45060.7 | V19: 34.276001 | W19: 45060.7 | X19: 52.02998 | Y19: 45060.701 | Z19: 34.166 | AA19: 45063.124 | AB19: 5.1260009 | AC19: 45066.041 | AD19: 0 | AE19: 45066.041 | AF19: 0 | AG19: 45064.713 | AH19: 0 | AI19: 45062.859 | AJ19: 3.96 | AK19: 45066.046 | AL19: 0 | AM19: 45063.713 | AN19: 0 | AO19: 45066.046 | AP19: 0 | AQ19: 45065.407 | AR19: 1.012 | AS19: 45065.239 | AT19: 1.012 | AU19: 45064.782 | AV19: 0 | AW19: 45064.893 | AX19: 0 | AY19: 45065.046 | AZ19: 0 | BA19: 45064.977 | BB19: 1.5179999 | BC19: 45066.046 | BD19: 0
A20: 45070.208 | B20: 2.9342833 | C20: 45070.208 | D20: 13.115029 | E20: 45070.208 | F20: 15.530494 | G20: 45070.208 | H20: 20.517696 | I20: 45070.208 | J20: 29.538092 | K20: 45070.208 | L20: 16.50119 | M20: 45070.208 | N20: 1.8632154 | O20: 45061.452 | P20: 5.3680005 | Q20: 45060.741 | R20: 26.971996 | S20: 45060.707 | T20: 36.784008 | U20: 45060.7 | V20: 34.738003 | W20: 45060.707 | X20: 52.02998 | Y20: 45060.708 | Z20: 34.166 | AA20: 45063.21 | AB20: 5.7640014 | AC20: 45066.323 | AD20: 1.98 | AE20: 45066.324 | AF20: 1.98 | AG20: 45065.041 | AH20: 0 | AI20: 45062.868 | AJ20: 5.9400001 | AK20: 45066.38 | AL20: 0 | AM20: 45064.046 | AN20: 0 | AO20: 45066.38 | AP20: 0 | AQ20: 45065.74 | AR20: 1.012 | AS20: 45065.242 | AT20: 2.0239999 | AU20: 45064.799 | AV20: 0.242 | AW20: 45064.898 | AX20: 0.50599998 | AY20: 45065.234 | AZ20: 0 | BA20: 45064.981 | BB20: 2.0239999 | BC20: 45066.38 | BD20: 0
O21: 45061.518 | P21: 6.5560007 | Q21: 45060.747 | R21: 27.411997 | S21: 45060.72 | T21: 37.730011 | U21: 45060.707 | V21: 34.738003 | W21: 45060.708 | X21: 52.711979 | Y21: 45060.708 | Z21: 34.605999 | AA21: 45063.214 | AB21: 0 | AC21: 45066.339 | AD21: 0 | AE21: 45066.339 | AF21: 0 | AG21: 45065.374 | AH21: 0 | AI21: 45062.881 | AJ21: 0 | AK21: 45066.713 | AL21: 0 | AM21: 45064.38 | AN21: 0 | AO21: 45066.713 | AP21: 0 | AQ21: 45066.073 | AR21: 1.012 | AS21: 45065.27 | AT21: 2.0239999 | AU21: 45065.133 | AV21: 0.242 | AW21: 45065.21 | AX21: 0.50599998 | AY21: 45065.234 | AZ21: 1.012 | BA21: 45065.211 | BB21: 2.0239999 | BC21: 45066.713 | BD21: 0
O22: 45061.534 | P22: 6.7320008 | Q22: 45060.754 | R22: 27.411997 | S22: 45060.727 | T22: 37.730011 | U22: 45060.707 | V22: 35.178001 | W22: 45060.714 | X22: 53.371979 | Y22: 45060.715 | Z22: 35.045998 | AA22: 45063.548 | AB22: 0 | AC22: 45066.666 | AD22: 0 | AE22: 45066.666 | AF22: 0 | AG22: 45065.707 | AH22: 0 | AI22: 45062.884 | AJ22: 1.98 | AK22: 45067.046 | AL22: 0 | AM22: 45064.713 | AN22: 0 | AO22: 45067.046 | AP22: 0 | AQ22: 45066.212 | AR22: 1.012 | AS22: 45065.272 | AT22: 4.026 | AU22: 45065.209 | AV22: 0.242 | AW22: 45065.214 | AX22: 0 | AY22: 45065.241 | AZ22: 1.012 | BA22: 45065.214 | BB22: 0 | BC22: 45067.046 | BD22: 0
O23: 45061.7 | P23: 10.097999 | Q23: 45060.754 | R23: 27.851997 | S23: 45060.727 | T23: 38.192013 | U23: 45060.721 | V23: 36.080002 | W23: 45060.721 | X23: 53.371979 | Y23: 45060.722 | Z23: 35.045998 | AA23: 45063.712 | AB23: Bad | AC23: 45066.686 | AD23: 1.98 | AE23: 45066.688 | AF23: 1.98 | AG23: 45066.041 | AH23: 0 | AI23: 45062.89 | AJ23: 3.96 | AK23: 45067.38 | AL23: 0 | AM23: 45065.044 | AN23: 0.99000001 | AO23: 45067.38 | AP23: 0 | AQ23: 45066.214 | AR23: 0 | AS23: 45065.286 | AT23: 4.026 | AU23: 45065.235 | AV23: 0 | AW23: 45065.228 | AX23: 0 | AY23: 45065.244 | AZ23: 2.0239999 | BA23: 45065.228 | BB23: 0 | BC23: 45067.38 | BD23: 0
O24: 45061.747 | P24: 10.955997 | Q24: 45060.761 | R24: 28.291998 | S24: 45060.734 | T24: 38.192013 | U24: 45060.727 | V24: 36.080002 | W24: 45060.721 | X24: 54.053978 | Y24: 45060.722 | Z24: 35.507999 | AA24: 45063.713 | AB24: 0 | AC24: 45066.714 | AD24: 0 | AE24: 45066.714 | AF24: 0 | AG24: 45066.325 | AH24: 1.98 | AI24: 45062.902 | AJ24: 5.9400001 | AK24: 45067.713 | AL24: 0 | AM24: 45065.302 | AN24: 2.97 | AO24: 45067.713 | AP24: 0 | AQ24: 45066.548 | AR24: 0 | AS24: 45065.292 | AT24: 5.0380001 | AU24: 45065.568 | AV24: 0 | AW24: 45065.233 | AX24: 1.012 | AY24: 45065.272 | AZ24: 2.0239999 | BA24: 45065.235 | BB24: 1.012 | BC24: 45067.713 | BD24: 0
O25: 45061.843 | P25: 12.803996 | Q25: 45060.768 | R25: 28.291998 | S25: 45060.734 | T25: 38.830013 | U25: 45060.727 | V25: 36.52 | W25: 45060.728 | X25: 54.053978 | Y25: 45060.729 | Z25: 35.947998 | AA25: 45064.046 | AB25: 0 | AC25: 45067.041 | AD25: 0 | AE25: 45067.041 | AF25: 0 | AG25: 45066.339 | AH25: 0 | AI25: 45062.909 | AJ25: 7.9200001 | AK25: 45068.046 | AL25: 0 | AM25: 45065.309 | AN25: 4.9499998 | AO25: 45068.046 | AP25: 0 | AQ25: 45066.881 | AR25: 0 | AS25: 45065.403 | AT25: 5.0380001 | AU25: 45065.902 | AV25: 0 | AW25: 45065.24 | AX25: 1.012 | AY25: 45065.276 | AZ25: 4.026 | BA25: 45065.242 | BB25: 1.012 | BC25: 45068.046 | BD25: 0
O26: 45061.871 | P26: 13.309996 | Q26: 45060.768 | R26: 28.709997 | S26: 45060.741 | T26: 38.830013 | U26: 45060.734 | V26: 36.52 | W26: 45060.728 | X26: 54.735977 | Y26: 45060.736 | Z26: 35.947998 | AA26: 45064.38 | AB26: 0 | AC26: 45067.327 | AD26: 1.98 | AE26: 45067.328 | AF26: 1.98 | AG26: 45066.666 | AH26: 0 | AI26: 45062.923 | AJ26: 0 | AK26: 45068.38 | AL26: 0 | AM26: 45065.312 | AN26: 6.9299998 | AO26: 45068.38 | AP26: 0 | AQ26: 45067.214 | AR26: 0 | AS26: 45065.408 | AT26: 6.0500002 | AU26: 45066.235 | AV26: 0 | AW26: 45065.243 | AX26: 2.0239999 | AY26: 45065.29 | AZ26: 4.026 | BA26: 45065.245 | BB26: 2.0239999 | BC26: 45068.38 | BD26: 0
O27: 45062.037 | P27: 16.675993 | Q27: 45060.775 | R27: 29.149998 | S27: 45060.742 | T27: 39.468014 | U27: 45060.735 | V27: 37.136002 | W27: 45060.735 | X27: 54.735977 | Y27: 45060.736 | Z27: 36.563999 | AA27: 45064.713 | AB27: 0 | AC27: 45067.339 | AD27: 0 | AE27: 45067.339 | AF27: 0 | AG27: 45066.706 | AH27: 1.98 | AI27: 45062.925 | AJ27: 1.98 | AK27: 45068.713 | AL27: 0 | AM27: 45065.327 | AN27: 8.9099998 | AO27: 45068.713 | AP27: 0 | AQ27: 45067.548 | AR27: 0 | AS27: 45065.741 | AT27: 6.0500002 | AU27: 45066.568 | AV27: 0 | AW27: 45065.271 | AX27: 2.0239999 | AY27: 45065.294 | AZ27: 5.0380001 | BA27: 45065.273 | BB27: 2.0239999 | BC27: 45068.713 | BD27: 0
O28: 45062.092 | P28: 17.665993 | Q28: 45060.782 | R28: 29.149998 | S28: 45060.748 | T28: 40.106014 | U28: 45060.742 | V28: 37.136002 | W28: 45060.736 | X28: 55.637978 | Y28: 45060.743 | Z28: 36.563999 | AA28: 45065.045 | AB28: 0.46200001 | AC28: 45067.484 | AD28: 1.98 | AE28: 45067.485 | AF28: 1.98 | AG28: 45066.714 | AH28: 0 | AI28: 45062.932 | AJ28: 3.96 | AK28: 45069.046 | AL28: 0 | AM28: 45065.339 | AN28: 0 | AO28: 45069.046 | AP28: 0 | AQ28: 45067.881 | AR28: 0 | AS28: 45066.074 | AT28: 6.0500002 | AU28: 45066.902 | AV28: 0 | AW28: 45065.274 | AX28: 4.026 | AY28: 45065.627 | AZ28: 5.0380001 | BA28: 45065.278 | BB28: 3.9159999 | BC28: 45069.046 | BD28: 0
O29: 45062.15 | P29: 18.545994 | Q29: 45060.782 | R29: 29.589998 | S29: 45060.755 | T29: 40.106014 | U29: 45060.742 | V29: 37.730003 | W29: 45060.743 | X29: 55.637978 | Y29: 45060.744 | Z29: 37.158001 | AA29: 45065.209 | AB29: 1.3420005 | AC29: 45067.506 | AD29: 0 | AE29: 45067.506 | AF29: 0 | AG29: 45066.755 | AH29: 1.98 | AI29: 45062.935 | AJ29: 5.9400001 | AK29: 45069.38 | AL29: 0 | AM29: 45065.673 | AN29: 0 | AO29: 45069.38 | AP29: 0 | AQ29: 45068.214 | AR29: 0 | AS29: 45066.213 | AT29: 6.0500002 | AU29: 45067.235 | AV29: 0 | AW29: 45065.288 | AX29: 4.026 | AY29: 45065.961 | AZ29: 5.0380001 | BA29: 45065.611 | BB29: 3.9159999 | BC29: 45069.38 | BD29: 0
O30: 45062.212 | P30: 19.535994 | Q30: 45060.802 | R30: 30.91 | S30: 45060.755 | T30: 40.744015 | U30: 45060.749 | V30: 38.324005 | W30: 45060.743 | X30: 56.539978 | Y30: 45060.75 | Z30: 37.752003 | AA30: 45065.214 | AB30: 0 | AC30: 45067.832 | AD30: 0 | AE30: 45067.679 | AF30: 1.98 | AG30: 45066.756 | AH30: 0 | AI30: 45062.937 | AJ30: 7.9200001 | AK30: 45069.713 | AL30: 0 | AM30: 45065.999 | AN30: 0 | AO30: 45069.713 | AP30: 0 | AQ30: 45068.548 | AR30: 0 | AS30: 45066.214 | AT30: 0 | AU30: 45067.249 | AV30: 0 | AW30: 45065.293 | AX30: 5.0380001 | AY30: 45066.211 | AZ30: 5.0380001 | BA30: 45065.945 | BB30: 3.9159999 | BC30: 45069.713 | BD30: 0
O31: 45062.214 | P31: 0 | Q31: 45060.809 | R31: 30.91 | S31: 45060.762 | T31: 41.360016 | U31: 45060.756 | V31: 38.324005 | W31: 45060.75 | X31: 57.419979 | Y31: 45060.757 | Z31: 37.752003 | AA31: 45065.325 | AB31: 0.39600003 | AC31: 45068.166 | AD31: 0 | AE31: 45067.707 | AF31: 3.96 | AG31: 45067.089 | AH31: 0 | AI31: 45062.94 | AJ31: 9.8999996 | AK31: 45070.046 | AL31: 0 | AM31: 45066.328 | AN31: 1.98 | AO31: 45070.046 | AP31: 0 | AQ31: 45068.881 | AR31: 0 | AS31: 45066.548 | AT31: 0 | AU31: 45067.253 | AV31: 1.012 | AW31: 45065.626 | AX31: 5.0380001 | AY31: 45066.214 | AZ31: 0 | BA31: 45066.208 | BB31: 3.9159999 | BC31: 45070.046 | BD31: 0
O32: 45062.256 | P32: 0.72600001 | Q32: 45060.809 | R32: 31.327999 | S32: 45060.769 | T32: 41.360016 | U32: 45060.756 | V32: 38.918007 | W32: 45060.757 | X32: 57.419979 | Y32: 45060.757 | Z32: 38.346004 | AA32: 45065.499 | AB32: 0.88000011 | AC32: 45068.499 | AD32: 0 | AE32: 45067.714 | AF32: 0 | AG32: 45067.329 | AH32: 1.98 | AI32: 45062.944 | AJ32: 11.879999 | AK32: 45070.38 | AL32: 0 | AM32: 45066.339 | AN32: 0 | AO32: 45070.38 | AP32: 0 | AQ32: 45069.214 | AR32: 0 | AS32: 45066.881 | AT32: 0 | AU32: 45067.586 | AV32: 1.012 | AW32: 45065.96 | AX32: 5.0380001 | AY32: 45066.548 | AZ32: 0 | BA32: 45066.214 | BB32: 0 | BC32: 45070.38 | BD32: 0
O33: 45062.315 | P33: 1.4960002 | Q33: 45060.816 | R33: 31.768 | S33: 45060.769 | T33: 41.998016 | U33: 45060.763 | V33: 39.534008 | W33: 45060.757 | X33: 58.32198 | Y33: 45060.764 | Z33: 38.962006 | AA33: 45065.697 | AB33: 1.1000003 | AC33: 45068.832 | AD33: 0 | AE33: 45068.048 | AF33: 0 | AG33: 45067.339 | AH33: 0 | AI33: 45062.951 | AJ33: 13.859999 | AK33: 45070.595 | AL33: 0 | AM33: 45066.666 | AN33: 0 | AO33: 45070.595 | AP33: 0 | AQ33: 45069.548 | AR33: 0 | AS33: 45067.214 | AT33: 0 | AU33: 45067.92 | AV33: 1.012 | AW33: 45066.21 | AX33: 5.0380001 | AY33: 45066.881 | AZ33: 0 | BA33: 45066.548 | BB33: 0 | BC33: 45070.595 | BD33: 0
O34: 45062.366 | P34: 2.5740004 | Q34: 45060.83 | R34: 31.768 | S34: 45060.776 | T34: 42.636017 | U34: 45060.77 | V34: 39.534008 | W34: 45060.763 | X34: 59.22398 | Y34: 45060.771 | Z34: 38.962006 | AA34: 45065.833 | AB34: 1.9360006 | AC34: 45069.166 | AD34: 0 | AE34: 45068.381 | AF34: 0 | AG34: 45067.486 | AH34: 1.98 | AI34: 45062.964 | AJ34: 0 | AK34: 45070.597 | AL34: 0 | AM34: 45066.992 | AN34: 0 | AO34: 45070.597 | AP34: 0 | AQ34: 45069.881 | AR34: 0 | AS34: 45067.249 | AT34: 0 | AU34: 45068.211 | AV34: 1.012 | AW34: 45066.214 | AX34: 0 | AY34: 45067.214 | AZ34: 0 | BA34: 45066.881 | BB34: 0 | BC34: 45070.597 | BD34: Bad
O35: 45062.412 | P35: 3.4980006 | Q35: 45060.836 | R35: 32.208 | S35: 45060.783 | T35: 42.636017 | U35: 45060.77 | V35: 40.12801 | W35: 45060.77 | X35: 59.22398 | Y35: 45060.771 | Z35: 39.556007 | AA35: 45065.906 | AB35: 2.5300009 | AC35: 45069.499 | AD35: 0 | AE35: 45068.714 | AF35: 0 | AG35: 45067.506 | AH35: 0 | AI35: 45062.976 | AJ35: 1.98 | AK35: 45070.611 | AL35: 0 | AM35: 45067.318 | AN35: 0.99000001 | AO35: 45070.611 | AP35: 0 | AQ35: 45070.214 | AR35: 0 | AS35: 45067.252 | AT35: 1.012 | AU35: 45068.214 | AV35: 0 | AW35: 45066.548 | AX35: 0 | AY35: 45067.249 | AZ35: 0 | BA35: 45067.214 | BB35: 0 | BC35: 45070.597 | BD35: 0
O36: 45062.507 | P36: 5.3459992 | Q36: 45060.843 | R36: 32.208 | S36: 45060.783 | T36: 43.274017 | U36: 45060.776 | V36: 40.722012 | W36: 45060.771 | X36: 60.12598 | Y36: 45060.778 | Z36: 40.150009 | AA36: 45066.165 | AB36: 4.6420016 | AC36: 45069.832 | AD36: 0 | AE36: 45069.048 | AF36: 0 | AG36: 45067.699 | AH36: 1.98 | AI36: 45062.98 | AJ36: 3.96 | AM36: 45067.652 | AN36: 0 | AQ36: 45070.548 | AR36: 0 | AS36: 45067.585 | AT36: 1.012 | AU36: 45068.402 | AV36: 0 | AW36: 45066.881 | AX36: 0 | AY36: 45067.255 | AZ36: 1.012 | BA36: 45067.256 | BB36: 0 | BC36: 45070.611 | BD36: 0
O37: 45062.563 | P37: 6.1159992 | Q37: 45060.843 | R37: 32.647999 | S37: 45060.803 | T37: 45.188019 | U37: 45060.783 | V37: 40.722012 | W37: 45060.777 | X37: 61.027981 | Y37: 45060.785 | Z37: 40.150009 | AA37: 45066.212 | AB37: 4.7740021 | AC37: 45070.166 | AD37: 0 | AE37: 45069.381 | AF37: 0 | AG37: 45067.709 | AH37: 3.96 | AI37: 45062.985 | AJ37: 5.9400001 | AM37: 45067.978 | AN37: 0 | AQ37: 45070.589 | AR37: 0 | AS37: 45067.919 | AT37: 1.012 | AU37: 45068.408 | AV37: 0.50599998 | AW37: 45067.214 | AX37: 0 | AY37: 45067.588 | AZ37: 1.012 | BA37: 45067.256 | BB37: 1.012
O38: 45062.598 | P38: 6.5119996 | Q38: 45060.85 | R38: 33.087997 | S38: 45060.81 | T38: 45.188019 | U38: 45060.784 | V38: 41.338013 | W38: 45060.784 | X38: 61.027981 | Y38: 45060.798 | Z38: 41.360012 | AA38: 45066.214 | AB38: 0 | AC38: 45070.499 | AD38: 0 | AE38: 45069.714 | AF38: 0 | AG38: 45067.714 | AH38: 0 | AI38: 45062.991 | AJ38: 7.9200001 | AM38: 45068.311 | AN38: 0 | AQ38: 45070.597 | AR38: Bad | AS38: 45068.21 | AT38: 1.012 | AU38: 45068.47 | AV38: 0.50599998 | AW38: 45067.249 | AX38: 0 | AY38: 45067.922 | AZ38: 1.012 | BA38: 45067.589 | BB38: 1.012
O39: 45062.663 | P39: 7.6559987 | Q39: 45060.857 | R39: 33.087997 | S39: 45060.81 | T39: 45.826019 | U39: 45060.804 | V39: 43.142017 | W39: 45060.804 | X39: 63.733982 | Y39: 45060.805 | Z39: 41.360012 | AA39: 45066.448 | AB39: 1.2980001 | AC39: 45070.589 | AD39: 0 | AE39: 45070.048 | AF39: 0 | AG39: 45068.048 | AH39: 0 | AI39: 45062.996 | AJ39: 9.8999996 | AM39: 45068.645 | AN39: 0 | AQ39: 45070.597 | AR39: 0 | AS39: 45068.214 | AT39: 0 | AU39: 45068.475 | AV39: 1.012 | AW39: 45067.254 | AX39: 1.012 | AY39: 45068.213 | AZ39: 1.012 | BA39: 45067.923 | BB39: 1.012
O40: 45062.67 | P40: 7.6559987 | Q40: 45060.857 | R40: 33.505997 | S40: 45060.817 | T40: 46.44202 | U40: 45060.81 | V40: 43.142017 | W40: 45060.811 | X40: 63.733982 | Y40: 45060.805 | Z40: 41.954014 | AA40: 45066.548 | AB40: 2.0680003 | AC40: 45070.597 | AD40: 0 | AE40: 45070.381 | AF40: 0 | AG40: 45068.381 | AH40: 0 | AI40: 45063.001 | AJ40: 11.879999 | AM40: 45068.978 | AN40: 0 | AQ40: 45070.611 | AR40: 0 | AS40: 45068.402 | AT40: 0 | AU40: 45068.808 | AV40: 1.012 | AW40: 45067.587 | AX40: 1.012 | AY40: 45068.214 | AZ40: 0 | BA40: 45068.207 | BB40: 1.012
...

Sheet Sheet2
B1: ACE.Profile.1 | D1: ACE.Profile.2 | F1: ACE.Profile.3 | H1: ACE.Profile.4 | J1: ACE.Profile.5 | L1: ACE.Profile.6 | N1: ACE.Profile.7 | P1: Autofeed.Port1.tot | R1: Autofeed.Port2.tot | T1: Autofeed.Port3.tot | V1: Autofeed.Port4.tot | X1: Autofeed.Port5.tot | Z1: Autofeed.Port6.tot | AB1: Autofeed.Port7.tot | AD1: Manual.Port1.tot | AF1: Manual.Port2.tot | AH1: Manual.Port3.tot | AJ1: Manual.Port4.tot | AL1: Manual.Port5.tot | AN1: Manual.Port6.tot | AP1: Manual.Port7.tot | AR1: TopUp.Port1.tot | AT1: TopUp.Port2.tot | AV1: TopUp.Port3.tot | AX1: TopUp.Port4.tot | AZ1: TopUp.Port5.tot | BB1: TopUp.Port6.tot | BD1: TopUp.Port7.tot
A2: 45061.208 | B2: 3.4358022 | C2: 45061.208 | D2: 14.541006 | E2: 45061.208 | F2: 20.598877 | G2: 45061.208 | H2: 18.928843 | I2: 45061.208 | J2: 24.492065 | K2: 45061.208 | L2: 16.168497 | M2: 45061.208 | N2: 1.8349104 | O2: 45060.629 | P2: 4.993999 | Q2: 45060.623 | R2: 20.569996 | S2: 45060.617 | T2: 30.601994 | U2: 45060.617 | V2: 29.303999 | W2: 45060.618 | X2: 43.911987 | Y2: 45060.618 | Z2: 28.731997 | AA2: 45060.876 | AB2: 5.323997 | AC2: 45060.881 | AD2: 0 | AE2: 45060.86 | AF2: 0 | AG2: 45060.86 | AH2: 0 | AI2: 45060.853 | AJ2: 0 | AK2: 45060.877 | AL2: 0 | AM2: 45060.867 | AN2: 0 | AO2: 45060.877 | AP2: 0 | AQ2: 45060.877 | AR2: 0 | AS2: 45060.877 | AT2: 0 | AU2: 45060.877 | AV2: 0 | AW2: 45060.877 | AX2: 0 | AY2: 45060.877 | AZ2: 0 | BA2: 45060.877 | BB2: 0 | BC2: 45060.877 | BD2: 0
A3: 45061.208 | B3: 4.2091274 | C3: 45061.208 | D3: 16.5853 | E3: 45061.208 | F3: 20.244591 | G3: 45061.208 | H3: 21.889366 | I3: 45061.208 | J3: 21.533861 | K3: 45061.208 | L3: 14.030433 | M3: 45061.208 | N3: 1.5073233 | O3: 45060.74 | P3: 6.2479978 | Q3: 45060.624 | R3: 21.229996 | S3: 45060.624 | T3: 30.601994 | U3: 45060.624 | V3: 29.303999 | W3: 45060.625 | X3: 43.911987 | Y3: 45060.625 | Z3: 28.731997 | AA3: 45060.983 | AB3: 5.9399972 | AC3: 45061.214 | AD3: 0 | AE3: 45061.193 | AF3: 0 | AG3: 45060.907 | AH3: 2.9920001 | AI3: 45060.91 | AJ3: 3.9820001 | AK3: 45061.21 | AL3: 0 | AM3: 45061.2 | AN3: 0 | AO3: 45061.21 | AP3: 0 | AQ3: 45061.21 | AR3: 0 | AS3: 45061.21 | AT3: 0 | AU3: 45061.21 | AV3: 0 | AW3: 45061.21 | AX3: 0 | AY3: 45061.21 | AZ3: 0 | BA3: 45061.21 | BB3: 0 | BC3: 45061.21 | BD3: 0
A4: 45062.208 | B4: 4.2091274 | C4: 45062.208 | D4: 16.5853 | E4: 45062.208 | F4: 20.244591 | G4: 45062.208 | H4: 21.889366 | I4: 45062.208 | J4: 21.533861 | K4: 45062.208 | L4: 14.030433 | M4: 45062.208 | N4: 1.5073233 | O4: 45060.782 | P4: 6.8419976 | Q4: 45060.636 | R4: 21.559996 | S4: 45060.624 | T4: 31.063993 | U4: 45060.624 | V4: 29.765999 | W4: 45060.625 | X4: 44.593987 | Y4: 45060.626 | Z4: 29.193996 | AA4: 45061.206 | AB4: 7.4799972 | AC4: 45061.547 | AD4: 0 | AE4: 45061.527 | AF4: 0 | AG4: 45060.922 | AH4: 0 | AI4: 45060.922 | AJ4: 0 | AK4: 45061.544 | AL4: 0 | AM4: 45061.534 | AN4: 0 | AO4: 45061.544 | AP4: 0 | AQ4: 45061.544 | AR4: 0 | AS4: 45061.544 | AT4: 0 | AU4: 45061.544 | AV4: 0 | AW4: 45061.544 | AX4: 0 | AY4: 45061.544 | AZ4: 0 | BA4: 45061.544 | BB4: 0 | BC4: 45061.544 | BD4: 0
A5: 45062.208 | B5: 3.5936167 | C5: 45062.208 | D5: 14.748515 | E5: 45062.208 | F5: 17.714237 | G5: 45062.208 | H5: 21.37466 | I5: 45062.208 | J5: 24.654325 | K5: 45062.208 | L5: 16.164593 | M5: 45062.208 | N5: 1.7500509 | O5: 45060.857 | P5: 7.6779981 | Q5: 45060.643 | R5: 21.559996 | S5: 45060.637 | T5: 32.031994 | U5: 45060.637 | V5: 30.667999 | W5: 45060.638 | X5: 45.957985 | Y5: 45060.638 | Z5: 30.095997 | AA5: 45061.213 | AB5: 7.5899973 | AC5: 45061.881 | AD5: 0 | AE5: 45061.86 | AF5: 0 | AG5: 45061.256 | AH5: 0 | AI5: 45061.256 | AJ5: 0 | AK5: 45061.877 | AL5: 0 | AM5: 45061.867 | AN5: 0 | AO5: 45061.877 | AP5: 0 | AQ5: 45061.877 | AR5: 0 | AS5: 45061.877 | AT5: 0 | AU5: 45061.877 | AV5: 0 | AW5: 45061.877 | AX5: 0 | AY5: 45061.877 | AZ5: 0 | BA5: 45061.877 | BB5: 0 | BC5: 45061.877 | BD5: 0
A6: 45063.208 | B6: 3.5936167 | C6: 45063.208 | D6: 14.748515 | E6: 45063.208 | F6: 17.714237 | G6: 45063.208 | H6: 21.37466 | I6: 45063.208 | J6: 24.654325 | K6: 45063.208 | L6: 16.164593 | M6: 45063.208 | N6: 1.7500509 | O6: 45060.88 | P6: 8.0959978 | Q6: 45060.644 | R6: 22.219995 | S6: 45060.644 | T6: 32.031994 | U6: 45060.644 | V6: 30.667999 | W6: 45060.645 | X6: 45.957985 | Y6: 45060.645 | Z6: 30.095997 | AA6: 45061.214 | AB6: 0 | AC6: 45062.214 | AD6: 0 | AE6: 45062.193 | AF6: 0 | AG6: 45061.589 | AH6: 0 | AI6: 45061.589 | AJ6: 0 | AK6: 45062.21 | AL6: 0 | AM6: 45062.2 | AN6: 0 | AO6: 45062.21 | AP6: 0 | AQ6: 45062.21 | AR6: 0 | AS6: 45062.21 | AT6: 0 | AU6: 45062.21 | AV6: 0 | AW6: 45062.21 | AX6: 0 | AY6: 45062.21 | AZ6: 0 | BA6: 45062.21 | BB6: 0 | BC6: 45062.21 | BD6: 0
A7: 45063.208 | B7: Bad Data | C7: 45063.208 | D7: Bad Data | E7: 45063.208 | F7: Bad Data | G7: 45063.208 | H7: Bad Data | I7: 45063.208 | J7: Bad Data | K7: 45063.208 | L7: Bad Data | M7: 45063.208 | N7: Bad Data | O7: 45060.902 | P7: 8.5359983 | Q7: 45060.651 | R7: 22.219995 | S7: 45060.644 | T7: 32.493996 | U7: 45060.645 | V7: 31.129999 | W7: 45060.645 | X7: 46.639984 | Y7: 45060.646 | Z7: 30.557997 | AA7: 45061.464 | AB7: 1.5180001 | AC7: 45062.547 | AD7: 0 | AE7: 45062.52 | AF7: 0 | AG7: 45061.922 | AH7: 0 | AI7: 45061.922 | AJ7: 0 | AK7: 45062.544 | AL7: 0 | AM7: 45062.263 | AN7: 2.9920001 | AO7: 45062.544 | AP7: 0 | AQ7: 45062.544 | AR7: 0 | AS7: 45062.544 | AT7: 0 | AU7: 45062.544 | AV7: 0 | AW7: 45062.544 | AX7: 0 | AY7: 45062.544 | AZ7: 0 | BA7: 45062.544 | BB7: 0 | BC7: 45062.544 | BD7: 0
A8: 45064.208 | B8: Bad Data | C8: 45064.208 | D8: Bad Data | E8: 45064.208 | F8: Bad Data | G8: 45064.208 | H8: Bad Data | I8: 45064.208 | J8: Bad Data | K8: 45064.208 | L8: Bad Data | M8: 45064.208 | N8: Bad Data | O8: 45060.931 | P8: 8.8439989 | Q8: 45060.664 | R8: 23.187996 | S8: 45060.651 | T8: 32.977997 | U8: 45060.651 | V8: 31.57 | W8: 45060.652 | X8: 47.299984 | Y8: 45060.652 | Z8: 30.997997 | AA8: 45061.563 | AB8: 2.0680001 | AC8: 45062.881 | AD8: 0 | AE8: 45062.853 | AF8: 0 | AG8: 45062.255 | AH8: 2.9920001 | AI8: 45062.256 | AJ8: 0 | AK8: 45062.877 | AL8: 0 | AM8: 45062.298 | AN8: 0 | AO8: 45062.877 | AP8: 0 | AQ8: 45062.877 | AR8: 0 | AS8: 45062.877 | AT8: 0 | AU8: 45062.766 | AV8: 0 | AW8: 45062.773 | AX8: 0 | AY8: 45062.773 | AZ8: 0 | BA8: 45062.877 | BB8: 0 | BC8: 45062.877 | BD8: 0
A9: 45064.208 | B9: 3.09517 | C9: 45064.208 | D9: 17.298235 | E9: 45064.208 | F9: 1.7356089 | G9: 45064.208 | H9: 26.554821 | I9: 45064.208 | J9: 28.89789 | K9: 45064.208 | L9: 20.65374 | M9: 45064.208 | N9: 1.7645364 | O9: 45060.955 | P9: 9.3059998 | Q9: 45060.671 | R9: 23.187996 | S9: 45060.658 | T9: 32.977997 | U9: 45060.658 | V9: 31.57 | W9: 45060.659 | X9: 47.299984 | Y9: 45060.659 | Z9: 30.997997 | AA9: 45061.761 | AB9: 3.2779989 | AC9: 45063.207 | AD9: 0 | AE9: 45063.179 | AF9: 0 | AG9: 45062.256 | AH9: 0 | AI9: 45062.258 | AJ9: 2.9920001 | AK9: 45063.21 | AL9: 0 | AM9: 45062.631 | AN9: 0 | AO9: 45063.21 | AP9: 0 | AQ9: 45063.21 | AR9: 0 | AS9: 45063.21 | AT9: 0 | AU9: 45062.773 | AV9: 1.012 | AW9: 45062.774 | AX9: 1.012 | AY9: 45062.775 | AZ9: 1.012 | BA9: 45063.21 | BB9: 0 | BC9: 45063.21 | BD9: 0
A10: 45065.208 | B10: 3.09517 | C10: 45065.208 | D10: 17.298235 | E10: 45065.208 | F10: 1.7356089 | G10: 45065.208 | H10: 26.554821 | I10: 45065.208 | J10: 28.89789 | K10: 45065.208 | L10: 20.65374 | M10: 45065.208 | N10: 1.7645364 | O10: 45060.974 | P10: 9.79 | Q10: 45060.671 | R10: 23.517996 | S10: 45060.658 | T10: 33.439999 | U10: 45060.658 | V10: 32.032001 | W10: 45060.659 | X10: 47.981983 | Y10: 45060.66 | Z10: 31.459997 | AA10: 45061.986 | AB10: 5.0379996 | AC10: 45063.541 | AD10: 0 | AE10: 45063.513 | AF10: 0 | AG10: 45062.589 | AH10: 0 | AI10: 45062.298 | AJ10: 0 | AK10: 45063.544 | AL10: 0 | AM10: 45062.843 | AN10: 2.9920001 | AO10: 45063.544 | AP10: 0 | AQ10: 45063.544 | AR10: 0 | AS10: 45063.544 | AT10: 0 | AU10: 45063.106 | AV10: 1.012 | AW10: 45063.107 | AX10: 1.012 | AY10: 45063.108 | AZ10: 1.012 | BA10: 45063.544 | BB10: 0 | BC10: 45063.544 | BD10: 0
A11: 45065.208 | B11: 3.5747097 | C11: 45065.208 | D11: 17.29945 | E11: 45065.208 | F11: 12.101957 | G11: 45065.208 | H11: 22.910294 | I11: 45065.208 | J11: 26.607471 | K11: 45065.208 | L11: 15.845064 | M11: 45065.208 | N11: 1.6610543 | O11: 45061.017 | P11: 10.669998 | Q11: 45060.685 | R11: 24.155996 | S11: 45060.665 | T11: 33.924 | U11: 45060.665 | V11: 32.472 | W11: 45060.666 | X11: 48.663982 | Y11: 45060.666 | Z11: 31.899998 | AA11: 45062.208 | AB11: 6.9960008 | AC11: 45063.712 | AD11: Bad | AE11: 45063.712 | AF11: Bad | AG11: 45062.923 | AH11: 0 | AI11: 45062.631 | AJ11: 0 | AK11: 45063.712 | AL11: Bad | AM11: 45062.853 | AN11: 5.9840002 | AO11: 45063.712 | AP11: Bad | AQ11: 45063.712 | AR11: Bad | AS11: 45063.712 | AT11: Bad | AU11: 45063.21 | AV11: 1.012 | AW11: 45063.211 | AX11: 1.012 | AY11: 45063.212 | AZ11: 1.012 | BA11: 45063.712 | BB11: Bad | BC11: 45063.712 | BD11: Bad
A12: 45066.208 | B12: 3.5747097 | C12: 45066.208 | D12: 17.29945 | E12: 45066.208 | F12: 12.101957 | G12: 45066.208 | H12: 22.910294 | I12: 45066.208 | J12: 26.607471 | K12: 45066.208 | L12: 15.845064 | M12: 45066.208 | N12: 1.6610543 | O12: 45061.046 | P12: 11.197997 | Q12: 45060.692 | R12: 24.155996 | S12: 45060.671 | T12: 33.924 | U12: 45060.672 | V12: 32.472 | W12: 45060.673 | X12: 48.663982 | Y12: 45060.673 | Z12: 31.899998 | AA12: 45062.214 | AB12: 0 | AC12: 45063.713 | AD12: 0 | AE12: 45063.713 | AF12: 0 | AG12: 45063.04 | AH12: 2.9920001 | AI12: 45062.779 | AJ12: 1.98 | AK12: 45063.713 | AL12: 0 | AM12: 45062.873 | AN12: 8.9759998 | AO12: 45063.713 | AP12: 0 | AQ12: 45063.713 | AR12: 0 | AS12: 45063.713 | AT12: 0 | AU12: 45063.214 | AV12: 0 | AW12: 45063.214 | AX12: 0 | AY12: 45063.214 | AZ12: 0 | BA12: 45063.713 | BB12: 0 | BC12: 45063.713 | BD12: 0
A13: 45066.208 | B13: 3.9453444 | C13: 45066.208 | D13: 15.905598 | E13: 45066.208 | F13: 17.780663 | G13: 45066.208 | H13: 20.199936 | I13: 45066.208 | J13: 26.032181 | K13: 45066.208 | L13: 14.545127 | M13: 45066.208 | N13: 1.5911504 | O13: 45061.133 | P13: 12.781994 | Q13: 45060.692 | R13: 24.485996 | S13: 45060.672 | T13: 34.408001 | U13: 45060.672 | V13: 32.934002 | W13: 45060.673 | X13: 49.323982 | Y13: 45060.673 | Z13: 32.362 | AA13: 45062.275 | AB13: 0.39600003 | AC13: 45064.046 | AD13: 0 | AE13: 45064.046 | AF13: 0 | AG13: 45063.048 | AH13: 0 | AI13: 45062.791 | AJ13: 3.96 | AK13: 45064.046 | AL13: 0 | AM13: 45062.881 | AN13: 0 | AO13: 45064.046 | AP13: 0 | AQ13: 45064.046 | AR13: 0 | AS13: 45064.046 | AT13: 0 | AU13: 45063.548 | AV13: 0 | AW13: 45063.548 | AX13: 0 | AY13: 45063.548 | AZ13: 0 | BA13: 45064.046 | BB13: 0 | BC13: 45064.046 | BD13: 0
A14: 45067.208 | B14: 3.9453444 | C14: 45067.208 | D14: 15.905598 | E14: 45067.208 | F14: 17.780663 | G14: 45067.208 | H14: 20.199936 | I14: 45067.208 | J14: 26.032181 | K14: 45067.208 | L14: 14.545127 | M14: 45067.208 | N14: 1.5911504 | O14: 45061.191 | P14: 13.859992 | Q14: 45060.706 | R14: 24.485996 | S14: 45060.685 | T14: 35.354004 | U14: 45060.679 | V14: 33.374001 | W14: 45060.68 | X14: 50.005981 | Y14: 45060.68 | Z14: 32.801998 | AA14: 45062.317 | AB14: 0.61600006 | AC14: 45064.38 | AD14: 0 | AE14: 45064.38 | AF14: 0 | AG14: 45063.381 | AH14: 0 | AI14: 45062.797 | AJ14: 5.9400001 | AK14: 45064.38 | AL14: 0 | AM14: 45062.894 | AN14: 2.9920001 | AO14: 45064.38 | AP14: 0 | AQ14: 45064.38 | AR14: 0 | AS14: 45064.38 | AT14: 0 | AU14: 45063.712 | AV14: Bad | AW14: 45063.712 | AX14: Bad | AY14: 45063.712 | AZ14: Bad | BA14: 45064.38 | BB14: 0 | BC14: 45064.38 | BD14: 0
A15: 45067.208 | B15: 4.0239472 | C15: 45067.208 | D15: 16.117363 | E15: 45067.208 | F15: 18.021469 | G15: 45067.208 | H15: 20.475748 | I15: 45067.208 | J15: 26.295933 | K15: 45067.208 | L15: 13.587575 | M15: 45067.208 | N15: 1.4779646 | O15: 45061.208 | P15: 14.211991 | Q15: 45060.706 | R15: 25.145996 | S15: 45060.692 | T15: 35.354004 | U15: 45060.686 | V15: 33.374001 | W15: 45060.686 | X15: 50.005981 | Y15: 45060.687 | Z15: 32.801998 | AA15: 45062.593 | AB15: 2.8379998 | AC15: 45064.713 | AD15: 0 | AE15: 45064.713 | AF15: 0 | AG15: 45063.712 | AH15: Bad | AI15: 45062.798 | AJ15: 0 | AK15: 45064.713 | AL15: 0 | AM15: 45062.923 | AN15: 0 | AO15: 45064.713 | AP15: 0 | AQ15: 45064.713 | AR15: 0 | AS15: 45064.713 | AT15: 0 | AU15: 45063.713 | AV15: 0 | AW15: 45063.713 | AX15: 0 | AY15: 45063.713 | AZ15: 0 | BA15: 45064.713 | BB15: 0 | BC15: 45064.713 | BD15: 0
A16: 45068.208 | B16: 4.0239472 | C16: 45068.208 | D16: 16.117363 | E16: 45068.208 | F16: 18.021469 | G16: 45068.208 | H16: 20.475748 | I16: 45068.208 | J16: 26.295933 | K16: 45068.208 | L16: 13.587575 | M16: 45068.208 | N16: 1.4779646 | O16: 45061.214 | P16: 0 | Q16: 45060.72 | R16: 25.783997 | S16: 45060.692 | T16: 35.816006 | U16: 45060.686 | V16: 33.836002 | W16: 45060.686 | X16: 50.687981 | Y16: 45060.687 | Z16: 33.264 | AA16: 45062.756 | AB16: 4.3780003 | AC16: 45065.046 | AD16: 0 | AE16: 45065.046 | AF16: 0 | AG16: 45063.713 | AH16: 0 | AI16: 45062.836 | AJ16: 1.98 | AK16: 45065.046 | AL16: 0 | AM16: 45063.256 | AN16: 0 | AO16: 45065.046 | AP16: 0 | AQ16: 45065.046 | AR16: 0 | AS16: 45065.046 | AT16: 0 | AU16: 45064.046 | AV16: 0 | AW16: 45064.046 | AX16: 0 | AY16: 45064.046 | AZ16: 0 | BA16: 45064.886 | BB16: 0 | BC16: 45065.046 | BD16: 0
A17: 45068.208 | B17: 2.9766212 | C17: 45068.208 | D17: 12.867215 | E17: 45068.208 | F17: 16.188148 | G17: 45068.208 | H17: 21.197315 | I17: 45068.208 | J17: 28.405615 | K17: 45068.208 | L17: 16.532463 | M17: 45068.208 | N17: 1.8326216 | O17: 45061.257 | P17: 1.056 | Q17: 45060.727 | R17: 25.783997 | S17: 45060.699 | T17: 35.816006 | U17: 45060.693 | V17: 33.836002 | W17: 45060.693 | X17: 51.34798 | Y17: 45060.694 | Z17: 33.703999 | AA17: 45062.791 | AB17: 4.6860003 | AC17: 45065.38 | AD17: 0 | AE17: 45065.374 | AF17: 0 | AG17: 45064.046 | AH17: 0 | AI17: 45062.839 | AJ17: 0 | AK17: 45065.38 | AL17: 0 | AM17: 45063.589 | AN17: 0 | AO17: 45065.38 | AP17: 0 | AQ17: 45065.38 | AR17: 0 | AS17: 45065.227 | AT17: 0 | AU17: 45064.38 | AV17: 0 | AW17: 45064.38 | AX17: 0 | AY17: 45064.38 | AZ17: 0 | BA17: 45064.891 | BB17: 0.50599998 | BC17: 45065.38 | BD17: 0
A18: 45069.208 | B18: 2.9766212 | C18: 45069.208 | D18: 12.867215 | E18: 45069.208 | F18: 16.188148 | G18: 45069.208 | H18: 21.197315 | I18: 45069.208 | J18: 28.405615 | K18: 45069.208 | L18: 16.532463 | M18: 45069.208 | N18: 1.8326216 | O18: 45061.293 | P18: 1.584 | Q18: 45060.727 | R18: 26.113997 | S18: 45060.699 | T18: 36.300007 | U18: 45060.693 | V18: 34.276001 | W18: 45060.7 | X18: 51.34798 | Y18: 45060.701 | Z18: 33.703999 | AA18: 45062.884 | AB18: 5.0160007 | AC18: 45065.707 | AD18: 0 | AE18: 45065.707 | AF18: 0 | AG18: 45064.38 | AH18: 0 | AI18: 45062.848 | AJ18: 1.98 | AK18: 45065.713 | AL18: 0 | AM18: 45063.712 | AN18: Bad | AO18: 45065.713 | AP18: 0 | AQ18: 45065.4 | AR18: 0 | AS18: 45065.232 | AT18: 1.012 | AU18: 45064.713 | AV18: 0 | AW18: 45064.713 | AX18: 0 | AY18: 45064.713 | AZ18: 0 | BA18: 45064.894 | BB18: 1.5179999 | BC18: 45065.713 | BD18: 0
A19: 45069.208 | B19: 2.9342833 | C19: 45069.208 | D19: 13.115029 | E19: 45069.208 | F19: 15.530494 | G19: 45069.208 | H19: 20.517696 | I19: 45069.208 | J19: 29.538092 | K19: 45069.208 | L19: 16.50119 | M19: 45069.208 | N19: 1.8632154 | O19: 45061.401 | P19: 4.0040002 | Q19: 45060.74 | R19: 26.113997 | S19: 45060.706 | T19: 36.300007 | U19: 45060.7 | V19: 34.276001 | W19: 45060.7 | X19: 52.02998 | Y19: 45060.701 | Z19: 34.166 | AA19: 45063.124 | AB19: 5.1260009 | AC19: 45066.041 | AD19: 0 | AE19: 45066.041 | AF19: 0 | AG19: 45064.713 | AH19: 0 | AI19: 45062.859 | AJ19: 3.96 | AK19: 45066.046 | AL19: 0 | AM19: 45063.713 | AN19: 0 | AO19: 45066.046 | AP19: 0 | AQ19: 45065.407 | AR19: 1.012 | AS19: 45065.239 | AT19: 1.012 | AU19: 45064.782 | AV19: 0 | AW19: 45064.893 | AX19: 0 | AY19: 45065.046 | AZ19: 0 | BA19: 45064.977 | BB19: 1.5179999 | BC19: 45066.046 | BD19: 0
A20: 45070.208 | B20: 2.9342833 | C20: 45070.208 | D20: 13.115029 | E20: 45070.208 | F20: 15.530494 | G20: 45070.208 | H20: 20.517696 | I20: 45070.208 | J20: 29.538092 | K20: 45070.208 | L20: 16.50119 | M20: 45070.208 | N20: 1.8632154 | O20: 45061.452 | P20: 5.3680005 | Q20: 45060.741 | R20: 26.971996 | S20: 45060.707 | T20: 36.784008 | U20: 45060.7 | V20: 34.738003 | W20: 45060.707 | X20: 52.02998 | Y20: 45060.708 | Z20: 34.166 | AA20: 45063.21 | AB20: 5.7640014 | AC20: 45066.323 | AD20: 1.98 | AE20: 45066.324 | AF20: 1.98 | AG20: 45065.041 | AH20: 0 | AI20: 45062.868 | AJ20: 5.9400001 | AK20: 45066.38 | AL20: 0 | AM20: 45064.046 | AN20: 0 | AO20: 45066.38 | AP20: 0 | AQ20: 45065.74 | AR20: 1.012 | AS20: 45065.242 | AT20: 2.0239999 | AU20: 45064.799 | AV20: 0.242 | AW20: 45064.898 | AX20: 0.50599998 | AY20: 45065.234 | AZ20: 0 | BA20: 45064.981 | BB20: 2.0239999 | BC20: 45066.38 | BD20: 0
O21: 45061.518 | P21: 6.5560007 | Q21: 45060.747 | R21: 27.411997 | S21: 45060.72 | T21: 37.730011 | U21: 45060.707 | V21: 34.738003 | W21: 45060.708 | X21: 52.711979 | Y21: 45060.708 | Z21: 34.605999 | AA21: 45063.214 | AB21: 0 | AC21: 45066.339 | AD21: 0 | AE21: 45066.339 | AF21: 0 | AG21: 45065.374 | AH21: 0 | AI21: 45062.881 | AJ21: 0 | AK21: 45066.713 | AL21: 0 | AM21: 45064.38 | AN21: 0 | AO21: 45066.713 | AP21: 0 | AQ21: 45066.073 | AR21: 1.012 | AS21: 45065.27 | AT21: 2.0239999 | AU21: 45065.133 | AV21: 0.242 | AW21: 45065.21 | AX21: 0.50599998 | AY21: 45065.234 | AZ21: 1.012 | BA21: 45065.211 | BB21: 2.0239999 | BC21: 45066.713 | BD21: 0
O22: 45061.534 | P22: 6.7320008 | Q22: 45060.754 | R22: 27.411997 | S22: 45060.727 | T22: 37.730011 | U22: 45060.707 | V22: 35.178001 | W22: 45060.714 | X22: 53.371979 | Y22: 45060.715 | Z22: 35.045998 | AA22: 45063.548 | AB22: 0 | AC22: 45066.666 | AD22: 0 | AE22: 45066.666 | AF22: 0 | AG22: 45065.707 | AH22: 0 | AI22: 45062.884 | AJ22: 1.98 | AK22: 45067.046 | AL22: 0 | AM22: 45064.713 | AN22: 0 | AO22: 45067.046 | AP22: 0 | AQ22: 45066.212 | AR22: 1.012 | AS22: 45065.272 | AT22: 4.026 | AU22: 45065.209 | AV22: 0.242 | AW22: 45065.214 | AX22: 0 | AY22: 45065.241 | AZ22: 1.012 | BA22: 45065.214 | BB22: 0 | BC22: 45067.046 | BD22: 0
O23: 45061.7 | P23: 10.097999 | Q23: 45060.754 | R23: 27.851997 | S23: 45060.727 | T23: 38.192013 | U23: 45060.721 | V23: 36.080002 | W23: 45060.721 | X23: 53.371979 | Y23: 45060.722 | Z23: 35.045998 | AA23: 45063.712 | AB23: Bad | AC23: 45066.686 | AD23: 1.98 | AE23: 45066.688 | AF23: 1.98 | AG23: 45066.041 | AH23: 0 | AI23: 45062.89 | AJ23: 3.96 | AK23: 45067.38 | AL23: 0 | AM23: 45065.044 | AN23: 0.99000001 | AO23: 45067.38 | AP23: 0 | AQ23: 45066.214 | AR23: 0 | AS23: 45065.286 | AT23: 4.026 | AU23: 45065.235 | AV23: 0 | AW23: 45065.228 | AX23: 0 | AY23: 45065.244 | AZ23: 2.0239999 | BA23: 45065.228 | BB23: 0 | BC23: 45067.38 | BD23: 0
O24: 45061.747 | P24: 10.955997 | Q24: 45060.761 | R24: 28.291998 | S24: 45060.734 | T24: 38.192013 | U24: 45060.727 | V24: 36.080002 | W24: 45060.721 | X24: 54.053978 | Y24: 45060.722 | Z24: 35.507999 | AA24: 45063.713 | AB24: 0 | AC24: 45066.714 | AD24: 0 | AE24: 45066.714 | AF24: 0 | AG24: 45066.325 | AH24: 1.98 | AI24: 45062.902 | AJ24: 5.9400001 | AK24: 45067.713 | AL24: 0 | AM24: 45065.302 | AN24: 2.97 | AO24: 45067.713 | AP24: 0 | AQ24: 45066.548 | AR24: 0 | AS24: 45065.292 | AT24: 5.0380001 | AU24: 45065.568 | AV24: 0 | AW24: 45065.233 | AX24: 1.012 | AY24: 45065.272 | AZ24: 2.0239999 | BA24: 45065.235 | BB24: 1.012 | BC24: 45067.713 | BD24: 0
O25: 45061.843 | P25: 12.803996 | Q25: 45060.768 | R25: 28.291998 | S25: 45060.734 | T25: 38.830013 | U25: 45060.727 | V25: 36.52 | W25: 45060.728 | X25: 54.053978 | Y25: 45060.729 | Z25: 35.947998 | AA25: 45064.046 | AB25: 0 | AC25: 45067.041 | AD25: 0 | AE25: 45067.041 | AF25: 0 | AG25: 45066.339 | AH25: 0 | AI25: 45062.909 | AJ25: 7.9200001 | AK25: 45068.046 | AL25: 0 | AM25: 45065.309 | AN25: 4.9499998 | AO25: 45068.046 | AP25: 0 | AQ25: 45066.881 | AR25: 0 | AS25: 45065.403 | AT25: 5.0380001 | AU25: 45065.902 | AV25: 0 | AW25: 45065.24 | AX25: 1.012 | AY25: 45065.276 | AZ25: 4.026 | BA25: 45065.242 | BB25: 1.012 | BC25: 45068.046 | BD25: 0
O26: 45061.871 | P26: 13.309996 | Q26: 45060.768 | R26: 28.709997 | S26: 45060.741 | T26: 38.830013 | U26: 45060.734 | V26: 36.52 | W26: 45060.728 | X26: 54.735977 | Y26: 45060.736 | Z26: 35.947998 | AA26: 45064.38 | AB26: 0 | AC26: 45067.327 | AD26: 1.98 | AE26: 45067.328 | AF26: 1.98 | AG26: 45066.666 | AH26: 0 | AI26: 45062.923 | AJ26: 0 | AK26: 45068.38 | AL26: 0 | AM26: 45065.312 | AN26: 6.9299998 | AO26: 45068.38 | AP26: 0 | AQ26: 45067.214 | AR26: 0 | AS26: 45065.408 | AT26: 6.0500002 | AU26: 45066.235 | AV26: 0 | AW26: 45065.243 | AX26: 2.0239999 | AY26: 45065.29 | AZ26: 4.026 | BA26: 45065.245 | BB26: 2.0239999 | BC26: 45068.38 | BD26: 0
O27: 45062.037 | P27: 16.675993 | Q27: 45060.775 | R27: 29.149998 | S27: 45060.742 | T27: 39.468014 | U27: 45060.735 | V27: 37.136002 | W27: 45060.735 | X27: 54.735977 | Y27: 45060.736 | Z27: 36.563999 | AA27: 45064.713 | AB27: 0 | AC27: 45067.339 | AD27: 0 | AE27: 45067.339 | AF27: 0 | AG27: 45066.706 | AH27: 1.98 | AI27: 45062.925 | AJ27: 1.98 | AK27: 45068.713 | AL27: 0 | AM27: 45065.327 | AN27: 8.9099998 | AO27: 45068.713 | AP27: 0 | AQ27: 45067.548 | AR27: 0 | AS27: 45065.741 | AT27: 6.0500002 | AU27: 45066.568 | AV27: 0 | AW27: 45065.271 | AX27: 2.0239999 | AY27: 45065.294 | AZ27: 5.0380001 | BA27: 45065.273 | BB27: 2.0239999 | BC27: 45068.713 | BD27: 0
O28: 45062.092 | P28: 17.665993 | Q28: 45060.782 | R28: 29.149998 | S28: 45060.748 | T28: 40.106014 | U28: 45060.742 | V28: 37.136002 | W28: 45060.736 | X28: 55.637978 | Y28: 45060.743 | Z28: 36.563999 | AA28: 45065.045 | AB28: 0.46200001 | AC28: 45067.484 | AD28: 1.98 | AE28: 45067.485 | AF28: 1.98 | AG28: 45066.714 | AH28: 0 | AI28: 45062.932 | AJ28: 3.96 | AK28: 45069.046 | AL28: 0 | AM28: 45065.339 | AN28: 0 | AO28: 45069.046 | AP28: 0 | AQ28: 45067.881 | AR28: 0 | AS28: 45066.074 | AT28: 6.0500002 | AU28: 45066.902 | AV28: 0 | AW28: 45065.274 | AX28: 4.026 | AY28: 45065.627 | AZ28: 5.0380001 | BA28: 45065.278 | BB28: 3.9159999 | BC28: 45069.046 | BD28: 0
O29: 45062.15 | P29: 18.545994 | Q29: 45060.782 | R29: 29.589998 | S29: 45060.755 | T29: 40.106014 | U29: 45060.742 | V29: 37.730003 | W29: 45060.743 | X29: 55.637978 | Y29: 45060.744 | Z29: 37.158001 | AA29: 45065.209 | AB29: 1.3420005 | AC29: 45067.506 | AD29: 0 | AE29: 45067.506 | AF29: 0 | AG29: 45066.755 | AH29: 1.98 | AI29: 45062.935 | AJ29: 5.9400001 | AK29: 45069.38 | AL29: 0 | AM29: 45065.673 | AN29: 0 | AO29: 45069.38 | AP29: 0 | AQ29: 45068.214 | AR29: 0 | AS29: 45066.213 | AT29: 6.0500002 | AU29: 45067.235 | AV29: 0 | AW29: 45065.288 | AX29: 4.026 | AY29: 45065.961 | AZ29: 5.0380001 | BA29: 45065.611 | BB29: 3.9159999 | BC29: 45069.38 | BD29: 0
O30: 45062.212 | P30: 19.535994 | Q30: 45060.802 | R30: 30.91 | S30: 45060.755 | T30: 40.744015 | U30: 45060.749 | V30: 38.324005 | W30: 45060.743 | X30: 56.539978 | Y30: 45060.75 | Z30: 37.752003 | AA30: 45065.214 | AB30: 0 | AC30: 45067.832 | AD30: 0 | AE30: 45067.679 | AF30: 1.98 | AG30: 45066.756 | AH30: 0 | AI30: 45062.937 | AJ30: 7.9200001 | AK30: 45069.713 | AL30: 0 | AM30: 45065.999 | AN30: 0 | AO30: 45069.713 | AP30: 0 | AQ30: 45068.548 | AR30: 0 | AS30: 45066.214 | AT30: 0 | AU30: 45067.249 | AV30: 0 | AW30: 45065.293 | AX30: 5.0380001 | AY30: 45066.211 | AZ30: 5.0380001 | BA30: 45065.945 | BB30: 3.9159999 | BC30: 45069.713 | BD30: 0
O31: 45062.214 | P31: 0 | Q31: 45060.809 | R31: 30.91 | S31: 45060.762 | T31: 41.360016 | U31: 45060.756 | V31: 38.324005 | W31: 45060.75 | X31: 57.419979 | Y31: 45060.757 | Z31: 37.752003 | AA31: 45065.325 | AB31: 0.39600003 | AC31: 45068.166 | AD31: 0 | AE31: 45067.707 | AF31: 3.96 | AG31: 45067.089 | AH31: 0 | AI31: 45062.94 | AJ31: 9.8999996 | AK31: 45070.046 | AL31: 0 | AM31: 45066.328 | AN31: 1.98 | AO31: 45070.046 | AP31: 0 | AQ31: 45068.881 | AR31: 0 | AS31: 45066.548 | AT31: 0 | AU31: 45067.253 | AV31: 1.012 | AW31: 45065.626 | AX31: 5.0380001 | AY31: 45066.214 | AZ31: 0 | BA31: 45066.208 | BB31: 3.9159999 | BC31: 45070.046 | BD31: 0
O32: 45062.256 | P32: 0.72600001 | Q32: 45060.809 | R32: 31.327999 | S32: 45060.769 | T32: 41.360016 | U32: 45060.756 | V32: 38.918007 | W32: 45060.757 | X32: 57.419979 | Y32: 45060.757 | Z32: 38.346004 | AA32: 45065.499 | AB32: 0.88000011 | AC32: 45068.499 | AD32: 0 | AE32: 45067.714 | AF32: 0 | AG32: 45067.329 | AH32: 1.98 | AI32: 45062.944 | AJ32: 11.879999 | AK32: 45070.38 | AL32: 0 | AM32: 45066.339 | AN32: 0 | AO32: 45070.38 | AP32: 0 | AQ32: 45069.214 | AR32: 0 | AS32: 45066.881 | AT32: 0 | AU32: 45067.586 | AV32: 1.012 | AW32: 45065.96 | AX32: 5.0380001 | AY32: 45066.548 | AZ32: 0 | BA32: 45066.214 | BB32: 0 | BC32: 45070.38 | BD32: 0
O33: 45062.315 | P33: 1.4960002 | Q33: 45060.816 | R33: 31.768 | S33: 45060.769 | T33: 41.998016 | U33: 45060.763 | V33: 39.534008 | W33: 45060.757 | X33: 58.32198 | Y33: 45060.764 | Z33: 38.962006 | AA33: 45065.697 | AB33: 1.1000003 | AC33: 45068.832 | AD33: 0 | AE33: 45068.048 | AF33: 0 | AG33: 45067.339 | AH33: 0 | AI33: 45062.951 | AJ33: 13.859999 | AK33: 45070.595 | AL33: 0 | AM33: 45066.666 | AN33: 0 | AO33: 45070.595 | AP33: 0 | AQ33: 45069.548 | AR33: 0 | AS33: 45067.214 | AT33: 0 | AU33: 45067.92 | AV33: 1.012 | AW33: 45066.21 | AX33: 5.0380001 | AY33: 45066.881 | AZ33: 0 | BA33: 45066.548 | BB33: 0 | BC33: 45070.595 | BD33: 0
