Workbook

Sheet Sheet1
B1: \\polsmes\POLSPI_MDB\AISPOLSPI01 ModuleDB\POLS Smelter\Furnace 1\Feed\Feed Profile\East|ACE.Profile.1 | D1: \\polsmes\POLSPI_MDB\AISPOLSPI01 ModuleDB\POLS Smelter\Furnace 1\Feed\Feed Profile\East|ACE.Profile.2 | F1: \\polsmes\POLSPI_MDB\AISPOLSPI01 ModuleDB\POLS Smelter\Furnace 1\Feed\Feed Profile\East|ACE.Profile.3 | H1: \\polsmes\POLSPI_MDB\AISPOLSPI01 ModuleDB\POLS Smelter\Furnace 1\Feed\Feed Profile\East|ACE.Profile.4 | J1: \\polsmes\POLSPI_MDB\AISPOLSPI01 ModuleDB\POLS Smelter\Furnace 1\Feed\Feed Profile\East|ACE.Profile.5 | L1: \\polsmes\POLSPI_MDB\AISPOLSPI01 ModuleDB\POLS Smelter\Furnace 1\Feed\Feed Profile\East|ACE.Profile.6 | N1: \\polsmes\POLSPI_MDB\AISPOLSPI01 ModuleDB\POLS Smelter\Furnace 1\Feed\Feed Profile\East|ACE.Profile.7 | P1: \\polsmes\POLSPI_MDB\AISPOLSPI01 ModuleDB\POLS Smelter\Furnace 1\Feed\Feed Profile\East|ACE.Profile.8 | R1: \\polsmes\POLSPI_MDB\AISPOLSPI01 ModuleDB\POLS Smelter\Furnace 1\Feed\Feed Profile\East|ACE.Profile.9 | T1: \\polsmes\POLSPI_MDB\AISPOLSPI01 ModuleDB\POLS Smelter\Furnace 1\Feed\Feed Profile\East|FeedBatch.Port1.tot | V1: \\polsmes\POLSPI_MDB\AISPOLSPI01 ModuleDB\POLS Smelter\Furnace 1\Feed\Feed Profile\East|FeedBatch.Port2.tot | X1: \\polsmes\POLSPI_MDB\AISPOLSPI01 ModuleDB\POLS Smelter\Furnace 1\Feed\Feed Profile\East|FeedBatch.Port3.tot | Z1: \\polsmes\POLSPI_MDB\AISPOLSPI01 ModuleDB\POLS Smelter\Furnace 1\Feed\Feed Profile\East|FeedBatch.Port4.tot | AB1: \\polsmes\POLSPI_MDB\AISPOLSPI01 ModuleDB\POLS Smelter\Furnace 1\Feed\Feed Profile\East|FeedBatch.Port5.tot | AD1: \\polsmes\POLSPI_MDB\AISPOLSPI01 ModuleDB\POLS Smelter\Furnace 1\Feed\Feed Profile\East|FeedBatch.Port6.tot | AF1: \\polsmes\POLSPI_MDB\AISPOLSPI01 ModuleDB\POLS Smelter\Furnace 1\Feed\Feed Profile\East|FeedBatch.Port7.tot | AH1: \\polsmes\POLSPI_MDB\AISPOLSPI01 ModuleDB\POLS Smelter\Furnace 1\Feed\Feed Profile\East|FeedBatch.Port8.tot | AJ1: \\polsmes\POLSPI_MDB\AISPOLSPI01 ModuleDB\POLS Smelter\Furnace 1\Feed\Feed Profile\East|FeedBatch.Port9.tot
A2: {=_xll.PICompDat(Sheet1!$B$1,"*-10d","*",9,"","inside")} -> #NAME? | B2: #NAME? | C2: {=_xll.PICompDat(Sheet1!$D$1,"*-10d","*",9,"","inside")} -> #NAME? | D2: #NAME? | E2: {=_xll.PICompDat(Sheet1!$F$1,"*-10d","*",9,"","inside")} -> #NAME? | F2: #NAME? | G2: {=_xll.PICompDat(Sheet1!$H$1,"*-10d","*",9,"","inside")} -> #NAME? | H2: #NAME? | I2: {=_xll.PICompDat(Sheet1!$J$1,"*-10d","*",9,"","inside")} -> #NAME? | J2: #NAME? | K2: {=_xll.PICompDat(Sheet1!$L$1,"*-10d","*",9,"","inside")} -> #NAME? | L2: #NAME? | M2: {=_xll.PICompDat(Sheet1!$N$1,"*-10d","*",9,"","inside")} -> #NAME? | N2: #NAME? | O2: {=_xll.PICompDat(Sheet1!$P$1,"*-10d","*",9,"","inside")} -> #NAME? | P2: #NAME? | Q2: {=_xll.PICompDat(Sheet1!$R$1,"*-10d","*",9,"","inside")} -> #NAME? | R2: #NAME? | S2: {=_xll.PICompDat(Sheet1!$T$1,"*-10d","*",9,"","inside")} -> #NAME? | T2: #NAME? | U2: {=_xll.PICompDat(Sheet1!$V$1,"*-10d","*",9,"","inside")} -> #NAME? | V2: #NAME? | W2: {=_xll.PICompDat(Sheet1!$X$1,"*-10d","*",9,"","inside")} -> #NAME? | X2: #NAME? | Y2: {=_xll.PICompDat(Sheet1!$Z$1,"*-10d","*",9,"","inside")} -> #NAME? | Z2: #NAME? | AA2: {=_xll.PICompDat(Sheet1!$AB$1,"*-10d","*",9,"","inside")} -> #NAME? | AB2: #NAME? | AC2: {=_xll.PICompDat(Sheet1!$AD$1,"*-10d","*",9,"","inside")} -> #NAME? | AD2: #NAME? | AE2: {=_xll.PICompDat(Sheet1!$AF$1,"*-10d","*",9,"","inside")} -> #NAME? | AF2: #NAME? | AG2: {=_xll.PICompDat(Sheet1!$AH$1,"*-10d","*",9,"","inside")} -> #NAME? | AH2: #NAME? | AI2: {=_xll.PICompDat(Sheet1!$AJ$1,"*-10d","*",9,"","inside")} -> #NAME? | AJ2: #NAME?
A3: #NAME? | B3: #NAME? | C3: #NAME? | D3: #NAME? | E3: #NAME? | F3: #NAME? | G3: #NAME? | H3: #NAME? | I3: #NAME? | J3: #NAME? | K3: #NAME? | L3: #NAME? | M3: #NAME? | N3: #NAME? | O3: #NAME? | P3: #NAME? | Q3: #NAME? | R3: #NAME? | S3: #NAME? | T3: #NAME? | U3: #NAME? | V3: #NAME? | W3: #NAME? | X3: #NAME? | Y3: #NAME? | Z3: #NAME? | AA3: #NAME? | AB3: #NAME? | AC3: #NAME? | AD3: #NAME? | AE3: #NAME? | AF3: #NAME? | AG3: #NAME? | AH3: #NAME? | AI3: #NAME? | AJ3: #NAME?
A4: #NAME? | B4: #NAME? | C4: #NAME? | D4: #NAME? | E4: #NAME? | F4: #NAME? | G4: #NAME? | H4: #NAME? | I4: #NAME? | J4: #NAME? | K4: #NAME? | L4: #NAME? | M4: #NAME? | N4: #NAME? | O4: #NAME? | P4: #NAME? | Q4: #NAME? | R4: #NAME? | S4: #NAME? | T4: #NAME? | U4: #NAME? | V4: #NAME? | W4: #NAME? | X4: #NAME? | Y4: #NAME? | Z4: #NAME? | AA4: #NAME? | AB4: #NAME? | AC4: #NAME? | AD4: #NAME? | AE4: #NAME? | AF4: #NAME? | AG4: #NAME? | AH4: #NAME? | AI4: #NAME? | AJ4: #NAME?
A5: #NAME? | B5: #NAME? | C5: #NAME? | D5: #NAME? | E5: #NAME? | F5: #NAME? | G5: #NAME? | H5: #NAME? | I5: #NAME? | J5: #NAME? | K5: #NAME? | L5: #NAME? | M5: #NAME? | N5: #NAME? | O5: #NAME? | P5: #NAME? | Q5: #NAME? | R5: #NAME? | S5: #NAME? | T5: #NAME? | U5: #NAME? | V5: #NAME? | W5: #NAME? | X5: #NAME? | Y5: #NAME? | Z5: #NAME? | AA5: #NAME? | AB5: #NAME? | AC5: #NAME? | AD5: #NAME? | AE5: #NAME? | AF5: #NAME? | AG5: #NAME? | AH5: #NAME? | AI5: #NAME? | AJ5: #NAME?
A6: #NAME? | B6: #NAME? | C6: #NAME? | D6: #NAME? | E6: #NAME? | F6: #NAME? | G6: #NAME? | H6: #NAME? | I6: #NAME? | J6: #NAME? | K6: #NAME? | L6: #NAME? | M6: #NAME? | N6: #NAME? | O6: #NAME? | P6: #NAME? | Q6: #NAME? | R6: #NAME? | S6: #NAME? | T6: #NAME? | U6: #NAME? | V6: #NAME? | W6: #NAME? | X6: #NAME? | Y6: #NAME? | Z6: #NAME? | AA6: #NAME? | AB6: #NAME? | AC6: #NAME? | AD6: #NAME? | AE6: #NAME? | AF6: #NAME? | AG6: #NAME? | AH6: #NAME? | AI6: #NAME? | AJ6: #NAME?
A7: #NAME? | B7: #NAME? | C7: #NAME? | D7: #NAME? | E7: #NAME? | F7: #NAME? | G7: #NAME? | H7: #NAME? | I7: #NAME? | J7: #NAME? | K7: #NAME? | L7: #NAME? | M7: #NAME? | N7: #NAME? | O7: #NAME? | P7: #NAME? | Q7: #NAME? | R7: #NAME? | S7: #NAME? | T7: #NAME? | U7: #NAME? | V7: #NAME? | W7: #NAME? | X7: #NAME? | Y7: #NAME? | Z7: #NAME? | AA7: #NAME? | AB7: #NAME? | AC7: #NAME? | AD7: #NAME? | AE7: #NAME? | AF7: #NAME? | AG7: #NAME? | AH7: #NAME? | AI7: #NAME? | AJ7: #NAME?
A8: #NAME? | B8: #NAME? | C8: #NAME? | D8: #NAME? | E8: #NAME? | F8: #NAME? | G8: #NAME? | H8: #NAME? | I8: #NAME? | J8: #NAME? | K8: #NAME? | L8: #NAME? | M8: #NAME? | N8: #NAME? | O8: #NAME? | P8: #NAME? | Q8: #NAME? | R8: #NAME? | S8: #NAME? | T8: #NAME? | U8: #NAME? | V8: #NAME? | W8: #NAME? | X8: #NAME? | Y8: #NAME? | Z8: #NAME? | AA8: #NAME? | AB8: #NAME? | AC8: #NAME? | AD8: #NAME? | AE8: #NAME? | AF8: #NAME? | AG8: #NAME? | AH8: #NAME? | AI8: #NAME? | AJ8: #NAME?
A9: #NAME? | B9: #NAME? | C9: #NAME? | D9: #NAME? | E9: #NAME? | F9: #NAME? | G9: #NAME? | H9: #NAME? | I9: #NAME? | J9: #NAME? | K9: #NAME? | L9: #NAME? | M9: #NAME? | N9: #NAME? | O9: #NAME? | P9: #NAME? | Q9: #NAME? | R9: #NAME? | S9: #NAME? | T9: #NAME? | U9: #NAME? | V9: #NAME? | W9: #NAME? | X9: #NAME? | Y9: #NAME? | Z9: #NAME? | AA9: #NAME? | AB9: #NAME? | AC9: #NAME? | AD9: #NAME? | AE9: #NAME? | AF9: #NAME? | AG9: #NAME? | AH9: #NAME? | AI9: #NAME? | AJ9: #NAME?
A10: #NAME? | B10: #NAME? | C10: #NAME? | D10: #NAME? | E10: #NAME? | F10: #NAME? | G10: #NAME? | H10: #NAME? | I10: #NAME? | J10: #NAME? | K10: #NAME? | L10: #NAME? | M10: #NAME? | N10: #NAME? | O10: #NAME? | P10: #NAME? | Q10: #NAME? | R10: #NAME? | S10: #NAME? | T10: #NAME? | U10: #NAME? | V10: #NAME? | W10: #NAME? | X10: #NAME? | Y10: #NAME? | Z10: #NAME? | AA10: #NAME? | AB10: #NAME? | AC10: #NAME? | AD10: #NAME? | AE10: #NAME? | AF10: #NAME? | AG10: #NAME? | AH10: #NAME? | AI10: #NAME? | AJ10: #NAME?
A11: #NAME? | B11: #NAME? | C11: #NAME? | D11: #NAME? | E11: #NAME? | F11: #NAME? | G11: #NAME? | H11: #NAME? | I11: #NAME? | J11: #NAME? | K11: #NAME? | L11: #NAME? | M11: #NAME? | N11: #NAME? | O11: #NAME? | P11: #NAME? | Q11: #NAME? | R11: #NAME? | S11: #NAME? | T11: #NAME? | U11: #NAME? | V11: #NAME? | W11: #NAME? | X11: #NAME? | Y11: #NAME? | Z11: #NAME? | AA11: #NAME? | AB11: #NAME? | AC11: #NAME? | AD11: #NAME? | AE11: #NAME? | AF11: #NAME? | AG11: #NAME? | AH11: #NAME? | AI11: #NAME? | AJ11: #NAME?
A12: #NAME? | B12: #NAME? | C12: #NAME? | D12: #NAME? | E12: #NAME? | F12: #NAME? | G12: #NAME? | H12: #NAME? | I12: #NAME? | J12: #NAME? | K12: #NAME? | L12: #NAME? | M12: #NAME? | N12: #NAME? | O12: #NAME? | P12: #NAME? | Q12: #NAME? | R12: #NAME? | S12: #NAME? | T12: #NAME? | U12: #NAME? | V12: #NAME? | W12: #NAME? | X12: #NAME? | Y12: #NAME? | Z12: #NAME? | AA12: #NAME? | AB12: #NAME? | AC12: #NAME? | AD12: #NAME? | AE12: #NAME? | AF12: #NAME? | AG12: #NAME? | AH12: #NAME? | AI12: #NAME? | AJ12: #NAME?
A13: #NAME? | B13: #NAME? | C13: #NAME? | D13: #NAME? | E13: #NAME? | F13: #NAME? | G13: #NAME? | H13: #NAME? | I13: #NAME? | J13: #NAME? | K13: #NAME? | L13: #NAME? | M13: #NAME? | N13: #NAME? | O13: #NAME? | P13: #NAME? | Q13: #NAME? | R13: #NAME? | S13: #NAME? | T13: #NAME? | U13: #NAME? | V13: #NAME? | W13: #NAME? | X13: #NAME? | Y13: #NAME? | Z13: #NAME? | AA13: #NAME? | AB13: #NAME? | AC13: #NAME? | AD13: #NAME? | AE13: #NAME? | AF13: #NAME? | AG13: #NAME? | AH13: #NAME? | AI13: #NAME? | AJ13: #NAME?
A14: #NAME? | B14: #NAME? | C14: #NAME? | D14: #NAME? | E14: #NAME? | F14: #NAME? | G14: #NAME? | H14: #NAME? | I14: #NAME? | J14: #NAME? | K14: #NAME? | L14: #NAME? | M14: #NAME? | N14: #NAME? | O14: #NAME? | P14: #NAME? | Q14: #NAME? | R14: #NAME? | S14: #NAME? | T14: #NAME? | U14: #NAME? | V14: #NAME? | W14: #NAME? | X14: #NAME? | Y14: #NAME? | Z14: #NAME? | AA14: #NAME? | AB14: #NAME? | AC14: #NAME? | AD14: #NAME? | AE14: #NAME? | AF14: #NAME? | AG14: #NAME? | AH14: #NAME? | AI14: #NAME? | AJ14: #NAME?
... A20: #NAME? | B20: #NAME? | C20: #NAME? | D20: #NAME? | E20: #NAME? | F20: #NAME? | G20: #NAME? | H20: #NAME? | I20: #NAME? | J20: #NAME? | K20: #NAME? | L20: #NAME? | M20: #NAME? | N20: #NAME? | O20: #NAME? | P20: #NAME? | Q20: #NAME? | R20: #NAME? | S20: #NAME? | T20: #NAME? | U20: #NAME? | V20: #NAME? | W20: #NAME? | X20: #NAME? | Y20: #NAME? | Z20: #NAME? | AA20: #NAME? | AB20: #NAME? | AC20: #NAME? | AD20: #NAME? | AE20: #NAME? | AF20: #NAME? | AG20: #NAME? | AH20: #NAME? | AI20: #NAME? | AJ20: #NAME?
S21: #NAME? | T21: #NAME? | U21: #NAME? | V21: #NAME? | W21: #NAME? | X21: #NAME? | Y21: #NAME? | Z21: #NAME? | AA21: #NAME? | AB21: #NAME? | AC21: #NAME? | AD21: #NAME? | AE21: #NAME? | AF21: #NAME? | AG21: #NAME? | AH21: #NAME? | AI21: #NAME? | AJ21: #NAME?
S22: #NAME? | T22: #NAME? | U22: #NAME? | V22: #NAME? | W22: #NAME? | X22: #NAME? | Y22: #NAME? | Z22: #NAME? | AA22: #NAME? | AB22: #NAME? | AC22: #NAME? | AD22: #NAME? | AE22: #NAME? | AF22: #NAME? | AG22: #NAME? | AH22: #NAME? | AI22: #NAME? | AJ22: #NAME?
S23: #NAME? | T23: #NAME? | U23: #NAME? | V23: #NAME? | W23: #NAME? | X23: #NAME? | Y23: #NAME? | Z23: #NAME? | AA23: #NAME? | AB23: #NAME? | AC23: #NAME? | AD23: #NAME? | AE23: #NAME? | AF23: #NAME? | AG23: #NAME? | AH23: #NAME? | AI23: #NAME? | AJ23: #NAME?
S24: #NAME? | T24: #NAME? | U24: #NAME? | V24: #NAME? | W24: #NAME? | X24: #NAME? | Y24: #NAME? | Z24: #NAME? | AA24: #NAME? | AB24: #NAME? | AC24: #NAME? | AD24: #NAME? | AE24: #NAME? | AF24: #NAME? | AG24: #NAME? | AH24: #NAME? | AI24: #NAME? | AJ24: #NAME?
S25: #NAME? | T25: #NAME? | U25: #NAME? | V25: #NAME? | W25: #NAME? | X25: #NAME? | Y25: #NAME? | Z25: #NAME? | AA25: #NAME? | AB25: #NAME? | AC25: #NAME? | AD25: #NAME? | AE25: #NAME? | AF25: #NAME? | AG25: #NAME? | AH25: #NAME? | AI25: #NAME? | AJ25: #NAME?
S26: #NAME? | T26: #NAME? | U26: #NAME? | V26: #NAME? | W26: #NAME? | X26: #NAME? | Y26: #NAME? | Z26: #NAME? | AA26: #NAME? | AB26: #NAME? | AC26: #NAME? | AD26: #NAME? | AE26: #NAME? | AF26: #NAME? | AG26: #NAME? | AH26: #NAME? | AI26: #NAME? | AJ26: #NAME?
S27: #NAME? | T27: #NAME? | U27: #NAME? | V27: #NAME? | W27: #NAME? | X27: #NAME? | Y27: #NAME? | Z27: #NAME? | AA27: #NAME? | AB27: #NAME? | AC27: #NAME? | AD27: #NAME? | AE27: #NAME? | AF27: #NAME? | AG27: #NAME? | AH27: #NAME? | AI27: #NAME? | AJ27: #NAME?
S28: #NAME? | T28: #NAME? | U28: #NAME? | V28: #NAME? | W28: #NAME? | X28: #NAME? | Y28: #NAME? | Z28: #NAME? | AA28: #NAME? | AB28: #NAME? | AC28: #NAME? | AD28: #NAME? | AE28: #NAME? | AF28: #NAME? | AG28: #NAME? | AH28: #NAME? | AI28: #NAME? | AJ28: #NAME?
S29: #NAME? | T29: #NAME? | U29: #NAME? | V29: #NAME? | W29: #NAME? | X29: #NAME? | Y29: #NAME? | Z29: #NAME? | AA29: #NAME? | AB29: #NAME? | AC29: #NAME? | AD29: #NAME? | AE29: #NAME? | AF29: #NAME? | AG29: #NAME? | AH29: #NAME? | AI29: #NAME? | AJ29: #NAME?
S30: #NAME? | T30: #NAME? | U30: #NAME? | V30: #NAME? | W30: #NAME? | X30: #NAME? | Y30: #NAME? | Z30: #NAME? | AA30: #NAME? | AB30: #NAME? | AC30: #NAME? | AD30: #NAME? | AE30: #NAME? | AF30: #NAME? | AG30: #NAME? | AH30: #NAME? | AI30: #NAME? | AJ30: #NAME?
S31: #NAME? | T31: #NAME? | U31: #NAME? | V31: #NAME? | W31: #NAME? | X31: #NAME? | Y31: #NAME? | Z31: #NAME? | AA31: #NAME? | AB31: #NAME? | AC31: #NAME? | AD31: #NAME? | AE31: #NAME? | AF31: #NAME? | AG31: #NAME? | AH31: #NAME? | AI31: #NAME? | AJ31: #NAME?
S32: #NAME? | T32: #NAME? | U32: #NAME? | V32: #NAME? | W32: #NAME? | X32: #NAME? | Y32: #NAME? | Z32: #NAME? | AA32: #NAME? | AB32: #NAME? | AC32: #NAME? | AD32: #NAME? | AE32: #NAME? | AF32: #NAME? | AG32: #NAME? | AH32: #NAME? | AI32: #NAME? | AJ32: #NAME?
S33: #NAME? | T33: #NAME? | U33: #NAME? | V33: #NAME? | W33: #NAME? | X33: #NAME? | Y33: #NAME? | Z33: #NAME? | AA33: #NAME? | AB33: #NAME? | AC33: #NAME? | AD33: #NAME? | AE33: #NAME? | AF33: #NAME?
S34: #NAME? | T34: #NAME? | U34: #NAME? | V34: #NAME? | W34: #NAME? | X34: #NAME? | Y34: #NAME? | Z34: #NAME? | AA34: #NAME? | AB34: #NAME? | AC34: #NAME? | AD34: #NAME? | AE34: #NAME? | AF34: #NAME?
S35: #NAME? | T35: #NAME? | U35: #NAME? | V35: #NAME? | W35: #NAME? | X35: #NAME? | Y35: #NAME? | Z35: #NAME? | AA35: #NAME? | AB35: #NAME? | AC35: #NAME? | AD35: #NAME? | AE35: #NAME? | AF35: #NAME?
S36: #NAME? | T36: #NAME? | U36: #NAME? | V36: #NAME? | W36: #NAME? | X36: #NAME? | Y36: #NAME? | Z36: #NAME? | AA36: #NAME? | AB36: #NAME? | AC36: #NAME? | AD36: #NAME? | AE36: #NAME? | AF36: #NAME?
S37: #NAME? | T37: #NAME? | U37: #NAME? | V37: #NAME? | W37: #NAME? | X37: #NAME? | Y37: #NAME? | Z37: #NAME? | AA37: #NAME? | AB37: #NAME? | AC37: #NAME? | AD37: #NAME? | AE37: #NAME? | AF37: #NAME?
S38: #NAME? | T38: #NAME? | U38: #NAME? | V38: #NAME? | W38: #NAME? | X38: #NAME? | Y38: #NAME? | Z38: #NAME? | AA38: #NAME? | AB38: #NAME? | AC38: #NAME? | AD38: #NAME? | AE38: #NAME? | AF38: #NAME?
S39: #NAME? | T39: #NAME? | U39: #NAME? | V39: #NAME? | W39: #NAME? | X39: #NAME? | Y39: #NAME? | Z39: #NAME? | AA39: #NAME? | AB39: #NAME? | AC39: #NAME? | AD39: #NAME? | AE39: #NAME? | AF39: #NAME?
S40: #NAME? | T40: #NAME? | U40: #NAME? | V40: #NAME? | W40: #NAME? | X40: #NAME? | Y40: #NAME? | Z40: #NAME? | AA40: #NAME? | AB40: #NAME? | AC40: #NAME? | AD40: #NAME? | AE40: #NAME? | AF40: #NAME?
S41: #NAME? | T41: #NAME? | U41: #NAME? | V41: #NAME? | W41: #NAME? | X41: #NAME? | Y41: #NAME? | Z41: #NAME? | AA41: #NAME? | AB41: #NAME? | AC41: #NAME? | AD41: #NAME? | AE41: #NAME? | AF41: #NAME?
S42: #NAME? | T42: #NAME? | U42: #NAME? | V42: #NAME? | W42: #NAME? | X42: #NAME? | Y42: #NAME? | Z42: #NAME? | AA42: #NAME? | AB42: #NAME? | AC42: #NAME? | AD42: #NAME? | AE42: #NAME? | AF42: #NAME?
S43: #NAME? | T43: #NAME? | U43: #NAME? | V43: #NAME? | W43: #NAME? | X43: #NAME? | Y43: #NAME? | Z43: #NAME? | AA43: #NAME? | AB43: #NAME? | AC43: #NAME? | AD43: #NAME? | AE43: #NAME? | AF43: #NAME?
S44: #NAME? | T44: #NAME? | U44: #NAME? | V44: #NAME? | W44: #NAME? | X44: #NAME? | Y44: #NAME? | Z44: #NAME? | AA44: #NAME? | AB44: #NAME? | AC44: #NAME? | AD44: #NAME? | AE44: #NAME? | AF44: #NAME?
... S442: #NAME? | T442: #NAME? | U442: #NAME? | V442: #NAME? | W442: #NAME? | X442: #NAME? | Y442: #NAME? | Z442: #NAME? | AA442: #NAME? | AB442: #NAME? | AC442: #NAME? | AD442: #NAME? | AE442: #NAME? | AF442: #NAME?
...

Sheet East
B1: ACE.Profile.1 | D1: ACE.Profile.2 | F1: ACE.Profile.3 | H1: ACE.Profile.4 | J1: ACE.Profile.5 | L1: ACE.Profile.6 | N1: ACE.Profile.7 | P1: ACE.Profile.8 | R1: ACE.Profile.9 | T1: FeedBatch.Port1.tot | V1: FeedBatch.Port2.tot | X1: FeedBatch.Port3.tot | Z1: FeedBatch.Port4.tot | AB1: FeedBatch.Port5.tot | AD1: FeedBatch.Port6.tot | AF1: FeedBatch.Port7.tot | AH1: FeedBatch.Port8.tot | AJ1: FeedBatch.Port9.tot
A2: 45089.25 | B2: 7.5768528 | C2: 45089.25 | D2: 8.1603928 | E2: 45089.25 | F2: 17.758892 | G2: 45089.25 | H2: 16.240957 | I2: 45089.25 | J2: 16.822083 | K2: 45089.25 | L2: 14.630309 | M2: 45089.25 | N2: 18.810513 | O2: 45089.25 | P2: 0 | Q2: 45089.25 | R2: 0 | S2: 45088.667 | T2: 25.734657 | U2: 45088.667 | V2: 30.38324 | W2: 45088.667 | X2: 169.92992 | Y2: 45088.667 | Z2: 60.027657 | AA2: 45088.667 | AB2: 65.208252 | AC2: 45088.667 | AD2: 55.193657 | AE2: 45088.674 | AF2: 70.313614 | AG2: 45088.924 | AH2: 0 | AI2: 45088.875 | AJ2: 0
A3: 45089.25 | B3: 9.401124 | C3: 45089.25 | D3: 8.0728493 | E3: 45089.25 | F3: 16.874994 | G3: 45089.25 | H3: 17.43726 | I3: 45089.25 | J3: 14.88307 | K3: 45089.25 | L3: 14.169609 | M3: 45089.25 | N3: 19.161093 | O3: 45089.25 | P3: 0 | Q3: 45089.25 | R3: 0 | S3: 45088.688 | T3: 27.281174 | U3: 45088.688 | V3: 31.708351 | W3: 45088.688 | X3: 168.418 | Y3: 45088.688 | Z3: 61.964111 | AA3: 45088.688 | AB3: 67.524376 | AC3: 45088.688 | AD3: 56.633911 | AE3: 45088.694 | AF3: 72.411919 | AG3: 45089.257 | AH3: 0 | AI3: 45089.208 | AJ3: 0
A4: 45090.25 | B4: 9.401124 | C4: 45090.25 | D4: 8.0728493 | E4: 45090.25 | F4: 16.874994 | G4: 45090.25 | H4: 17.43726 | I4: 45090.25 | J4: 14.88307 | K4: 45090.25 | L4: 14.169609 | M4: 45090.25 | N4: 19.161093 | O4: 45090.25 | P4: 0 | Q4: 45090.25 | R4: 0 | S4: 45088.729 | T4: 29.438828 | U4: 45088.708 | V4: 32.749397 | W4: 45088.729 | X4: 163.79945 | Y4: 45088.708 | Z4: 63.971031 | AA4: 45088.708 | AB4: 69.740784 | AC4: 45088.708 | AD4: 58.554092 | AE4: 45088.708 | AF4: 75.015831 | AG4: 45089.59 | AH4: 0 | AI4: 45089.542 | AJ4: 0
A5: 45090.25 | B5: 8.3439779 | C5: 45090.25 | D5: 7.3935189 | E5: 45090.25 | F5: 16.866995 | G5: 45090.25 | H5: 16.114475 | I5: 45090.25 | J5: 16.147541 | K5: 45090.25 | L5: 15.597409 | M5: 45090.25 | N5: 19.536083 | O5: 45090.25 | P5: 0 | Q5: 45090.25 | R5: 0 | S5: 45088.771 | T5: 31.114929 | U5: 45088.729 | V5: 33.707153 | W5: 45088.75 | X5: 161.4491 | Y5: 45088.729 | Z5: 65.961121 | AA5: 45088.729 | AB5: 71.63353 | AC5: 45088.729 | AD5: 60.680099 | AE5: 45088.736 | AF5: 77.50882 | AG5: 45089.924 | AH5: 0 | AI5: 45089.875 | AJ5: 0
A6: 45091.25 | B6: 8.3439779 | C6: 45091.25 | D6: 7.3935189 | E6: 45091.25 | F6: 16.866995 | G6: 45091.25 | H6: 16.114475 | I6: 45091.25 | J6: 16.147541 | K6: 45091.25 | L6: 15.597409 | M6: 45091.25 | N6: 19.536083 | O6: 45091.25 | P6: 0 | Q6: 45091.25 | R6: 0 | S6: 45088.792 | T6: 32.246307 | U6: 45088.771 | V6: 35.976212 | W6: 45088.771 | X6: 160.0817 | Y6: 45088.75 | Z6: 68.307037 | AA6: 45088.75 | AB6: 74.042435 | AC6: 45088.75 | AD6: 62.164948 | AE6: 45088.75 | AF6: 80.09201 | AG6: 45090.257 | AH6: 0 | AI6: 45090.208 | AJ6: 0
A7: 45091.25 | B7: 7.222846 | C7: 45091.25 | D7: 9.1056843 | E7: 45091.25 | F7: 16.115328 | G7: 45091.25 | H7: 16.794268 | I7: 45091.25 | J7: 15.391739 | K7: 45091.25 | L7: 15.99353 | M7: 45091.25 | N7: 19.376606 | O7: 45091.25 | P7: 0 | Q7: 45091.25 | R7: 0 | S7: 45088.833 | T7: 34.736168 | U7: 45088.792 | V7: 36.668365 | W7: 45088.792 | X7: 158.46609 | Y7: 45088.771 | Z7: 69.896614 | AA7: 45088.771 | AB7: 75.849449 | AC7: 45088.771 | AD7: 63.573898 | AE7: 45088.778 | AF7: 82.15435 | AG7: 45090.59 | AH7: 0 | AI7: 45090.542 | AJ7: 0
A8: 45092.25 | B8: 7.222846 | C8: 45092.25 | D8: 9.1056843 | E8: 45092.25 | F8: 16.115328 | G8: 45092.25 | H8: 16.794268 | I8: 45092.25 | J8: 15.391739 | K8: 45092.25 | L8: 15.99353 | M8: 45092.25 | N8: 19.376606 | O8: 45092.25 | P8: 0 | Q8: 45092.25 | R8: 0 | S8: 45088.854 | T8: 36.635017 | U8: 45088.812 | V8: 37.742325 | W8: 45088.812 | X8: 155.63614 | Y8: 45088.792 | Z8: 71.805595 | AA8: 45088.792 | AB8: 78.335686 | AC8: 45088.792 | AD8: 65.650864 | AE8: 45088.792 | AF8: 84.009254 | AG8: 45090.924 | AH8: 0 | AI8: 45090.875 | AJ8: 0
A9: 45092.25 | B9: 7.810451 | C9: 45092.25 | D9: 8.1113253 | E9: 45092.25 | F9: 17.184971 | G9: 45092.25 | H9: 17.19515 | I9: 45092.25 | J9: 16.590179 | K9: 45092.25 | L9: 14.690483 | M9: 45092.25 | N9: 18.41744 | O9: 45092.25 | P9: 0 | Q9: 45092.25 | R9: 0 | S9: 45088.875 | T9: 38.093391 | U9: 45088.833 | V9: 39.55381 | W9: 45088.833 | X9: 155.11165 | Y9: 45088.812 | Z9: 74.117172 | AA9: 45088.812 | AB9: 80.126709 | AC9: 45088.812 | AD9: 67.220657 | AE9: 45088.799 | AF9: 84.52478 | AG9: 45091.257 | AH9: 0 | AI9: 45091.208 | AJ9: 0
A10: 45093.25 | B10: 7.810451 | C10: 45093.25 | D10: 8.1113253 | E10: 45093.25 | F10: 17.184971 | G10: 45093.25 | H10: 17.19515 | I10: 45093.25 | J10: 16.590179 | K10: 45093.25 | L10: 14.690483 | M10: 45093.25 | N10: 18.41744 | O10: 45093.25 | P10: 0 | Q10: 45093.25 | R10: 0 | S10: 45088.896 | T10: 39.962807 | U10: 45088.854 | V10: 41.726723 | W10: 45089.021 | X10: 155.78308 | Y10: 45088.833 | Z10: 76.932579 | AA10: 45088.833 | AB10: 82.985497 | AC10: 45088.84 | AD10: 70.182854 | AE10: 45088.812 | AF10: 85.85508 | AG10: 45091.59 | AH10: 0 | AI10: 45091.542 | AJ10: 0
A11: 45093.25 | B11: 8.2263784 | C11: 45093.25 | D11: 8.3583841 | E11: 45093.25 | F11: 16.690279 | G11: 45093.25 | H11: 16.241983 | I11: 45093.25 | J11: 16.5874 | K11: 45093.25 | L11: 14.351972 | M11: 45093.25 | N11: 19.543604 | O11: 45093.25 | P11: 0 | Q11: 45093.25 | R11: 0 | S11: 45088.917 | T11: 41.826927 | U11: 45088.875 | V11: 43.010689 | W11: 45089.042 | X11: 159.26721 | Y11: 45088.854 | Z11: 80.821213 | AA11: 45088.854 | AB11: 85.034561 | AC11: 45088.861 | AD11: 73.717331 | AE11: 45088.819 | AF11: 87.045227 | AG11: 45091.924 | AH11: 0 | AI11: 45091.875 | AJ11: 0
A12: 45094.25 | B12: 8.2263784 | C12: 45094.25 | D12: 8.3583841 | E12: 45094.25 | F12: 16.690279 | G12: 45094.25 | H12: 16.241983 | I12: 45094.25 | J12: 16.5874 | K12: 45094.25 | L12: 14.351972 | M12: 45094.25 | N12: 19.543604 | O12: 45094.25 | P12: 0 | Q12: 45094.25 | R12: 0 | S12: 45088.938 | T12: 43.555405 | U12: 45088.896 | V12: 44.748306 | W12: 45089.062 | X12: 158.49062 | Y12: 45088.875 | Z12: 84.736877 | AA12: 45088.861 | AB12: 86.69529 | AC12: 45088.882 | AD12: 77.232185 | AE12: 45088.84 | AF12: 90.378647 | AG12: 45092.257 | AH12: 0 | AI12: 45092.208 | AJ12: 0
A13: 45094.25 | B13: 8.5566425 | C13: 45094.25 | D13: 7.7938814 | E13: 45094.25 | F13: 17.828072 | G13: 45094.25 | H13: 16.118006 | I13: 45094.25 | J13: 17.245636 | K13: 45094.25 | L13: 14.470352 | M13: 45094.25 | N13: 17.98741 | O13: 45094.25 | P13: 0 | Q13: 45094.25 | R13: 0 | S13: 45088.958 | T13: 45.178841 | U13: 45088.917 | V13: 46.716637 | W13: 45089.132 | X13: 157.35977 | Y13: 45088.896 | Z13: 88.512329 | AA13: 45088.875 | AB13: 89.755577 | AC13: 45088.903 | AD13: 80.411926 | AE13: 45088.861 | AF13: 94.931831 | AG13: 45092.59 | AH13: 0 | AI13: 45092.542 | AJ13: 0
... A20: 45098.25 | B20: 5.5695691 | C20: 45098.25 | D20: 7.7737212 | E20: 45098.25 | F20: 31.874147 | G20: 45098.25 | H20: 14.150042 | I20: 45098.25 | J20: 13.412466 | K20: 45098.25 | L20: 11.146185 | M20: 45098.25 | N20: 16.07387 | O20: 45098.25 | P20: 0 | Q20: 45098.25 | R20: 0 | S20: 45089.104 | T20: 58.164375 | U20: 45089.062 | V20: 59.779266 | W20: 45089.194 | X20: 155.82608 | Y20: 45089.042 | Z20: 114.76258 | AA20: 45088.944 | AB20: 100.70251 | AC20: 45089.049 | AD20: 103.51598 | AE20: 45089.007 | AF20: 124.77313 | AG20: 45094.924 | AH20: 0 | AI20: 45094.875 | AJ20: 0
S21: 45089.125 | T21: 60.256081 | U21: 45089.083 | V21: 61.57193 | W21: 45089.201 | X21: 155.15646 | Y21: 45089.062 | Z21: 118.72266 | AA21: 45088.958 | AB21: 104.48778 | AC21: 45089.069 | AD21: 106.95818 | AE21: 45089.028 | AF21: 128.92978 | AG21: 45095.257 | AH21: 0 | AI21: 45095.208 | AJ21: 0
S22: 45089.146 | T22: 62.150558 | U22: 45089.104 | V22: 63.509171 | W22: 45089.208 | X22: 159.09698 | Y22: 45089.083 | Z22: 122.83382 | AA22: 45088.979 | AB22: 108.27287 | AC22: 45089.09 | AD22: 110.26116 | AE22: 45089.049 | AF22: 133.40732 | AG22: 45095.59 | AH22: 0 | AI22: 45095.542 | AJ22: 0
S23: 45089.167 | T23: 64.091904 | U23: 45089.125 | V23: 65.641266 | W23: 45089.215 | X23: 155.97809 | Y23: 45089.104 | Z23: 126.49315 | AA23: 45089 | AB23: 110.34674 | AC23: 45089.111 | AD23: 113.66395 | AE23: 45089.069 | AF23: 137.70477 | AG23: 45095.924 | AH23: 0 | AI23: 45095.875 | AJ23: 0
S24: 45089.188 | T24: 65.875793 | U24: 45089.146 | V24: 67.357857 | W24: 45089.222 | X24: 155.12524 | Y24: 45089.125 | Z24: 130.30386 | AA24: 45089.007 | AB24: 112.78532 | AC24: 45089.132 | AD24: 117.18963 | AE24: 45089.09 | AF24: 142.01755 | AG24: 45096.257 | AH24: 0 | AI24: 45096.208 | AJ24: 0
S25: 45089.208 | T25: 67.878922 | U25: 45089.167 | V25: 69.247505 | W25: 45089.229 | X25: 158.90274 | Y25: 45089.146 | Z25: 134.28555 | AA25: 45089.021 | AB25: 113.40164 | AC25: 45089.153 | AD25: 121.00259 | AE25: 45089.111 | AF25: 146.603 | AG25: 45096.59 | AH25: 0 | AI25: 45096.542 | AJ25: 0
S26: 45089.229 | T26: 69.799721 | U26: 45089.188 | V26: 71.209763 | W26: 45089.236 | X26: 155.68483 | Y26: 45089.167 | Z26: 137.9509 | AA26: 45089.028 | AB26: 116.69953 | AC26: 45089.174 | AD26: 124.16292 | AE26: 45089.132 | AF26: 151.18919 | AG26: 45096.924 | AH26: 0 | AI26: 45096.875 | AJ26: 0
S27: 45089.25 | T27: 71.426552 | U27: 45089.208 | V27: 73.106697 | W27: 45089.25 | X27: 159.29874 | Y27: 45089.188 | Z27: 141.86076 | AA27: 45089.042 | AB27: 118.46558 | AC27: 45089.194 | AD27: 127.75669 | AE27: 45089.153 | AF27: 155.26181 | AG27: 45097.257 | AH27: 0 | AI27: 45097.208 | AJ27: 0
S28: 45089.257 | T28: 0 | U28: 45089.229 | V28: 75.295601 | W28: 45089.257 | X28: 155.51929 | Y28: 45089.208 | Z28: 145.49823 | AA28: 45089.049 | AB28: 120.03766 | AC28: 45089.215 | AD28: 131.06888 | AE28: 45089.174 | AF28: 159.73727 | AG28: 45097.59 | AH28: 0 | AI28: 45097.542 | AJ28: 0
S29: 45089.271 | T29: 2.0051575 | U29: 45089.25 | V29: 77.232307 | W29: 45089.271 | X29: 159.68869 | Y29: 45089.229 | Z29: 149.49055 | AA29: 45089.062 | AB29: 122.26784 | AC29: 45089.236 | AD29: 134.6315 | AE29: 45089.194 | AF29: 164.30521 | AG29: 45097.924 | AH29: 0 | AI29: 45097.875 | AJ29: 0
S30: 45089.306 | T30: 3.6118622 | U30: 45089.257 | V30: 0 | W30: 45089.278 | X30: 156.80722 | Y30: 45089.25 | Z30: 153.28027 | AA30: 45089.069 | AB30: 124.34322 | AC30: 45089.257 | AD30: 3.2472839 | AE30: 45089.215 | AF30: 168.51816 | AG30: 45098.257 | AH30: 0 | AI30: 45098.208 | AJ30: 0
S31: 45089.312 | T31: 4.9710541 | U31: 45089.271 | V31: 1.7714539 | W31: 45089.285 | X31: 155.46091 | Y31: 45089.257 | Z31: 0 | AA31: 45089.09 | AB31: 128.0112 | AC31: 45089.278 | AD31: 6.9211349 | AE31: 45089.236 | AF31: 173.21613 | AG31: 45098.59 | AH31: 0 | AI31: 45098.542 | AJ31: 0
S32: 45089.326 | T32: 6.503891 | U32: 45089.312 | V32: 4.8921356 | W32: 45089.299 | X32: 152.12305 | Y32: 45089.271 | Z32: 3.8026962 | AA32: 45089.104 | AB32: 129.03552 | AC32: 45089.312 | AD32: 11.04689 | AE32: 45089.257 | AF32: 3.9235153 | AG32: 45098.653 | AH32: 0 | AI32: 45098.653 | AJ32: 0
S33: 45089.347 | T33: 7.8254547 | U33: 45089.333 | V33: 6.7294006 | W33: 45089.312 | X33: 157.46841 | Y33: 45089.312 | Z33: 8.8644257 | AA33: 45089.111 | AB33: 132.08344 | AC33: 45089.333 | AD33: 14.855713 | AE33: 45089.278 | AF33: 8.4753494
S34: 45089.354 | T34: 8.641449 | U34: 45089.354 | V34: 8.3444214 | W34: 45089.319 | X34: 153.94312 | Y34: 45089.333 | Z34: 13.035278 | AA34: 45089.125 | AB34: 134.58347 | AC34: 45089.354 | AD34: 18.218735 | AE34: 45089.312 | AF34: 13.76503
S35: 45089.368 | T35: 10.261795 | U35: 45089.375 | V35: 10.144043 | W35: 45089.333 | X35: 156.81541 | Y35: 45089.354 | Z35: 16.317123 | AA35: 45089.132 | AB35: 135.44861 | AC35: 45089.375 | AD35: 21.425987 | AE35: 45089.333 | AF35: 18.012199
S36: 45089.389 | T36: 12.02417 | U36: 45089.396 | V36: 11.995178 | W36: 45089.34 | X36: 153.11177 | Y36: 45089.375 | Z36: 20.243454 | AA36: 45089.146 | AB36: 137.57309 | AC36: 45089.396 | AD36: 24.527832 | AE36: 45089.354 | AF36: 22.115654
S37: 45089.417 | T37: 14.40773 | U37: 45089.417 | V37: 13.779129 | W37: 45089.354 | X37: 157.00699 | Y37: 45089.396 | Z37: 23.914597 | AA37: 45089.153 | AB37: 139.21857 | AC37: 45089.424 | AD37: 28.109291 | AE37: 45089.375 | AF37: 27.007156
S38: 45089.438 | T38: 16.183273 | U38: 45089.438 | V38: 15.637848 | W38: 45089.361 | X38: 153.45255 | Y38: 45089.417 | Z38: 27.750969 | AA38: 45089.167 | AB38: 139.95261 | AC38: 45089.444 | AD38: 31.618423 | AE38: 45089.396 | AF38: 31.166985
S39: 45089.458 | T39: 18.121933 | U39: 45089.472 | V39: 18.748718 | W39: 45089.375 | X39: 157.30571 | Y39: 45089.438 | Z39: 31.61039 | AA39: 45089.174 | AB39: 143.26645 | AC39: 45089.479 | AD39: 36.125771 | AE39: 45089.424 | AF39: 35.734177
S40: 45089.472 | T40: 24.813576 | U40: 45089.493 | V40: 23.723862 | W40: 45089.382 | X40: 154.06415 | Y40: 45089.479 | Z40: 37.717102 | AA40: 45089.188 | AB40: 144.85666 | AC40: 45089.5 | AD40: 39.323029 | AE40: 45089.444 | AF40: 40.266579
S41: 45089.493 | T41: 32.387291 | U41: 45089.514 | V41: 26.470459 | W41: 45089.396 | X41: 157.86987 | Y41: 45089.493 | Z41: 40.831406 | AA41: 45089.194 | AB41: 146.73386 | AC41: 45089.521 | AD41: 41.210014 | AE41: 45089.479 | AF41: 45.584572
S42: 45089.535 | T42: 39.823662 | U42: 45089.535 | V42: 28.704178 | W42: 45089.403 | X42: 154.38333 | Y42: 45089.5 | Z42: 54.635757 | AA42: 45089.208 | AB42: 149.61476 | AC42: 45089.542 | AD42: 44.813217 | AE42: 45089.5 | AF42: 49.071297
S43: 45089.556 | T43: 44.020844 | U43: 45089.556 | V43: 29.90271 | W43: 45089.417 | X43: 158.01994 | Y43: 45089.514 | Z43: 61.318489 | AA43: 45089.215 | AB43: 150.70438 | AC43: 45089.562 | AD43: 51.945732 | AE43: 45089.521 | AF43: 53.635818
S44: 45089.576 | T44: 47.379623 | U44: 45089.576 | V44: 39.228218 | W44: 45089.424 | X44: 155.10706 | Y44: 45089.521 | Z44: 63.221375 | AA44: 45089.229 | AB44: 152.9924 | AC44: 45089.583 | AD44: 61.166168 | AE44: 45089.542 | AF44: 59.075302
... S442: 45098.528 | T442: 16.914009 | U442: 45098.653 | V442: 42.048363 | W442: 45095.312 | X442: 184.6797 | Y442: 45097.632 | Z442: 61.153389 | AA442: 45097.736 | AB442: 79.474525 | AC442: 45098.104 | AD442: 105.32981 | AE442: 45097.993 | AF442: 120.60659
S443: 45098.542 | T443: 19.992691 | W443: 45095.319 | X443: 181.3445 | Y443: 45097.653 | Z443: 64.914513 | AA443: 45097.757 | AB443: 82.834618 | AC443: 45098.118 | AD443: 106.46818 | AE443: 45098 | AF443: 122.32214
...

Sheet Sheet2
B1: \\polsmes\POLSPI_MDB\AISPOLSPI01 ModuleDB\POLS Smelter\Furnace 1\Feed\Feed Profile\West|ACE.Profile.1 | D1: \\polsmes\POLSPI_MDB\AISPOLSPI01 ModuleDB\POLS Smelter\Furnace 1\Feed\Feed Profile\West|ACE.Profile.2 | F1: \\polsmes\POLSPI_MDB\AISPOLSPI01 ModuleDB\POLS Smelter\Furnace 1\Feed\Feed Profile\West|ACE.Profile.3 | H1: \\polsmes\POLSPI_MDB\AISPOLSPI01 ModuleDB\POLS Smelter\Furnace 1\Feed\Feed Profile\West|ACE.Profile.4 | J1: \\polsmes\POLSPI_MDB\AISPOLSPI01 ModuleDB\POLS Smelter\Furnace 1\Feed\Feed Profile\West|ACE.Profile.5 | L1: \\polsmes\POLSPI_MDB\AISPOLSPI01 ModuleDB\POLS Smelter\Furnace 1\Feed\Feed Profile\West|ACE.Profile.6 | N1: \\polsmes\POLSPI_MDB\AISPOLSPI01 ModuleDB\POLS Smelter\Furnace 1\Feed\Feed Profile\West|ACE.Profile.7 | P1: \\polsmes\POLSPI_MDB\AISPOLSPI01 ModuleDB\POLS Smelter\Furnace 1\Feed\Feed Profile\West|ACE.Profile.8 | R1: \\polsmes\POLSPI_MDB\AISPOLSPI01 ModuleDB\POLS Smelter\Furnace 1\Feed\Feed Profile\West|ACE.Profile.9 | T1: \\polsmes\POLSPI_MDB\AISPOLSPI01 ModuleDB\POLS Smelter\Furnace 1\Feed\Feed Profile\West|FeedBatch.Port1.tot | V1: \\polsmes\POLSPI_MDB\AISPOLSPI01 ModuleDB\POLS Smelter\Furnace 1\Feed\Feed Profile\West|FeedBatch.Port2.tot | X1: \\polsmes\POLSPI_MDB\AISPOLSPI01 ModuleDB\POLS Smelter\Furnace 1\Feed\Feed Profile\West|FeedBatch.Port3.tot | Z1: \\polsmes\POLSPI_MDB\AISPOLSPI01 ModuleDB\POLS Smelter\Furnace 1\Feed\Feed Profile\West|FeedBatch.Port4.tot | AB1: \\polsmes\POLSPI_MDB\AISPOLSPI01 ModuleDB\POLS Smelter\Furnace 1\Feed\Feed Profile\West|FeedBatch.Port5.tot | AD1: \\polsmes\POLSPI_MDB\AISPOLSPI01 ModuleDB\POLS Smelter\Furnace 1\Feed\Feed Profile\West|FeedBatch.Port6.tot | AF1: \\polsmes\POLSPI_MDB\AISPOLSPI01 ModuleDB\POLS Smelter\Furnace 1\Feed\Feed Profile\West|FeedBatch.Port7.tot | AH1: \\polsmes\POLSPI_MDB\AISPOLSPI01 ModuleDB\POLS Smelter\Furnace 1\Feed\Feed Profile\West|FeedBatch.Port8.tot | AJ1: \\polsmes\POLSPI_MDB\AISPOLSPI01 ModuleDB\POLS Smelter\Furnace 1\Feed\Feed Profile\West|FeedBatch.Port9.tot
A2: {=_xll.PICompDat(Sheet2!$B$1,"*-11d","*-1d",9,"","inside")} -> #NAME? | B2: #NAME? | C2: {=_xll.PICompDat(Sheet2!$D$1,"*-11d","*-1d",9,"","inside")} -> #NAME? | D2: #NAME? | E2: {=_xll.PICompDat(Sheet2!$F$1,"*-11d","*-1d",9,"","inside")} -> #NAME? | F2: #NAME? | G2: {=_xll.PICompDat(Sheet2!$H$1,"*-11d","*-1d",9,"","inside")} -> #NAME? | H2: #NAME? | I2: {=_xll.PICompDat(Sheet2!$J$1,"*-11d","*-1d",9,"","inside")} -> #NAME? | J2: #NAME? | K2: {=_xll.PICompDat(Sheet2!$L$1,"*-11d","*-1d",9,"","inside")} -> #NAME? | L2: #NAME? | M2: {=_xll.PICompDat(Sheet2!$N$1,"*-11d","*-1d",9,"","inside")} -> #NAME? | N2: #NAME? | O2: {=_xll.PICompDat(Sheet2!$P$1,"*-11d","*-1d",9,"","inside")} -> #NAME? | P2: #NAME? | Q2: {=_xll.PICompDat(Sheet2!$R$1,"*-11d","*-1d",9,"","inside")} -> #NAME? | R2: #NAME? | S2: {=_xll.PICompDat(Sheet2!$T$1,"*-11d","*-1d",9,"","inside")} -> #NAME? | T2: #NAME? | U2: {=_xll.PICompDat(Sheet2!$V$1,"*-11d","*-1d",9,"","inside")} -> #NAME? | V2: #NAME? | W2: {=_xll.PICompDat(Sheet2!$X$1,"*-11d","*-1d",9,"","inside")} -> #NAME? | X2: #NAME? | Y2: {=_xll.PICompDat(Sheet2!$Z$1,"*-11d","*-1d",9,"","inside")} -> #NAME? | Z2: #NAME? | AA2: {=_xll.PICompDat(Sheet2!$AB$1,"*-11d","*-1d",9,"","inside")} -> #NAME? | AB2: #NAME? | AC2: {=_xll.PICompDat(Sheet2!$AD$1,"*-11d","*-1d",9,"","inside")} -> #NAME? | AD2: #NAME? | AE2: {=_xll.PICompDat(Sheet2!$AF$1,"*-11d","*-1d",9,"","inside")} -> #NAME? | AF2: #NAME? | AG2: {=_xll.PICompDat(Sheet2!$AH$1,"*-11d","*-1d",9,"","inside")} -> #NAME? | AH2: #NAME? | AI2: {=_xll.PICompDat(Sheet2!$AJ$1,"*-11d","*-1d",9,"","inside")} -> #NAME? | AJ2: #NAME?
A3: #NAME? | B3: #NAME? | C3: #NAME? | D3: #NAME? | E3: #NAME? | F3: #NAME? | G3: #NAME? | H3: #NAME? | I3: #NAME? | J3: #NAME? | K3: #NAME? | L3: #NAME? | M3: #NAME? | N3: #NAME? | O3: #NAME? | P3: #NAME? | Q3: #NAME? | R3: #NAME? | S3: #NAME? | T3: #NAME? | U3: #NAME? | V3: #NAME? | W3: #NAME? | X3: #NAME? | Y3: #NAME? | Z3: #NAME? | AA3: #NAME? | AB3: #NAME? | AC3: #NAME? | AD3: #NAME? | AE3: #NAME? | AF3: #NAME? | AG3: #NAME? | AH3: #NAME? | AI3: #NAME? | AJ3: #NAME?
A4: #NAME? | B4: #NAME? | C4: #NAME? | D4: #NAME? | E4: #NAME? | F4: #NAME? | G4: #NAME? | H4: #NAME? | I4: #NAME? | J4: #NAME? | K4: #NAME? | L4: #NAME? | M4: #NAME? | N4: #NAME? | O4: #NAME? | P4: #NAME? | Q4: #NAME? | R4: #NAME? | S4: #NAME? | T4: #NAME? | U4: #NAME? | V4: #NAME? | W4: #NAME? | X4: #NAME? | Y4: #NAME? | Z4: #NAME? | AA4: #NAME? | AB4: #NAME? | AC4: #NAME? | AD4: #NAME? | AE4: #NAME? | AF4: #NAME? | AG4: #NAME? | AH4: #NAME? | AI4: #NAME? | AJ4: #NAME?
A5: #NAME? | B5: #NAME? | C5: #NAME? | D5: #NAME? | E5: #NAME? | F5: #NAME? | G5: #NAME? | H5: #NAME? | I5: #NAME? | J5: #NAME? | K5: #NAME? | L5: #NAME? | M5: #NAME? | N5: #NAME? | O5: #NAME? | P5: #NAME? | Q5: #NAME? | R5: #NAME? | S5: #NAME? | T5: #NAME? | U5: #NAME? | V5: #NAME? | W5: #NAME? | X5: #NAME? | Y5: #NAME? | Z5: #NAME? | AA5: #NAME? | AB5: #NAME? | AC5: #NAME? | AD5: #NAME? | AE5: #NAME? | AF5: #NAME? | AG5: #NAME? | AH5: #NAME? | AI5: #NAME? | AJ5: #NAME?
A6: #NAME? | B6: #NAME? | C6: #NAME? | D6: #NAME? | E6: #NAME? | F6: #NAME? | G6: #NAME? | H6: #NAME? | I6: #NAME? | J6: #NAME? | K6: #NAME? | L6: #NAME? | M6: #NAME? | N6: #NAME? | O6: #NAME? | P6: #NAME? | Q6: #NAME? | R6: #NAME? | S6: #NAME? | T6: #NAME? | U6: #NAME? | V6: #NAME? | W6: #NAME? | X6: #NAME? | Y6: #NAME? | Z6: #NAME? | AA6: #NAME? | AB6: #NAME? | AC6: #NAME? | AD6: #NAME? | AE6: #NAME? | AF6: #NAME? | AG6: #NAME? | AH6: #NAME? | AI6: #NAME? | AJ6: #NAME?
A7: #NAME? | B7: #NAME? | C7: #NAME? | D7: #NAME? | E7: #NAME? | F7: #NAME? | G7: #NAME? | H7: #NAME? | I7: #NAME? | J7: #NAME? | K7: #NAME? | L7: #NAME? | M7: #NAME? | N7: #NAME? | O7: #NAME? | P7: #NAME? | Q7: #NAME? | R7: #NAME? | S7: #NAME? | T7: #NAME? | U7: #NAME? | V7: #NAME? | W7: #NAME? | X7: #NAME? | Y7: #NAME? | Z7: #NAME? | AA7: #NAME? | AB7: #NAME? | AC7: #NAME? | AD7: #NAME? | AE7: #NAME? | AF7: #NAME? | AG7: #NAME? | AH7: #NAME? | AI7: #NAME? | AJ7: #NAME?
A8: #NAME? | B8: #NAME? | C8: #NAME? | D8: #NAME? | E8: #NAME? | F8: #NAME? | G8: #NAME? | H8: #NAME? | I8: #NAME? | J8: #NAME? | K8: #NAME? | L8: #NAME? | M8: #NAME? | N8: #NAME? | O8: #NAME? | P8: #NAME? | Q8: #NAME? | R8: #NAME? | S8: #NAME? | T8: #NAME? | U8: #NAME? | V8: #NAME? | W8: #NAME? | X8: #NAME? | Y8: #NAME? | Z8: #NAME? | AA8: #NAME? | AB8: #NAME? | AC8: #NAME? | AD8: #NAME? | AE8: #NAME? | AF8: #NAME? | AG8: #NAME? | AH8: #NAME? | AI8: #NAME? | AJ8: #NAME?
A9: #NAME? | B9: #NAME? | C9: #NAME? | D9: #NAME? | E9: #NAME? | F9: #NAME? | G9: #NAME? | H9: #NAME? | I9: #NAME? | J9: #NAME? | K9: #NAME? | L9: #NAME? | M9: #NAME? | N9: #NAME? | O9: #NAME? | P9: #NAME? | Q9: #NAME? | R9: #NAME? | S9: #NAME? | T9: #NAME? | U9: #NAME? | V9: #NAME? | W9: #NAME? | X9: #NAME? | Y9: #NAME? | Z9: #NAME? | AA9: #NAME? | AB9: #NAME? | AC9: #NAME? | AD9: #NAME? | AE9: #NAME? | AF9: #NAME? | AG9: #NAME? | AH9: #NAME? | AI9: #NAME? | AJ9: #NAME?
A10: #NAME? | B10: #NAME? | C10: #NAME? | D10: #NAME? | E10: #NAME? | F10: #NAME? | G10: #NAME? | H10: #NAME? | I10: #NAME? | J10: #NAME? | K10: #NAME? | L10: #NAME? | M10: #NAME? | N10: #NAME? | O10: #NAME? | P10: #NAME? | Q10: #NAME? | R10: #NAME? | S10: #NAME? | T10: #NAME? | U10: #NAME? | V10: #NAME? | W10: #NAME? | X10: #NAME? | Y10: #NAME? | Z10: #NAME? | AA10: #NAME? | AB10: #NAME? | AC10: #NAME? | AD10: #NAME? | AE10: #NAME? | AF10: #NAME? | AG10: #NAME? | AH10: #NAME? | AI10: #NAME? | AJ10: #NAME?
A11: #NAME? | B11: #NAME? | C11: #NAME? | D11: #NAME? | E11: #NAME? | F11: #NAME? | G11: #NAME? | H11: #NAME? | I11: #NAME? | J11: #NAME? | K11: #NAME? | L11: #NAME? | M11: #NAME? | N11: #NAME? | O11: #NAME? | P11: #NAME? | Q11: #NAME? | R11: #NAME? | S11: #NAME? | T11: #NAME? | U11: #NAME? | V11: #NAME? | W11: #NAME? | X11: #NAME? | Y11: #NAME? | Z11: #NAME? | AA11: #NAME? | AB11: #NAME? | AC11: #NAME? | AD11: #NAME? | AE11: #NAME? | AF11: #NAME? | AG11: #NAME? | AH11: #NAME? | AI11: #NAME? | AJ11: #NAME?
A12: #NAME? | B12: #NAME? | C12: #NAME? | D12: #NAME? | E12: #NAME? | F12: #NAME? | G12: #NAME? | H12: #NAME? | I12: #NAME? | J12: #NAME? | K12: #NAME? | L12: #NAME? | M12: #NAME? | N12: #NAME? | O12: #NAME? | P12: #NAME? | Q12: #NAME? | R12: #NAME? | S12: #NAME? | T12: #NAME? | U12: #NAME? | V12: #NAME? | W12: #NAME? | X12: #NAME? | Y12: #NAME? | Z12: #NAME? | AA12: #NAME? | AB12: #NAME? | AC12: #NAME? | AD12: #NAME? | AE12: #NAME? | AF12: #NAME? | AG12: #NAME? | AH12: #NAME? | AI12: #NAME? | AJ12: #NAME?
A13: #NAME? | B13: #NAME? | C13: #NAME? | D13: #NAME? | E13: #NAME? | F13: #NAME? | G13: #NAME? | H13: #NAME? | I13: #NAME? | J13: #NAME? | K13: #NAME? | L13: #NAME? | M13: #NAME? | N13: #NAME? | O13: #NAME? | P13: #NAME? | Q13: #NAME? | R13: #NAME? | S13: #NAME? | T13: #NAME? | U13: #NAME? | V13: #NAME? | W13: #NAME? | X13: #NAME? | Y13: #NAME? | Z13: #NAME? | AA13: #NAME? | AB13: #NAME? | AC13: #NAME? | AD13: #NAME? | AE13: #NAME? | AF13: #NAME? | AG13: #NAME? | AH13: #NAME? | AI13: #NAME? | AJ13: #NAME?
A14: #NAME? | B14: #NAME? | C14: #NAME? | D14: #NAME? | E14: #NAME? | F14: #NAME? | G14: #NAME? | H14: #NAME? | I14: #NAME? | J14: #NAME? | K14: #NAME? | L14: #NAME? | M14: #NAME? | N14: #NAME? | O14: #NAME? | P14: #NAME? | Q14: #NAME? | R14: #NAME? | S14: #NAME? | T14: #NAME? | U14: #NAME? | V14: #NAME? | W14: #NAME? | X14: #NAME? | Y14: #NAME? | Z14: #NAME? | AA14: #NAME? | AB14: #NAME? | AC14: #NAME? | AD14: #NAME? | AE14: #NAME? | AF14: #NAME? | AG14: #NAME? | AH14: #NAME? | AI14: #NAME? | AJ14: #NAME?
... A21: #NAME? | B21: #NAME? | C21: #NAME? | D21: #NAME? | E21: #NAME? | F21: #NAME? | G21: #NAME? | H21: #NAME? | I21: #NAME? | J21: #NAME? | K21: #NAME? | L21: #NAME? | M21: #NAME? | N21: #NAME? | O21: #NAME? | P21: #NAME? | Q21: #NAME? | R21: #NAME? | S21: #NAME? | T21: #NAME? | U21: #NAME? | V21: #NAME? | W21: #NAME? | X21: #NAME? | Y21: #NAME? | Z21: #NAME? | AA21: #NAME? | AB21: #NAME? | AC21: #NAME? | AD21: #NAME? | AE21: #NAME? | AF21: #NAME? | AG21: #NAME? | AH21: #NAME? | AI21: #NAME? | AJ21: #NAME?
S22: #NAME? | T22: #NAME? | U22: #NAME? | V22: #NAME? | W22: #NAME? | X22: #NAME? | Y22: #NAME? | Z22: #NAME? | AA22: #NAME? | AB22: #NAME? | AC22: #NAME? | AD22: #NAME? | AE22: #NAME? | AF22: #NAME? | AG22: #NAME? | AH22: #NAME? | AI22: #NAME? | AJ22: #NAME?
S23: #NAME? | T23: #NAME? | U23: #NAME? | V23: #NAME? | W23: #NAME? | X23: #NAME? | Y23: #NAME? | Z23: #NAME? | AA23: #NAME? | AB23: #NAME? | AC23: #NAME? | AD23: #NAME? | AE23: #NAME? | AF23: #NAME? | AG23: #NAME? | AH23: #NAME? | AI23: #NAME? | AJ23: #NAME?
S24: #NAME? | T24: #NAME? | U24: #NAME? | V24: #NAME? | W24: #NAME? | X24: #NAME? | Y24: #NAME? | Z24: #NAME? | AA24: #NAME? | AB24: #NAME? | AC24: #NAME? | AD24: #NAME? | AE24: #NAME? | AF24: #NAME? | AG24: #NAME? | AH24: #NAME? | AI24: #NAME? | AJ24: #NAME?
S25: #NAME? | T25: #NAME? | U25: #NAME? | V25: #NAME? | W25: #NAME? | X25: #NAME? | Y25: #NAME? | Z25: #NAME? | AA25: #NAME? | AB25: #NAME? | AC25: #NAME? | AD25: #NAME? | AE25: #NAME? | AF25: #NAME? | AG25: #NAME? | AH25: #NAME? | AI25: #NAME? | AJ25: #NAME?
S26: #NAME? | T26: #NAME? | U26: #NAME? | V26: #NAME? | W26: #NAME? | X26: #NAME? | Y26: #NAME? | Z26: #NAME? | AA26: #NAME? | AB26: #NAME? | AC26: #NAME? | AD26: #NAME? | AE26: #NAME? | AF26: #NAME? | AG26: #NAME? | AH26: #NAME? | AI26: #NAME? | AJ26: #NAME?
S27: #NAME? | T27: #NAME? | U27: #NAME? | V27: #NAME? | W27: #NAME? | X27: #NAME? | Y27: #NAME? | Z27: #NAME? | AA27: #NAME? | AB27: #NAME? | AC27: #NAME? | AD27: #NAME? | AE27: #NAME? | AF27: #NAME? | AG27: #NAME? | AH27: #NAME? | AI27: #NAME? | AJ27: #NAME?
S28: #NAME? | T28: #NAME? | U28: #NAME? | V28: #NAME? | W28: #NAME? | X28: #NAME? | Y28: #NAME? | Z28: #NAME? | AA28: #NAME? | AB28: #NAME? | AC28: #NAME? | AD28: #NAME? | AE28: #NAME? | AF28: #NAME? | AG28: #NAME? | AH28: #NAME? | AI28: #NAME? | AJ28: #NAME?
S29: #NAME? | T29: #NAME? | U29: #NAME? | V29: #NAME? | W29: #NAME? | X29: #NAME? | Y29: #NAME? | Z29: #NAME? | AA29: #NAME? | AB29: #NAME? | AC29: #NAME? | AD29: #NAME? | AE29: #NAME? | AF29: #NAME? | AG29: #NAME? | AH29: #NAME? | AI29: #NAME? | AJ29: #NAME?
S30: #NAME? | T30: #NAME? | U30: #NAME? | V30: #NAME? | W30: #NAME? | X30: #NAME? | Y30: #NAME? | Z30: #NAME? | AA30: #NAME? | AB30: #NAME? | AC30: #NAME? | AD30: #NAME? | AE30: #NAME? | AF30: #NAME? | AG30: #NAME? | AH30: #NAME? | AI30: #NAME? | AJ30: #NAME?
S31: #NAME? | T31: #NAME? | U31: #NAME? | V31: #NAME? | W31: #NAME? | X31: #NAME? | Y31: #NAME? | Z31: #NAME? | AA31: #NAME? | AB31: #NAME? | AC31: #NAME? | AD31: #NAME? | AE31: #NAME? | AF31: #NAME? | AG31: #NAME? | AH31: #NAME? | AI31: #NAME? | AJ31: #NAME?
S32: #NAME? | T32: #NAME? | U32: #NAME? | V32: #NAME? | W32: #NAME? | X32: #NAME? | Y32: #NAME? | Z32: #NAME? | AA32: #NAME? | AB32: #NAME? | AC32: #NAME? | AD32: #NAME? | AE32: #NAME? | AF32: #NAME?
S33: #NAME? | T33: #NAME? | U33: #NAME? | V33: #NAME? | W33: #NAME? | X33: #NAME? | Y33: #NAME? | Z33: #NAME? | AA33: #NAME? | AB33: #NAME? | AC33: #NAME? | AD33: #NAME? | AE33: #NAME? | AF33: #NAME?
S34: #NAME? | T34: #NAME? | U34: #NAME? | V34: #NAME? | W34: #NAME? | X34: #NAME? | Y34: #NAME? | Z34: #NAME? | AA34: #NAME? | AB34: #NAME? | AC34: #NAME? | AD34: #NAME? | AE34: #NAME? | AF34: #NAME?
S35: #NAME? | T35: #NAME? | U35: #NAME? | V35: #NAME? | W35: #NAME? | X35: #NAME? | Y35: #NAME? | Z35: #NAME? | AA35: #NAME? | AB35: #NAME? | AC35: #NAME? | AD35: #NAME? | AE35: #NAME? | AF35: #NAME?
S36: #NAME? | T36: #NAME? | U36: #NAME? | V36: #NAME? | W36: #NAME? | X36: #NAME? | Y36: #NAME? | Z36: #NAME? | AA36: #NAME? | AB36: #NAME? | AC36: #NAME? | AD36: #NAME? | AE36: #NAME? | AF36: #NAME?
S37: #NAME? | T37: #NAME? | U37: #NAME? | V37: #NAME? | W37: #NAME? | X37: #NAME? | Y37: #NAME? | Z37: #NAME? | AA37: #NAME? | AB37: #NAME? | AC37: #NAME? | AD37: #NAME? | AE37: #NAME? | AF37: #NAME?
S38: #NAME? | T38: #NAME? | U38: #NAME? | V38: #NAME? | W38: #NAME? | X38: #NAME? | Y38: #NAME? | Z38: #NAME? | AA38: #NAME? | AB38: #NAME? | AC38: #NAME? | AD38: #NAME? | AE38: #NAME? | AF38: #NAME?
S39: #NAME? | T39: #NAME? | U39: #NAME? | V39: #NAME? | W39: #NAME? | X39: #NAME? | Y39: #NAME? | Z39: #NAME? | AA39: #NAME? | AB39: #NAME? | AC39: #NAME? | AD39: #NAME? | AE39: #NAME? | AF39: #NAME?
S40: #NAME? | T40: #NAME? | U40: #NAME? | V40: #NAME? | W40: #NAME? | X40: #NAME? | Y40: #NAME? | Z40: #NAME? | AA40: #NAME? | AB40: #NAME? | AC40: #NAME? | AD40: #NAME? | AE40: #NAME? | AF40: #NAME?
S41: #NAME? | T41: #NAME? | U41: #NAME? | V41: #NAME? | W41: #NAME? | X41: #NAME? | Y41: #NAME? | Z41: #NAME? | AA41: #NAME? | AB41: #NAME? | AC41: #NAME? | AD41: #NAME? | AE41: #NAME? | AF41: #NAME?
S42: #NAME? | T42: #NAME? | U42: #NAME? | V42: #NAME? | W42: #NAME? | X42: #NAME? | Y42: #NAME? | Z42: #NAME? | AA42: #NAME? | AB42: #NAME? | AC42: #NAME? | AD42: #NAME? | AE42: #NAME? | AF42: #NAME?
S43: #NAME? | T43: #NAME? | U43: #NAME? | V43: #NAME? | W43: #NAME? | X43: #NAME? | Y43: #NAME? | Z43: #NAME? | AA43: #NAME? | AB43: #NAME? | AC43: #NAME? | AD43: #NAME? | AE43: #NAME? | AF43: #NAME?
... S451: #NAME? | T451: #NAME? | U451: #NAME? | V451: #NAME? | W451: #NAME? | X451: #NAME? | Y451: #NAME? | Z451: #NAME? | AA451: #NAME? | AB451: #NAME? | AC451: #NAME? | AD451: #NAME? | AE451: #NAME? | AF451: #NAME?
U452: #NAME? | V452: #NAME? | W452: #NAME? | X452: #NAME? | Y452: #NAME? | Z452: #NAME? | AA452: #NAME? | AB452: #NAME? | AC452: #NAME? | AD452: #NAME? | AE452: #NAME? | AF452: #NAME?
U453: #NAME? | V453: #NAME? | W453: #NAME? | X453: #NAME? | Y453: #NAME? | Z453: #NAME? | AA453: #NAME? | AB453: #NAME? | AC453: #NAME? | AD453: #NAME? | AE453: #NAME? | AF453: #NAME?
...

Sheet West
B1: ACE.Profile.1 | D1: ACE.Profile.2 | F1: ACE.Profile.3 | H1: ACE.Profile.4 | J1: ACE.Profile.5 | L1: ACE.Profile.6 | N1: ACE.Profile.7 | P1: ACE.Profile.8 | R1: ACE.Profile.9 | T1: FeedBatch.Port1.tot.2 | V1: FeedBatch.Port2.tot.2 | X1: FeedBatch.Port3.tot.2 | Z1: FeedBatch.Port4.tot.2 | AB1: FeedBatch.Port5.tot.2 | AD1: FeedBatch.Port6.tot.2 | AF1: FeedBatch.Port7.tot.2 | AH1: FeedBatch.Port8.tot.2 | AJ1: FeedBatch.Port9.tot.2
A2: 45089.25 | B2: 7.9381514 | C2: 45089.25 | D2: 9.5888138 | E2: 45089.25 | F2: 15.5372 | G2: 45089.25 | H2: 17.568584 | I2: 45089.25 | J2: 15.645837 | K2: 45089.25 | L2: 15.754207 | M2: 45089.25 | N2: 17.967207 | O2: 45089.25 | P2: 0 | Q2: 45089.25 | R2: 0 | S2: 45088.479 | T2: 16.730621 | U2: 45088.479 | V2: 20.181465 | W2: 45088.479 | X2: 32.846123 | Y2: 45088.479 | Z2: 37.208473 | AA2: 45088.479 | AB2: 33.621475 | AC2: 45088.479 | AD2: 33.723656 | AE2: 45088.479 | AF2: 41.923874 | AG2: 45088.528 | AH2: 0 | AI2: 45088.556 | AJ2: 0
A3: 45089.25 | B3: 8.0764084 | C3: 45089.25 | D3: 10.226711 | E3: 45089.25 | F3: 15.291079 | G3: 45089.25 | H3: 17.460733 | I3: 45089.25 | J3: 15.476195 | K3: 45089.25 | L3: 15.527145 | M3: 45089.25 | N3: 17.941727 | O3: 45089.25 | P3: 0 | Q3: 45089.25 | R3: 0 | S3: 45088.507 | T3: 18.223976 | U3: 45088.507 | V3: 20.93605 | W3: 45088.514 | X3: 35.042793 | Y3: 45088.514 | Z3: 39.696899 | AA3: 45088.514 | AB3: 35.905838 | AC3: 45088.514 | AD3: 36.207504 | AE3: 45088.514 | AF3: 44.769638 | AG3: 45088.861 | AH3: 0 | AI3: 45088.889 | AJ3: 0
A4: 45090.25 | B4: 8.0764084 | C4: 45090.25 | D4: 10.226711 | E4: 45090.25 | F4: 15.291079 | G4: 45090.25 | H4: 17.460733 | I4: 45090.25 | J4: 15.476195 | K4: 45090.25 | L4: 15.527145 | M4: 45090.25 | N4: 17.941727 | O4: 45090.25 | P4: 0 | Q4: 45090.25 | R4: 0 | S4: 45088.528 | T4: 18.749962 | U4: 45088.514 | V4: 21.635841 | W4: 45088.535 | X4: 37.048698 | Y4: 45088.535 | Z4: 41.962448 | AA4: 45088.535 | AB4: 38.091629 | AC4: 45088.535 | AD4: 38.361099 | AE4: 45088.535 | AF4: 46.381042 | AG4: 45089.194 | AH4: 0 | AI4: 45089.222 | AJ4: 0
A5: 45090.25 | B5: 8.6922607 | C5: 45090.25 | D5: 10.67916 | E5: 45090.25 | F5: 15.389266 | G5: 45090.25 | H5: 17.542864 | I5: 45090.25 | J5: 14.988297 | K5: 45090.25 | L5: 15.122135 | M5: 45090.25 | N5: 17.586018 | O5: 45090.25 | P5: 0 | Q5: 45090.25 | R5: 0 | S5: 45088.535 | T5: 20.383553 | U5: 45088.535 | V5: 23.243774 | W5: 45088.556 | X5: 39.392456 | Y5: 45088.556 | Z5: 44.299362 | AA5: 45088.556 | AB5: 40.01889 | AC5: 45088.556 | AD5: 40.728851 | AE5: 45088.556 | AF5: 49.001198 | AG5: 45089.528 | AH5: 0 | AI5: 45089.556 | AJ5: 0
A6: 45091.25 | B6: 8.6922607 | C6: 45091.25 | D6: 10.67916 | E6: 45091.25 | F6: 15.389266 | G6: 45091.25 | H6: 17.542864 | I6: 45091.25 | J6: 14.988297 | K6: 45091.25 | L6: 15.122135 | M6: 45091.25 | N6: 17.586018 | O6: 45091.25 | P6: 0 | Q6: 45091.25 | R6: 0 | S6: 45088.576 | T6: 22.199272 | U6: 45088.556 | V6: 24.298973 | W6: 45088.576 | X6: 41.583755 | Y6: 45088.576 | Z6: 47.000237 | AA6: 45088.576 | AB6: 42.259079 | AC6: 45088.576 | AD6: 42.710167 | AE6: 45088.576 | AF6: 51.649055 | AG6: 45089.861 | AH6: 0 | AI6: 45089.889 | AJ6: 0
A7: 45091.25 | B7: 7.6817746 | C7: 45091.25 | D7: 9.766881 | E7: 45091.25 | F7: 15.694324 | G7: 45091.25 | H7: 17.646484 | I7: 45091.25 | J7: 15.810327 | K7: 45091.25 | L7: 15.624814 | M7: 45091.25 | N7: 17.775394 | O7: 45091.25 | P7: 0 | Q7: 45091.25 | R7: 0 | S7: 45088.618 | T7: 23.9375 | U7: 45088.576 | V7: 25.453491 | W7: 45088.597 | X7: 43.590034 | Y7: 45088.597 | Z7: 49.488518 | AA7: 45088.597 | AB7: 44.645813 | AC7: 45088.597 | AD7: 44.953392 | AE7: 45088.597 | AF7: 53.895554 | AG7: 45090.194 | AH7: 0 | AI7: 45090.222 | AJ7: 0
A8: 45092.25 | B8: 7.6817746 | C8: 45092.25 | D8: 9.766881 | E8: 45092.25 | F8: 15.694324 | G8: 45092.25 | H8: 17.646484 | I8: 45092.25 | J8: 15.810327 | K8: 45092.25 | L8: 15.624814 | M8: 45092.25 | N8: 17.775394 | O8: 45092.25 | P8: 0 | Q8: 45092.25 | R8: 0 | S8: 45088.639 | T8: 25.022385 | U8: 45088.597 | V8: 26.562477 | W8: 45088.618 | X8: 45.553078 | Y8: 45088.618 | Z8: 51.328484 | AA8: 45088.618 | AB8: 46.310349 | AC8: 45088.618 | AD8: 46.562164 | AE8: 45088.618 | AF8: 56.384239 | AG8: 45090.528 | AH8: 0 | AI8: 45090.556 | AJ8: 0
A9: 45092.25 | B9: 7.6931109 | C9: 45092.25 | D9: 9.577858 | E9: 45092.25 | F9: 15.338949 | G9: 45092.25 | H9: 17.667013 | I9: 45092.25 | J9: 15.776491 | K9: 45092.25 | L9: 15.70414 | M9: 45092.25 | N9: 18.242437 | O9: 45092.25 | P9: 0 | Q9: 45092.25 | R9: 0 | S9: 45088.66 | T9: 26.153442 | U9: 45088.618 | V9: 27.936363 | W9: 45088.639 | X9: 47.34127 | Y9: 45088.639 | Z9: 53.383675 | AA9: 45088.639 | AB9: 48.039223 | AC9: 45088.639 | AD9: 48.952492 | AE9: 45088.639 | AF9: 58.917549 | AG9: 45090.861 | AH9: 0 | AI9: 45090.889 | AJ9: 0
A10: 45093.25 | B10: 7.6931109 | C10: 45093.25 | D10: 9.577858 | E10: 45093.25 | F10: 15.338949 | G10: 45093.25 | H10: 17.667013 | I10: 45093.25 | J10: 15.776491 | K10: 45093.25 | L10: 15.70414 | M10: 45093.25 | N10: 18.242437 | O10: 45093.25 | P10: 0 | Q10: 45093.25 | R10: 0 | S10: 45088.681 | T10: 27.480667 | U10: 45088.639 | V10: 29.18055 | W10: 45088.66 | X10: 48.897987 | Y10: 45088.66 | Z10: 55.87178 | AA10: 45088.66 | AB10: 49.644897 | AC10: 45088.66 | AD10: 50.819771 | AE10: 45088.66 | AF10: 60.870804 | AG10: 45091.194 | AH10: 0 | AI10: 45091.222 | AJ10: 0
A11: 45093.25 | B11: 7.8505816 | C11: 45093.25 | D11: 9.8681698 | E11: 45093.25 | F11: 15.343834 | G11: 45093.25 | H11: 17.692968 | I11: 45093.25 | J11: 15.737271 | K11: 45093.25 | L11: 15.498178 | M11: 45093.25 | N11: 18.008997 | O11: 45093.25 | P11: 0 | Q11: 45093.25 | R11: 0 | S11: 45088.722 | T11: 29.231224 | U11: 45088.66 | V11: 30.367638 | W11: 45088.681 | X11: 50.986351 | Y11: 45088.681 | Z11: 57.850212 | AA11: 45088.681 | AB11: 51.941879 | AC11: 45088.681 | AD11: 52.565628 | AE11: 45088.681 | AF11: 63.043137 | AG11: 45091.528 | AH11: 0 | AI11: 45091.556 | AJ11: 0
A12: 45094.25 | B12: 7.8505816 | C12: 45094.25 | D12: 9.8681698 | E12: 45094.25 | F12: 15.343834 | G12: 45094.25 | H12: 17.692968 | I12: 45094.25 | J12: 15.737271 | K12: 45094.25 | L12: 15.498178 | M12: 45094.25 | N12: 18.008997 | O12: 45094.25 | P12: 0 | Q12: 45094.25 | R12: 0 | S12: 45088.764 | T12: 31.294792 | U12: 45088.681 | V12: 31.666115 | W12: 45088.701 | X12: 53.072655 | Y12: 45088.701 | Z12: 60.058693 | AA12: 45088.701 | AB12: 53.680069 | AC12: 45088.701 | AD12: 54.883362 | AE12: 45088.701 | AF12: 64.762115 | AG12: 45091.861 | AH12: 0 | AI12: 45091.889 | AJ12: 0
A13: 45094.25 | B13: 7.849288 | C13: 45094.25 | D13: 9.8433609 | E13: 45094.25 | F13: 15.586185 | G13: 45094.25 | H13: 17.599361 | I13: 45094.25 | J13: 15.544608 | K13: 45094.25 | L13: 15.521418 | M13: 45094.25 | N13: 18.055779 | O13: 45094.25 | P13: 0 | Q13: 45094.25 | R13: 0 | S13: 45088.806 | T13: 33.065376 | U13: 45088.701 | V13: 32.36982 | W13: 45088.722 | X13: 55.005981 | Y13: 45088.722 | Z13: 62.405891 | AA13: 45088.722 | AB13: 55.691811 | AC13: 45088.722 | AD13: 56.555328 | AE13: 45088.722 | AF13: 66.944626 | AG13: 45092.194 | AH13: 0 | AI13: 45092.222 | AJ13: 0
... A21: 45098.25 | B21: 7.6532097 | C21: 45098.25 | D21: 9.638298 | E21: 45098.25 | F21: 15.600675 | G21: 45098.25 | H21: 17.580486 | I21: 45098.25 | J21: 15.597288 | K21: 45098.25 | L21: 15.470716 | M21: 45098.25 | N21: 18.126566 | O21: 45098.25 | P21: 0 | Q21: 45098.25 | R21: 0 | S21: 45088.993 | T21: 48.138023 | U21: 45088.868 | V21: 44.472244 | W21: 45088.889 | X21: 74.814468 | Y21: 45088.889 | Z21: 84.943748 | AA21: 45088.889 | AB21: 76.203873 | AC21: 45088.889 | AD21: 77.097206 | AE21: 45088.868 | AF21: 83.775276 | AG21: 45094.861 | AH21: 0 | AI21: 45094.889 | AJ21: 0
S22: 45089.014 | T22: 49.724342 | U22: 45088.889 | V22: 46.79277 | W22: 45088.91 | X22: 78.460297 | Y22: 45088.91 | Z22: 88.657211 | AA22: 45088.91 | AB22: 79.508621 | AC22: 45088.91 | AD22: 80.637802 | AE22: 45088.889 | AF22: 88.003189 | AG22: 45095.194 | AH22: 0 | AI22: 45095.222 | AJ22: 0
S23: 45089.035 | T23: 51.68412 | U23: 45088.91 | V23: 48.947647 | W23: 45088.931 | X23: 81.899559 | Y23: 45088.931 | Z23: 92.690331 | AA23: 45088.931 | AB23: 83.180557 | AC23: 45088.931 | AD23: 83.72805 | AE23: 45088.91 | AF23: 92.174187 | AG23: 45095.528 | AH23: 0 | AI23: 45095.556 | AJ23: 0
S24: 45089.056 | T24: 53.731575 | U24: 45088.931 | V24: 50.915977 | W24: 45088.951 | X24: 85.398102 | Y24: 45088.951 | Z24: 96.680344 | AA24: 45088.951 | AB24: 86.359818 | AC24: 45088.951 | AD24: 87.363998 | AE24: 45088.931 | AF24: 95.989395 | AG24: 45095.861 | AH24: 0 | AI24: 45095.889 | AJ24: 0
S25: 45089.076 | T25: 54.848015 | U25: 45088.951 | V25: 53.000526 | W25: 45088.972 | X25: 88.493073 | Y25: 45088.972 | Z25: 100.46809 | AA25: 45088.972 | AB25: 89.723145 | AC25: 45088.972 | AD25: 91.175789 | AE25: 45088.951 | AF25: 100.14001 | AG25: 45096.194 | AH25: 0 | AI25: 45096.222 | AJ25: 0
S26: 45089.097 | T26: 56.740822 | U26: 45088.972 | V26: 55.282143 | W26: 45088.993 | X26: 92.008736 | Y26: 45088.993 | Z26: 104.47349 | AA26: 45088.993 | AB26: 93.599731 | AC26: 45088.993 | AD26: 94.128395 | AE26: 45088.972 | AF26: 103.81705 | AG26: 45096.528 | AH26: 0 | AI26: 45096.556 | AJ26: 0
S27: 45089.118 | T27: 58.520821 | U27: 45088.993 | V27: 57.061707 | W27: 45089.014 | X27: 95.803131 | Y27: 45089.014 | Z27: 108.50863 | AA27: 45089.014 | AB27: 96.880249 | AC27: 45089.014 | AD27: 97.934067 | AE27: 45088.993 | AF27: 107.46135 | AG27: 45096.861 | AH27: 0 | AI27: 45096.889 | AJ27: 0
S28: 45089.139 | T28: 60.240929 | U28: 45089.014 | V28: 59.385849 | W28: 45089.035 | X28: 99.312241 | Y28: 45089.035 | Z28: 112.13629 | AA28: 45089.035 | AB28: 100.56706 | AC28: 45089.035 | AD28: 101.30936 | AE28: 45089.014 | AF28: 111.14062 | AG28: 45097.194 | AH28: 0 | AI28: 45097.222 | AJ28: 0
S29: 45089.16 | T29: 62.021477 | U29: 45089.035 | V29: 61.795448 | W29: 45089.056 | X29: 102.85851 | Y29: 45089.056 | Z29: 116.17491 | AA29: 45089.056 | AB29: 103.93062 | AC29: 45089.056 | AD29: 104.95555 | AE29: 45089.035 | AF29: 115.63039 | AG29: 45097.528 | AH29: 0 | AI29: 45097.556 | AJ29: 0
S30: 45089.181 | T30: 63.764359 | U30: 45089.056 | V30: 63.657707 | W30: 45089.076 | X30: 106.34648 | Y30: 45089.076 | Z30: 120.41755 | AA30: 45089.076 | AB30: 106.98064 | AC30: 45089.076 | AD30: 108.6101 | AE30: 45089.056 | AF30: 119.41061 | AG30: 45097.861 | AH30: 0 | AI30: 45097.889 | AJ30: 0
S31: 45089.201 | T31: 65.729996 | U31: 45089.076 | V31: 65.872337 | W31: 45089.097 | X31: 109.9243 | Y31: 45089.097 | Z31: 124.34664 | AA31: 45089.097 | AB31: 110.842 | AC31: 45089.097 | AD31: 111.72328 | AE31: 45089.076 | AF31: 122.94667 | AG31: 45098.194 | AH31: 0 | AI31: 45098.222 | AJ31: 0
S32: 45089.222 | T32: 67.133362 | U32: 45089.097 | V32: 68.40564 | W32: 45089.118 | X32: 113.32055 | Y32: 45089.118 | Z32: 128.42009 | AA32: 45089.118 | AB32: 114.6199 | AC32: 45089.118 | AD32: 115.48561 | AE32: 45089.097 | AF32: 126.81697
S33: 45089.243 | T33: 69.10376 | U33: 45089.118 | V33: 69.961395 | W33: 45089.139 | X33: 116.98476 | Y33: 45089.139 | Z33: 132.65039 | AA33: 45089.139 | AB33: 117.81609 | AC33: 45089.139 | AD33: 119.13833 | AE33: 45089.104 | AF33: 127.52854
S34: 45089.257 | T34: 0 | U34: 45089.139 | V34: 72.754356 | W34: 45089.16 | X34: 120.62525 | Y34: 45089.16 | Z34: 136.72368 | AA34: 45089.16 | AB34: 121.52437 | AC34: 45089.16 | AD34: 122.75523 | AE34: 45089.118 | AF34: 131.30615
S35: 45089.264 | T35: 1.7429199 | U35: 45089.16 | V35: 74.760017 | W35: 45089.181 | X35: 124.07169 | Y35: 45089.181 | Z35: 140.70081 | AA35: 45089.181 | AB35: 125.15401 | AC35: 45089.181 | AD35: 126.00493 | AE35: 45089.139 | AF35: 134.45937
S36: 45089.299 | T36: 3.0761414 | U36: 45089.181 | V36: 76.83445 | W36: 45089.201 | X36: 127.68924 | Y36: 45089.201 | Z36: 144.67587 | AA36: 45089.201 | AB36: 128.67763 | AC36: 45089.201 | AD36: 129.74881 | AE36: 45089.146 | AF36: 135.47644
S37: 45089.319 | T37: 5.0921173 | U37: 45089.201 | V37: 78.746437 | W37: 45089.222 | X37: 131.39891 | Y37: 45089.222 | Z37: 148.57843 | AA37: 45089.222 | AB37: 132.31766 | AC37: 45089.222 | AD37: 133.23415 | AE37: 45089.16 | AF37: 139.79616
S38: 45089.34 | T38: 6.8158875 | U38: 45089.222 | V38: 81.093102 | W38: 45089.243 | X38: 134.52055 | Y38: 45089.243 | Z38: 152.42041 | AA38: 45089.243 | AB38: 135.60013 | AC38: 45089.243 | AD38: 136.87585 | AE38: 45089.181 | AF38: 143.54327
S39: 45089.361 | T39: 8.5504379 | U39: 45089.243 | V39: 83.440865 | W39: 45089.257 | X39: 0 | Y39: 45089.257 | Z39: 0 | AA39: 45089.257 | AB39: 0 | AC39: 45089.257 | AD39: 0 | AE39: 45089.201 | AF39: 147.88931
S40: 45089.382 | T40: 10.251732 | U40: 45089.257 | V40: 0 | W40: 45089.264 | X40: 3.9291 | Y40: 45089.264 | Z40: 3.8965759 | AA40: 45089.264 | AB40: 4.0613937 | AC40: 45089.264 | AD40: 3.7097931 | AE40: 45089.222 | AF40: 151.94962
S41: 45089.403 | T41: 11.901009 | U41: 45089.264 | V41: 2.2178955 | W41: 45089.299 | X41: 7.5326462 | Y41: 45089.299 | Z41: 7.8139191 | AA41: 45089.299 | AB41: 6.3595047 | AC41: 45089.306 | AD41: 7.3449326 | AE41: 45089.243 | AF41: 155.99216
S42: 45089.431 | T42: 14.20948 | U42: 45089.299 | V42: 4.2753448 | W42: 45089.319 | X42: 11.126343 | Y42: 45089.319 | Z42: 11.642906 | AA42: 45089.306 | AB42: 7.5965881 | AC42: 45089.326 | AD42: 11.074707 | AE42: 45089.257 | AF42: 0
S43: 45089.451 | T43: 16.153725 | U43: 45089.319 | V43: 6.7217865 | W43: 45089.34 | X43: 14.852119 | Y43: 45089.34 | Z43: 16.023872 | AA43: 45089.319 | AB43: 9.6611023 | AC43: 45089.347 | AD43: 14.483704 | AE43: 45089.264 | AF43: 4.3577881
... S451: 45098.451 | T451: 15.492317 | U451: 45098.056 | V451: 65.849251 | W451: 45097.069 | X451: 116.24971 | Y451: 45097.049 | Z451: 125.85719 | AA451: 45097.618 | AB451: 50.929321 | AC451: 45097.514 | AD451: 38.3871 | AE451: 45097.75 | AF451: 76.562096
U452: 45098.09 | V452: 68.228485 | W452: 45097.09 | X452: 119.62372 | Y452: 45097.056 | Z452: 126.9496 | AA452: 45097.646 | AB452: 53.314804 | AC452: 45097.535 | AD452: 40.324593 | AE452: 45097.771 | AF452: 79.889519
